Workbook

Sheet Cover Page
A1: Code | B1: SYB_16_3
A2: Version | B2: V1
A3: اسم القالب | B3: أعداد الصحف والمجلات والدوريات
A4: Template Name | B4: Number of Newspapers, Magazines and Periodicals
A5: دورية البيانات | B5: سنوي
A6: Data Frequency | B6: Yearly
A7: الجهة المصدرية | B7: هيئة الإعلام
A8: Data Source | B8: Media Commission

Sheet Source Table
B2: ='Cover Page'!B4 -> Number of Newspapers, Magazines and Periodicals
B3: ='Cover Page'!B3 -> أعداد الصحف والمجلات والدوريات
B4: Year | F4: =YEAR('Template Data'!B1) -> 2024 | K4: السنة
B5: Publications | C5: نصف شهرية | D5: نصف سنوية | E5: كل شهرين | F5: سنوية | G5: فصلية | H5: شهرية | I5: أسبوعية | J5: يومية | K5: النشرات
C6: Mid Monthly | D6: Mid year | E6: Every two months | F6: Yearly | G6: Seasonal | H6: Monthly | I6: Weekly | J6: Daily
B7: Political Newspapers | K7: صحف سياسية
B8: Parties Newspapers | K8: صحف حزبية
B9: Children Magazines & Periodicals | K9: المجلات والدوريات الأطفال
B10: Economic Magazines & Periodicals | K10: المجلات والدوريات الاقتصادية
B11: Army & Police Magazines & Periodicals | K11: المجلات والدوريات العسكرية و شرطية
B12: Youths & Arts Magazines & Periodicals | K12: المجلات والدوريات الشباب و الفنون
B13: Cultural & Educational Magazines & Periodicals | K13: المجلات والدوريات الثقافية و المدرسية
B14: Religious Magazines & Periodicals | K14: المجلات والدوريات الدينية
B15: Scientific Magazines & Periodicals | K15: المجلات والدوريات العلمية
B16: Financial Magazines & Periodicals | K16: المجلات والدوريات المالية
B17: Tourist Magazines & Periodicals | K17: المجلات والدوريات سياحية
B18: Other Magazines & Periodicals | K18: المجلات والدوريات أخرى

Sheet Relational DB
A1: Relational Sheet
A2: Measure_Name_Ar | B2: Measure_Name_En | C2: Measure_ID | D2: Unit_EN | E2: Unit_AR | F2: CL_PUBLICATION_EN_V1 | G2: CL_PUBLICATION_AR_V1 | H2: CL_PERIOD_EN_V1 | I2: CL_PERIOD_AR_V1 | J2: Obs_Value | K2: Time_Period_Y | L2: Time_Period_M
A3: اسم المؤشر | B3: Measure Name | C3: رمز المؤشر | D3: Unit | E3: الوحدة | F3: Publications | G3: النشرات | H3: Period | I3: الفترة | J3: قيمة المؤشر | K3: سنة فترة القياس | L3: شهر فترة القياس
A4: أعداد الصحف والمجلات والدوريات | B4: Number of Newspapers, Magazines and Periodicals | C4: M1 | D4: Number | E4: عدد | F4: ='Source Table'!$B$7 -> Political Newspapers | G4: ='Source Table'!$K$7 -> صحف سياسية | H4: ='Source Table'!$J$6 -> Daily | I4: ='Source Table'!$J$5 -> يومية | J4: 10 | K4: 2023
A5: أعداد الصحف والمجلات والدوريات | B5: Number of Newspapers, Magazines and Periodicals | C5: M1 | D5: Number | E5: عدد | F5: ='Source Table'!$B$8 -> Parties Newspapers | G5: ='Source Table'!$K$8 -> صحف حزبية | H5: ='Source Table'!$J$6 -> Daily | I5: ='Source Table'!$J$5 -> يومية | J5: 0 | K5: 2023
A6: أعداد الصحف والمجلات والدوريات | B6: Number of Newspapers, Magazines and Periodicals | C6: M1 | D6: Number | E6: عدد | F6: ='Source Table'!$B$9 -> Children Magazines & Periodicals | G6: ='Source Table'!$K$9 -> المجلات والدوريات الأطفال | H6: ='Source Table'!$J$6 -> Daily | I6: ='Source Table'!$J$5 -> يومية | J6: 0 | K6: 2023
A7: أعداد الصحف والمجلات والدوريات | B7: Number of Newspapers, Magazines and Periodicals | C7: M1 | D7: Number | E7: عدد | F7: ='Source Table'!$B$10 -> Economic Magazines & Periodicals | G7: ='Source Table'!$K$10 -> المجلات والدوريات الاقتصادية | H7: ='Source Table'!$J$6 -> Daily | I7: ='Source Table'!$J$5 -> يومية | J7: 0 | K7: 2023
A8: أعداد الصحف والمجلات والدوريات | B8: Number of Newspapers, Magazines and Periodicals | C8: M1 | D8: Number | E8: عدد | F8: ='Source Table'!$B$11 -> Army & Police Magazines & Periodicals | G8: ='Source Table'!$K$11 -> المجلات والدوريات العسكرية و شرطية | H8: ='Source Table'!$J$6 -> Daily | I8: ='Source Table'!$J$5 -> يومية | J8: 0 | K8: 2023
A9: أعداد الصحف والمجلات والدوريات | B9: Number of Newspapers, Magazines and Periodicals | C9: M1 | D9: Number | E9: عدد | F9: ='Source Table'!$B$12 -> Youths & Arts Magazines & Periodicals | G9: ='Source Table'!$K$12 -> المجلات والدوريات الشباب و الفنون | H9: ='Source Table'!$J$6 -> Daily | I9: ='Source Table'!$J$5 -> يومية | J9: 0 | K9: 2023
A10: أعداد الصحف والمجلات والدوريات | B10: Number of Newspapers, Magazines and Periodicals | C10: M1 | D10: Number | E10: عدد | F10: ='Source Table'!$B$13 -> Cultural & Educational Magazines & Periodicals | G10: ='Source Table'!$K$13 -> المجلات والدوريات الثقافية و المدرسية | H10: ='Source Table'!$J$6 -> Daily | I10: ='Source Table'!$J$5 -> يومية | J10: 0 | K10: 2023
A11: أعداد الصحف والمجلات والدوريات | B11: Number of Newspapers, Magazines and Periodicals | C11: M1 | D11: Number | E11: عدد | F11: ='Source Table'!$B$14 -> Religious Magazines & Periodicals | G11: ='Source Table'!$K$14 -> المجلات والدوريات الدينية | H11: ='Source Table'!$J$6 -> Daily | I11: ='Source Table'!$J$5 -> يومية | J11: 0 | K11: 2023
A12: أعداد الصحف والمجلات والدوريات | B12: Number of Newspapers, Magazines and Periodicals | C12: M1 | D12: Number | E12: عدد | F12: ='Source Table'!$B$15 -> Scientific Magazines & Periodicals | G12: ='Source Table'!$K$15 -> المجلات والدوريات العلمية | H12: ='Source Table'!$J$6 -> Daily | I12: ='Source Table'!$J$5 -> يومية | J12: 0 | K12: 2023
A13: أعداد الصحف والمجلات والدوريات | B13: Number of Newspapers, Magazines and Periodicals | C13: M1 | D13: Number | E13: عدد | F13: ='Source Table'!$B$16 -> Financial Magazines & Periodicals | G13: ='Source Table'!$K$16 -> المجلات والدوريات المالية | H13: ='Source Table'!$J$6 -> Daily | I13: ='Source Table'!$J$5 -> يومية | J13: 0 | K13: 2023
A14: أعداد الصحف والمجلات والدوريات | B14: Number of Newspapers, Magazines and Periodicals | C14: M1 | D14: Number | E14: عدد | F14: ='Source Table'!$B$17 -> Tourist Magazines & Periodicals | G14: ='Source Table'!$K$17 -> المجلات والدوريات سياحية | H14: ='Source Table'!$J$6 -> Daily | I14: ='Source Table'!$J$5 -> يومية | J14: 0 | K14: 2023
A15: أعداد الصحف والمجلات والدوريات | B15: Number of Newspapers, Magazines and Periodicals | C15: M1 | D15: Number | E15: عدد | F15: ='Source Table'!$B$18 -> Other Magazines & Periodicals | G15: ='Source Table'!$K$18 -> المجلات والدوريات أخرى | H15: ='Source Table'!$J$6 -> Daily | I15: ='Source Table'!$J$5 -> يومية | J15: 0 | K15: 2023
A16: أعداد الصحف والمجلات والدوريات | B16: Number of Newspapers, Magazines and Periodicals | C16: M1 | D16: Number | E16: عدد | F16: ='Source Table'!$B$7 -> Political Newspapers | G16: ='Source Table'!$K$7 -> صحف سياسية | H16: ='Source Table'!$I$6 -> Weekly | I16: ='Source Table'!$I$5 -> أسبوعية | J16: 6 | K16: 2023
A17: أعداد الصحف والمجلات والدوريات | B17: Number of Newspapers, Magazines and Periodicals | C17: M1 | D17: Number | E17: عدد | F17: ='Source Table'!$B$8 -> Parties Newspapers | G17: ='Source Table'!$K$8 -> صحف حزبية | H17: ='Source Table'!$I$6 -> Weekly | I17: ='Source Table'!$I$5 -> أسبوعية | J17: 1 | K17: 2023
A18: أعداد الصحف والمجلات والدوريات | B18: Number of Newspapers, Magazines and Periodicals | C18: M1 | D18: Number | E18: عدد | F18: ='Source Table'!$B$9 -> Children Magazines & Periodicals | G18: ='Source Table'!$K$9 -> المجلات والدوريات الأطفال | H18: ='Source Table'!$I$6 -> Weekly | I18: ='Source Table'!$I$5 -> أسبوعية | J18: 0 | K18: 2023
A19: أعداد الصحف والمجلات والدوريات | B19: Number of Newspapers, Magazines and Periodicals | C19: M1 | D19: Number | E19: عدد | F19: ='Source Table'!$B$10 -> Economic Magazines & Periodicals | G19: ='Source Table'!$K$10 -> المجلات والدوريات الاقتصادية | H19: ='Source Table'!$I$6 -> Weekly | I19: ='Source Table'!$I$5 -> أسبوعية | J19: 0 | K19: 2023
A20: أعداد الصحف والمجلات والدوريات | B20: Number of Newspapers, Magazines and Periodicals | C20: M1 | D20: Number | E20: عدد | F20: ='Source Table'!$B$11 -> Army & Police Magazines & Periodicals | G20: ='Source Table'!$K$11 -> المجلات والدوريات العسكرية و شرطية | H20: ='Source Table'!$I$6 -> Weekly | I20: ='Source Table'!$I$5 -> أسبوعية | J20: 0 | K20: 2023
A21: أعداد الصحف والمجلات والدوريات | B21: Number of Newspapers, Magazines and Periodicals | C21: M1 | D21: Number | E21: عدد | F21: ='Source Table'!$B$12 -> Youths & Arts Magazines & Periodicals | G21: ='Source Table'!$K$12 -> المجلات والدوريات الشباب و الفنون | H21: ='Source Table'!$I$6 -> Weekly | I21: ='Source Table'!$I$5 -> أسبوعية | J21: 1 | K21: 2023
A22: أعداد الصحف والمجلات والدوريات | B22: Number of Newspapers, Magazines and Periodicals | C22: M1 | D22: Number | E22: عدد | F22: ='Source Table'!$B$13 -> Cultural & Educational Magazines & Periodicals | G22: ='Source Table'!$K$13 -> المجلات والدوريات الثقافية و المدرسية | H22: ='Source Table'!$I$6 -> Weekly | I22: ='Source Table'!$I$5 -> أسبوعية | J22: 0 | K22: 2023
A23: أعداد الصحف والمجلات والدوريات | B23: Number of Newspapers, Magazines and Periodicals | C23: M1 | D23: Number | E23: عدد | F23: ='Source Table'!$B$14 -> Religious Magazines & Periodicals | G23: ='Source Table'!$K$14 -> المجلات والدوريات الدينية | H23: ='Source Table'!$I$6 -> Weekly | I23: ='Source Table'!$I$5 -> أسبوعية | J23: 0 | K23: 2023
A24: أعداد الصحف والمجلات والدوريات | B24: Number of Newspapers, Magazines and Periodicals | C24: M1 | D24: Number | E24: عدد | F24: ='Source Table'!$B$15 -> Scientific Magazines & Periodicals | G24: ='Source Table'!$K$15 -> المجلات والدوريات العلمية | H24: ='Source Table'!$I$6 -> Weekly | I24: ='Source Table'!$I$5 -> أسبوعية | J24: 0 | K24: 2023
A25: أعداد الصحف والمجلات والدوريات | B25: Number of Newspapers, Magazines and Periodicals | C25: M1 | D25: Number | E25: عدد | F25: ='Source Table'!$B$16 -> Financial Magazines & Periodicals | G25: ='Source Table'!$K$16 -> المجلات والدوريات المالية | H25: ='Source Table'!$I$6 -> Weekly | I25: ='Source Table'!$I$5 -> أسبوعية | J25: 0 | K25: 2023
A26: أعداد الصحف والمجلات والدوريات | B26: Number of Newspapers, Magazines and Periodicals | C26: M1 | D26: Number | E26: عدد | F26: ='Source Table'!$B$17 -> Tourist Magazines & Periodicals | G26: ='Source Table'!$K$17 -> المجلات والدوريات سياحية | H26: ='Source Table'!$I$6 -> Weekly | I26: ='Source Table'!$I$5 -> أسبوعية | J26: 1 | K26: 2023
A27: أعداد الصحف والمجلات والدوريات | B27: Number of Newspapers, Magazines and Periodicals | C27: M1 | D27: Number | E27: عدد | F27: ='Source Table'!$B$18 -> Other Magazines & Periodicals | G27: ='Source Table'!$K$18 -> المجلات والدوريات أخرى | H27: ='Source Table'!$I$6 -> Weekly | I27: ='Source Table'!$I$5 -> أسبوعية | J27: 2 | K27: 2023
A28: أعداد الصحف والمجلات والدوريات | B28: Number of Newspapers, Magazines and Periodicals | C28: M1 | D28: Number | E28: عدد | F28: ='Source Table'!$B$7 -> Political Newspapers | G28: ='Source Table'!$K$7 -> صحف سياسية | H28: ='Source Table'!$H$6 -> Monthly | I28: ='Source Table'!$H$5 -> شهرية | J28: 2 | K28: 2023
A29: أعداد الصحف والمجلات والدوريات | B29: Number of Newspapers, Magazines and Periodicals | C29: M1 | D29: Number | E29: عدد | F29: ='Source Table'!$B$8 -> Parties Newspapers | G29: ='Source Table'!$K$8 -> صحف حزبية | H29: ='Source Table'!$H$6 -> Monthly | I29: ='Source Table'!$H$5 -> شهرية | J29: 0 | K29: 2023
A30: أعداد الصحف والمجلات والدوريات | B30: Number of Newspapers, Magazines and Periodicals | C30: M1 | D30: Number | E30: عدد | F30: ='Source Table'!$B$9 -> Children Magazines & Periodicals | G30: ='Source Table'!$K$9 -> المجلات والدوريات الأطفال | H30: ='Source Table'!$H$6 -> Monthly | I30: ='Source Table'!$H$5 -> شهرية | J30: 1 | K30: 2023
A31: أعداد الصحف والمجلات والدوريات | B31: Number of Newspapers, Magazines and Periodicals | C31: M1 | D31: Number | E31: عدد | F31: ='Source Table'!$B$10 -> Economic Magazines & Periodicals | G31: ='Source Table'!$K$10 -> المجلات والدوريات الاقتصادية | H31: ='Source Table'!$H$6 -> Monthly | I31: ='Source Table'!$H$5 -> شهرية | J31: 2 | K31: 2023
A32: أعداد الصحف والمجلات والدوريات | B32: Number of Newspapers, Magazines and Periodicals | C32: M1 | D32: Number | E32: عدد | F32: ='Source Table'!$B$11 -> Army & Police Magazines & Periodicals | G32: ='Source Table'!$K$11 -> المجلات والدوريات العسكرية و شرطية | H32: ='Source Table'!$H$6 -> Monthly | I32: ='Source Table'!$H$5 -> شهرية | J32: 0 | K32: 2023
A33: أعداد الصحف والمجلات والدوريات | B33: Number of Newspapers, Magazines and Periodicals | C33: M1 | D33: Number | E33: عدد | F33: ='Source Table'!$B$12 -> Youths & Arts Magazines & Periodicals | G33: ='Source Table'!$K$12 -> المجلات والدوريات الشباب و الفنون | H33: ='Source Table'!$H$6 -> Monthly | I33: ='Source Table'!$H$5 -> شهرية | J33: 0 | K33: 2023
A34: أعداد الصحف والمجلات والدوريات | B34: Number of Newspapers, Magazines and Periodicals | C34: M1 | D34: Number | E34: عدد | F34: ='Source Table'!$B$13 -> Cultural & Educational Magazines & Periodicals | G34: ='Source Table'!$K$13 -> المجلات والدوريات الثقافية و المدرسية | H34: ='Source Table'!$H$6 -> Monthly | I34: ='Source Table'!$H$5 -> شهرية | J34: 0 | K34: 2023
A35: أعداد الصحف والمجلات والدوريات | B35: Number of Newspapers, Magazines and Periodicals | C35: M1 | D35: Number | E35: عدد | F35: ='Source Table'!$B$14 -> Religious Magazines & Periodicals | G35: ='Source Table'!$K$14 -> المجلات والدوريات الدينية | H35: ='Source Table'!$H$6 -> Monthly | I35: ='Source Table'!$H$5 -> شهرية | J35: 0 | K35: 2023
A36: أعداد الصحف والمجلات والدوريات | B36: Number of Newspapers, Magazines and Periodicals | C36: M1 | D36: Number | E36: عدد | F36: ='Source Table'!$B$15 -> Scientific Magazines & Periodicals | G36: ='Source Table'!$K$15 -> المجلات والدوريات العلمية | H36: ='Source Table'!$H$6 -> Monthly | I36: ='Source Table'!$H$5 -> شهرية | J36: 1 | K36: 2023
A37: أعداد الصحف والمجلات والدوريات | B37: Number of Newspapers, Magazines and Periodicals | C37: M1 | D37: Number | E37: عدد | F37: ='Source Table'!$B$16 -> Financial Magazines & Periodicals | G37: ='Source Table'!$K$16 -> المجلات والدوريات المالية | H37: ='Source Table'!$H$6 -> Monthly | I37: ='Source Table'!$H$5 -> شهرية | J37: 0 | K37: 2023
A38: أعداد الصحف والمجلات والدوريات | B38: Number of Newspapers, Magazines and Periodicals | C38: M1 | D38: Number | E38: عدد | F38: ='Source Table'!$B$17 -> Tourist Magazines & Periodicals | G38: ='Source Table'!$K$17 -> المجلات والدوريات سياحية | H38: ='Source Table'!$H$6 -> Monthly | I38: ='Source Table'!$H$5 -> شهرية | J38: 0 | K38: 2023
A39: أعداد الصحف والمجلات والدوريات | B39: Number of Newspapers, Magazines and Periodicals | C39: M1 | D39: Number | E39: عدد | F39: ='Source Table'!$B$18 -> Other Magazines & Periodicals | G39: ='Source Table'!$K$18 -> المجلات والدوريات أخرى | H39: ='Source Table'!$H$6 -> Monthly | I39: ='Source Table'!$H$5 -> شهرية | J39: 5 | K39: 2023
A40: أعداد الصحف والمجلات والدوريات | B40: Number of Newspapers, Magazines and Periodicals | C40: M1 | D40: Number | E40: عدد | F40: ='Source Table'!$B$7 -> Political Newspapers | G40: ='Source Table'!$K$7 -> صحف سياسية | I40: ='Source Table'!$G$5 -> فصلية | J40: 0 | K40: 2023
...

Sheet Template Data
A1: Date | B1: =DATE(B2,B3,1) -> 45292
A2: Year | B2: 2024
A3: Month | B3: 1
A4: Measure_Name_Ar | B4: Measure_Name_En | C4: Measure_ID | D4: Unit_EN | E4: Unit_AR | F4: CL_PUBLICATION_EN_V1 | G4: CL_PUBLICATION_AR_V1 | H4: CL_PERIOD_EN_V1 | I4: CL_PERIOD_AR_V1 | J4: Obs_Value | K4: Time_Period_Y | L4: Time_Period_M
A5: اسم المؤشر | B5: Measure Name | C5: رمز المؤشر | D5: Unit | E5: الوحدة | F5: Publications | G5: النشرات | H5: Period | I5: الفترة | J5: قيمة المؤشر | K5: سنة فترة القياس | L5: شهر فترة القياس

Sheet Help
A2: Step 1: Cover Page | C2: الخطوة 1: Cover Page
A4: Update the template information, to ensure that any meta-information about the template, such as the title, version, and description, is accurate and up-to-date. | C4: قم بتحديث معلومات القالب للتأكد من أن أي معلومات وصفية حول القالب، مثل العنوان والإصدار والوصف، دقيقة ومحدثة.
A6: Step 2: Source Table | C6: الخطوة 2: Source Table
A8: Design your template, ensuring that the time period is mapped correctly to the date information in rows 1-3 of the Template Data Sheet. | C8: قم بتصميم القالب الخاص بك، مع التأكد من أن فترة الوقت مرتبطة بشكل صحيح مع معلومات التاريخ في الصفوف 1-3 في ورقة Template Data.
A10: Step 3: Relational Sheet | C10: الخطوة 3: Relational Sheet
A12: Unpivot the data in the source table into a flat format. Follow these guidelines: | C12: قم بتحويل البيانات في جدول المصدر إلى تنسيق مسطح. اتبع هذه الإرشادات:
A13: 1. Blue Columns: Do not change the names of the blue columns. Update the data as per the current template. | C13: 1. الأعمدة الزرقاء: لا تقم بتغيير أسماء الأعمدة الزرقاء. قم بتحديث البيانات وفقًا للقالب الحالي.
A14: 2. Code Lists: Use the naming convention CL_XXX_EN_V# for code lists, where XXX is the name, and V# is the version, conforming with the definitions in the data dictionary. | C14: 2. قوائم الرموز: استخدم قاعدة التسمية CL_XXX_EN_V# لقوائم الرموز، حيث أن XXX هو الاسم و V# هو الإصدار، وفقًا للتعريفات في قاموس البيانات.
A15: 3. Code List Values: Ensure the code list values match the definitions in the data dictionary. | C15: 3. قيم قائمة الرموز: تأكد من أن قيم قائمة الرموز تتوافق مع التعريفات في قاموس البيانات.
A16: 4. Time_Period_M: Leave empty if the data frequency is yearly. | C16: 4. Time_Period_M: اتركها فارغة إذا كانت دورية البيانات سنوية.
A17: 5. Time_Period_M Format: Use one of these formats: | C17: 5. تنسيق Time_Period_M: استخدم أحد التنسيقات التالية:
A18: Numeric: (1, 2, 3, ..., 12) for months. | C18: رقمي: (1، 2، 3، ...، 12) للأشهر.
... A38: Protect the entire workbook to prevent unauthorized or accidental changes to the structure of the file. | C38: قم بحماية الكتاب بأكمله لمنع التغييرات غير المصرح بها أو غير المقصودة على هيكل الملف.

Sheet Sheet1
A1: أعداد الصحف والمجلات والدوريات | B1: Number of Newspapers, Magazines and Periodicals | C1: M1 | D1: Number | E1: عدد | F1: ='Source Table'!$B$7 -> Political Newspapers | G1: ='Source Table'!$K$7 -> صحف سياسية | H1: ='Source Table'!$J$6 -> Daily | I1: ='Source Table'!$J$5 -> يومية | J1: 10 | K1: 2023
A2: أعداد الصحف والمجلات والدوريات | B2: Number of Newspapers, Magazines and Periodicals | C2: M1 | D2: Number | E2: عدد | F2: ='Source Table'!$B$8 -> Parties Newspapers | G2: ='Source Table'!$K$8 -> صحف حزبية | H2: ='Source Table'!$J$6 -> Daily | I2: ='Source Table'!$J$5 -> يومية | J2: 0 | K2: 2023
A3: أعداد الصحف والمجلات والدوريات | B3: Number of Newspapers, Magazines and Periodicals | C3: M1 | D3: Number | E3: عدد | F3: ='Source Table'!$B$9 -> Children Magazines & Periodicals | G3: ='Source Table'!$K$9 -> المجلات والدوريات الأطفال | H3: ='Source Table'!$J$6 -> Daily | I3: ='Source Table'!$J$5 -> يومية | J3: 0 | K3: 2023
A4: أعداد الصحف والمجلات والدوريات | B4: Number of Newspapers, Magazines and Periodicals | C4: M1 | D4: Number | E4: عدد | F4: ='Source Table'!$B$10 -> Economic Magazines & Periodicals | G4: ='Source Table'!$K$10 -> المجلات والدوريات الاقتصادية | H4: ='Source Table'!$J$6 -> Daily | I4: ='Source Table'!$J$5 -> يومية | J4: 0 | K4: 2023
A5: أعداد الصحف والمجلات والدوريات | B5: Number of Newspapers, Magazines and Periodicals | C5: M1 | D5: Number | E5: عدد | F5: ='Source Table'!$B$11 -> Army & Police Magazines & Periodicals | G5: ='Source Table'!$K$11 -> المجلات والدوريات العسكرية و شرطية | H5: ='Source Table'!$J$6 -> Daily | I5: ='Source Table'!$J$5 -> يومية | J5: 0 | K5: 2023
A6: أعداد الصحف والمجلات والدوريات | B6: Number of Newspapers, Magazines and Periodicals | C6: M1 | D6: Number | E6: عدد | F6: ='Source Table'!$B$12 -> Youths & Arts Magazines & Periodicals | G6: ='Source Table'!$K$12 -> المجلات والدوريات الشباب و الفنون | H6: ='Source Table'!$J$6 -> Daily | I6: ='Source Table'!$J$5 -> يومية | J6: 0 | K6: 2023
A7: أعداد الصحف والمجلات والدوريات | B7: Number of Newspapers, Magazines and Periodicals | C7: M1 | D7: Number | E7: عدد | F7: ='Source Table'!$B$13 -> Cultural & Educational Magazines & Periodicals | G7: ='Source Table'!$K$13 -> المجلات والدوريات الثقافية و المدرسية | H7: ='Source Table'!$J$6 -> Daily | I7: ='Source Table'!$J$5 -> يومية | J7: 0 | K7: 2023
A8: أعداد الصحف والمجلات والدوريات | B8: Number of Newspapers, Magazines and Periodicals | C8: M1 | D8: Number | E8: عدد | F8: ='Source Table'!$B$14 -> Religious Magazines & Periodicals | G8: ='Source Table'!$K$14 -> المجلات والدوريات الدينية | H8: ='Source Table'!$J$6 -> Daily | I8: ='Source Table'!$J$5 -> يومية | J8: 0 | K8: 2023
A9: أعداد الصحف والمجلات والدوريات | B9: Number of Newspapers, Magazines and Periodicals | C9: M1 | D9: Number | E9: عدد | F9: ='Source Table'!$B$15 -> Scientific Magazines & Periodicals | G9: ='Source Table'!$K$15 -> المجلات والدوريات العلمية | H9: ='Source Table'!$J$6 -> Daily | I9: ='Source Table'!$J$5 -> يومية | J9: 0 | K9: 2023
A10: أعداد الصحف والمجلات والدوريات | B10: Number of Newspapers, Magazines and Periodicals | C10: M1 | D10: Number | E10: عدد | F10: ='Source Table'!$B$16 -> Financial Magazines & Periodicals | G10: ='Source Table'!$K$16 -> المجلات والدوريات المالية | H10: ='Source Table'!$J$6 -> Daily | I10: ='Source Table'!$J$5 -> يومية | J10: 0 | K10: 2023
A11: أعداد الصحف والمجلات والدوريات | B11: Number of Newspapers, Magazines and Periodicals | C11: M1 | D11: Number | E11: عدد | F11: ='Source Table'!$B$17 -> Tourist Magazines & Periodicals | G11: ='Source Table'!$K$17 -> المجلات والدوريات سياحية | H11: ='Source Table'!$J$6 -> Daily | I11: ='Source Table'!$J$5 -> يومية | J11: 0 | K11: 2023
A12: أعداد الصحف والمجلات والدوريات | B12: Number of Newspapers, Magazines and Periodicals | C12: M1 | D12: Number | E12: عدد | F12: ='Source Table'!$B$18 -> Other Magazines & Periodicals | G12: ='Source Table'!$K$18 -> المجلات والدوريات أخرى | H12: ='Source Table'!$J$6 -> Daily | I12: ='Source Table'!$J$5 -> يومية | J12: 0 | K12: 2023
A13: أعداد الصحف والمجلات والدوريات | B13: Number of Newspapers, Magazines and Periodicals | C13: M1 | D13: Number | E13: عدد | F13: ='Source Table'!$B$7 -> Political Newspapers | G13: ='Source Table'!$K$7 -> صحف سياسية | H13: ='Source Table'!$I$6 -> Weekly | I13: ='Source Table'!$I$5 -> أسبوعية | J13: 6 | K13: 2023
A14: أعداد الصحف والمجلات والدوريات | B14: Number of Newspapers, Magazines and Periodicals | C14: M1 | D14: Number | E14: عدد | F14: ='Source Table'!$B$8 -> Parties Newspapers | G14: ='Source Table'!$K$8 -> صحف حزبية | H14: ='Source Table'!$I$6 -> Weekly | I14: ='Source Table'!$I$5 -> أسبوعية | J14: 1 | K14: 2023
A15: أعداد الصحف والمجلات والدوريات | B15: Number of Newspapers, Magazines and Periodicals | C15: M1 | D15: Number | E15: عدد | F15: ='Source Table'!$B$9 -> Children Magazines & Periodicals | G15: ='Source Table'!$K$9 -> المجلات والدوريات الأطفال | H15: ='Source Table'!$I$6 -> Weekly | I15: ='Source Table'!$I$5 -> أسبوعية | J15: 0 | K15: 2023
A16: أعداد الصحف والمجلات والدوريات | B16: Number of Newspapers, Magazines and Periodicals | C16: M1 | D16: Number | E16: عدد | F16: ='Source Table'!$B$10 -> Economic Magazines & Periodicals | G16: ='Source Table'!$K$10 -> المجلات والدوريات الاقتصادية | H16: ='Source Table'!$I$6 -> Weekly | I16: ='Source Table'!$I$5 -> أسبوعية | J16: 0 | K16: 2023
A17: أعداد الصحف والمجلات والدوريات | B17: Number of Newspapers, Magazines and Periodicals | C17: M1 | D17: Number | E17: عدد | F17: ='Source Table'!$B$11 -> Army & Police Magazines & Periodicals | G17: ='Source Table'!$K$11 -> المجلات والدوريات العسكرية و شرطية | H17: ='Source Table'!$I$6 -> Weekly | I17: ='Source Table'!$I$5 -> أسبوعية | J17: 0 | K17: 2023
A18: أعداد الصحف والمجلات والدوريات | B18: Number of Newspapers, Magazines and Periodicals | C18: M1 | D18: Number | E18: عدد | F18: ='Source Table'!$B$12 -> Youths & Arts Magazines & Periodicals | G18: ='Source Table'!$K$12 -> المجلات والدوريات الشباب و الفنون | H18: ='Source Table'!$I$6 -> Weekly | I18: ='Source Table'!$I$5 -> أسبوعية | J18: 1 | K18: 2023
A19: أعداد الصحف والمجلات والدوريات | B19: Number of Newspapers, Magazines and Periodicals | C19: M1 | D19: Number | E19: عدد | F19: ='Source Table'!$B$13 -> Cultural & Educational Magazines & Periodicals | G19: ='Source Table'!$K$13 -> المجلات والدوريات الثقافية و المدرسية | H19: ='Source Table'!$I$6 -> Weekly | I19: ='Source Table'!$I$5 -> أسبوعية | J19: 0 | K19: 2023
A20: أعداد الصحف والمجلات والدوريات | B20: Number of Newspapers, Magazines and Periodicals | C20: M1 | D20: Number | E20: عدد | F20: ='Source Table'!$B$14 -> Religious Magazines & Periodicals | G20: ='Source Table'!$K$14 -> المجلات والدوريات الدينية | H20: ='Source Table'!$I$6 -> Weekly | I20: ='Source Table'!$I$5 -> أسبوعية | J20: 0 | K20: 2023
A21: أعداد الصحف والمجلات والدوريات | B21: Number of Newspapers, Magazines and Periodicals | C21: M1 | D21: Number | E21: عدد | F21: ='Source Table'!$B$15 -> Scientific Magazines & Periodicals | G21: ='Source Table'!$K$15 -> المجلات والدوريات العلمية | H21: ='Source Table'!$I$6 -> Weekly | I21: ='Source Table'!$I$5 -> أسبوعية | J21: 0 | K21: 2023
A22: أعداد الصحف والمجلات والدوريات | B22: Number of Newspapers, Magazines and Periodicals | C22: M1 | D22: Number | E22: عدد | F22: ='Source Table'!$B$16 -> Financial Magazines & Periodicals | G22: ='Source Table'!$K$16 -> المجلات والدوريات المالية | H22: ='Source Table'!$I$6 -> Weekly | I22: ='Source Table'!$I$5 -> أسبوعية | J22: 0 | K22: 2023
A23: أعداد الصحف والمجلات والدوريات | B23: Number of Newspapers, Magazines and Periodicals | C23: M1 | D23: Number | E23: عدد | F23: ='Source Table'!$B$17 -> Tourist Magazines & Periodicals | G23: ='Source Table'!$K$17 -> المجلات والدوريات سياحية | H23: ='Source Table'!$I$6 -> Weekly | I23: ='Source Table'!$I$5 -> أسبوعية | J23: 1 | K23: 2023
A24: أعداد الصحف والمجلات والدوريات | B24: Number of Newspapers, Magazines and Periodicals | C24: M1 | D24: Number | E24: عدد | F24: ='Source Table'!$B$18 -> Other Magazines & Periodicals | G24: ='Source Table'!$K$18 -> المجلات والدوريات أخرى | H24: ='Source Table'!$I$6 -> Weekly | I24: ='Source Table'!$I$5 -> أسبوعية | J24: 2 | K24: 2023
A25: أعداد الصحف والمجلات والدوريات | B25: Number of Newspapers, Magazines and Periodicals | C25: M1 | D25: Number | E25: عدد | F25: ='Source Table'!$B$7 -> Political Newspapers | G25: ='Source Table'!$K$7 -> صحف سياسية | H25: ='Source Table'!$H$6 -> Monthly | I25: ='Source Table'!$H$5 -> شهرية | J25: 2 | K25: 2023
A26: أعداد الصحف والمجلات والدوريات | B26: Number of Newspapers, Magazines and Periodicals | C26: M1 | D26: Number | E26: عدد | F26: ='Source Table'!$B$8 -> Parties Newspapers | G26: ='Source Table'!$K$8 -> صحف حزبية | H26: ='Source Table'!$H$6 -> Monthly | I26: ='Source Table'!$H$5 -> شهرية | J26: 0 | K26: 2023
A27: أعداد الصحف والمجلات والدوريات | B27: Number of Newspapers, Magazines and Periodicals | C27: M1 | D27: Number | E27: عدد | F27: ='Source Table'!$B$9 -> Children Magazines & Periodicals | G27: ='Source Table'!$K$9 -> المجلات والدوريات الأطفال | H27: ='Source Table'!$H$6 -> Monthly | I27: ='Source Table'!$H$5 -> شهرية | J27: 1 | K27: 2023
A28: أعداد الصحف والمجلات والدوريات | B28: Number of Newspapers, Magazines and Periodicals | C28: M1 | D28: Number | E28: عدد | F28: ='Source Table'!$B$10 -> Economic Magazines & Periodicals | G28: ='Source Table'!$K$10 -> المجلات والدوريات الاقتصادية | H28: ='Source Table'!$H$6 -> Monthly | I28: ='Source Table'!$H$5 -> شهرية | J28: 2 | K28: 2023
A29: أعداد الصحف والمجلات والدوريات | B29: Number of Newspapers, Magazines and Periodicals | C29: M1 | D29: Number | E29: عدد | F29: ='Source Table'!$B$11 -> Army & Police Magazines & Periodicals | G29: ='Source Table'!$K$11 -> المجلات والدوريات العسكرية و شرطية | H29: ='Source Table'!$H$6 -> Monthly | I29: ='Source Table'!$H$5 -> شهرية | J29: 0 | K29: 2023
A30: أعداد الصحف والمجلات والدوريات | B30: Number of Newspapers, Magazines and Periodicals | C30: M1 | D30: Number | E30: عدد | F30: ='Source Table'!$B$12 -> Youths & Arts Magazines & Periodicals | G30: ='Source Table'!$K$12 -> المجلات والدوريات الشباب و الفنون | H30: ='Source Table'!$H$6 -> Monthly | I30: ='Source Table'!$H$5 -> شهرية | J30: 0 | K30: 2023
A31: أعداد الصحف والمجلات والدوريات | B31: Number of Newspapers, Magazines and Periodicals | C31: M1 | D31: Number | E31: عدد | F31: ='Source Table'!$B$13 -> Cultural & Educational Magazines & Periodicals | G31: ='Source Table'!$K$13 -> المجلات والدوريات الثقافية و المدرسية | H31: ='Source Table'!$H$6 -> Monthly | I31: ='Source Table'!$H$5 -> شهرية | J31: 0 | K31: 2023
A32: أعداد الصحف والمجلات والدوريات | B32: Number of Newspapers, Magazines and Periodicals | C32: M1 | D32: Number | E32: عدد | F32: ='Source Table'!$B$14 -> Religious Magazines & Periodicals | G32: ='Source Table'!$K$14 -> المجلات والدوريات الدينية | H32: ='Source Table'!$H$6 -> Monthly | I32: ='Source Table'!$H$5 -> شهرية | J32: 0 | K32: 2023
A33: أعداد الصحف والمجلات والدوريات | B33: Number of Newspapers, Magazines and Periodicals | C33: M1 | D33: Number | E33: عدد | F33: ='Source Table'!$B$15 -> Scientific Magazines & Periodicals | G33: ='Source Table'!$K$15 -> المجلات والدوريات العلمية | H33: ='Source Table'!$H$6 -> Monthly | I33: ='Source Table'!$H$5 -> شهرية | J33: 1 | K33: 2023
A34: أعداد الصحف والمجلات والدوريات | B34: Number of Newspapers, Magazines and Periodicals | C34: M1 | D34: Number | E34: عدد | F34: ='Source Table'!$B$16 -> Financial Magazines & Periodicals | G34: ='Source Table'!$K$16 -> المجلات والدوريات المالية | H34: ='Source Table'!$H$6 -> Monthly | I34: ='Source Table'!$H$5 -> شهرية | J34: 0 | K34: 2023
A35: أعداد الصحف والمجلات والدوريات | B35: Number of Newspapers, Magazines and Periodicals | C35: M1 | D35: Number | E35: عدد | F35: ='Source Table'!$B$17 -> Tourist Magazines & Periodicals | G35: ='Source Table'!$K$17 -> المجلات والدوريات سياحية | H35: ='Source Table'!$H$6 -> Monthly | I35: ='Source Table'!$H$5 -> شهرية | J35: 0 | K35: 2023
A36: أعداد الصحف والمجلات والدوريات | B36: Number of Newspapers, Magazines and Periodicals | C36: M1 | D36: Number | E36: عدد | F36: ='Source Table'!$B$18 -> Other Magazines & Periodicals | G36: ='Source Table'!$K$18 -> المجلات والدوريات أخرى | H36: ='Source Table'!$H$6 -> Monthly | I36: ='Source Table'!$H$5 -> شهرية | J36: 5 | K36: 2023
A37: أعداد الصحف والمجلات والدوريات | B37: Number of Newspapers, Magazines and Periodicals | C37: M1 | D37: Number | E37: عدد | F37: ='Source Table'!$B$7 -> Political Newspapers | G37: ='Source Table'!$K$7 -> صحف سياسية | I37: ='Source Table'!$G$5 -> فصلية | J37: 0 | K37: 2023
A38: أعداد الصحف والمجلات والدوريات | B38: Number of Newspapers, Magazines and Periodicals | C38: M1 | D38: Number | E38: عدد | F38: ='Source Table'!$B$8 -> Parties Newspapers | G38: ='Source Table'!$K$8 -> صحف حزبية | I38: ='Source Table'!$G$5 -> فصلية | J38: 0 | K38: 2023
A39: أعداد الصحف والمجلات والدوريات | B39: Number of Newspapers, Magazines and Periodicals | C39: M1 | D39: Number | E39: عدد | F39: ='Source Table'!$B$9 -> Children Magazines & Periodicals | G39: ='Source Table'!$K$9 -> المجلات والدوريات الأطفال | I39: ='Source Table'!$G$5 -> فصلية | J39: 0 | K39: 2023
A40: أعداد الصحف والمجلات والدوريات | B40: Number of Newspapers, Magazines and Periodicals | C40: M1 | D40: Number | E40: عدد | F40: ='Source Table'!$B$10 -> Economic Magazines & Periodicals | G40: ='Source Table'!$K$10 -> المجلات والدوريات الاقتصادية | I40: ='Source Table'!$G$5 -> فصلية | J40: 1 | K40: 2023
...
