Workbook
Name _Toc175817975: 'Relational DB'!$J$4
Name _Toc175817976: 'Relational DB'!$J$10
Name _Toc175817980: 'Relational DB'!$J$5
Name _Toc175817981: 'Relational DB'!$J$11
Name _Toc175817985: 'Relational DB'!$J$6
Name _Toc175817986: 'Relational DB'!$J$12
Name _Toc175817990: 'Relational DB'!$J$7
Name _Toc175817991: 'Relational DB'!$J$13
Name _Toc175817995: 'Relational DB'!$J$8
Name _Toc175817996: 'Relational DB'!$J$14
Name _Toc175818000: 'Relational DB'!$J$9
Name _Toc175818001: 'Relational DB'!$J$15

Sheet Cover Page
A1: Code | B1: SYB_19_2_4
A2: Version | B2: V1
A3: اسم القالب | B3: المهندسون الزراعيون المسجّلون في نقابة المهندسين الزراعيين حسب التخصص والجنس
A4: Template Name | B4: Agricultural Engineers Registered at the Agricultural Engineers Syndicate by Specialization and Sex
A5: دورية البيانات | B5: سنوي
A6: Data Frequency | B6: Annual
A7: الجهة المصدرية | B7: نقابة المهندسين الزراعيين
A8: Data Source | B8: Agricultural Engineers Syndicate

Sheet Source Table
B2: ='Cover Page'!B4 -> Agricultural Engineers Registered at the Agricultural Engineers Syndicate by Specialization and Sex
B3: ='Cover Page'!B3 -> المهندسون الزراعيون المسجّلون في نقابة المهندسين الزراعيين حسب التخصص والجنس
B4: Year | C4: =YEAR('Template Data'!B1) -> 2024 | E4: السنة
B5: Specialization | C5: أنثى | D5: ذكر | E5: التخصص
C6: Female | D6: Male
B7: Plants Protection | E7: الوقاية النباتية
B8: Plants Production | E8: الإنتاج النباتي
B9: Agricultural Economics | E9: الاقتصاد الزراعي
B10: Animal Production | E10: الإنتاج الحيواني
B11: Environment & Irrigation | E11: الموارد المائيةوالبيئة
B12: Nutrition and Industries | E12: التغذية والصناعات

Sheet Relational DB
A1: Relational Sheet
A2: Measure_Name_Ar | B2: Measure_Name_En | C2: Measure_ID | D2: Unit_EN | E2: Unit_AR | F2: CL_SEX_EN_V1 | G2: CL_SEX_AR_V1 | H2: CL_AGR_ENG_SPECALIZATION_EN_V1 | I2: CL_AGR_ENG_SPECALIZATION_AR_V1 | J2: Obs_Value | K2: Time_Period_Y | L2: Time_Period_M
A3: اسم المؤشر | B3: Measure Name | C3: رمز المؤشر | D3: Unit | E3: الوحدة | F3: Sex | G3: الجنس | H3: Agricultural Engineers Specialization | I3: تخصص المهندسون الزراعيون | J3: قيمة المؤشر | K3: سنة فترة القياس | L3: شهر فترة القياس
A4: المهندسون الزراعيون المسجّلون في نقابة المهندسين الزراعيين | B4: Agricultural Engineers Registered at the Agricultural Engineers Syndicate | C4: M1 | D4: Number | E4: عدد | F4: ='Source Table'!$D$6 -> Male | G4: ='Source Table'!$D$5 -> ذكر | H4: ='Source Table'!$B$7 -> Plants Protection | I4: ='Source Table'!$E$7 -> الوقاية النباتية | J4: 820 | K4: 2023
A5: المهندسون الزراعيون المسجّلون في نقابة المهندسين الزراعيين | B5: Agricultural Engineers Registered at the Agricultural Engineers Syndicate | C5: M1 | D5: Number | E5: عدد | F5: ='Source Table'!$D$6 -> Male | G5: ='Source Table'!$D$5 -> ذكر | H5: ='Source Table'!$B$8 -> Plants Production | I5: ='Source Table'!$E$8 -> الإنتاج النباتي | J5: 3312 | K5: 2023
A6: المهندسون الزراعيون المسجّلون في نقابة المهندسين الزراعيين | B6: Agricultural Engineers Registered at the Agricultural Engineers Syndicate | C6: M1 | D6: Number | E6: عدد | F6: ='Source Table'!$D$6 -> Male | G6: ='Source Table'!$D$5 -> ذكر | H6: ='Source Table'!$B$9 -> Agricultural Economics | I6: ='Source Table'!$E$9 -> الاقتصاد الزراعي | J6: 762 | K6: 2023
A7: المهندسون الزراعيون المسجّلون في نقابة المهندسين الزراعيين | B7: Agricultural Engineers Registered at the Agricultural Engineers Syndicate | C7: M1 | D7: Number | E7: عدد | F7: ='Source Table'!$D$6 -> Male | G7: ='Source Table'!$D$5 -> ذكر | H7: ='Source Table'!$B$10 -> Animal Production | I7: ='Source Table'!$E$10 -> الإنتاج الحيواني | J7: 1884 | K7: 2023
A8: المهندسون الزراعيون المسجّلون في نقابة المهندسين الزراعيين | B8: Agricultural Engineers Registered at the Agricultural Engineers Syndicate | C8: M1 | D8: Number | E8: عدد | F8: ='Source Table'!$D$6 -> Male | G8: ='Source Table'!$D$5 -> ذكر | H8: ='Source Table'!$B$11 -> Environment & Irrigation | I8: ='Source Table'!$E$11 -> الموارد المائيةوالبيئة | J8: 1048 | K8: 2023
A9: المهندسون الزراعيون المسجّلون في نقابة المهندسين الزراعيين | B9: Agricultural Engineers Registered at the Agricultural Engineers Syndicate | C9: M1 | D9: Number | E9: عدد | F9: ='Source Table'!$D$6 -> Male | G9: ='Source Table'!$D$5 -> ذكر | H9: ='Source Table'!$B$12 -> Nutrition and Industries | I9: ='Source Table'!$E$12 -> التغذية والصناعات | J9: 1785 | K9: 2023
A10: المهندسون الزراعيون المسجّلون في نقابة المهندسين الزراعيين | B10: Agricultural Engineers Registered at the Agricultural Engineers Syndicate | C10: M1 | D10: Number | E10: عدد | F10: ='Source Table'!$C$6 -> Female | G10: ='Source Table'!$C$5 -> أنثى | H10: ='Source Table'!$B$7 -> Plants Protection | I10: ='Source Table'!$E$7 -> الوقاية النباتية | J10: 451 | K10: 2023
A11: المهندسون الزراعيون المسجّلون في نقابة المهندسين الزراعيين | B11: Agricultural Engineers Registered at the Agricultural Engineers Syndicate | C11: M1 | D11: Number | E11: عدد | F11: ='Source Table'!$C$6 -> Female | G11: ='Source Table'!$C$5 -> أنثى | H11: ='Source Table'!$B$8 -> Plants Production | I11: ='Source Table'!$E$8 -> الإنتاج النباتي | J11: 2467 | K11: 2023
A12: المهندسون الزراعيون المسجّلون في نقابة المهندسين الزراعيين | B12: Agricultural Engineers Registered at the Agricultural Engineers Syndicate | C12: M1 | D12: Number | E12: عدد | F12: ='Source Table'!$C$6 -> Female | G12: ='Source Table'!$C$5 -> أنثى | H12: ='Source Table'!$B$9 -> Agricultural Economics | I12: ='Source Table'!$E$9 -> الاقتصاد الزراعي | J12: 643 | K12: 2023
A13: المهندسون الزراعيون المسجّلون في نقابة المهندسين الزراعيين | B13: Agricultural Engineers Registered at the Agricultural Engineers Syndicate | C13: M1 | D13: Number | E13: عدد | F13: ='Source Table'!$C$6 -> Female | G13: ='Source Table'!$C$5 -> أنثى | H13: ='Source Table'!$B$10 -> Animal Production | I13: ='Source Table'!$E$10 -> الإنتاج الحيواني | J13: 371 | K13: 2023
A14: المهندسون الزراعيون المسجّلون في نقابة المهندسين الزراعيين | B14: Agricultural Engineers Registered at the Agricultural Engineers Syndicate | C14: M1 | D14: Number | E14: عدد | F14: ='Source Table'!$C$6 -> Female | G14: ='Source Table'!$C$5 -> أنثى | H14: ='Source Table'!$B$11 -> Environment & Irrigation | I14: ='Source Table'!$E$11 -> الموارد المائيةوالبيئة | J14: 1883 | K14: 2023
A15: المهندسون الزراعيون المسجّلون في نقابة المهندسين الزراعيين | B15: Agricultural Engineers Registered at the Agricultural Engineers Syndicate | C15: M1 | D15: Number | E15: عدد | F15: ='Source Table'!$C$6 -> Female | G15: ='Source Table'!$C$5 -> أنثى | H15: ='Source Table'!$B$12 -> Nutrition and Industries | I15: ='Source Table'!$E$12 -> التغذية والصناعات | J15: 5119 | K15: 2023
A16: المهندسون الزراعيون المسجّلون في نقابة المهندسين الزراعيين | B16: Agricultural Engineers Registered at the Agricultural Engineers Syndicate | C16: M1 | D16: Number | E16: عدد | F16: ='Source Table'!$D$6 -> Male | G16: ='Source Table'!$D$5 -> ذكر | H16: ='Source Table'!$B$7 -> Plants Protection | I16: ='Source Table'!$E$7 -> الوقاية النباتية | J16: 755 | K16: 2022
A17: المهندسون الزراعيون المسجّلون في نقابة المهندسين الزراعيين | B17: Agricultural Engineers Registered at the Agricultural Engineers Syndicate | C17: M1 | D17: Number | E17: عدد | F17: ='Source Table'!$D$6 -> Male | G17: ='Source Table'!$D$5 -> ذكر | H17: ='Source Table'!$B$8 -> Plants Production | I17: ='Source Table'!$E$8 -> الإنتاج النباتي | J17: 2870 | K17: 2022
A18: المهندسون الزراعيون المسجّلون في نقابة المهندسين الزراعيين | B18: Agricultural Engineers Registered at the Agricultural Engineers Syndicate | C18: M1 | D18: Number | E18: عدد | F18: ='Source Table'!$D$6 -> Male | G18: ='Source Table'!$D$5 -> ذكر | H18: ='Source Table'!$B$9 -> Agricultural Economics | I18: ='Source Table'!$E$9 -> الاقتصاد الزراعي | J18: 747 | K18: 2022
A19: المهندسون الزراعيون المسجّلون في نقابة المهندسين الزراعيين | B19: Agricultural Engineers Registered at the Agricultural Engineers Syndicate | C19: M1 | D19: Number | E19: عدد | F19: ='Source Table'!$D$6 -> Male | G19: ='Source Table'!$D$5 -> ذكر | H19: ='Source Table'!$B$10 -> Animal Production | I19: ='Source Table'!$E$10 -> الإنتاج الحيواني | J19: 1669 | K19: 2022
A20: المهندسون الزراعيون المسجّلون في نقابة المهندسين الزراعيين | B20: Agricultural Engineers Registered at the Agricultural Engineers Syndicate | C20: M1 | D20: Number | E20: عدد | F20: ='Source Table'!$D$6 -> Male | G20: ='Source Table'!$D$5 -> ذكر | H20: ='Source Table'!$B$11 -> Environment & Irrigation | I20: ='Source Table'!$E$11 -> الموارد المائيةوالبيئة | J20: 1001 | K20: 2022
A21: المهندسون الزراعيون المسجّلون في نقابة المهندسين الزراعيين | B21: Agricultural Engineers Registered at the Agricultural Engineers Syndicate | C21: M1 | D21: Number | E21: عدد | F21: ='Source Table'!$D$6 -> Male | G21: ='Source Table'!$D$5 -> ذكر | H21: ='Source Table'!$B$12 -> Nutrition and Industries | I21: ='Source Table'!$E$12 -> التغذية والصناعات | J21: 1650 | K21: 2022
A22: المهندسون الزراعيون المسجّلون في نقابة المهندسين الزراعيين | B22: Agricultural Engineers Registered at the Agricultural Engineers Syndicate | C22: M1 | D22: Number | E22: عدد | F22: ='Source Table'!$C$6 -> Female | G22: ='Source Table'!$C$5 -> أنثى | H22: ='Source Table'!$B$7 -> Plants Protection | I22: ='Source Table'!$E$7 -> الوقاية النباتية | J22: 432 | K22: 2022
A23: المهندسون الزراعيون المسجّلون في نقابة المهندسين الزراعيين | B23: Agricultural Engineers Registered at the Agricultural Engineers Syndicate | C23: M1 | D23: Number | E23: عدد | F23: ='Source Table'!$C$6 -> Female | G23: ='Source Table'!$C$5 -> أنثى | H23: ='Source Table'!$B$8 -> Plants Production | I23: ='Source Table'!$E$8 -> الإنتاج النباتي | J23: 2241 | K23: 2022
A24: المهندسون الزراعيون المسجّلون في نقابة المهندسين الزراعيين | B24: Agricultural Engineers Registered at the Agricultural Engineers Syndicate | C24: M1 | D24: Number | E24: عدد | F24: ='Source Table'!$C$6 -> Female | G24: ='Source Table'!$C$5 -> أنثى | H24: ='Source Table'!$B$9 -> Agricultural Economics | I24: ='Source Table'!$E$9 -> الاقتصاد الزراعي | J24: 635 | K24: 2022
A25: المهندسون الزراعيون المسجّلون في نقابة المهندسين الزراعيين | B25: Agricultural Engineers Registered at the Agricultural Engineers Syndicate | C25: M1 | D25: Number | E25: عدد | F25: ='Source Table'!$C$6 -> Female | G25: ='Source Table'!$C$5 -> أنثى | H25: ='Source Table'!$B$10 -> Animal Production | I25: ='Source Table'!$E$10 -> الإنتاج الحيواني | J25: 332 | K25: 2022
A26: المهندسون الزراعيون المسجّلون في نقابة المهندسين الزراعيين | B26: Agricultural Engineers Registered at the Agricultural Engineers Syndicate | C26: M1 | D26: Number | E26: عدد | F26: ='Source Table'!$C$6 -> Female | G26: ='Source Table'!$C$5 -> أنثى | H26: ='Source Table'!$B$11 -> Environment & Irrigation | I26: ='Source Table'!$E$11 -> الموارد المائيةوالبيئة | J26: 1805 | K26: 2022
A27: المهندسون الزراعيون المسجّلون في نقابة المهندسين الزراعيين | B27: Agricultural Engineers Registered at the Agricultural Engineers Syndicate | C27: M1 | D27: Number | E27: عدد | F27: ='Source Table'!$C$6 -> Female | G27: ='Source Table'!$C$5 -> أنثى | H27: ='Source Table'!$B$12 -> Nutrition and Industries | I27: ='Source Table'!$E$12 -> التغذية والصناعات | J27: 4785 | K27: 2022
A28: المهندسون الزراعيون المسجّلون في نقابة المهندسين الزراعيين | B28: Agricultural Engineers Registered at the Agricultural Engineers Syndicate | C28: M1 | D28: Number | E28: عدد | F28: ='Source Table'!$D$6 -> Male | G28: ='Source Table'!$D$5 -> ذكر | H28: ='Source Table'!$B$7 -> Plants Protection | I28: ='Source Table'!$E$7 -> الوقاية النباتية | J28: 801 | K28: 2020
A29: المهندسون الزراعيون المسجّلون في نقابة المهندسين الزراعيين | B29: Agricultural Engineers Registered at the Agricultural Engineers Syndicate | C29: M1 | D29: Number | E29: عدد | F29: ='Source Table'!$D$6 -> Male | G29: ='Source Table'!$D$5 -> ذكر | H29: ='Source Table'!$B$8 -> Plants Production | I29: ='Source Table'!$E$8 -> الإنتاج النباتي | J29: 2863 | K29: 2020
A30: المهندسون الزراعيون المسجّلون في نقابة المهندسين الزراعيين | B30: Agricultural Engineers Registered at the Agricultural Engineers Syndicate | C30: M1 | D30: Number | E30: عدد | F30: ='Source Table'!$D$6 -> Male | G30: ='Source Table'!$D$5 -> ذكر | H30: ='Source Table'!$B$9 -> Agricultural Economics | I30: ='Source Table'!$E$9 -> الاقتصاد الزراعي | J30: 743 | K30: 2020
A31: المهندسون الزراعيون المسجّلون في نقابة المهندسين الزراعيين | B31: Agricultural Engineers Registered at the Agricultural Engineers Syndicate | C31: M1 | D31: Number | E31: عدد | F31: ='Source Table'!$D$6 -> Male | G31: ='Source Table'!$D$5 -> ذكر | H31: ='Source Table'!$B$10 -> Animal Production | I31: ='Source Table'!$E$10 -> الإنتاج الحيواني | J31: 1658 | K31: 2020
A32: المهندسون الزراعيون المسجّلون في نقابة المهندسين الزراعيين | B32: Agricultural Engineers Registered at the Agricultural Engineers Syndicate | C32: M1 | D32: Number | E32: عدد | F32: ='Source Table'!$D$6 -> Male | G32: ='Source Table'!$D$5 -> ذكر | H32: ='Source Table'!$B$11 -> Environment & Irrigation | I32: ='Source Table'!$E$11 -> الموارد المائيةوالبيئة | J32: 974 | K32: 2020
A33: المهندسون الزراعيون المسجّلون في نقابة المهندسين الزراعيين | B33: Agricultural Engineers Registered at the Agricultural Engineers Syndicate | C33: M1 | D33: Number | E33: عدد | F33: ='Source Table'!$D$6 -> Male | G33: ='Source Table'!$D$5 -> ذكر | H33: ='Source Table'!$B$12 -> Nutrition and Industries | I33: ='Source Table'!$E$12 -> التغذية والصناعات | J33: 1375 | K33: 2020
A34: المهندسون الزراعيون المسجّلون في نقابة المهندسين الزراعيين | B34: Agricultural Engineers Registered at the Agricultural Engineers Syndicate | C34: M1 | D34: Number | E34: عدد | F34: ='Source Table'!$C$6 -> Female | G34: ='Source Table'!$C$5 -> أنثى | H34: ='Source Table'!$B$7 -> Plants Protection | I34: ='Source Table'!$E$7 -> الوقاية النباتية | J34: 425 | K34: 2020
A35: المهندسون الزراعيون المسجّلون في نقابة المهندسين الزراعيين | B35: Agricultural Engineers Registered at the Agricultural Engineers Syndicate | C35: M1 | D35: Number | E35: عدد | F35: ='Source Table'!$C$6 -> Female | G35: ='Source Table'!$C$5 -> أنثى | H35: ='Source Table'!$B$8 -> Plants Production | I35: ='Source Table'!$E$8 -> الإنتاج النباتي | J35: 2166 | K35: 2020
A36: المهندسون الزراعيون المسجّلون في نقابة المهندسين الزراعيين | B36: Agricultural Engineers Registered at the Agricultural Engineers Syndicate | C36: M1 | D36: Number | E36: عدد | F36: ='Source Table'!$C$6 -> Female | G36: ='Source Table'!$C$5 -> أنثى | H36: ='Source Table'!$B$9 -> Agricultural Economics | I36: ='Source Table'!$E$9 -> الاقتصاد الزراعي | J36: 624 | K36: 2020
A37: المهندسون الزراعيون المسجّلون في نقابة المهندسين الزراعيين | B37: Agricultural Engineers Registered at the Agricultural Engineers Syndicate | C37: M1 | D37: Number | E37: عدد | F37: ='Source Table'!$C$6 -> Female | G37: ='Source Table'!$C$5 -> أنثى | H37: ='Source Table'!$B$10 -> Animal Production | I37: ='Source Table'!$E$10 -> الإنتاج الحيواني | J37: 332 | K37: 2020
A38: المهندسون الزراعيون المسجّلون في نقابة المهندسين الزراعيين | B38: Agricultural Engineers Registered at the Agricultural Engineers Syndicate | C38: M1 | D38: Number | E38: عدد | F38: ='Source Table'!$C$6 -> Female | G38: ='Source Table'!$C$5 -> أنثى | H38: ='Source Table'!$B$11 -> Environment & Irrigation | I38: ='Source Table'!$E$11 -> الموارد المائيةوالبيئة | J38: 1681 | K38: 2020
A39: المهندسون الزراعيون المسجّلون في نقابة المهندسين الزراعيين | B39: Agricultural Engineers Registered at the Agricultural Engineers Syndicate | C39: M1 | D39: Number | E39: عدد | F39: ='Source Table'!$C$6 -> Female | G39: ='Source Table'!$C$5 -> أنثى | H39: ='Source Table'!$B$12 -> Nutrition and Industries | I39: ='Source Table'!$E$12 -> التغذية والصناعات | J39: 4061 | K39: 2020
A40: المهندسون الزراعيون المسجّلون في نقابة المهندسين الزراعيين | B40: Agricultural Engineers Registered at the Agricultural Engineers Syndicate | C40: M1 | D40: Number | E40: عدد | F40: ='Source Table'!$D$6 -> Male | G40: ='Source Table'!$D$5 -> ذكر | H40: ='Source Table'!$B$7 -> Plants Protection | I40: ='Source Table'!$E$7 -> الوقاية النباتية | J40: 808 | K40: 2021
...

Sheet Template Data
A1: Date | B1: =DATE(B2,B3,1) -> 45292
A2: Year | B2: 2024
A3: Month | B3: 1
A4: Measure_Name_Ar | B4: Measure_Name_En | C4: Measure_ID | D4: Unit_EN | E4: Unit_AR | F4: CL_SEX_EN_V1 | G4: CL_SEX_AR_V1 | H4: CL_AGR_ENG_SPECALIZATION_EN_V1 | I4: CL_AGR_ENG_SPECALIZATION_AR_V1 | J4: Obs_Value | K4: Time_Period_Y | L4: Time_Period_M
A5: اسم المؤشر | B5: Measure Name | C5: رمز المؤشر | D5: Unit | E5: الوحدة | F5: Sex | G5: الجنس | H5: Agricultural Engineers Specialization | I5: تخصص المهندسون الزراعيون | J5: قيمة المؤشر | K5: سنة فترة القياس | L5: شهر فترة القياس

Sheet Help
A2: Step 1: Cover Page | C2: الخطوة 1: Cover Page
A4: Update the template information, to ensure that any meta-information about the template, such as the title, version, and description, is accurate and up-to-date. | C4: قم بتحديث معلومات القالب للتأكد من أن أي معلومات وصفية حول القالب، مثل العنوان والإصدار والوصف، دقيقة ومحدثة.
A6: Step 2: Source Table | C6: الخطوة 2: Source Table
A8: Design your template, ensuring that the time period is mapped correctly to the date information in rows 1-3 of the Template Data Sheet. | C8: قم بتصميم القالب الخاص بك، مع التأكد من أن فترة الوقت مرتبطة بشكل صحيح مع معلومات التاريخ في الصفوف 1-3 في ورقة Template Data.
A10: Step 3: Relational Sheet | C10: الخطوة 3: Relational Sheet
A12: Unpivot the data in the source table into a flat format. Follow these guidelines: | C12: قم بتحويل البيانات في جدول المصدر إلى تنسيق مسطح. اتبع هذه الإرشادات:
A13: 1. Blue Columns: Do not change the names of the blue columns. Update the data as per the current template. | C13: 1. الأعمدة الزرقاء: لا تقم بتغيير أسماء الأعمدة الزرقاء. قم بتحديث البيانات وفقًا للقالب الحالي.
A14: 2. Code Lists: Use the naming convention CL_XXX_EN_V# for code lists, where XXX is the name, and V# is the version, conforming with the definitions in the data dictionary. | C14: 2. قوائم الرموز: استخدم قاعدة التسمية CL_XXX_EN_V# لقوائم الرموز، حيث أن XXX هو الاسم و V# هو الإصدار، وفقًا للتعريفات في قاموس البيانات.
A15: 3. Code List Values: Ensure the code list values match the definitions in the data dictionary. | C15: 3. قيم قائمة الرموز: تأكد من أن قيم قائمة الرموز تتوافق مع التعريفات في قاموس البيانات.
A16: 4. Time_Period_M: Leave empty if the data frequency is yearly. | C16: 4. Time_Period_M: اتركها فارغة إذا كانت دورية البيانات سنوية.
A17: 5. Time_Period_M Format: Use one of these formats: | C17: 5. تنسيق Time_Period_M: استخدم أحد التنسيقات التالية:
A18: Numeric: (1, 2, 3, ..., 12) for months. | C18: رقمي: (1، 2، 3، ...، 12) للأشهر.
... A38: Protect the entire workbook to prevent unauthorized or accidental changes to the structure of the file. | C38: قم بحماية الكتاب بأكمله لمنع التغييرات غير المصرح بها أو غير المقصودة على هيكل الملف.
