Workbook
Name _Toc175818022: 'Source Table'!$G$7
Name _Toc175818030: 'Source Table'!$G$8
Name _Toc175818038: 'Relational DB'!$L$4
Name _Toc175818039: 'Relational DB'!$L$29
Name _Toc175818040: 'Relational DB'!$L$54
Name _Toc175818041: 'Relational DB'!$L$79
Name _Toc175818042: 'Relational DB'!$L$104
Name _Toc175818043: 'Relational DB'!$L$129
Name _Toc175818044: 'Relational DB'!$L$154
Name _Toc175818048: 'Relational DB'!$L$5
Name _Toc175818049: 'Relational DB'!$L$30
Name _Toc175818050: 'Relational DB'!$L$55
Name _Toc175818051: 'Relational DB'!$L$80
Name _Toc175818052: 'Relational DB'!$L$105
Name _Toc175818053: 'Relational DB'!$L$130
Name _Toc175818054: 'Relational DB'!$L$155
Name _Toc175818058: 'Relational DB'!$L$6
Name _Toc175818059: 'Relational DB'!$L$31
Name _Toc175818060: 'Relational DB'!$L$56
Name _Toc175818061: 'Relational DB'!$L$81
Name _Toc175818062: 'Relational DB'!$L$106
Name _Toc175818063: 'Relational DB'!$L$131
Name _Toc175818064: 'Relational DB'!$L$156
Name _Toc175818068: 'Relational DB'!$L$7
Name _Toc175818069: 'Relational DB'!$L$32
Name _Toc175818070: 'Relational DB'!$L$57
Name _Toc175818071: 'Relational DB'!$L$82
Name _Toc175818072: 'Relational DB'!$L$107
Name _Toc175818073: 'Relational DB'!$L$132
Name _Toc175818074: 'Relational DB'!$L$157
Name _Toc175818078: 'Relational DB'!$L$8
Name _Toc175818079: 'Relational DB'!$L$33
Name _Toc175818080: 'Relational DB'!$L$58
Name _Toc175818081: 'Relational DB'!$L$83
Name _Toc175818082: 'Relational DB'!$L$108
Name _Toc175818083: 'Relational DB'!$L$133
Name _Toc175818084: 'Relational DB'!$L$158
Name _Toc175818088: 'Relational DB'!$L$9
Name _Toc175818089: 'Relational DB'!$L$34
Name _Toc175818090: 'Relational DB'!$L$59
Name _Toc175818091: 'Relational DB'!$L$84
Name _Toc175818092: 'Relational DB'!$L$109
Name _Toc175818093: 'Relational DB'!$L$134
Name _Toc175818094: 'Relational DB'!$L$159
Name _Toc175818098: 'Relational DB'!$L$10
Name _Toc175818099: 'Relational DB'!$L$35
Name _Toc175818100: 'Relational DB'!$L$60
Name _Toc175818101: 'Relational DB'!$L$85
Name _Toc175818102: 'Relational DB'!$L$110
Name _Toc175818103: 'Relational DB'!$L$135
Name _Toc175818104: 'Relational DB'!$L$160
Name _Toc175818108: 'Relational DB'!$L$11
Name _Toc175818109: 'Relational DB'!$L$36
Name _Toc175818110: 'Relational DB'!$L$61
Name _Toc175818111: 'Relational DB'!$L$86
Name _Toc175818112: 'Relational DB'!$L$111
Name _Toc175818113: 'Relational DB'!$L$136
Name _Toc175818114: 'Relational DB'!$L$161
Name _Toc175818118: 'Relational DB'!$L$12
Name _Toc175818119: 'Relational DB'!$L$37

Sheet Cover Page
A1: Code | B1: SYB_19_2_5
A2: Version | B2: V1
A3: اسم القالب | B3: الأطباء المسجّلون في نقابة الأطباء حسب الاختصاص والجنس ونوع القطاع
A4: Template Name | B4: Physicians Registered at the Physicians Syndicate by Specialization, Sex and Kind of Sector
A5: دورية البيانات | B5: سنوي
A6: Data Frequency | B6: Annual
A7: الجهة المصدرية | B7: نقابة الأطباء الأردنيين
A8: Data Source | B8: Jordanian Medical Syndicate

Sheet Source Table
B2: ='Cover Page'!B4 -> Physicians Registered at the Physicians Syndicate by Specialization, Sex and Kind of Sector
B3: ='Cover Page'!B3 -> الأطباء المسجّلون في نقابة الأطباء حسب الاختصاص والجنس ونوع القطاع
B4: Year | F4: =YEAR('Template Data'!B1) -> 2024 | I4: السنة
B5: Specialization | C5: آخرون | E5: القطاع الخاص | G5: القطاع العام | I5: التخصص
C6: Others | E6: Private Sector | G6: Public Sector
C7: أنثى | D7: ذكر | E7: أنثى | F7: ذكر | G7: أنثى | H7: ذكر
C8: Female | D8: Male | E8: Female | F8: Male | G8: Female | H8: Male
B9: General Practitioner | I9: طبيب عام
B10: Surgeon | I10: جراحة عامة
B11: Internist | I11: باطنية
B12: Gynecologist and Obst. | I12: نسائية وتوليد
B13: Pediatrics | I13: أطفال
B14: Ophthalmologist | I14: العيون
B15: Orthopedic Surg. | I15: العظام
B16: E.N.T.Surg. | I16: أذن وأنف وحنجرة
B17: Neurosurgery | I17: جراحةأعصاب
B18: Cardiothoracic | I18: جراحة قلب
B19: Plastic Surgeon | I19: التجميل
B20: Psychiatry | I20: النفسية
... B33: Others | I33: أخرى

Sheet Relational DB
A1: Relational Sheet
A2: Measure_Name_Ar | B2: Measure_Name_En | C2: Measure_ID | D2: Unit_EN | E2: Unit_AR | F2: CL_SECTOR_EN_V2 | G2: CL_SECTOR_AR_V2 | H2: CL_SEX_EN_V1 | I2: CL_SEX_AR_V1 | J2: CL_PHY_SPECALIZATION_EN_V1 | K2: CL_PHY_SPECALIZATION_AR_V1 | L2: Obs_Value | M2: Time_Period_Y | N2: Time_Period_M
A3: اسم المؤشر | B3: Measure Name | C3: رمز المؤشر | D3: Unit | E3: الوحدة | F3: Sector | G3: القطاع | H3: Sex | I3: الجنس | J3: Physicians Specialization | K3: التخصص الطبي | L3: قيمة المؤشر | M3: سنة فترة القياس | N3: شهر فترة القياس
A4: الأطباء المسجّلون في نقابة الأطباء | B4: Physicians Registered at the Physicians Syndicate | C4: M1 | D4: Number | E4: عدد | F4: ='Source Table'!$G$6 -> Public Sector | G4: ='Source Table'!$G$5 -> القطاع العام | H4: ='Source Table'!$H$8 -> Male | I4: ='Source Table'!$H$7 -> ذكر | J4: ='Source Table'!$B$9 -> General Practitioner | K4: ='Source Table'!$I$9 -> طبيب عام | L4: 4402 | M4: 2023
A5: الأطباء المسجّلون في نقابة الأطباء | B5: Physicians Registered at the Physicians Syndicate | C5: M1 | D5: Number | E5: عدد | F5: ='Source Table'!$G$6 -> Public Sector | G5: ='Source Table'!$G$5 -> القطاع العام | H5: ='Source Table'!$H$8 -> Male | I5: ='Source Table'!$H$7 -> ذكر | J5: ='Source Table'!$B$10 -> Surgeon | K5: ='Source Table'!$I$10 -> جراحة عامة | L5: 655 | M5: 2023
A6: الأطباء المسجّلون في نقابة الأطباء | B6: Physicians Registered at the Physicians Syndicate | C6: M1 | D6: Number | E6: عدد | F6: ='Source Table'!$G$6 -> Public Sector | G6: ='Source Table'!$G$5 -> القطاع العام | H6: ='Source Table'!$H$8 -> Male | I6: ='Source Table'!$H$7 -> ذكر | J6: ='Source Table'!$B$11 -> Internist | K6: ='Source Table'!$I$11 -> باطنية | L6: 487 | M6: 2023
A7: الأطباء المسجّلون في نقابة الأطباء | B7: Physicians Registered at the Physicians Syndicate | C7: M1 | D7: Number | E7: عدد | F7: ='Source Table'!$G$6 -> Public Sector | G7: ='Source Table'!$G$5 -> القطاع العام | H7: ='Source Table'!$H$8 -> Male | I7: ='Source Table'!$H$7 -> ذكر | J7: ='Source Table'!$B$12 -> Gynecologist and Obst. | K7: ='Source Table'!$I$12 -> نسائية وتوليد | L7: 250 | M7: 2023
A8: الأطباء المسجّلون في نقابة الأطباء | B8: Physicians Registered at the Physicians Syndicate | C8: M1 | D8: Number | E8: عدد | F8: ='Source Table'!$G$6 -> Public Sector | G8: ='Source Table'!$G$5 -> القطاع العام | H8: ='Source Table'!$H$8 -> Male | I8: ='Source Table'!$H$7 -> ذكر | J8: ='Source Table'!$B$13 -> Pediatrics | K8: ='Source Table'!$I$13 -> أطفال | L8: 319 | M8: 2023
A9: الأطباء المسجّلون في نقابة الأطباء | B9: Physicians Registered at the Physicians Syndicate | C9: M1 | D9: Number | E9: عدد | F9: ='Source Table'!$G$6 -> Public Sector | G9: ='Source Table'!$G$5 -> القطاع العام | H9: ='Source Table'!$H$8 -> Male | I9: ='Source Table'!$H$7 -> ذكر | J9: ='Source Table'!$B$14 -> Ophthalmologist | K9: ='Source Table'!$I$14 -> العيون | L9: 201 | M9: 2023
A10: الأطباء المسجّلون في نقابة الأطباء | B10: Physicians Registered at the Physicians Syndicate | C10: M1 | D10: Number | E10: عدد | F10: ='Source Table'!$G$6 -> Public Sector | G10: ='Source Table'!$G$5 -> القطاع العام | H10: ='Source Table'!$H$8 -> Male | I10: ='Source Table'!$H$7 -> ذكر | J10: ='Source Table'!$B$15 -> Orthopedic Surg. | K10: ='Source Table'!$I$15 -> العظام | L10: 315 | M10: 2023
A11: الأطباء المسجّلون في نقابة الأطباء | B11: Physicians Registered at the Physicians Syndicate | C11: M1 | D11: Number | E11: عدد | F11: ='Source Table'!$G$6 -> Public Sector | G11: ='Source Table'!$G$5 -> القطاع العام | H11: ='Source Table'!$H$8 -> Male | I11: ='Source Table'!$H$7 -> ذكر | J11: ='Source Table'!$B$16 -> E.N.T.Surg. | K11: ='Source Table'!$I$16 -> أذن وأنف وحنجرة | L11: 195 | M11: 2023
A12: الأطباء المسجّلون في نقابة الأطباء | B12: Physicians Registered at the Physicians Syndicate | C12: M1 | D12: Number | E12: عدد | F12: ='Source Table'!$G$6 -> Public Sector | G12: ='Source Table'!$G$5 -> القطاع العام | H12: ='Source Table'!$H$8 -> Male | I12: ='Source Table'!$H$7 -> ذكر | J12: ='Source Table'!$B$17 -> Neurosurgery | K12: ='Source Table'!$I$17 -> جراحةأعصاب | L12: 66 | M12: 2023
A13: الأطباء المسجّلون في نقابة الأطباء | B13: Physicians Registered at the Physicians Syndicate | C13: M1 | D13: Number | E13: عدد | F13: ='Source Table'!$G$6 -> Public Sector | G13: ='Source Table'!$G$5 -> القطاع العام | H13: ='Source Table'!$H$8 -> Male | I13: ='Source Table'!$H$7 -> ذكر | J13: ='Source Table'!$B$18 -> Cardiothoracic | K13: ='Source Table'!$I$18 -> جراحة قلب | L13: 27 | M13: 2023
A14: الأطباء المسجّلون في نقابة الأطباء | B14: Physicians Registered at the Physicians Syndicate | C14: M1 | D14: Number | E14: عدد | F14: ='Source Table'!$G$6 -> Public Sector | G14: ='Source Table'!$G$5 -> القطاع العام | H14: ='Source Table'!$H$8 -> Male | I14: ='Source Table'!$H$7 -> ذكر | J14: ='Source Table'!$B$19 -> Plastic Surgeon | K14: ='Source Table'!$I$19 -> التجميل | L14: 26 | M14: 2023
A15: الأطباء المسجّلون في نقابة الأطباء | B15: Physicians Registered at the Physicians Syndicate | C15: M1 | D15: Number | E15: عدد | F15: ='Source Table'!$G$6 -> Public Sector | G15: ='Source Table'!$G$5 -> القطاع العام | H15: ='Source Table'!$H$8 -> Male | I15: ='Source Table'!$H$7 -> ذكر | J15: ='Source Table'!$B$20 -> Psychiatry | K15: ='Source Table'!$I$20 -> النفسية | L15: 70 | M15: 2023
A16: الأطباء المسجّلون في نقابة الأطباء | B16: Physicians Registered at the Physicians Syndicate | C16: M1 | D16: Number | E16: عدد | F16: ='Source Table'!$G$6 -> Public Sector | G16: ='Source Table'!$G$5 -> القطاع العام | H16: ='Source Table'!$H$8 -> Male | I16: ='Source Table'!$H$7 -> ذكر | J16: ='Source Table'!$B$21 -> Dermatologist Venereal | K16: ='Source Table'!$I$21 -> جلدية وتناسلية | L16: 87 | M16: 2023
A17: الأطباء المسجّلون في نقابة الأطباء | B17: Physicians Registered at the Physicians Syndicate | C17: M1 | D17: Number | E17: عدد | F17: ='Source Table'!$G$6 -> Public Sector | G17: ='Source Table'!$G$5 -> القطاع العام | H17: ='Source Table'!$H$8 -> Male | I17: ='Source Table'!$H$7 -> ذكر | J17: ='Source Table'!$B$22 -> Neurology/ Nervous | K17: ='Source Table'!$I$22 -> مرض الأعصاب | L17: 21 | M17: 2023
A18: الأطباء المسجّلون في نقابة الأطباء | B18: Physicians Registered at the Physicians Syndicate | C18: M1 | D18: Number | E18: عدد | F18: ='Source Table'!$G$6 -> Public Sector | G18: ='Source Table'!$G$5 -> القطاع العام | H18: ='Source Table'!$H$8 -> Male | I18: ='Source Table'!$H$7 -> ذكر | J18: ='Source Table'!$B$23 -> Pumologist | K18: ='Source Table'!$I$23 -> صدرية | L18: 21 | M18: 2023
A19: الأطباء المسجّلون في نقابة الأطباء | B19: Physicians Registered at the Physicians Syndicate | C19: M1 | D19: Number | E19: عدد | F19: ='Source Table'!$G$6 -> Public Sector | G19: ='Source Table'!$G$5 -> القطاع العام | H19: ='Source Table'!$H$8 -> Male | I19: ='Source Table'!$H$7 -> ذكر | J19: ='Source Table'!$B$24 -> G.I.T. Specialist | K19: ='Source Table'!$I$24 -> جهاز هضمي | L19: 27 | M19: 2023
A20: الأطباء المسجّلون في نقابة الأطباء | B20: Physicians Registered at the Physicians Syndicate | C20: M1 | D20: Number | E20: عدد | F20: ='Source Table'!$G$6 -> Public Sector | G20: ='Source Table'!$G$5 -> القطاع العام | H20: ='Source Table'!$H$8 -> Male | I20: ='Source Table'!$H$7 -> ذكر | J20: ='Source Table'!$B$25 -> Diagnostic Radiology | K20: ='Source Table'!$I$25 -> أشعة تشخيصية | L20: 178 | M20: 2023
A21: الأطباء المسجّلون في نقابة الأطباء | B21: Physicians Registered at the Physicians Syndicate | C21: M1 | D21: Number | E21: عدد | F21: ='Source Table'!$G$6 -> Public Sector | G21: ='Source Table'!$G$5 -> القطاع العام | H21: ='Source Table'!$H$8 -> Male | I21: ='Source Table'!$H$7 -> ذكر | J21: ='Source Table'!$B$26 -> Anesthetic | K21: ='Source Table'!$I$26 -> تخدير وإنعاش | L21: 327 | M21: 2023
A22: الأطباء المسجّلون في نقابة الأطباء | B22: Physicians Registered at the Physicians Syndicate | C22: M1 | D22: Number | E22: عدد | F22: ='Source Table'!$G$6 -> Public Sector | G22: ='Source Table'!$G$5 -> القطاع العام | H22: ='Source Table'!$H$8 -> Male | I22: ='Source Table'!$H$7 -> ذكر | J22: ='Source Table'!$B$27 -> Physiotherapist | K22: ='Source Table'!$I$27 -> طب طبيعي | L22: 62 | M22: 2023
A23: الأطباء المسجّلون في نقابة الأطباء | B23: Physicians Registered at the Physicians Syndicate | C23: M1 | D23: Number | E23: عدد | F23: ='Source Table'!$G$6 -> Public Sector | G23: ='Source Table'!$G$5 -> القطاع العام | H23: ='Source Table'!$H$8 -> Male | I23: ='Source Table'!$H$7 -> ذكر | J23: ='Source Table'!$B$28 -> Forensic | K23: ='Source Table'!$I$28 -> طب شرعي | L23: 41 | M23: 2023
A24: الأطباء المسجّلون في نقابة الأطباء | B24: Physicians Registered at the Physicians Syndicate | C24: M1 | D24: Number | E24: عدد | F24: ='Source Table'!$G$6 -> Public Sector | G24: ='Source Table'!$G$5 -> القطاع العام | H24: ='Source Table'!$H$8 -> Male | I24: ='Source Table'!$H$7 -> ذكر | J24: ='Source Table'!$B$29 -> Family | K24: ='Source Table'!$I$29 -> طب أسرة | L24: 122 | M24: 2023
A25: الأطباء المسجّلون في نقابة الأطباء | B25: Physicians Registered at the Physicians Syndicate | C25: M1 | D25: Number | E25: عدد | F25: ='Source Table'!$G$6 -> Public Sector | G25: ='Source Table'!$G$5 -> القطاع العام | H25: ='Source Table'!$H$8 -> Male | I25: ='Source Table'!$H$7 -> ذكر | J25: ='Source Table'!$B$30 -> Urologist | K25: ='Source Table'!$I$30 -> المسالك البولية | L25: 123 | M25: 2023
A26: الأطباء المسجّلون في نقابة الأطباء | B26: Physicians Registered at the Physicians Syndicate | C26: M1 | D26: Number | E26: عدد | F26: ='Source Table'!$G$6 -> Public Sector | G26: ='Source Table'!$G$5 -> القطاع العام | H26: ='Source Table'!$H$8 -> Male | I26: ='Source Table'!$H$7 -> ذكر | J26: ='Source Table'!$B$31 -> Cardiology | K26: ='Source Table'!$I$31 -> أمراض القلب | L26: 44 | M26: 2023
A27: الأطباء المسجّلون في نقابة الأطباء | B27: Physicians Registered at the Physicians Syndicate | C27: M1 | D27: Number | E27: عدد | F27: ='Source Table'!$G$6 -> Public Sector | G27: ='Source Table'!$G$5 -> القطاع العام | H27: ='Source Table'!$H$8 -> Male | I27: ='Source Table'!$H$7 -> ذكر | J27: ='Source Table'!$B$32 -> Laboratory | K27: ='Source Table'!$I$32 -> مختبرات | L27: 20 | M27: 2023
A28: الأطباء المسجّلون في نقابة الأطباء | B28: Physicians Registered at the Physicians Syndicate | C28: M1 | D28: Number | E28: عدد | F28: ='Source Table'!$G$6 -> Public Sector | G28: ='Source Table'!$G$5 -> القطاع العام | H28: ='Source Table'!$H$8 -> Male | I28: ='Source Table'!$H$7 -> ذكر | J28: ='Source Table'!$B$33 -> Others | K28: ='Source Table'!$I$33 -> أخرى | L28: 571 | M28: 2023
A29: الأطباء المسجّلون في نقابة الأطباء | B29: Physicians Registered at the Physicians Syndicate | C29: M1 | D29: Number | E29: عدد | F29: ='Source Table'!$G$6 -> Public Sector | G29: ='Source Table'!$G$5 -> القطاع العام | H29: ='Source Table'!$G$8 -> Female | I29: ='Source Table'!$G$7 -> أنثى | J29: ='Source Table'!$B$9 -> General Practitioner | K29: ='Source Table'!$I$9 -> طبيب عام | L29: 1032 | M29: 2023
A30: الأطباء المسجّلون في نقابة الأطباء | B30: Physicians Registered at the Physicians Syndicate | C30: M1 | D30: Number | E30: عدد | F30: ='Source Table'!$G$6 -> Public Sector | G30: ='Source Table'!$G$5 -> القطاع العام | H30: ='Source Table'!$G$8 -> Female | I30: ='Source Table'!$G$7 -> أنثى | J30: ='Source Table'!$B$10 -> Surgeon | K30: ='Source Table'!$I$10 -> جراحة عامة | L30: 27 | M30: 2023
A31: الأطباء المسجّلون في نقابة الأطباء | B31: Physicians Registered at the Physicians Syndicate | C31: M1 | D31: Number | E31: عدد | F31: ='Source Table'!$G$6 -> Public Sector | G31: ='Source Table'!$G$5 -> القطاع العام | H31: ='Source Table'!$G$8 -> Female | I31: ='Source Table'!$G$7 -> أنثى | J31: ='Source Table'!$B$11 -> Internist | K31: ='Source Table'!$I$11 -> باطنية | L31: 80 | M31: 2023
A32: الأطباء المسجّلون في نقابة الأطباء | B32: Physicians Registered at the Physicians Syndicate | C32: M1 | D32: Number | E32: عدد | F32: ='Source Table'!$G$6 -> Public Sector | G32: ='Source Table'!$G$5 -> القطاع العام | H32: ='Source Table'!$G$8 -> Female | I32: ='Source Table'!$G$7 -> أنثى | J32: ='Source Table'!$B$12 -> Gynecologist and Obst. | K32: ='Source Table'!$I$12 -> نسائية وتوليد | L32: 139 | M32: 2023
A33: الأطباء المسجّلون في نقابة الأطباء | B33: Physicians Registered at the Physicians Syndicate | C33: M1 | D33: Number | E33: عدد | F33: ='Source Table'!$G$6 -> Public Sector | G33: ='Source Table'!$G$5 -> القطاع العام | H33: ='Source Table'!$G$8 -> Female | I33: ='Source Table'!$G$7 -> أنثى | J33: ='Source Table'!$B$13 -> Pediatrics | K33: ='Source Table'!$I$13 -> أطفال | L33: 202 | M33: 2023
A34: الأطباء المسجّلون في نقابة الأطباء | B34: Physicians Registered at the Physicians Syndicate | C34: M1 | D34: Number | E34: عدد | F34: ='Source Table'!$G$6 -> Public Sector | G34: ='Source Table'!$G$5 -> القطاع العام | H34: ='Source Table'!$G$8 -> Female | I34: ='Source Table'!$G$7 -> أنثى | J34: ='Source Table'!$B$14 -> Ophthalmologist | K34: ='Source Table'!$I$14 -> العيون | L34: 92 | M34: 2023
A35: الأطباء المسجّلون في نقابة الأطباء | B35: Physicians Registered at the Physicians Syndicate | C35: M1 | D35: Number | E35: عدد | F35: ='Source Table'!$G$6 -> Public Sector | G35: ='Source Table'!$G$5 -> القطاع العام | H35: ='Source Table'!$G$8 -> Female | I35: ='Source Table'!$G$7 -> أنثى | J35: ='Source Table'!$B$15 -> Orthopedic Surg. | K35: ='Source Table'!$I$15 -> العظام | L35: 0 | M35: 2023
A36: الأطباء المسجّلون في نقابة الأطباء | B36: Physicians Registered at the Physicians Syndicate | C36: M1 | D36: Number | E36: عدد | F36: ='Source Table'!$G$6 -> Public Sector | G36: ='Source Table'!$G$5 -> القطاع العام | H36: ='Source Table'!$G$8 -> Female | I36: ='Source Table'!$G$7 -> أنثى | J36: ='Source Table'!$B$16 -> E.N.T.Surg. | K36: ='Source Table'!$I$16 -> أذن وأنف وحنجرة | L36: 35 | M36: 2023
A37: الأطباء المسجّلون في نقابة الأطباء | B37: Physicians Registered at the Physicians Syndicate | C37: M1 | D37: Number | E37: عدد | F37: ='Source Table'!$G$6 -> Public Sector | G37: ='Source Table'!$G$5 -> القطاع العام | H37: ='Source Table'!$G$8 -> Female | I37: ='Source Table'!$G$7 -> أنثى | J37: ='Source Table'!$B$17 -> Neurosurgery | K37: ='Source Table'!$I$17 -> جراحةأعصاب | L37: 1 | M37: 2023
A38: الأطباء المسجّلون في نقابة الأطباء | B38: Physicians Registered at the Physicians Syndicate | C38: M1 | D38: Number | E38: عدد | F38: ='Source Table'!$G$6 -> Public Sector | G38: ='Source Table'!$G$5 -> القطاع العام | H38: ='Source Table'!$G$8 -> Female | I38: ='Source Table'!$G$7 -> أنثى | J38: ='Source Table'!$B$18 -> Cardiothoracic | K38: ='Source Table'!$I$18 -> جراحة قلب | L38: 0 | M38: 2023
A39: الأطباء المسجّلون في نقابة الأطباء | B39: Physicians Registered at the Physicians Syndicate | C39: M1 | D39: Number | E39: عدد | F39: ='Source Table'!$G$6 -> Public Sector | G39: ='Source Table'!$G$5 -> القطاع العام | H39: ='Source Table'!$G$8 -> Female | I39: ='Source Table'!$G$7 -> أنثى | J39: ='Source Table'!$B$19 -> Plastic Surgeon | K39: ='Source Table'!$I$19 -> التجميل | L39: 0 | M39: 2023
A40: الأطباء المسجّلون في نقابة الأطباء | B40: Physicians Registered at the Physicians Syndicate | C40: M1 | D40: Number | E40: عدد | F40: ='Source Table'!$G$6 -> Public Sector | G40: ='Source Table'!$G$5 -> القطاع العام | H40: ='Source Table'!$G$8 -> Female | I40: ='Source Table'!$G$7 -> أنثى | J40: ='Source Table'!$B$20 -> Psychiatry | K40: ='Source Table'!$I$20 -> النفسية | L40: 16 | M40: 2023
...

Sheet Template Data
A1: Date | B1: =DATE(B2,B3,1) -> 45292
A2: Year | B2: 2024
A3: Month | B3: 1
A4: Measure_Name_Ar | B4: Measure_Name_En | C4: Measure_ID | D4: Unit_EN | E4: Unit_AR | F4: CL_SECTOR_EN_V2 | G4: CL_SECTOR_AR_V2 | H4: CL_SEX_EN_V1 | I4: CL_SEX_AR_V1 | J4: CL_PHY_SPECALIZATION_EN_V1 | K4: CL_PHY_SPECALIZATION_AR_V1 | L4: Obs_Value | M4: Time_Period_Y | N4: Time_Period_M
A5: اسم المؤشر | B5: Measure Name | C5: رمز المؤشر | D5: Unit | E5: الوحدة | F5: Sector | G5: القطاع | H5: Sex | I5: الجنس | J5: Physicians Specialization | K5: التخصص الطبي | L5: قيمة المؤشر | M5: سنة فترة القياس | N5: شهر فترة القياس

Sheet Help
A2: Step 1: Cover Page | C2: الخطوة 1: Cover Page
A4: Update the template information, to ensure that any meta-information about the template, such as the title, version, and description, is accurate and up-to-date. | C4: قم بتحديث معلومات القالب للتأكد من أن أي معلومات وصفية حول القالب، مثل العنوان والإصدار والوصف، دقيقة ومحدثة.
A6: Step 2: Source Table | C6: الخطوة 2: Source Table
A8: Design your template, ensuring that the time period is mapped correctly to the date information in rows 1-3 of the Template Data Sheet. | C8: قم بتصميم القالب الخاص بك، مع التأكد من أن فترة الوقت مرتبطة بشكل صحيح مع معلومات التاريخ في الصفوف 1-3 في ورقة Template Data.
A10: Step 3: Relational Sheet | C10: الخطوة 3: Relational Sheet
A12: Unpivot the data in the source table into a flat format. Follow these guidelines: | C12: قم بتحويل البيانات في جدول المصدر إلى تنسيق مسطح. اتبع هذه الإرشادات:
A13: 1. Blue Columns: Do not change the names of the blue columns. Update the data as per the current template. | C13: 1. الأعمدة الزرقاء: لا تقم بتغيير أسماء الأعمدة الزرقاء. قم بتحديث البيانات وفقًا للقالب الحالي.
A14: 2. Code Lists: Use the naming convention CL_XXX_EN_V# for code lists, where XXX is the name, and V# is the version, conforming with the definitions in the data dictionary. | C14: 2. قوائم الرموز: استخدم قاعدة التسمية CL_XXX_EN_V# لقوائم الرموز، حيث أن XXX هو الاسم و V# هو الإصدار، وفقًا للتعريفات في قاموس البيانات.
A15: 3. Code List Values: Ensure the code list values match the definitions in the data dictionary. | C15: 3. قيم قائمة الرموز: تأكد من أن قيم قائمة الرموز تتوافق مع التعريفات في قاموس البيانات.
A16: 4. Time_Period_M: Leave empty if the data frequency is yearly. | C16: 4. Time_Period_M: اتركها فارغة إذا كانت دورية البيانات سنوية.
A17: 5. Time_Period_M Format: Use one of these formats: | C17: 5. تنسيق Time_Period_M: استخدم أحد التنسيقات التالية:
A18: Numeric: (1, 2, 3, ..., 12) for months. | C18: رقمي: (1، 2، 3، ...، 12) للأشهر.
... A38: Protect the entire workbook to prevent unauthorized or accidental changes to the structure of the file. | C38: قم بحماية الكتاب بأكمله لمنع التغييرات غير المصرح بها أو غير المقصودة على هيكل الملف.
