Workbook
Name _Toc175817829: 'Relational DB'!$L$34
Name _Toc175817830: 'Relational DB'!$L$28
Name _Toc175817831: 'Relational DB'!$L$22
Name _Toc175817832: 'Relational DB'!$L$16
Name _Toc175817833: 'Relational DB'!$L$10
Name _Toc175817834: 'Relational DB'!$L$4
Name _Toc175817840: 'Relational DB'!$L$35
Name _Toc175817841: 'Relational DB'!$L$29
Name _Toc175817842: 'Relational DB'!$L$23
Name _Toc175817843: 'Relational DB'!$L$17
Name _Toc175817844: 'Relational DB'!$L$11
Name _Toc175817845: 'Relational DB'!$L$5
Name _Toc175817851: 'Relational DB'!$L$36
Name _Toc175817852: 'Relational DB'!$L$30
Name _Toc175817853: 'Relational DB'!$L$24
Name _Toc175817854: 'Relational DB'!$L$18
Name _Toc175817855: 'Relational DB'!$L$12
Name _Toc175817856: 'Relational DB'!$L$6
Name _Toc175817862: 'Relational DB'!$L$37
Name _Toc175817863: 'Relational DB'!$L$31
Name _Toc175817864: 'Relational DB'!$L$25
Name _Toc175817865: 'Relational DB'!$L$19
Name _Toc175817866: 'Relational DB'!$L$13
Name _Toc175817867: 'Relational DB'!$L$7
Name _Toc175817873: 'Relational DB'!$L$38
Name _Toc175817874: 'Relational DB'!$L$32
Name _Toc175817875: 'Relational DB'!$L$26
Name _Toc175817876: 'Relational DB'!$L$20
Name _Toc175817877: 'Relational DB'!$L$14
Name _Toc175817878: 'Relational DB'!$L$8
Name _Toc175817884: 'Relational DB'!$L$39
Name _Toc175817885: 'Relational DB'!$L$33
Name _Toc175817886: 'Relational DB'!$L$27
Name _Toc175817887: 'Relational DB'!$L$21
Name _Toc175817888: 'Relational DB'!$L$15
Name _Toc175817889: 'Relational DB'!$L$9

Sheet Cover Page
A1: Code | B1: SYB_19_2_2
A2: Version | B2: V1
A3: اسم القالب | B3: المهندسون المسجّلون في نقابة المهندسين الأردنيين حسب التخصص والجنس والجنسية
A4: Template Name | B4: Engineers Registered at the Jordanian Engineers Syndicate by Specialization, Sex and NationalitySocially Insured Employees by Economic Activity
A5: دورية البيانات | B5: سنوي
A6: Data Frequency | B6: Annual
A7: الجهة المصدرية | B7: نقابة المهندسين الأردنيين
A8: Data Source | B8: Jordanian Engineers Syndicate

Sheet Source Table
B2: ='Cover Page'!B4 -> Engineers Registered at the Jordanian Engineers Syndicate by Specialization, Sex and NationalitySocially Insured Employees by Economic Activity
B3: ='Cover Page'!B3 -> المهندسون المسجّلون في نقابة المهندسين الأردنيين حسب التخصص والجنس والجنسية
B4: Year | E4: =YEAR('Template Data'!B1) -> 2024 | I4: السنة
B5: Specialization | C5: أنثى | F5: ذكر | I5: التخصص
C6: Female | F6: Male
C7: أجنبي | D7: عربي | E7: أردني | F7: أجنبي | G7: عربي | H7: أردني
C8: Foreign | D8: Arab | E8: Jordanian | F8: Foreign | G8: Arab | H8: Jordanian
B9: Civil | I9: مدني
B10: Architecture | I10: عمارة
B11: Mechanical | I11: ميكانيك
B12: Electricity | I12: كهرباء
B13: Mining | I13: تعدين
B14: Chemistry | I14: كيمياء

Sheet Relational DB
A1: Relational Sheet
A2: Measure_Name_Ar | B2: Measure_Name_En | C2: Measure_ID | D2: Unit_EN | E2: Unit_AR | F2: CL_SEX_EN_V1 | G2: CL_SEX_AR_V1 | H2: CL_NATIONALITY_EN_V4 | I2: CL_NATIONALITY_AR_V4 | J2: CL_ENG_SPECALIZATION_EN_V1 | K2: CL_ENG_SPECALIZATION_AR_V1 | L2: Obs_Value | M2: Time_Period_Y | N2: Time_Period_M
A3: اسم المؤشر | B3: Measure Name | C3: رمز المؤشر | D3: Unit | E3: الوحدة | F3: Sex | G3: الجنس | H3: Nationality | I3: الجنسية | J3: Engineers Specialization | K3: التخصص الهندسي | L3: قيمة المؤشر | M3: سنة فترة القياس | N3: شهر فترة القياس
A4: المهندسون المسجّلون في نقابة المهندسين الأردنيين | B4: Engineers Registered at the Jordanian Engineers Syndicate | C4: M1 | D4: Number | E4: عدد | F4: ='Source Table'!$F$6 -> Male | G4: ='Source Table'!$F$5 -> ذكر | H4: ='Source Table'!$H$8 -> Jordanian | I4: ='Source Table'!$H$7 -> أردني | J4: ='Source Table'!$B$9 -> Civil | K4: ='Source Table'!$I$9 -> مدني | L4: 43403 | M4: 2023
A5: المهندسون المسجّلون في نقابة المهندسين الأردنيين | B5: Engineers Registered at the Jordanian Engineers Syndicate | C5: M1 | D5: Number | E5: عدد | F5: ='Source Table'!$F$6 -> Male | G5: ='Source Table'!$F$5 -> ذكر | H5: ='Source Table'!$H$8 -> Jordanian | I5: ='Source Table'!$H$7 -> أردني | J5: ='Source Table'!$B$10 -> Architecture | K5: ='Source Table'!$I$10 -> عمارة | L5: 7426 | M5: 2023
A6: المهندسون المسجّلون في نقابة المهندسين الأردنيين | B6: Engineers Registered at the Jordanian Engineers Syndicate | C6: M1 | D6: Number | E6: عدد | F6: ='Source Table'!$F$6 -> Male | G6: ='Source Table'!$F$5 -> ذكر | H6: ='Source Table'!$H$8 -> Jordanian | I6: ='Source Table'!$H$7 -> أردني | J6: ='Source Table'!$B$11 -> Mechanical | K6: ='Source Table'!$I$11 -> ميكانيك | L6: 33568 | M6: 2023
A7: المهندسون المسجّلون في نقابة المهندسين الأردنيين | B7: Engineers Registered at the Jordanian Engineers Syndicate | C7: M1 | D7: Number | E7: عدد | F7: ='Source Table'!$F$6 -> Male | G7: ='Source Table'!$F$5 -> ذكر | H7: ='Source Table'!$H$8 -> Jordanian | I7: ='Source Table'!$H$7 -> أردني | J7: ='Source Table'!$B$12 -> Electricity | K7: ='Source Table'!$I$12 -> كهرباء | L7: 47232 | M7: 2023
A8: المهندسون المسجّلون في نقابة المهندسين الأردنيين | B8: Engineers Registered at the Jordanian Engineers Syndicate | C8: M1 | D8: Number | E8: عدد | F8: ='Source Table'!$F$6 -> Male | G8: ='Source Table'!$F$5 -> ذكر | H8: ='Source Table'!$H$8 -> Jordanian | I8: ='Source Table'!$H$7 -> أردني | J8: ='Source Table'!$B$13 -> Mining | K8: ='Source Table'!$I$13 -> تعدين | L8: 1520 | M8: 2023
A9: المهندسون المسجّلون في نقابة المهندسين الأردنيين | B9: Engineers Registered at the Jordanian Engineers Syndicate | C9: M1 | D9: Number | E9: عدد | F9: ='Source Table'!$F$6 -> Male | G9: ='Source Table'!$F$5 -> ذكر | H9: ='Source Table'!$H$8 -> Jordanian | I9: ='Source Table'!$H$7 -> أردني | J9: ='Source Table'!$B$14 -> Chemistry | K9: ='Source Table'!$I$14 -> كيمياء | L9: 4540 | M9: 2023
A10: المهندسون المسجّلون في نقابة المهندسين الأردنيين | B10: Engineers Registered at the Jordanian Engineers Syndicate | C10: M1 | D10: Number | E10: عدد | F10: ='Source Table'!$F$6 -> Male | G10: ='Source Table'!$F$5 -> ذكر | H10: ='Source Table'!$G$8 -> Arab | I10: ='Source Table'!$G$7 -> عربي | J10: ='Source Table'!$B$9 -> Civil | K10: ='Source Table'!$I$9 -> مدني | L10: 1827 | M10: 2023
A11: المهندسون المسجّلون في نقابة المهندسين الأردنيين | B11: Engineers Registered at the Jordanian Engineers Syndicate | C11: M1 | D11: Number | E11: عدد | F11: ='Source Table'!$F$6 -> Male | G11: ='Source Table'!$F$5 -> ذكر | H11: ='Source Table'!$G$8 -> Arab | I11: ='Source Table'!$G$7 -> عربي | J11: ='Source Table'!$B$10 -> Architecture | K11: ='Source Table'!$I$10 -> عمارة | L11: 604 | M11: 2023
A12: المهندسون المسجّلون في نقابة المهندسين الأردنيين | B12: Engineers Registered at the Jordanian Engineers Syndicate | C12: M1 | D12: Number | E12: عدد | F12: ='Source Table'!$F$6 -> Male | G12: ='Source Table'!$F$5 -> ذكر | H12: ='Source Table'!$G$8 -> Arab | I12: ='Source Table'!$G$7 -> عربي | J12: ='Source Table'!$B$11 -> Mechanical | K12: ='Source Table'!$I$11 -> ميكانيك | L12: 578 | M12: 2023
A13: المهندسون المسجّلون في نقابة المهندسين الأردنيين | B13: Engineers Registered at the Jordanian Engineers Syndicate | C13: M1 | D13: Number | E13: عدد | F13: ='Source Table'!$F$6 -> Male | G13: ='Source Table'!$F$5 -> ذكر | H13: ='Source Table'!$G$8 -> Arab | I13: ='Source Table'!$G$7 -> عربي | J13: ='Source Table'!$B$12 -> Electricity | K13: ='Source Table'!$I$12 -> كهرباء | L13: 971 | M13: 2023
A14: المهندسون المسجّلون في نقابة المهندسين الأردنيين | B14: Engineers Registered at the Jordanian Engineers Syndicate | C14: M1 | D14: Number | E14: عدد | F14: ='Source Table'!$F$6 -> Male | G14: ='Source Table'!$F$5 -> ذكر | H14: ='Source Table'!$G$8 -> Arab | I14: ='Source Table'!$G$7 -> عربي | J14: ='Source Table'!$B$13 -> Mining | K14: ='Source Table'!$I$13 -> تعدين | L14: 17 | M14: 2023
A15: المهندسون المسجّلون في نقابة المهندسين الأردنيين | B15: Engineers Registered at the Jordanian Engineers Syndicate | C15: M1 | D15: Number | E15: عدد | F15: ='Source Table'!$F$6 -> Male | G15: ='Source Table'!$F$5 -> ذكر | H15: ='Source Table'!$G$8 -> Arab | I15: ='Source Table'!$G$7 -> عربي | J15: ='Source Table'!$B$14 -> Chemistry | K15: ='Source Table'!$I$14 -> كيمياء | L15: 62 | M15: 2023
A16: المهندسون المسجّلون في نقابة المهندسين الأردنيين | B16: Engineers Registered at the Jordanian Engineers Syndicate | C16: M1 | D16: Number | E16: عدد | F16: ='Source Table'!$F$6 -> Male | G16: ='Source Table'!$F$5 -> ذكر | H16: ='Source Table'!$F$8 -> Foreign | I16: ='Source Table'!$F$7 -> أجنبي | J16: ='Source Table'!$B$9 -> Civil | K16: ='Source Table'!$I$9 -> مدني | L16: 187 | M16: 2023
A17: المهندسون المسجّلون في نقابة المهندسين الأردنيين | B17: Engineers Registered at the Jordanian Engineers Syndicate | C17: M1 | D17: Number | E17: عدد | F17: ='Source Table'!$F$6 -> Male | G17: ='Source Table'!$F$5 -> ذكر | H17: ='Source Table'!$F$8 -> Foreign | I17: ='Source Table'!$F$7 -> أجنبي | J17: ='Source Table'!$B$10 -> Architecture | K17: ='Source Table'!$I$10 -> عمارة | L17: 39 | M17: 2023
A18: المهندسون المسجّلون في نقابة المهندسين الأردنيين | B18: Engineers Registered at the Jordanian Engineers Syndicate | C18: M1 | D18: Number | E18: عدد | F18: ='Source Table'!$F$6 -> Male | G18: ='Source Table'!$F$5 -> ذكر | H18: ='Source Table'!$F$8 -> Foreign | I18: ='Source Table'!$F$7 -> أجنبي | J18: ='Source Table'!$B$11 -> Mechanical | K18: ='Source Table'!$I$11 -> ميكانيك | L18: 41 | M18: 2023
A19: المهندسون المسجّلون في نقابة المهندسين الأردنيين | B19: Engineers Registered at the Jordanian Engineers Syndicate | C19: M1 | D19: Number | E19: عدد | F19: ='Source Table'!$F$6 -> Male | G19: ='Source Table'!$F$5 -> ذكر | H19: ='Source Table'!$F$8 -> Foreign | I19: ='Source Table'!$F$7 -> أجنبي | J19: ='Source Table'!$B$12 -> Electricity | K19: ='Source Table'!$I$12 -> كهرباء | L19: 33 | M19: 2023
A20: المهندسون المسجّلون في نقابة المهندسين الأردنيين | B20: Engineers Registered at the Jordanian Engineers Syndicate | C20: M1 | D20: Number | E20: عدد | F20: ='Source Table'!$F$6 -> Male | G20: ='Source Table'!$F$5 -> ذكر | H20: ='Source Table'!$F$8 -> Foreign | I20: ='Source Table'!$F$7 -> أجنبي | J20: ='Source Table'!$B$13 -> Mining | K20: ='Source Table'!$I$13 -> تعدين | L20: 3 | M20: 2023
A21: المهندسون المسجّلون في نقابة المهندسين الأردنيين | B21: Engineers Registered at the Jordanian Engineers Syndicate | C21: M1 | D21: Number | E21: عدد | F21: ='Source Table'!$F$6 -> Male | G21: ='Source Table'!$F$5 -> ذكر | H21: ='Source Table'!$F$8 -> Foreign | I21: ='Source Table'!$F$7 -> أجنبي | J21: ='Source Table'!$B$14 -> Chemistry | K21: ='Source Table'!$I$14 -> كيمياء | L21: 4 | M21: 2023
A22: المهندسون المسجّلون في نقابة المهندسين الأردنيين | B22: Engineers Registered at the Jordanian Engineers Syndicate | C22: M1 | D22: Number | E22: عدد | F22: ='Source Table'!$C$6 -> Female | G22: ='Source Table'!$C$5 -> أنثى | H22: ='Source Table'!$H$8 -> Jordanian | I22: ='Source Table'!$H$7 -> أردني | J22: ='Source Table'!$B$9 -> Civil | K22: ='Source Table'!$I$9 -> مدني | L22: 13309 | M22: 2023
A23: المهندسون المسجّلون في نقابة المهندسين الأردنيين | B23: Engineers Registered at the Jordanian Engineers Syndicate | C23: M1 | D23: Number | E23: عدد | F23: ='Source Table'!$C$6 -> Female | G23: ='Source Table'!$C$5 -> أنثى | H23: ='Source Table'!$H$8 -> Jordanian | I23: ='Source Table'!$H$7 -> أردني | J23: ='Source Table'!$B$10 -> Architecture | K23: ='Source Table'!$I$10 -> عمارة | L23: 9462 | M23: 2023
A24: المهندسون المسجّلون في نقابة المهندسين الأردنيين | B24: Engineers Registered at the Jordanian Engineers Syndicate | C24: M1 | D24: Number | E24: عدد | F24: ='Source Table'!$C$6 -> Female | G24: ='Source Table'!$C$5 -> أنثى | H24: ='Source Table'!$H$8 -> Jordanian | I24: ='Source Table'!$H$7 -> أردني | J24: ='Source Table'!$B$11 -> Mechanical | K24: ='Source Table'!$I$11 -> ميكانيك | L24: 5380 | M24: 2023
A25: المهندسون المسجّلون في نقابة المهندسين الأردنيين | B25: Engineers Registered at the Jordanian Engineers Syndicate | C25: M1 | D25: Number | E25: عدد | F25: ='Source Table'!$C$6 -> Female | G25: ='Source Table'!$C$5 -> أنثى | H25: ='Source Table'!$H$8 -> Jordanian | I25: ='Source Table'!$H$7 -> أردني | J25: ='Source Table'!$B$12 -> Electricity | K25: ='Source Table'!$I$12 -> كهرباء | L25: 18011 | M25: 2023
A26: المهندسون المسجّلون في نقابة المهندسين الأردنيين | B26: Engineers Registered at the Jordanian Engineers Syndicate | C26: M1 | D26: Number | E26: عدد | F26: ='Source Table'!$C$6 -> Female | G26: ='Source Table'!$C$5 -> أنثى | H26: ='Source Table'!$H$8 -> Jordanian | I26: ='Source Table'!$H$7 -> أردني | J26: ='Source Table'!$B$13 -> Mining | K26: ='Source Table'!$I$13 -> تعدين | L26: 153 | M26: 2023
A27: المهندسون المسجّلون في نقابة المهندسين الأردنيين | B27: Engineers Registered at the Jordanian Engineers Syndicate | C27: M1 | D27: Number | E27: عدد | F27: ='Source Table'!$C$6 -> Female | G27: ='Source Table'!$C$5 -> أنثى | H27: ='Source Table'!$H$8 -> Jordanian | I27: ='Source Table'!$H$7 -> أردني | J27: ='Source Table'!$B$14 -> Chemistry | K27: ='Source Table'!$I$14 -> كيمياء | L27: 5253 | M27: 2023
A28: المهندسون المسجّلون في نقابة المهندسين الأردنيين | B28: Engineers Registered at the Jordanian Engineers Syndicate | C28: M1 | D28: Number | E28: عدد | F28: ='Source Table'!$C$6 -> Female | G28: ='Source Table'!$C$5 -> أنثى | H28: ='Source Table'!$G$8 -> Arab | I28: ='Source Table'!$G$7 -> عربي | J28: ='Source Table'!$B$9 -> Civil | K28: ='Source Table'!$I$9 -> مدني | L28: 196 | M28: 2023
A29: المهندسون المسجّلون في نقابة المهندسين الأردنيين | B29: Engineers Registered at the Jordanian Engineers Syndicate | C29: M1 | D29: Number | E29: عدد | F29: ='Source Table'!$C$6 -> Female | G29: ='Source Table'!$C$5 -> أنثى | H29: ='Source Table'!$G$8 -> Arab | I29: ='Source Table'!$G$7 -> عربي | J29: ='Source Table'!$B$10 -> Architecture | K29: ='Source Table'!$I$10 -> عمارة | L29: 359 | M29: 2023
A30: المهندسون المسجّلون في نقابة المهندسين الأردنيين | B30: Engineers Registered at the Jordanian Engineers Syndicate | C30: M1 | D30: Number | E30: عدد | F30: ='Source Table'!$C$6 -> Female | G30: ='Source Table'!$C$5 -> أنثى | H30: ='Source Table'!$G$8 -> Arab | I30: ='Source Table'!$G$7 -> عربي | J30: ='Source Table'!$B$11 -> Mechanical | K30: ='Source Table'!$I$11 -> ميكانيك | L30: 34 | M30: 2023
A31: المهندسون المسجّلون في نقابة المهندسين الأردنيين | B31: Engineers Registered at the Jordanian Engineers Syndicate | C31: M1 | D31: Number | E31: عدد | F31: ='Source Table'!$C$6 -> Female | G31: ='Source Table'!$C$5 -> أنثى | H31: ='Source Table'!$G$8 -> Arab | I31: ='Source Table'!$G$7 -> عربي | J31: ='Source Table'!$B$12 -> Electricity | K31: ='Source Table'!$I$12 -> كهرباء | L31: 130 | M31: 2023
A32: المهندسون المسجّلون في نقابة المهندسين الأردنيين | B32: Engineers Registered at the Jordanian Engineers Syndicate | C32: M1 | D32: Number | E32: عدد | F32: ='Source Table'!$C$6 -> Female | G32: ='Source Table'!$C$5 -> أنثى | H32: ='Source Table'!$G$8 -> Arab | I32: ='Source Table'!$G$7 -> عربي | J32: ='Source Table'!$B$13 -> Mining | K32: ='Source Table'!$I$13 -> تعدين | L32: 0 | M32: 2023
A33: المهندسون المسجّلون في نقابة المهندسين الأردنيين | B33: Engineers Registered at the Jordanian Engineers Syndicate | C33: M1 | D33: Number | E33: عدد | F33: ='Source Table'!$C$6 -> Female | G33: ='Source Table'!$C$5 -> أنثى | H33: ='Source Table'!$G$8 -> Arab | I33: ='Source Table'!$G$7 -> عربي | J33: ='Source Table'!$B$14 -> Chemistry | K33: ='Source Table'!$I$14 -> كيمياء | L33: 29 | M33: 2023
A34: المهندسون المسجّلون في نقابة المهندسين الأردنيين | B34: Engineers Registered at the Jordanian Engineers Syndicate | C34: M1 | D34: Number | E34: عدد | F34: ='Source Table'!$C$6 -> Female | G34: ='Source Table'!$C$5 -> أنثى | H34: ='Source Table'!$F$8 -> Foreign | I34: ='Source Table'!$F$7 -> أجنبي | J34: ='Source Table'!$B$9 -> Civil | K34: ='Source Table'!$I$9 -> مدني | L34: 23 | M34: 2023
A35: المهندسون المسجّلون في نقابة المهندسين الأردنيين | B35: Engineers Registered at the Jordanian Engineers Syndicate | C35: M1 | D35: Number | E35: عدد | F35: ='Source Table'!$C$6 -> Female | G35: ='Source Table'!$C$5 -> أنثى | H35: ='Source Table'!$F$8 -> Foreign | I35: ='Source Table'!$F$7 -> أجنبي | J35: ='Source Table'!$B$10 -> Architecture | K35: ='Source Table'!$I$10 -> عمارة | L35: 19 | M35: 2023
A36: المهندسون المسجّلون في نقابة المهندسين الأردنيين | B36: Engineers Registered at the Jordanian Engineers Syndicate | C36: M1 | D36: Number | E36: عدد | F36: ='Source Table'!$C$6 -> Female | G36: ='Source Table'!$C$5 -> أنثى | H36: ='Source Table'!$F$8 -> Foreign | I36: ='Source Table'!$F$7 -> أجنبي | J36: ='Source Table'!$B$11 -> Mechanical | K36: ='Source Table'!$I$11 -> ميكانيك | L36: 8 | M36: 2023
A37: المهندسون المسجّلون في نقابة المهندسين الأردنيين | B37: Engineers Registered at the Jordanian Engineers Syndicate | C37: M1 | D37: Number | E37: عدد | F37: ='Source Table'!$C$6 -> Female | G37: ='Source Table'!$C$5 -> أنثى | H37: ='Source Table'!$F$8 -> Foreign | I37: ='Source Table'!$F$7 -> أجنبي | J37: ='Source Table'!$B$12 -> Electricity | K37: ='Source Table'!$I$12 -> كهرباء | L37: 3 | M37: 2023
A38: المهندسون المسجّلون في نقابة المهندسين الأردنيين | B38: Engineers Registered at the Jordanian Engineers Syndicate | C38: M1 | D38: Number | E38: عدد | F38: ='Source Table'!$C$6 -> Female | G38: ='Source Table'!$C$5 -> أنثى | H38: ='Source Table'!$F$8 -> Foreign | I38: ='Source Table'!$F$7 -> أجنبي | J38: ='Source Table'!$B$13 -> Mining | K38: ='Source Table'!$I$13 -> تعدين | L38: 0 | M38: 2023
A39: المهندسون المسجّلون في نقابة المهندسين الأردنيين | B39: Engineers Registered at the Jordanian Engineers Syndicate | C39: M1 | D39: Number | E39: عدد | F39: ='Source Table'!$C$6 -> Female | G39: ='Source Table'!$C$5 -> أنثى | H39: ='Source Table'!$F$8 -> Foreign | I39: ='Source Table'!$F$7 -> أجنبي | J39: ='Source Table'!$B$14 -> Chemistry | K39: ='Source Table'!$I$14 -> كيمياء | L39: 3 | M39: 2023
A40: المهندسون المسجّلون في نقابة المهندسين الأردنيين | B40: Engineers Registered at the Jordanian Engineers Syndicate | C40: M1 | D40: Number | E40: عدد | F40: ='Source Table'!$F$6 -> Male | G40: ='Source Table'!$F$5 -> ذكر | H40: ='Source Table'!$H$8 -> Jordanian | I40: ='Source Table'!$H$7 -> أردني | J40: ='Source Table'!$B$9 -> Civil | K40: ='Source Table'!$I$9 -> مدني | L40: 42319 | M40: 2022
...

Sheet Template Data
A1: Date | B1: =DATE(B2,B3,1) -> 45292
A2: Year | B2: 2024
A3: Month | B3: 1
A4: Measure_Name_Ar | B4: Measure_Name_En | C4: Measure_ID | D4: Unit_EN | E4: Unit_AR | F4: CL_SEX_EN_V1 | G4: CL_SEX_AR_V1 | H4: CL_NATIONALITY_EN_V4 | I4: CL_NATIONALITY_AR_V4 | J4: CL_ENG_SPECALIZATION_EN_V1 | K4: CL_ENG_SPECALIZATION_AR_V1 | L4: Obs_Value | M4: Time_Period_Y | N4: Time_Period_M
A5: اسم المؤشر | B5: Measure Name | C5: رمز المؤشر | D5: Unit | E5: الوحدة | F5: Sex | G5: الجنس | H5: Nationality | I5: الجنسية | J5: Engineers Specialization | K5: التخصص الهندسي | L5: قيمة المؤشر | M5: سنة فترة القياس | N5: شهر فترة القياس

Sheet Help
A2: Step 1: Cover Page | C2: الخطوة 1: Cover Page
A4: Update the template information, to ensure that any meta-information about the template, such as the title, version, and description, is accurate and up-to-date. | C4: قم بتحديث معلومات القالب للتأكد من أن أي معلومات وصفية حول القالب، مثل العنوان والإصدار والوصف، دقيقة ومحدثة.
A6: Step 2: Source Table | C6: الخطوة 2: Source Table
A8: Design your template, ensuring that the time period is mapped correctly to the date information in rows 1-3 of the Template Data Sheet. | C8: قم بتصميم القالب الخاص بك، مع التأكد من أن فترة الوقت مرتبطة بشكل صحيح مع معلومات التاريخ في الصفوف 1-3 في ورقة Template Data.
A10: Step 3: Relational Sheet | C10: الخطوة 3: Relational Sheet
A12: Unpivot the data in the source table into a flat format. Follow these guidelines: | C12: قم بتحويل البيانات في جدول المصدر إلى تنسيق مسطح. اتبع هذه الإرشادات:
A13: 1. Blue Columns: Do not change the names of the blue columns. Update the data as per the current template. | C13: 1. الأعمدة الزرقاء: لا تقم بتغيير أسماء الأعمدة الزرقاء. قم بتحديث البيانات وفقًا للقالب الحالي.
A14: 2. Code Lists: Use the naming convention CL_XXX_EN_V# for code lists, where XXX is the name, and V# is the version, conforming with the definitions in the data dictionary. | C14: 2. قوائم الرموز: استخدم قاعدة التسمية CL_XXX_EN_V# لقوائم الرموز، حيث أن XXX هو الاسم و V# هو الإصدار، وفقًا للتعريفات في قاموس البيانات.
A15: 3. Code List Values: Ensure the code list values match the definitions in the data dictionary. | C15: 3. قيم قائمة الرموز: تأكد من أن قيم قائمة الرموز تتوافق مع التعريفات في قاموس البيانات.
A16: 4. Time_Period_M: Leave empty if the data frequency is yearly. | C16: 4. Time_Period_M: اتركها فارغة إذا كانت دورية البيانات سنوية.
A17: 5. Time_Period_M Format: Use one of these formats: | C17: 5. تنسيق Time_Period_M: استخدم أحد التنسيقات التالية:
A18: Numeric: (1, 2, 3, ..., 12) for months. | C18: رقمي: (1، 2، 3، ...، 12) للأشهر.
... A38: Protect the entire workbook to prevent unauthorized or accidental changes to the structure of the file. | C38: قم بحماية الكتاب بأكمله لمنع التغييرات غير المصرح بها أو غير المقصودة على هيكل الملف.
