Workbook

Sheet Cover Page
A1: Code | B1: SYB_23_10
A2: Version | B2: V1
A3: اسم القالب | B3: التكوين الرأسمالي الإجمالي حسب نوع الأصول بالأسعار الجارية
A4: Template Name | B4: Gross Capital Formation by Type of Assets at Current Prices
A5: دورية البيانات | B5: سنوي
A6: Data Frequency | B6: Annual
A7: الجهة المصدرية | B7: دائرة الإحصاءات العامة/ الحسابات القومية
A8: Data Source | B8: Department of Statistics/ National Account

Sheet Source Table
B2: ='Cover Page'!B4 -> Gross Capital Formation by Type of Assets at Current Prices
B3: ='Cover Page'!B3 -> التكوين الرأسمالي الإجمالي حسب نوع الأصول بالأسعار الجارية
B4: Year | C4: 2022 | D4: السنة
B5: Type of Assets | D5: نوع الأصول
B8: Residential Buildings | D8: الأبنية السكنية
B9: Non-Residential Buildings and Other Construction | D9: الأبنية غير السكنية وإنشاءات أخرى
B10: Transport Equipments | D10: معدات النقل
B11: Machinery, Equipment and Others | D11: آلات ومعدات أخرى
B12: Gross Fixed Capital Formation | D12: تكوين رأس المال الثابت الإجمالي
B13: Change in Stocks | D13: التغير في المخزون
B14: Gross Capital Formation | D14: تكوين رأس المال الإجمالي

Sheet Relational DB
A1: Relational Sheet
A2: Measure_Name_Ar | B2: Measure_Name_En | C2: Measure_ID | D2: Unit_EN | E2: Unit_AR | F2: CL_TYPE_ASSETS_EN_V1 | G2: CL_TYPE_ASSETS_AR_V1 | H2: Obs_Value | I2: Time_Period_Y | J2: Time_Period_M
A3: اسم المؤشر | B3: Measure Name | C3: رمز المؤشر | D3: Unit | E3: الوحدة | F3: Type of Assets | G3: نوع الاصول | H3: قيمة المؤشر | I3: سنة فترة القياس | J3: شهر فترة القياس
A4: التكوين الرأسمالي الإجمالي حسب نوع الأصول بالأسعار الجارية | B4: Gross Capital Formation by Type of Assets at Current Prices | C4: M1 | D4: Million JD | E4: مليون دينار | F4: =+'Source Table'!$B$8 -> Residential Buildings | G4: =+'Source Table'!$D$8 -> الأبنية السكنية | H4: 2321 | I4: 2015
A5: التكوين الرأسمالي الإجمالي حسب نوع الأصول بالأسعار الجارية | B5: Gross Capital Formation by Type of Assets at Current Prices | C5: M1 | D5: Million JD | E5: مليون دينار | F5: =+'Source Table'!$B$9 -> Non-Residential Buildings and Other Construction | G5: =+'Source Table'!$D$9 -> الأبنية غير السكنية وإنشاءات أخرى | H5: 1179 | I5: =+I4 -> 2015
A6: التكوين الرأسمالي الإجمالي حسب نوع الأصول بالأسعار الجارية | B6: Gross Capital Formation by Type of Assets at Current Prices | C6: M1 | D6: Million JD | E6: مليون دينار | F6: =+'Source Table'!$B$10 -> Transport Equipments | G6: =+'Source Table'!$D$10 -> معدات النقل | H6: 408 | I6: =+I5 -> 2015
A7: التكوين الرأسمالي الإجمالي حسب نوع الأصول بالأسعار الجارية | B7: Gross Capital Formation by Type of Assets at Current Prices | C7: M1 | D7: Million JD | E7: مليون دينار | F7: =+'Source Table'!$B$11 -> Machinery, Equipment and Others | G7: =+'Source Table'!$D$11 -> آلات ومعدات أخرى | H7: 2073 | I7: =+I6 -> 2015
A8: التكوين الرأسمالي الإجمالي حسب نوع الأصول بالأسعار الجارية | B8: Gross Capital Formation by Type of Assets at Current Prices | C8: M1 | D8: Million JD | E8: مليون دينار | F8: =+'Source Table'!$B$12 -> Gross Fixed Capital Formation | G8: =+'Source Table'!$D$12 -> تكوين رأس المال الثابت الإجمالي | H8: 5981 | I8: =+I7 -> 2015
A9: التكوين الرأسمالي الإجمالي حسب نوع الأصول بالأسعار الجارية | B9: Gross Capital Formation by Type of Assets at Current Prices | C9: M1 | D9: Million JD | E9: مليون دينار | F9: =+'Source Table'!$B$13 -> Change in Stocks | G9: =+'Source Table'!$D$13 -> التغير في المخزون | H9: 823 | I9: =+I8 -> 2015
A10: التكوين الرأسمالي الإجمالي حسب نوع الأصول بالأسعار الجارية | B10: Gross Capital Formation by Type of Assets at Current Prices | C10: M1 | D10: Million JD | E10: مليون دينار | F10: =+'Source Table'!$B$14 -> Gross Capital Formation | G10: =+'Source Table'!$D$14 -> تكوين رأس المال الإجمالي | H10: 6804 | I10: =+I9 -> 2015
A11: التكوين الرأسمالي الإجمالي حسب نوع الأصول بالأسعار الجارية | B11: Gross Capital Formation by Type of Assets at Current Prices | C11: M1 | D11: Million JD | E11: مليون دينار | F11: =+'Source Table'!$B$8 -> Residential Buildings | G11: =+'Source Table'!$D$8 -> الأبنية السكنية | H11: 2202 | I11: =+I4+1 -> 2016
A12: التكوين الرأسمالي الإجمالي حسب نوع الأصول بالأسعار الجارية | B12: Gross Capital Formation by Type of Assets at Current Prices | C12: M1 | D12: Million JD | E12: مليون دينار | F12: =+'Source Table'!$B$9 -> Non-Residential Buildings and Other Construction | G12: =+'Source Table'!$D$9 -> الأبنية غير السكنية وإنشاءات أخرى | H12: 1119 | I12: =+I11 -> 2016
A13: التكوين الرأسمالي الإجمالي حسب نوع الأصول بالأسعار الجارية | B13: Gross Capital Formation by Type of Assets at Current Prices | C13: M1 | D13: Million JD | E13: مليون دينار | F13: =+'Source Table'!$B$10 -> Transport Equipments | G13: =+'Source Table'!$D$10 -> معدات النقل | H13: 387 | I13: =+I12 -> 2016
A14: التكوين الرأسمالي الإجمالي حسب نوع الأصول بالأسعار الجارية | B14: Gross Capital Formation by Type of Assets at Current Prices | C14: M1 | D14: Million JD | E14: مليون دينار | F14: =+'Source Table'!$B$11 -> Machinery, Equipment and Others | G14: =+'Source Table'!$D$11 -> آلات ومعدات أخرى | H14: 1968 | I14: =+I13 -> 2016
A15: التكوين الرأسمالي الإجمالي حسب نوع الأصول بالأسعار الجارية | B15: Gross Capital Formation by Type of Assets at Current Prices | C15: M1 | D15: Million JD | E15: مليون دينار | F15: =+'Source Table'!$B$12 -> Gross Fixed Capital Formation | G15: =+'Source Table'!$D$12 -> تكوين رأس المال الثابت الإجمالي | H15: 5676.2551 | I15: =+I14 -> 2016
A16: التكوين الرأسمالي الإجمالي حسب نوع الأصول بالأسعار الجارية | B16: Gross Capital Formation by Type of Assets at Current Prices | C16: M1 | D16: Million JD | E16: مليون دينار | F16: =+'Source Table'!$B$13 -> Change in Stocks | G16: =+'Source Table'!$D$13 -> التغير في المخزون | H16: 953.254 | I16: =+I15 -> 2016
A17: التكوين الرأسمالي الإجمالي حسب نوع الأصول بالأسعار الجارية | B17: Gross Capital Formation by Type of Assets at Current Prices | C17: M1 | D17: Million JD | E17: مليون دينار | F17: =+'Source Table'!$B$14 -> Gross Capital Formation | G17: =+'Source Table'!$D$14 -> تكوين رأس المال الإجمالي | H17: 6629.5091 | I17: =+I16 -> 2016
A18: التكوين الرأسمالي الإجمالي حسب نوع الأصول بالأسعار الجارية | B18: Gross Capital Formation by Type of Assets at Current Prices | C18: M1 | D18: Million JD | E18: مليون دينار | F18: =+'Source Table'!$B$8 -> Residential Buildings | G18: =+'Source Table'!$D$8 -> الأبنية السكنية | H18: 2309 | I18: =+I11+1 -> 2017
A19: التكوين الرأسمالي الإجمالي حسب نوع الأصول بالأسعار الجارية | B19: Gross Capital Formation by Type of Assets at Current Prices | C19: M1 | D19: Million JD | E19: مليون دينار | F19: =+'Source Table'!$B$9 -> Non-Residential Buildings and Other Construction | G19: =+'Source Table'!$D$9 -> الأبنية غير السكنية وإنشاءات أخرى | H19: 1173 | I19: =+I18 -> 2017
A20: التكوين الرأسمالي الإجمالي حسب نوع الأصول بالأسعار الجارية | B20: Gross Capital Formation by Type of Assets at Current Prices | C20: M1 | D20: Million JD | E20: مليون دينار | F20: =+'Source Table'!$B$10 -> Transport Equipments | G20: =+'Source Table'!$D$10 -> معدات النقل | H20: 406 | I20: =+I19 -> 2017
A21: التكوين الرأسمالي الإجمالي حسب نوع الأصول بالأسعار الجارية | B21: Gross Capital Formation by Type of Assets at Current Prices | C21: M1 | D21: Million JD | E21: مليون دينار | F21: =+'Source Table'!$B$11 -> Machinery, Equipment and Others | G21: =+'Source Table'!$D$11 -> آلات ومعدات أخرى | H21: 2063 | I21: =+I20 -> 2017
A22: التكوين الرأسمالي الإجمالي حسب نوع الأصول بالأسعار الجارية | B22: Gross Capital Formation by Type of Assets at Current Prices | C22: M1 | D22: Million JD | E22: مليون دينار | F22: =+'Source Table'!$B$12 -> Gross Fixed Capital Formation | G22: =+'Source Table'!$D$12 -> تكوين رأس المال الثابت الإجمالي | H22: 5952 | I22: =+I21 -> 2017
A23: التكوين الرأسمالي الإجمالي حسب نوع الأصول بالأسعار الجارية | B23: Gross Capital Formation by Type of Assets at Current Prices | C23: M1 | D23: Million JD | E23: مليون دينار | F23: =+'Source Table'!$B$13 -> Change in Stocks | G23: =+'Source Table'!$D$13 -> التغير في المخزون | H23: 1350 | I23: =+I22 -> 2017
A24: التكوين الرأسمالي الإجمالي حسب نوع الأصول بالأسعار الجارية | B24: Gross Capital Formation by Type of Assets at Current Prices | C24: M1 | D24: Million JD | E24: مليون دينار | F24: =+'Source Table'!$B$14 -> Gross Capital Formation | G24: =+'Source Table'!$D$14 -> تكوين رأس المال الإجمالي | H24: 7302 | I24: =+I23 -> 2017
A25: التكوين الرأسمالي الإجمالي حسب نوع الأصول بالأسعار الجارية | B25: Gross Capital Formation by Type of Assets at Current Prices | C25: M1 | D25: Million JD | E25: مليون دينار | F25: =+'Source Table'!$B$8 -> Residential Buildings | G25: =+'Source Table'!$D$8 -> الأبنية السكنية | H25: 2436 | I25: =+I18+1 -> 2018
A26: التكوين الرأسمالي الإجمالي حسب نوع الأصول بالأسعار الجارية | B26: Gross Capital Formation by Type of Assets at Current Prices | C26: M1 | D26: Million JD | E26: مليون دينار | F26: =+'Source Table'!$B$9 -> Non-Residential Buildings and Other Construction | G26: =+'Source Table'!$D$9 -> الأبنية غير السكنية وإنشاءات أخرى | H26: 1238 | I26: =+I25 -> 2018
A27: التكوين الرأسمالي الإجمالي حسب نوع الأصول بالأسعار الجارية | B27: Gross Capital Formation by Type of Assets at Current Prices | C27: M1 | D27: Million JD | E27: مليون دينار | F27: =+'Source Table'!$B$10 -> Transport Equipments | G27: =+'Source Table'!$D$10 -> معدات النقل | H27: 428 | I27: =+I26 -> 2018
A28: التكوين الرأسمالي الإجمالي حسب نوع الأصول بالأسعار الجارية | B28: Gross Capital Formation by Type of Assets at Current Prices | C28: M1 | D28: Million JD | E28: مليون دينار | F28: =+'Source Table'!$B$11 -> Machinery, Equipment and Others | G28: =+'Source Table'!$D$11 -> آلات ومعدات أخرى | H28: 2177 | I28: =+I27 -> 2018
A29: التكوين الرأسمالي الإجمالي حسب نوع الأصول بالأسعار الجارية | B29: Gross Capital Formation by Type of Assets at Current Prices | C29: M1 | D29: Million JD | E29: مليون دينار | F29: =+'Source Table'!$B$12 -> Gross Fixed Capital Formation | G29: =+'Source Table'!$D$12 -> تكوين رأس المال الثابت الإجمالي | H29: 6278.7829 | I29: =+I28 -> 2018
A30: التكوين الرأسمالي الإجمالي حسب نوع الأصول بالأسعار الجارية | B30: Gross Capital Formation by Type of Assets at Current Prices | C30: M1 | D30: Million JD | E30: مليون دينار | F30: =+'Source Table'!$B$13 -> Change in Stocks | G30: =+'Source Table'!$D$13 -> التغير في المخزون | H30: 1222.654 | I30: =+I29 -> 2018
A31: التكوين الرأسمالي الإجمالي حسب نوع الأصول بالأسعار الجارية | B31: Gross Capital Formation by Type of Assets at Current Prices | C31: M1 | D31: Million JD | E31: مليون دينار | F31: =+'Source Table'!$B$14 -> Gross Capital Formation | G31: =+'Source Table'!$D$14 -> تكوين رأس المال الإجمالي | H31: 7501.4369 | I31: =+I30 -> 2018
A32: التكوين الرأسمالي الإجمالي حسب نوع الأصول بالأسعار الجارية | B32: Gross Capital Formation by Type of Assets at Current Prices | C32: M1 | D32: Million JD | E32: مليون دينار | F32: =+'Source Table'!$B$8 -> Residential Buildings | G32: =+'Source Table'!$D$8 -> الأبنية السكنية | H32: 2252 | I32: =+I25+1 -> 2019
A33: التكوين الرأسمالي الإجمالي حسب نوع الأصول بالأسعار الجارية | B33: Gross Capital Formation by Type of Assets at Current Prices | C33: M1 | D33: Million JD | E33: مليون دينار | F33: =+'Source Table'!$B$9 -> Non-Residential Buildings and Other Construction | G33: =+'Source Table'!$D$9 -> الأبنية غير السكنية وإنشاءات أخرى | H33: 1144 | I33: =+I32 -> 2019
A34: التكوين الرأسمالي الإجمالي حسب نوع الأصول بالأسعار الجارية | B34: Gross Capital Formation by Type of Assets at Current Prices | C34: M1 | D34: Million JD | E34: مليون دينار | F34: =+'Source Table'!$B$10 -> Transport Equipments | G34: =+'Source Table'!$D$10 -> معدات النقل | H34: 396 | I34: =+I33 -> 2019
A35: التكوين الرأسمالي الإجمالي حسب نوع الأصول بالأسعار الجارية | B35: Gross Capital Formation by Type of Assets at Current Prices | C35: M1 | D35: Million JD | E35: مليون دينار | F35: =+'Source Table'!$B$11 -> Machinery, Equipment and Others | G35: =+'Source Table'!$D$11 -> آلات ومعدات أخرى | H35: 2012 | I35: =+I34 -> 2019
A36: التكوين الرأسمالي الإجمالي حسب نوع الأصول بالأسعار الجارية | B36: Gross Capital Formation by Type of Assets at Current Prices | C36: M1 | D36: Million JD | E36: مليون دينار | F36: =+'Source Table'!$B$12 -> Gross Fixed Capital Formation | G36: =+'Source Table'!$D$12 -> تكوين رأس المال الثابت الإجمالي | H36: 5804 | I36: =+I35 -> 2019
A37: التكوين الرأسمالي الإجمالي حسب نوع الأصول بالأسعار الجارية | B37: Gross Capital Formation by Type of Assets at Current Prices | C37: M1 | D37: Million JD | E37: مليون دينار | F37: =+'Source Table'!$B$13 -> Change in Stocks | G37: =+'Source Table'!$D$13 -> التغير في المخزون | H37: 961.83456 | I37: =+I36 -> 2019
A38: التكوين الرأسمالي الإجمالي حسب نوع الأصول بالأسعار الجارية | B38: Gross Capital Formation by Type of Assets at Current Prices | C38: M1 | D38: Million JD | E38: مليون دينار | F38: =+'Source Table'!$B$14 -> Gross Capital Formation | G38: =+'Source Table'!$D$14 -> تكوين رأس المال الإجمالي | H38: 6765.8346 | I38: =+I37 -> 2019
A39: التكوين الرأسمالي الإجمالي حسب نوع الأصول بالأسعار الجارية | B39: Gross Capital Formation by Type of Assets at Current Prices | C39: M1 | D39: Million JD | E39: مليون دينار | F39: =+'Source Table'!$B$8 -> Residential Buildings | G39: =+'Source Table'!$D$8 -> الأبنية السكنية | H39: 2268 | I39: =+I32+1 -> 2020
A40: التكوين الرأسمالي الإجمالي حسب نوع الأصول بالأسعار الجارية | B40: Gross Capital Formation by Type of Assets at Current Prices | C40: M1 | D40: Million JD | E40: مليون دينار | F40: =+'Source Table'!$B$9 -> Non-Residential Buildings and Other Construction | G40: =+'Source Table'!$D$9 -> الأبنية غير السكنية وإنشاءات أخرى | H40: 1159 | I40: =+I39 -> 2020
...

Sheet Template Data
A1: Date | B1: =DATE(B2,B3,1) -> 44927
A2: Year | B2: 2023
A3: Month | B3: 1
A4: Measure_Name_Ar | B4: Measure_Name_En | C4: Measure_ID | D4: Unit_EN | E4: Unit_AR | F4: CL_TYPE_ASSETS_EN_V1 | G4: CL_TYPE_ASSETS_AR_V1 | H4: Obs_Value | I4: Time_Period_Y | J4: Time_Period_M
A5: اسم المؤشر | B5: Measure Name | C5: رمز المؤشر | D5: Unit | E5: الوحدة | F5: Type of Assets | G5: نوع الاصول | H5: قيمة المؤشر | I5: سنة فترة القياس | J5: شهر فترة القياس

Sheet Help
A2: Step 1: Cover Page | C2: الخطوة 1: Cover Page
A4: Update the template information, to ensure that any meta-information about the template, such as the title, version, and description, is accurate and up-to-date. | C4: قم بتحديث معلومات القالب للتأكد من أن أي معلومات وصفية حول القالب، مثل العنوان والإصدار والوصف، دقيقة ومحدثة.
A6: Step 2: Source Table | C6: الخطوة 2: Source Table
A8: Design your template, ensuring that the time period is mapped correctly to the date information in rows 1-3 of the Template Data Sheet. | C8: قم بتصميم القالب الخاص بك، مع التأكد من أن فترة الوقت مرتبطة بشكل صحيح مع معلومات التاريخ في الصفوف 1-3 في ورقة Template Data.
A10: Step 3: Relational Sheet | C10: الخطوة 3: Relational Sheet
A12: Unpivot the data in the source table into a flat format. Follow these guidelines: | C12: قم بتحويل البيانات في جدول المصدر إلى تنسيق مسطح. اتبع هذه الإرشادات:
A13: 1. Blue Columns: Do not change the names of the blue columns. Update the data as per the current template. | C13: 1. الأعمدة الزرقاء: لا تقم بتغيير أسماء الأعمدة الزرقاء. قم بتحديث البيانات وفقًا للقالب الحالي.
A14: 2. Code Lists: Use the naming convention CL_XXX_EN_V# for code lists, where XXX is the name, and V# is the version, conforming with the definitions in the data dictionary. | C14: 2. قوائم الرموز: استخدم قاعدة التسمية CL_XXX_EN_V# لقوائم الرموز، حيث أن XXX هو الاسم و V# هو الإصدار، وفقًا للتعريفات في قاموس البيانات.
A15: 3. Code List Values: Ensure the code list values match the definitions in the data dictionary. | C15: 3. قيم قائمة الرموز: تأكد من أن قيم قائمة الرموز تتوافق مع التعريفات في قاموس البيانات.
A16: 4. Time_Period_M: Leave empty if the data frequency is yearly. | C16: 4. Time_Period_M: اتركها فارغة إذا كانت دورية البيانات سنوية.
A17: 5. Time_Period_M Format: Use one of these formats: | C17: 5. تنسيق Time_Period_M: استخدم أحد التنسيقات التالية:
A18: Numeric: (1, 2, 3, ..., 12) for months. | C18: رقمي: (1، 2، 3، ...، 12) للأشهر.
... A38: Protect the entire workbook to prevent unauthorized or accidental changes to the structure of the file. | C38: قم بحماية الكتاب بأكمله لمنع التغييرات غير المصرح بها أو غير المقصودة على هيكل الملف.
