Workbook

Sheet Cover Page
A1: Code | B1: SYB3_3_20
A2: Version | B2: V1
A3: اسم القالب | B3: وقوعات الطلاق المسجلة حسب المحافظة وأرباع السنة
A4: Template Name | B4: Registered Divorce by Governorate and Quarters of the Year
A5: دورية البيانات | B5: سنوي
A6: Data Frequency | B6: Yearly
A7: الجهة المصدرية | B7: المحاكم الشرعية
A8: Data Source | B8: Shariah Courts

Sheet Source Table
B2: ='Cover Page'!B4 -> Registered Divorce by Governorate and Quarters of the Year
B3: ='Cover Page'!B3 -> وقوعات الطلاق المسجلة حسب المحافظة وأرباع السنة
B4: Year | C4: 2024 | G4: السنة
B5: Governorate | C5: 1st Quarter | D5: 2nd Quarter | E5: 3rd Quarter | F5: 4th Quarter | G5: المحافظة
C6: الربع الأول | D6: الربع الثاني | E6: الربع الثالث | F6: الربع الرابع
B8: Amman | G8: العاصمة
B9: Balqa | G9: البلقاء
B10: Zarqa | G10: الزرقاء
B11: Madaba | G11: مأدبا
B12: Irbid | G12: إربد
B13: Mafraq | G13: المفرق
B14: Jarash | G14: جرش
B15: Ajloun | G15: عجلون
B16: Karak | G16: الكرك
B17: Tafiela | G17: الطفيله
B18: Ma'an | G18: معان
B19: Aqaba | G19: العقبة

Sheet Relational DB
A1: Relational Sheet
A2: Measure_Name_Ar | B2: Measure_Name_En | C2: Measure_ID | D2: Unit_EN | E2: Unit_AR | F2: CL_GOVERNORATE_EN_V1 | G2: CL_GOVERNORATE_AR_V1 | H2: Obs_Value | I2: Time_Period_Y | J2: Time_Period_M
A3: اسم المؤشر | B3: Measure Name | C3: رمز المؤشر | D3: Unit | E3: الوحدة | F3: Governorate | G3: المحافظة | H3: قيمة المؤشر | I3: سنة فترة القياس | J3: شهر فترة القياس
A4: وقوعات الطلاق المسجلة | B4: Registered Divorce | C4: M1 | D4: Number | E4: عدد | F4: ='Source Table'!$B$8 -> Amman | G4: ='Source Table'!$G$8 -> العاصمة | H4: 1697 | I4: 2023 | J4: Jan
A5: وقوعات الطلاق المسجلة | B5: Registered Divorce | C5: M1 | D5: Number | E5: عدد | F5: ='Source Table'!$B$9 -> Balqa | G5: ='Source Table'!$G$9 -> البلقاء | H5: 321 | I5: 2023 | J5: Jan
A6: وقوعات الطلاق المسجلة | B6: Registered Divorce | C6: M1 | D6: Number | E6: عدد | F6: ='Source Table'!$B$10 -> Zarqa | G6: ='Source Table'!$G$10 -> الزرقاء | H6: 746 | I6: 2023 | J6: Jan
A7: وقوعات الطلاق المسجلة | B7: Registered Divorce | C7: M1 | D7: Number | E7: عدد | F7: ='Source Table'!$B$11 -> Madaba | G7: ='Source Table'!$G$11 -> مأدبا | H7: 139 | I7: 2023 | J7: Jan
A8: وقوعات الطلاق المسجلة | B8: Registered Divorce | C8: M1 | D8: Number | E8: عدد | F8: ='Source Table'!$B$12 -> Irbid | G8: ='Source Table'!$G$12 -> إربد | H8: 794 | I8: 2023 | J8: Jan
A9: وقوعات الطلاق المسجلة | B9: Registered Divorce | C9: M1 | D9: Number | E9: عدد | F9: ='Source Table'!$B$13 -> Mafraq | G9: ='Source Table'!$G$13 -> المفرق | H9: 282 | I9: 2023 | J9: Jan
A10: وقوعات الطلاق المسجلة | B10: Registered Divorce | C10: M1 | D10: Number | E10: عدد | F10: ='Source Table'!$B$14 -> Jarash | G10: ='Source Table'!$G$14 -> جرش | H10: 126 | I10: 2023 | J10: Jan
A11: وقوعات الطلاق المسجلة | B11: Registered Divorce | C11: M1 | D11: Number | E11: عدد | F11: ='Source Table'!$B$15 -> Ajloun | G11: ='Source Table'!$G$15 -> عجلون | H11: 74 | I11: 2023 | J11: Jan
A12: وقوعات الطلاق المسجلة | B12: Registered Divorce | C12: M1 | D12: Number | E12: عدد | F12: ='Source Table'!$B$16 -> Karak | G12: ='Source Table'!$G$16 -> الكرك | H12: 117 | I12: 2023 | J12: Jan
A13: وقوعات الطلاق المسجلة | B13: Registered Divorce | C13: M1 | D13: Number | E13: عدد | F13: ='Source Table'!$B$17 -> Tafiela | G13: ='Source Table'!$G$17 -> الطفيله | H13: 42 | I13: 2023 | J13: Jan
A14: وقوعات الطلاق المسجلة | B14: Registered Divorce | C14: M1 | D14: Number | E14: عدد | F14: ='Source Table'!$B$18 -> Ma'an | G14: ='Source Table'!$G$18 -> معان | H14: 82 | I14: 2023 | J14: Jan
A15: وقوعات الطلاق المسجلة | B15: Registered Divorce | C15: M1 | D15: Number | E15: عدد | F15: ='Source Table'!$B$19 -> Aqaba | G15: ='Source Table'!$G$19 -> العقبة | H15: 118 | I15: 2023 | J15: Jan
A16: وقوعات الطلاق المسجلة | B16: Registered Divorce | C16: M1 | D16: Number | E16: عدد | F16: ='Source Table'!$B$8 -> Amman | G16: ='Source Table'!$G$8 -> العاصمة | H16: 1602 | I16: 2023 | J16: Apr
A17: وقوعات الطلاق المسجلة | B17: Registered Divorce | C17: M1 | D17: Number | E17: عدد | F17: ='Source Table'!$B$9 -> Balqa | G17: ='Source Table'!$G$9 -> البلقاء | H17: 279 | I17: 2023 | J17: Apr
A18: وقوعات الطلاق المسجلة | B18: Registered Divorce | C18: M1 | D18: Number | E18: عدد | F18: ='Source Table'!$B$10 -> Zarqa | G18: ='Source Table'!$G$10 -> الزرقاء | H18: 638 | I18: 2023 | J18: Apr
A19: وقوعات الطلاق المسجلة | B19: Registered Divorce | C19: M1 | D19: Number | E19: عدد | F19: ='Source Table'!$B$11 -> Madaba | G19: ='Source Table'!$G$11 -> مأدبا | H19: 131 | I19: 2023 | J19: Apr
A20: وقوعات الطلاق المسجلة | B20: Registered Divorce | C20: M1 | D20: Number | E20: عدد | F20: ='Source Table'!$B$12 -> Irbid | G20: ='Source Table'!$G$12 -> إربد | H20: 788 | I20: 2023 | J20: Apr
A21: وقوعات الطلاق المسجلة | B21: Registered Divorce | C21: M1 | D21: Number | E21: عدد | F21: ='Source Table'!$B$13 -> Mafraq | G21: ='Source Table'!$G$13 -> المفرق | H21: 276 | I21: 2023 | J21: Apr
A22: وقوعات الطلاق المسجلة | B22: Registered Divorce | C22: M1 | D22: Number | E22: عدد | F22: ='Source Table'!$B$14 -> Jarash | G22: ='Source Table'!$G$14 -> جرش | H22: 94 | I22: 2023 | J22: Apr
A23: وقوعات الطلاق المسجلة | B23: Registered Divorce | C23: M1 | D23: Number | E23: عدد | F23: ='Source Table'!$B$15 -> Ajloun | G23: ='Source Table'!$G$15 -> عجلون | H23: 72 | I23: 2023 | J23: Apr
A24: وقوعات الطلاق المسجلة | B24: Registered Divorce | C24: M1 | D24: Number | E24: عدد | F24: ='Source Table'!$B$16 -> Karak | G24: ='Source Table'!$G$16 -> الكرك | H24: 133 | I24: 2023 | J24: Apr
A25: وقوعات الطلاق المسجلة | B25: Registered Divorce | C25: M1 | D25: Number | E25: عدد | F25: ='Source Table'!$B$17 -> Tafiela | G25: ='Source Table'!$G$17 -> الطفيله | H25: 35 | I25: 2023 | J25: Apr
A26: وقوعات الطلاق المسجلة | B26: Registered Divorce | C26: M1 | D26: Number | E26: عدد | F26: ='Source Table'!$B$18 -> Ma'an | G26: ='Source Table'!$G$18 -> معان | H26: 73 | I26: 2023 | J26: Apr
A27: وقوعات الطلاق المسجلة | B27: Registered Divorce | C27: M1 | D27: Number | E27: عدد | F27: ='Source Table'!$B$19 -> Aqaba | G27: ='Source Table'!$G$19 -> العقبة | H27: 123 | I27: 2023 | J27: Apr
A28: وقوعات الطلاق المسجلة | B28: Registered Divorce | C28: M1 | D28: Number | E28: عدد | F28: ='Source Table'!$B$8 -> Amman | G28: ='Source Table'!$G$8 -> العاصمة | H28: 2092 | I28: 2023 | J28: Jul
A29: وقوعات الطلاق المسجلة | B29: Registered Divorce | C29: M1 | D29: Number | E29: عدد | F29: ='Source Table'!$B$9 -> Balqa | G29: ='Source Table'!$G$9 -> البلقاء | H29: 358 | I29: 2023 | J29: Jul
A30: وقوعات الطلاق المسجلة | B30: Registered Divorce | C30: M1 | D30: Number | E30: عدد | F30: ='Source Table'!$B$10 -> Zarqa | G30: ='Source Table'!$G$10 -> الزرقاء | H30: 917 | I30: 2023 | J30: Jul
A31: وقوعات الطلاق المسجلة | B31: Registered Divorce | C31: M1 | D31: Number | E31: عدد | F31: ='Source Table'!$B$11 -> Madaba | G31: ='Source Table'!$G$11 -> مأدبا | H31: 166 | I31: 2023 | J31: Jul
A32: وقوعات الطلاق المسجلة | B32: Registered Divorce | C32: M1 | D32: Number | E32: عدد | F32: ='Source Table'!$B$12 -> Irbid | G32: ='Source Table'!$G$12 -> إربد | H32: 1023 | I32: 2023 | J32: Jul
A33: وقوعات الطلاق المسجلة | B33: Registered Divorce | C33: M1 | D33: Number | E33: عدد | F33: ='Source Table'!$B$13 -> Mafraq | G33: ='Source Table'!$G$13 -> المفرق | H33: 331 | I33: 2023 | J33: Jul
A34: وقوعات الطلاق المسجلة | B34: Registered Divorce | C34: M1 | D34: Number | E34: عدد | F34: ='Source Table'!$B$14 -> Jarash | G34: ='Source Table'!$G$14 -> جرش | H34: 106 | I34: 2023 | J34: Jul
A35: وقوعات الطلاق المسجلة | B35: Registered Divorce | C35: M1 | D35: Number | E35: عدد | F35: ='Source Table'!$B$15 -> Ajloun | G35: ='Source Table'!$G$15 -> عجلون | H35: 91 | I35: 2023 | J35: Jul
A36: وقوعات الطلاق المسجلة | B36: Registered Divorce | C36: M1 | D36: Number | E36: عدد | F36: ='Source Table'!$B$16 -> Karak | G36: ='Source Table'!$G$16 -> الكرك | H36: 145 | I36: 2023 | J36: Jul
A37: وقوعات الطلاق المسجلة | B37: Registered Divorce | C37: M1 | D37: Number | E37: عدد | F37: ='Source Table'!$B$17 -> Tafiela | G37: ='Source Table'!$G$17 -> الطفيله | H37: 41 | I37: 2023 | J37: Jul
A38: وقوعات الطلاق المسجلة | B38: Registered Divorce | C38: M1 | D38: Number | E38: عدد | F38: ='Source Table'!$B$18 -> Ma'an | G38: ='Source Table'!$G$18 -> معان | H38: 130 | I38: 2023 | J38: Jul
A39: وقوعات الطلاق المسجلة | B39: Registered Divorce | C39: M1 | D39: Number | E39: عدد | F39: ='Source Table'!$B$19 -> Aqaba | G39: ='Source Table'!$G$19 -> العقبة | H39: 136 | I39: 2023 | J39: Jul
A40: وقوعات الطلاق المسجلة | B40: Registered Divorce | C40: M1 | D40: Number | E40: عدد | F40: ='Source Table'!$B$8 -> Amman | G40: ='Source Table'!$G$8 -> العاصمة | H40: 1928 | I40: 2023 | J40: Oct
...

Sheet Template Data
A1: Date | B1: =DATE(B2,B3,1) -> 45292
A2: Year | B2: 2024
A3: Month | B3: 1
A4: Measure_Name_Ar | B4: Measure_Name_En | C4: Measure_ID | D4: Unit_EN | E4: Unit_AR | F4: CL_GOVERNORATE_EN_V1 | G4: CL_GOVERNORATE_AR_V1 | H4: Obs_Value | I4: Time_Period_Y | J4: Time_Period_M
A5: اسم المؤشر | B5: Measure Name | C5: رمز المؤشر | D5: Unit | E5: الوحدة | F5: Governorate | G5: المحافظة | H5: قيمة المؤشر | I5: سنة فترة القياس | J5: شهر فترة القياس

Sheet Help
A2: Step 1: Cover Page | C2: الخطوة 1: Cover Page
A4: Update the template information, to ensure that any meta-information about the template, such as the title, version, and description, is accurate and up-to-date. | C4: قم بتحديث معلومات القالب للتأكد من أن أي معلومات وصفية حول القالب، مثل العنوان والإصدار والوصف، دقيقة ومحدثة.
A6: Step 2: Source Table | C6: الخطوة 2: Source Table
A8: Design your template, ensuring that the time period is mapped correctly to the date information in rows 1-3 of the Template Data Sheet. | C8: قم بتصميم القالب الخاص بك، مع التأكد من أن فترة الوقت مرتبطة بشكل صحيح مع معلومات التاريخ في الصفوف 1-3 في ورقة Template Data.
A10: Step 3: Relational Sheet | C10: الخطوة 3: Relational Sheet
A12: Unpivot the data in the source table into a flat format. Follow these guidelines: | C12: قم بتحويل البيانات في جدول المصدر إلى تنسيق مسطح. اتبع هذه الإرشادات:
A13: 1. Blue Columns: Do not change the names of the blue columns. Update the data as per the current template. | C13: 1. الأعمدة الزرقاء: لا تقم بتغيير أسماء الأعمدة الزرقاء. قم بتحديث البيانات وفقًا للقالب الحالي.
A14: 2. Code Lists: Use the naming convention CL_XXX_EN_V# for code lists, where XXX is the name, and V# is the version, conforming with the definitions in the data dictionary. | C14: 2. قوائم الرموز: استخدم قاعدة التسمية CL_XXX_EN_V# لقوائم الرموز، حيث أن XXX هو الاسم و V# هو الإصدار، وفقًا للتعريفات في قاموس البيانات.
A15: 3. Code List Values: Ensure the code list values match the definitions in the data dictionary. | C15: 3. قيم قائمة الرموز: تأكد من أن قيم قائمة الرموز تتوافق مع التعريفات في قاموس البيانات.
A16: 4. Time_Period_M: Leave empty if the data frequency is yearly. | C16: 4. Time_Period_M: اتركها فارغة إذا كانت دورية البيانات سنوية.
A17: 5. Time_Period_M Format: Use one of these formats: | C17: 5. تنسيق Time_Period_M: استخدم أحد التنسيقات التالية:
A18: Numeric: (1, 2, 3, ..., 12) for months. | C18: رقمي: (1، 2، 3، ...، 12) للأشهر.
... A38: Protect the entire workbook to prevent unauthorized or accidental changes to the structure of the file. | C38: قم بحماية الكتاب بأكمله لمنع التغييرات غير المصرح بها أو غير المقصودة على هيكل الملف.
