Workbook
Name _Toc175816405: 'Relational DB'!$H$44
Name _Toc175816406: 'Relational DB'!$H$34
Name _Toc175816407: 'Relational DB'!$H$24
Name _Toc175816408: 'Relational DB'!$H$14
Name _Toc175816409: 'Relational DB'!$H$4
Name _Toc175816412: 'Relational DB'!$H$45
Name _Toc175816413: 'Relational DB'!$H$35
Name _Toc175816414: 'Relational DB'!$H$25
Name _Toc175816415: 'Relational DB'!$H$15
Name _Toc175816416: 'Relational DB'!$H$5
Name _Toc175816419: 'Relational DB'!$H$46
Name _Toc175816420: 'Relational DB'!$H$36
Name _Toc175816421: 'Relational DB'!$H$26
Name _Toc175816422: 'Relational DB'!$H$16
Name _Toc175816423: 'Relational DB'!$H$6
Name _Toc175816426: 'Relational DB'!$H$47
Name _Toc175816427: 'Relational DB'!$H$37
Name _Toc175816428: 'Relational DB'!$H$27
Name _Toc175816429: 'Relational DB'!$H$17
Name _Toc175816430: 'Relational DB'!$H$7
Name _Toc175816433: 'Relational DB'!$H$48
Name _Toc175816434: 'Relational DB'!$H$38
Name _Toc175816435: 'Relational DB'!$H$28
Name _Toc175816436: 'Relational DB'!$H$18
Name _Toc175816437: 'Relational DB'!$H$8
Name _Toc175816440: 'Relational DB'!$H$49
Name _Toc175816441: 'Relational DB'!$H$39
Name _Toc175816442: 'Relational DB'!$H$29
Name _Toc175816443: 'Relational DB'!$H$19
Name _Toc175816444: 'Relational DB'!$H$9
Name _Toc175816447: 'Relational DB'!$H$50
Name _Toc175816448: 'Relational DB'!$H$40
Name _Toc175816449: 'Relational DB'!$H$30
Name _Toc175816450: 'Relational DB'!$H$20
Name _Toc175816451: 'Relational DB'!$H$10
Name _Toc175816454: 'Relational DB'!$H$51
Name _Toc175816455: 'Relational DB'!$H$41
Name _Toc175816456: 'Relational DB'!$H$31
Name _Toc175816457: 'Relational DB'!$H$21
Name _Toc175816458: 'Relational DB'!$H$11
Name _Toc175816461: 'Relational DB'!$H$52
Name _Toc175816462: 'Relational DB'!$H$42
Name _Toc175816463: 'Relational DB'!$H$32
Name _Toc175816464: 'Relational DB'!$H$22
Name _Toc175816465: 'Relational DB'!$H$12
Name _Toc175816468: 'Relational DB'!$H$53
Name _Toc175816469: 'Relational DB'!$H$43
Name _Toc175816470: 'Relational DB'!$H$33
Name _Toc175816471: 'Relational DB'!$H$23
Name _Toc175816472: 'Relational DB'!$H$13

Sheet Cover Page
A1: Code | B1: SYB_18_2
A2: Version | B2: V1
A3: اسم القالب | B3: العاملون المؤمن عليهم اجتماعياً حسب النشاط الإقتصادي
A4: Template Name | B4: Socially Insured Employees by Economic Activity
A5: دورية البيانات | B5: سنوي
A6: Data Frequency | B6: Annual
A7: الجهة المصدرية | B7: المؤسسة العامة للضمان الإجتماعي
A8: Data Source | B8: Social Security Corporation

Sheet Source Table
B2: ='Cover Page'!B4
B3: ='Cover Page'!B3
B4: Year | C4: =YEAR('Template Data'!B1) | D4: السنة
B5: Agriculture | D5: زراعة
B6: Industry | D6: صـناعة
B7: Commerce | D7: تـجارة
B8: Constructions | D8: إنـشاءات
B9: Transport | D9: نـقـل
B10: Finance & Banking | D10: مالية ومصرفية
B11: Tourism | D11: سياحة
B12: Other Services | D12: خدمات أخرى
B13: Not Coded(Voluntary submission facility) | D13: غير مرمز (منشأة الخضوع الإختياري)
B14: free inclusion | D14: الشمول الحر

Sheet Relational DB
A1: Relational Sheet
A2: Measure_Name_Ar | B2: Measure_Name_En | C2: Measure_ID | D2: Unit_EN | E2: Unit_AR | F2: CL_SI_ACTIVITIES_EN_V1 | G2: CL_SI_ACTIVITIES_AR_V1 | H2: Obs_Value | I2: Time_Period_Y | J2: Time_Period_M
A3: اسم المؤشر | B3: Measure Name | C3: رمز المؤشر | D3: Unit | E3: الوحدة | F3: Economic Activity | G3: النشاط الإقتصادي | H3: قيمة المؤشر | I3: سنة فترة القياس | J3: شهر فترة القياس
A4: العاملون المؤمن عليهم اجتماعيا | B4: Socially Insured Employees | C4: M1 | D4: Number | E4: عدد | F4: ='Source Table'!$B$5 | G4: ='Source Table'!$D$5 | H4: 17389 | I4: 2023
A5: العاملون المؤمن عليهم اجتماعيا | B5: Socially Insured Employees | C5: M1 | D5: Number | E5: عدد | F5: ='Source Table'!$B$6 | G5: ='Source Table'!$D$6 | H5: 213176 | I5: 2023
A6: العاملون المؤمن عليهم اجتماعيا | B6: Socially Insured Employees | C6: M1 | D6: Number | E6: عدد | F6: ='Source Table'!$B$7 | G6: ='Source Table'!$D$7 | H6: 147528 | I6: 2023
A7: العاملون المؤمن عليهم اجتماعيا | B7: Socially Insured Employees | C7: M1 | D7: Number | E7: عدد | F7: ='Source Table'!$B$8 | G7: ='Source Table'!$D$8 | H7: 38786 | I7: 2023
A8: العاملون المؤمن عليهم اجتماعيا | B8: Socially Insured Employees | C8: M1 | D8: Number | E8: عدد | F8: ='Source Table'!$B$9 | G8: ='Source Table'!$D$9 | H8: 50893 | I8: 2023
A9: العاملون المؤمن عليهم اجتماعيا | B9: Socially Insured Employees | C9: M1 | D9: Number | E9: عدد | F9: ='Source Table'!$B$10 | G9: ='Source Table'!$D$10 | H9: 39920 | I9: 2023
A10: العاملون المؤمن عليهم اجتماعيا | B10: Socially Insured Employees | C10: M1 | D10: Number | E10: عدد | F10: ='Source Table'!$B$11 | G10: ='Source Table'!$D$11 | H10: 55027 | I10: 2023
A11: العاملون المؤمن عليهم اجتماعيا | B11: Socially Insured Employees | C11: M1 | D11: Number | E11: عدد | F11: ='Source Table'!$B$12 | G11: ='Source Table'!$D$12 | H11: 859990 | I11: 2023
A12: العاملون المؤمن عليهم اجتماعيا | B12: Socially Insured Employees | C12: M1 | D12: Number | E12: عدد | F12: ='Source Table'!$B$13 | G12: ='Source Table'!$D$13 | H12: 90484 | I12: 2023
A13: العاملون المؤمن عليهم اجتماعيا | B13: Socially Insured Employees | C13: M1 | D13: Number | E13: عدد | F13: ='Source Table'!$B$14 | G13: ='Source Table'!$D$14 | H13: 42039 | I13: 2023
A14: العاملون المؤمن عليهم اجتماعيا | B14: Socially Insured Employees | C14: M1 | D14: Number | E14: عدد | F14: ='Source Table'!$B$5 | G14: ='Source Table'!$D$5 | H14: 18320 | I14: 2022
A15: العاملون المؤمن عليهم اجتماعيا | B15: Socially Insured Employees | C15: M1 | D15: Number | E15: عدد | F15: ='Source Table'!$B$6 | G15: ='Source Table'!$D$6 | H15: 209664 | I15: 2022
A16: العاملون المؤمن عليهم اجتماعيا | B16: Socially Insured Employees | C16: M1 | D16: Number | E16: عدد | F16: ='Source Table'!$B$7 | G16: ='Source Table'!$D$7 | H16: 143758 | I16: 2022
A17: العاملون المؤمن عليهم اجتماعيا | B17: Socially Insured Employees | C17: M1 | D17: Number | E17: عدد | F17: ='Source Table'!$B$8 | G17: ='Source Table'!$D$8 | H17: 39650 | I17: 2022
A18: العاملون المؤمن عليهم اجتماعيا | B18: Socially Insured Employees | C18: M1 | D18: Number | E18: عدد | F18: ='Source Table'!$B$9 | G18: ='Source Table'!$D$9 | H18: 47126 | I18: 2022
A19: العاملون المؤمن عليهم اجتماعيا | B19: Socially Insured Employees | C19: M1 | D19: Number | E19: عدد | F19: ='Source Table'!$B$10 | G19: ='Source Table'!$D$10 | H19: 38570 | I19: 2022
A20: العاملون المؤمن عليهم اجتماعيا | B20: Socially Insured Employees | C20: M1 | D20: Number | E20: عدد | F20: ='Source Table'!$B$11 | G20: ='Source Table'!$D$11 | H20: 55514 | I20: 2022
A21: العاملون المؤمن عليهم اجتماعيا | B21: Socially Insured Employees | C21: M1 | D21: Number | E21: عدد | F21: ='Source Table'!$B$12 | G21: ='Source Table'!$D$12 | H21: 834181 | I21: 2022
A22: العاملون المؤمن عليهم اجتماعيا | B22: Socially Insured Employees | C22: M1 | D22: Number | E22: عدد | F22: ='Source Table'!$B$13 | G22: ='Source Table'!$D$13 | H22: 86991 | I22: 2022
A23: العاملون المؤمن عليهم اجتماعيا | B23: Socially Insured Employees | C23: M1 | D23: Number | E23: عدد | F23: ='Source Table'!$B$14 | G23: ='Source Table'!$D$14 | H23: 29245 | I23: 2022
A24: العاملون المؤمن عليهم اجتماعيا | B24: Socially Insured Employees | C24: M1 | D24: Number | E24: عدد | F24: ='Source Table'!$B$5 | G24: ='Source Table'!$D$5 | H24: 15362 | I24: 2021
A25: العاملون المؤمن عليهم اجتماعيا | B25: Socially Insured Employees | C25: M1 | D25: Number | E25: عدد | F25: ='Source Table'!$B$6 | G25: ='Source Table'!$D$6 | H25: 196054 | I25: 2021
A26: العاملون المؤمن عليهم اجتماعيا | B26: Socially Insured Employees | C26: M1 | D26: Number | E26: عدد | F26: ='Source Table'!$B$7 | G26: ='Source Table'!$D$7 | H26: 137301 | I26: 2021
A27: العاملون المؤمن عليهم اجتماعيا | B27: Socially Insured Employees | C27: M1 | D27: Number | E27: عدد | F27: ='Source Table'!$B$8 | G27: ='Source Table'!$D$8 | H27: 32959 | I27: 2021
A28: العاملون المؤمن عليهم اجتماعيا | B28: Socially Insured Employees | C28: M1 | D28: Number | E28: عدد | F28: ='Source Table'!$B$9 | G28: ='Source Table'!$D$9 | H28: 42605 | I28: 2021
A29: العاملون المؤمن عليهم اجتماعيا | B29: Socially Insured Employees | C29: M1 | D29: Number | E29: عدد | F29: ='Source Table'!$B$10 | G29: ='Source Table'!$D$10 | H29: 36840 | I29: 2021
A30: العاملون المؤمن عليهم اجتماعيا | B30: Socially Insured Employees | C30: M1 | D30: Number | E30: عدد | F30: ='Source Table'!$B$11 | G30: ='Source Table'!$D$11 | H30: 49723 | I30: 2021
A31: العاملون المؤمن عليهم اجتماعيا | B31: Socially Insured Employees | C31: M1 | D31: Number | E31: عدد | F31: ='Source Table'!$B$12 | G31: ='Source Table'!$D$12 | H31: 810008 | I31: 2021
A32: العاملون المؤمن عليهم اجتماعيا | B32: Socially Insured Employees | C32: M1 | D32: Number | E32: عدد | F32: ='Source Table'!$B$13 | G32: ='Source Table'!$D$13 | H32: 78128 | I32: 2021
A33: العاملون المؤمن عليهم اجتماعيا | B33: Socially Insured Employees | C33: M1 | D33: Number | E33: عدد | F33: ='Source Table'!$B$14 | G33: ='Source Table'!$D$14 | H33: 13061 | I33: 2021
A34: العاملون المؤمن عليهم اجتماعيا | B34: Socially Insured Employees | C34: M1 | D34: Number | E34: عدد | F34: ='Source Table'!$B$5 | G34: ='Source Table'!$D$5 | H34: 5854 | I34: 2020
A35: العاملون المؤمن عليهم اجتماعيا | B35: Socially Insured Employees | C35: M1 | D35: Number | E35: عدد | F35: ='Source Table'!$B$6 | G35: ='Source Table'!$D$6 | H35: 186961 | I35: 2020
A36: العاملون المؤمن عليهم اجتماعيا | B36: Socially Insured Employees | C36: M1 | D36: Number | E36: عدد | F36: ='Source Table'!$B$7 | G36: ='Source Table'!$D$7 | H36: 132989 | I36: 2020
A37: العاملون المؤمن عليهم اجتماعيا | B37: Socially Insured Employees | C37: M1 | D37: Number | E37: عدد | F37: ='Source Table'!$B$8 | G37: ='Source Table'!$D$8 | H37: 36809 | I37: 2020
A38: العاملون المؤمن عليهم اجتماعيا | B38: Socially Insured Employees | C38: M1 | D38: Number | E38: عدد | F38: ='Source Table'!$B$9 | G38: ='Source Table'!$D$9 | H38: 41208 | I38: 2020
A39: العاملون المؤمن عليهم اجتماعيا | B39: Socially Insured Employees | C39: M1 | D39: Number | E39: عدد | F39: ='Source Table'!$B$10 | G39: ='Source Table'!$D$10 | H39: 35775 | I39: 2020
A40: العاملون المؤمن عليهم اجتماعيا | B40: Socially Insured Employees | C40: M1 | D40: Number | E40: عدد | F40: ='Source Table'!$B$11 | G40: ='Source Table'!$D$11 | H40: 42687 | I40: 2020
...

Sheet Template Data
A1: Date | B1: =DATE(B2,B3,1)
A2: Year | B2: 2024
A3: Month | B3: 1
A4: Measure_Name_Ar | B4: Measure_Name_En | C4: Measure_ID | D4: Unit_EN | E4: Unit_AR | F4: CL_SI_ACTIVITIES_EN_V1 | G4: CL_SI_ACTIVITIES_AR_V1 | H4: Obs_Value | I4: Time_Period_Y | J4: Time_Period_M
A5: اسم المؤشر | B5: Measure Name | C5: رمز المؤشر | D5: Unit | E5: الوحدة | F5: Economic Activity | G5: النشاط الإقتصادي | H5: قيمة المؤشر | I5: سنة فترة القياس | J5: شهر فترة القياس

Sheet Help
A2: Step 1: Cover Page | C2: الخطوة 1: Cover Page
A4: Update the template information, to ensure that any meta-information about the template, such as the title, version, and description, is accurate and up-to-date. | C4: قم بتحديث معلومات القالب للتأكد من أن أي معلومات وصفية حول القالب، مثل العنوان والإصدار والوصف، دقيقة ومحدثة.
A6: Step 2: Source Table | C6: الخطوة 2: Source Table
A8: Design your template, ensuring that the time period is mapped correctly to the date information in rows 1-3 of the Template Data Sheet. | C8: قم بتصميم القالب الخاص بك، مع التأكد من أن فترة الوقت مرتبطة بشكل صحيح مع معلومات التاريخ في الصفوف 1-3 في ورقة Template Data.
A10: Step 3: Relational Sheet | C10: الخطوة 3: Relational Sheet
A12: Unpivot the data in the source table into a flat format. Follow these guidelines: | C12: قم بتحويل البيانات في جدول المصدر إلى تنسيق مسطح. اتبع هذه الإرشادات:
A13: 1. Blue Columns: Do not change the names of the blue columns. Update the data as per the current template. | C13: 1. الأعمدة الزرقاء: لا تقم بتغيير أسماء الأعمدة الزرقاء. قم بتحديث البيانات وفقًا للقالب الحالي.
A14: 2. Code Lists: Use the naming convention CL_XXX_EN_V# for code lists, where XXX is the name, and V# is the version, conforming with the definitions in the data dictionary. | C14: 2. قوائم الرموز: استخدم قاعدة التسمية CL_XXX_EN_V# لقوائم الرموز، حيث أن XXX هو الاسم و V# هو الإصدار، وفقًا للتعريفات في قاموس البيانات.
A15: 3. Code List Values: Ensure the code list values match the definitions in the data dictionary. | C15: 3. قيم قائمة الرموز: تأكد من أن قيم قائمة الرموز تتوافق مع التعريفات في قاموس البيانات.
A16: 4. Time_Period_M: Leave empty if the data frequency is yearly. | C16: 4. Time_Period_M: اتركها فارغة إذا كانت دورية البيانات سنوية.
A17: 5. Time_Period_M Format: Use one of these formats: | C17: 5. تنسيق Time_Period_M: استخدم أحد التنسيقات التالية:
A18: Numeric: (1, 2, 3, ..., 12) for months. | C18: رقمي: (1، 2، 3، ...، 12) للأشهر.
... A38: Protect the entire workbook to prevent unauthorized or accidental changes to the structure of the file. | C38: قم بحماية الكتاب بأكمله لمنع التغييرات غير المصرح بها أو غير المقصودة على هيكل الملف.
