Workbook
Name _Toc175816507: 'Relational DB'!$N$40
Name _Toc175816508: 'Relational DB'!$N$76
Name _Toc175816510: 'Relational DB'!$N$148
Name _Toc175816511: 'Relational DB'!$N$184
Name _Toc175816515: 'Relational DB'!$N$41
Name _Toc175816516: 'Relational DB'!$N$77
Name _Toc175816518: 'Relational DB'!$N$149
Name _Toc175816519: 'Relational DB'!$N$185
Name _Toc175816525: 'Relational DB'!$N$42
Name _Toc175816526: 'Relational DB'!$N$78
Name _Toc175816528: 'Relational DB'!$N$150
Name _Toc175816529: 'Relational DB'!$N$186
Name _Toc175816533: 'Relational DB'!$N$43
Name _Toc175816534: 'Relational DB'!$N$79
Name _Toc175816536: 'Relational DB'!$N$151
Name _Toc175816537: 'Relational DB'!$N$187
Name _Toc175816543: 'Relational DB'!$N$44
Name _Toc175816544: 'Relational DB'!$N$80
Name _Toc175816546: 'Relational DB'!$N$152
Name _Toc175816547: 'Relational DB'!$N$188
Name _Toc175816551: 'Relational DB'!$N$45
Name _Toc175816552: 'Relational DB'!$N$81
Name _Toc175816554: 'Relational DB'!$N$153
Name _Toc175816555: 'Relational DB'!$N$189
Name _Toc175816561: 'Relational DB'!$N$46
Name _Toc175816562: 'Relational DB'!$N$82
Name _Toc175816564: 'Relational DB'!$N$154
Name _Toc175816565: 'Relational DB'!$N$190
Name _Toc175816569: 'Relational DB'!$N$47
Name _Toc175816570: 'Relational DB'!$N$83
Name _Toc175816572: 'Relational DB'!$N$155
Name _Toc175816573: 'Relational DB'!$N$191
Name _Toc175816579: 'Relational DB'!$N$48
Name _Toc175816580: 'Relational DB'!$N$84
Name _Toc175816582: 'Relational DB'!$N$156
Name _Toc175816583: 'Relational DB'!$N$192
Name _Toc175816587: 'Relational DB'!$N$49
Name _Toc175816588: 'Relational DB'!$N$85
Name _Toc175816590: 'Relational DB'!$N$157
Name _Toc175816591: 'Relational DB'!$N$193
Name _Toc175816597: 'Relational DB'!$N$50
Name _Toc175816598: 'Relational DB'!$N$86
Name _Toc175816600: 'Relational DB'!$N$158
Name _Toc175816601: 'Relational DB'!$N$194
Name _Toc175816605: 'Relational DB'!$N$51
Name _Toc175816606: 'Relational DB'!$N$87
Name _Toc175816608: 'Relational DB'!$N$159
Name _Toc175816609: 'Relational DB'!$N$195
Name _Toc175816615: 'Relational DB'!$N$52
Name _Toc175816616: 'Relational DB'!$N$88
Name _Toc175816618: 'Relational DB'!$N$160
Name _Toc175816619: 'Relational DB'!$N$196
Name _Toc175816623: 'Relational DB'!$N$53
Name _Toc175816624: 'Relational DB'!$N$89
Name _Toc175816626: 'Relational DB'!$N$161
Name _Toc175816627: 'Relational DB'!$N$197
Name _Toc175816633: 'Relational DB'!$N$54
Name _Toc175816634: 'Relational DB'!$N$90
Name _Toc175816636: 'Relational DB'!$N$162
Name _Toc175816637: 'Relational DB'!$N$198

Sheet Cover Page
A1: Code | B1: SYB_18_2
A2: Version | B2: V1
A3: اسم القالب | B3: العاملون المؤمن عليهم اجتماعياً حسب الجنسية والجنس ومجموع الأجور ومتوسط الأجر الشهري (بالدينار) والنشاط الإقتصادي
A4: Template Name | B4: Socially Insured Employees by Nationality, Sex, Total Wages, Monthly Average Wage (JD) and Economic Activity
A5: دورية البيانات | B5: سنوي
A6: Data Frequency | B6: Annual
A7: الجهة المصدرية | B7: المؤسسة العامة للضمان الإجتماعي
A8: Data Source | B8: Social Security Corporation

Sheet Source Table
A2: ='Cover Page'!B4
A3: ='Cover Page'!B3
A4: Year | F4: =YEAR('Template Data'!B1) | I4: السنة
A5: Economic Activity | B5: Sex | C5: غير أردنيين | F5: أردنيون | I5: الجنس | J5: النشاط الإقتصادي
C6: Non-Jordanians | F6: Jordanians
C7: متوسط الأجر الشهري | D7: مجموع الأجور | E7: العدد | F7: متوسط الأجر الشهري | G7: مجموع الأجور | H7: العدد
C8: Monthly Average Wage | D8: Total Wages | E8: No | F8: Monthly Average Wage | G8: Total Wages | H8: No
A9: Agriculture,Forestry&Fishing | B9: Female | C9: 1 | D9: 1 | E9: 1 | F9: 1 | G9: 1 | H9: 1 | I9: أنثى | J9: الزراعة والصيد والحراجة
B10: Male | C10: 1 | D10: 1 | E10: 1 | F10: 1 | G10: 1 | H10: 1 | I10: ذكر
A11: Mining &Quarrying | B11: Female | C11: 1 | D11: 1 | E11: 1 | F11: 1 | G11: 1 | H11: 1 | I11: أنثى | J11: التعدين واستغلال المحاجر
B12: Male | C12: 1 | D12: 1 | E12: 1 | F12: 1 | G12: 1 | H12: 1 | I12: ذكر
A13: Manufacturing | B13: Female | C13: 1 | D13: 1 | E13: 1 | F13: 1 | G13: 1 | H13: 1 | I13: أنثى | J13: الصناعات التحويلية
B14: Male | C14: 1 | D14: 1 | E14: 1 | F14: 1 | G14: 1 | H14: 1 | I14: ذكر
A15: Electricity,Gas,Stem | B15: Female | C15: 1 | D15: 1 | E15: 1 | F15: 1 | G15: 1 | H15: 1 | I15: أنثى | J15: امدادات الكهرباء والغاز والماء
B16: Male | C16: 1 | D16: 1 | E16: 1 | F16: 1 | G16: 1 | H16: 1 | I16: ذكر
A17: Construction | B17: Female | C17: 1 | D17: 1 | E17: 1 | F17: 1 | G17: 1 | H17: 1 | I17: أنثى | J17: الإنشاءات
B18: Male | C18: 1 | D18: 1 | E18: 1 | F18: 1 | G18: 1 | H18: 1 | I18: ذكر
A19: Wholesale &Retail Trade | B19: Female | C19: 1 | D19: 1 | E19: 1 | F19: 1 | G19: 1 | H19: 1 | I19: أنثى | J19: تجارة الجملة والتجزئة
B20: Male | C20: 1 | D20: 1 | E20: 1 | F20: 1 | G20: 1 | H20: 1 | I20: ذكر
A21: Tourism | B21: Female | C21: 1 | D21: 1 | E21: 1 | F21: 1 | G21: 1 | H21: 1 | I21: أنثى | J21: السياحة
B22: Male | C22: 1 | D22: 1 | E22: 1 | F22: 1 | G22: 1 | H22: 1 | I22: ذكر
A23: Transportation,Storge& Com-munication | B23: Female | C23: 1 | D23: 1 | E23: 1 | F23: 1 | G23: 1 | H23: 1 | I23: أنثى | J23: النقل والتخزين والإتصالات
B24: Male | C24: 1 | D24: 1 | E24: 1 | F24: 1 | G24: 1 | H24: 1 | I24: ذكر
A25: Financial &Insurance | B25: Female | C25: 1 | D25: 1 | E25: 1 | F25: 1 | G25: 1 | H25: 1 | I25: أنثى | J25: الوساطة المالية
B26: Male | C26: 1 | D26: 1 | E26: 1 | F26: 1 | G26: 1 | H26: 1 | I26: ذكر
A27: Real Estate Activities | B27: Female | C27: 1 | D27: 1 | E27: 1 | F27: 1 | G27: 1 | H27: 1 | I27: أنثى | J27: الأنشطة العقارية والإيجارية
B28: Male | C28: 1 | D28: 1 | E28: 1 | F28: 1 | G28: 1 | H28: 1 | I28: ذكر
A29: Public Administration defence&Socials Security | B29: Female | C29: 1 | D29: 1 | E29: 1 | F29: 1 | G29: 1 | H29: 1 | I29: أنثى | J29: الإدارة العامة والدفاع والضمان الاجتماعي
B30: Male | C30: 1 | D30: 1 | E30: 1 | F30: 1 | G30: 1 | H30: 1 | I30: ذكر
A31: Education | B31: Female | C31: 1 | D31: 1 | E31: 1 | F31: 1 | G31: 1 | H31: 1 | I31: أنثى | J31: التعليم
B32: Male | C32: 1 | D32: 1 | E32: 1 | F32: 1 | G32: 1 | H32: 1 | I32: ذكر
A33: Health &Social Work | B33: Female | C33: 1 | D33: 1 | E33: 1 | F33: 1 | G33: 1 | H33: 1 | I33: أنثى | J33: الصحة والعمل الاجتماعي
B34: Male | C34: 1 | D34: 1 | E34: 1 | F34: 1 | G34: 1 | H34: 1 | I34: ذكر
A35: Social Services Activities | B35: Female | C35: 1 | D35: 1 | E35: 1 | F35: 1 | G35: 1 | H35: 1 | I35: أنثى | J35: أنشطة الخدمة المجتمعية
B36: Male | C36: 1 | D36: 1 | E36: 1 | F36: 1 | G36: 1 | H36: 1 | I36: ذكر
A37: Activitie of Extraterritoril Org | B37: Female | C37: 1 | D37: 1 | E37: 1 | F37: 1 | G37: 1 | H37: 1 | I37: أنثى | J37: المنظمات والهيئات غير الإقليمية
B38: Male | C38: 1 | D38: 1 | E38: 1 | F38: 1 | G38: 1 | H38: 1 | I38: ذكر
A39: Activities of Households as Employers of Domestic Personnel | B39: Female | C39: 1 | D39: 1 | E39: 1 | F39: 1 | G39: 1 | H39: 1 | I39: أنثى | J39: الأسر الخاصة التي تعين أفراداً لأداء الأعمال المنزلية
B40: Male | C40: 1 | D40: 1 | E40: 1 | F40: 1 | G40: 1 | H40: 1 | I40: ذكر
A41: Out of service death | B41: Female | C41: 1 | D41: 1 | E41: 1 | F41: 1 | G41: 1 | H41: 1 | I41: أنثى | J41: وفاة خارج الخدمة
...

Sheet Relational DB
A1: Relational Sheet
A2: Measure_Name_Ar | B2: Measure_Name_En | C2: Measure_ID | D2: Unit_EN | E2: Unit_AR | F2: CL_NATIONALITY_EN_V1 | G2: CL_NATIONALITY_AR_V1 | H2: CL_SI_STATS_EN_V1 | I2: CL_SI_STATS_AR_V1 | J2: CL_SEX_EN_V1 | K2: CL_SEX_EN_V1 | L2: CL_SI_ACTIVITIES_EN_V2 | M2: CL_SI_ACTIVITIES_AR_V2 | N2: Obs_Value | O2: Time_Period_Y | P2: Time_Period_M
A3: اسم المؤشر | B3: Measure Name | C3: رمز المؤشر | D3: Unit | E3: الوحدة | F3: Nationality | G3: الجنسية | H3: Social Insures Statistics | I3: إحصاءات الضمان الاجتماعي | J3: Sex | K3: الجنس | L3: Economic Activity | M3: النشاط الإقتصادي | N3: قيمة المؤشر | O3: سنة فترة القياس | P3: شهر فترة القياس
A4: العاملون المؤمن عليهم اجتماعيا | B4: Socially Insured Employees | C4: M1 | D4: Number | E4: عدد | F4: ='Source Table'!$F$6 | G4: ='Source Table'!$F$5 | H4: ='Source Table'!$H$8 | I4: ='Source Table'!$H$7 | J4: ='Source Table'!$B$9 | K4: ='Source Table'!$I$9 | L4: ='Source Table'!$A$9 | M4: ='Source Table'!$J$9 | N4: 655 | O4: 2023
A5: العاملون المؤمن عليهم اجتماعيا | B5: Socially Insured Employees | C5: M1 | D5: Number | E5: عدد | F5: ='Source Table'!$F$6 | G5: ='Source Table'!$F$5 | H5: ='Source Table'!$H$8 | I5: ='Source Table'!$H$7 | J5: ='Source Table'!$B$10 | K5: ='Source Table'!$I$10 | L5: ='Source Table'!$A$9 | M5: ='Source Table'!$J$9 | N5: 4190 | O5: 2023
A6: العاملون المؤمن عليهم اجتماعيا | B6: Socially Insured Employees | C6: M1 | D6: Number | E6: عدد | F6: ='Source Table'!$F$6 | G6: ='Source Table'!$F$5 | H6: ='Source Table'!$H$8 | I6: ='Source Table'!$H$7 | J6: ='Source Table'!$B$9 | K6: ='Source Table'!$I$9 | L6: ='Source Table'!$A$11 | M6: ='Source Table'!$J$11 | N6: 358 | O6: 2023
A7: العاملون المؤمن عليهم اجتماعيا | B7: Socially Insured Employees | C7: M1 | D7: Number | E7: عدد | F7: ='Source Table'!$F$6 | G7: ='Source Table'!$F$5 | H7: ='Source Table'!$H$8 | I7: ='Source Table'!$H$7 | J7: ='Source Table'!$B$10 | K7: ='Source Table'!$I$10 | L7: ='Source Table'!$A$11 | M7: ='Source Table'!$J$11 | N7: 6683 | O7: 2023
A8: العاملون المؤمن عليهم اجتماعيا | B8: Socially Insured Employees | C8: M1 | D8: Number | E8: عدد | F8: ='Source Table'!$F$6 | G8: ='Source Table'!$F$5 | H8: ='Source Table'!$H$8 | I8: ='Source Table'!$H$7 | J8: ='Source Table'!$B$9 | K8: ='Source Table'!$I$9 | L8: ='Source Table'!$A$13 | M8: ='Source Table'!$J$13 | N8: 34675 | O8: 2023
A9: العاملون المؤمن عليهم اجتماعيا | B9: Socially Insured Employees | C9: M1 | D9: Number | E9: عدد | F9: ='Source Table'!$F$6 | G9: ='Source Table'!$F$5 | H9: ='Source Table'!$H$8 | I9: ='Source Table'!$H$7 | J9: ='Source Table'!$B$10 | K9: ='Source Table'!$I$10 | L9: ='Source Table'!$A$13 | M9: ='Source Table'!$J$13 | N9: 91102 | O9: 2023
A10: العاملون المؤمن عليهم اجتماعيا | B10: Socially Insured Employees | C10: M1 | D10: Number | E10: عدد | F10: ='Source Table'!$F$6 | G10: ='Source Table'!$F$5 | H10: ='Source Table'!$H$8 | I10: ='Source Table'!$H$7 | J10: ='Source Table'!$B$9 | K10: ='Source Table'!$I$9 | L10: ='Source Table'!$A$15 | M10: ='Source Table'!$J$15 | N10: 1732 | O10: 2023
A11: العاملون المؤمن عليهم اجتماعيا | B11: Socially Insured Employees | C11: M1 | D11: Number | E11: عدد | F11: ='Source Table'!$F$6 | G11: ='Source Table'!$F$5 | H11: ='Source Table'!$H$8 | I11: ='Source Table'!$H$7 | J11: ='Source Table'!$B$10 | K11: ='Source Table'!$I$10 | L11: ='Source Table'!$A$15 | M11: ='Source Table'!$J$15 | N11: 14371 | O11: 2023
A12: العاملون المؤمن عليهم اجتماعيا | B12: Socially Insured Employees | C12: M1 | D12: Number | E12: عدد | F12: ='Source Table'!$F$6 | G12: ='Source Table'!$F$5 | H12: ='Source Table'!$H$8 | I12: ='Source Table'!$H$7 | J12: ='Source Table'!$B$9 | K12: ='Source Table'!$I$9 | L12: ='Source Table'!$A$17 | M12: ='Source Table'!$J$17 | N12: 3303 | O12: 2023
A13: العاملون المؤمن عليهم اجتماعيا | B13: Socially Insured Employees | C13: M1 | D13: Number | E13: عدد | F13: ='Source Table'!$F$6 | G13: ='Source Table'!$F$5 | H13: ='Source Table'!$H$8 | I13: ='Source Table'!$H$7 | J13: ='Source Table'!$B$10 | K13: ='Source Table'!$I$10 | L13: ='Source Table'!$A$17 | M13: ='Source Table'!$J$17 | N13: 20499 | O13: 2023
A14: العاملون المؤمن عليهم اجتماعيا | B14: Socially Insured Employees | C14: M1 | D14: Number | E14: عدد | F14: ='Source Table'!$F$6 | G14: ='Source Table'!$F$5 | H14: ='Source Table'!$H$8 | I14: ='Source Table'!$H$7 | J14: ='Source Table'!$B$9 | K14: ='Source Table'!$I$9 | L14: ='Source Table'!$A$19 | M14: ='Source Table'!$J$19 | N14: 21728 | O14: 2023
A15: العاملون المؤمن عليهم اجتماعيا | B15: Socially Insured Employees | C15: M1 | D15: Number | E15: عدد | F15: ='Source Table'!$F$6 | G15: ='Source Table'!$F$5 | H15: ='Source Table'!$H$8 | I15: ='Source Table'!$H$7 | J15: ='Source Table'!$B$10 | K15: ='Source Table'!$I$10 | L15: ='Source Table'!$A$19 | M15: ='Source Table'!$J$19 | N15: 103002 | O15: 2023
A16: العاملون المؤمن عليهم اجتماعيا | B16: Socially Insured Employees | C16: M1 | D16: Number | E16: عدد | F16: ='Source Table'!$F$6 | G16: ='Source Table'!$F$5 | H16: ='Source Table'!$H$8 | I16: ='Source Table'!$H$7 | J16: ='Source Table'!$B$9 | K16: ='Source Table'!$I$9 | L16: ='Source Table'!$A$21 | M16: ='Source Table'!$J$21 | N16: 4848 | O16: 2023
A17: العاملون المؤمن عليهم اجتماعيا | B17: Socially Insured Employees | C17: M1 | D17: Number | E17: عدد | F17: ='Source Table'!$F$6 | G17: ='Source Table'!$F$5 | H17: ='Source Table'!$H$8 | I17: ='Source Table'!$H$7 | J17: ='Source Table'!$B$10 | K17: ='Source Table'!$I$10 | L17: ='Source Table'!$A$21 | M17: ='Source Table'!$J$21 | N17: 35837 | O17: 2023
A18: العاملون المؤمن عليهم اجتماعيا | B18: Socially Insured Employees | C18: M1 | D18: Number | E18: عدد | F18: ='Source Table'!$F$6 | G18: ='Source Table'!$F$5 | H18: ='Source Table'!$H$8 | I18: ='Source Table'!$H$7 | J18: ='Source Table'!$B$9 | K18: ='Source Table'!$I$9 | L18: ='Source Table'!$A$23 | M18: ='Source Table'!$J$23 | N18: 10868 | O18: 2023
A19: العاملون المؤمن عليهم اجتماعيا | B19: Socially Insured Employees | C19: M1 | D19: Number | E19: عدد | F19: ='Source Table'!$F$6 | G19: ='Source Table'!$F$5 | H19: ='Source Table'!$H$8 | I19: ='Source Table'!$H$7 | J19: ='Source Table'!$B$10 | K19: ='Source Table'!$I$10 | L19: ='Source Table'!$A$23 | M19: ='Source Table'!$J$23 | N19: 36242 | O19: 2023
A20: العاملون المؤمن عليهم اجتماعيا | B20: Socially Insured Employees | C20: M1 | D20: Number | E20: عدد | F20: ='Source Table'!$F$6 | G20: ='Source Table'!$F$5 | H20: ='Source Table'!$H$8 | I20: ='Source Table'!$H$7 | J20: ='Source Table'!$B$9 | K20: ='Source Table'!$I$9 | L20: ='Source Table'!$A$25 | M20: ='Source Table'!$J$25 | N20: 14241 | O20: 2023
A21: العاملون المؤمن عليهم اجتماعيا | B21: Socially Insured Employees | C21: M1 | D21: Number | E21: عدد | F21: ='Source Table'!$F$6 | G21: ='Source Table'!$F$5 | H21: ='Source Table'!$H$8 | I21: ='Source Table'!$H$7 | J21: ='Source Table'!$B$10 | K21: ='Source Table'!$I$10 | L21: ='Source Table'!$A$25 | M21: ='Source Table'!$J$25 | N21: 25136 | O21: 2023
A22: العاملون المؤمن عليهم اجتماعيا | B22: Socially Insured Employees | C22: M1 | D22: Number | E22: عدد | F22: ='Source Table'!$F$6 | G22: ='Source Table'!$F$5 | H22: ='Source Table'!$H$8 | I22: ='Source Table'!$H$7 | J22: ='Source Table'!$B$9 | K22: ='Source Table'!$I$9 | L22: ='Source Table'!$A$27 | M22: ='Source Table'!$J$27 | N22: 19604 | O22: 2023
A23: العاملون المؤمن عليهم اجتماعيا | B23: Socially Insured Employees | C23: M1 | D23: Number | E23: عدد | F23: ='Source Table'!$F$6 | G23: ='Source Table'!$F$5 | H23: ='Source Table'!$H$8 | I23: ='Source Table'!$H$7 | J23: ='Source Table'!$B$10 | K23: ='Source Table'!$I$10 | L23: ='Source Table'!$A$27 | M23: ='Source Table'!$J$27 | N23: 46985 | O23: 2023
A24: العاملون المؤمن عليهم اجتماعيا | B24: Socially Insured Employees | C24: M1 | D24: Number | E24: عدد | F24: ='Source Table'!$F$6 | G24: ='Source Table'!$F$5 | H24: ='Source Table'!$H$8 | I24: ='Source Table'!$H$7 | J24: ='Source Table'!$B$9 | K24: ='Source Table'!$I$9 | L24: ='Source Table'!$A$29 | M24: ='Source Table'!$J$29 | N24: 140908 | O24: 2023
A25: العاملون المؤمن عليهم اجتماعيا | B25: Socially Insured Employees | C25: M1 | D25: Number | E25: عدد | F25: ='Source Table'!$F$6 | G25: ='Source Table'!$F$5 | H25: ='Source Table'!$H$8 | I25: ='Source Table'!$H$7 | J25: ='Source Table'!$B$10 | K25: ='Source Table'!$I$10 | L25: ='Source Table'!$A$29 | M25: ='Source Table'!$J$29 | N25: 420639 | O25: 2023
A26: العاملون المؤمن عليهم اجتماعيا | B26: Socially Insured Employees | C26: M1 | D26: Number | E26: عدد | F26: ='Source Table'!$F$6 | G26: ='Source Table'!$F$5 | H26: ='Source Table'!$H$8 | I26: ='Source Table'!$H$7 | J26: ='Source Table'!$B$9 | K26: ='Source Table'!$I$9 | L26: ='Source Table'!$A$31 | M26: ='Source Table'!$J$31 | N26: 79972 | O26: 2023
A27: العاملون المؤمن عليهم اجتماعيا | B27: Socially Insured Employees | C27: M1 | D27: Number | E27: عدد | F27: ='Source Table'!$F$6 | G27: ='Source Table'!$F$5 | H27: ='Source Table'!$H$8 | I27: ='Source Table'!$H$7 | J27: ='Source Table'!$B$10 | K27: ='Source Table'!$I$10 | L27: ='Source Table'!$A$31 | M27: ='Source Table'!$J$31 | N27: 37366 | O27: 2023
A28: العاملون المؤمن عليهم اجتماعيا | B28: Socially Insured Employees | C28: M1 | D28: Number | E28: عدد | F28: ='Source Table'!$F$6 | G28: ='Source Table'!$F$5 | H28: ='Source Table'!$H$8 | I28: ='Source Table'!$H$7 | J28: ='Source Table'!$B$9 | K28: ='Source Table'!$I$9 | L28: ='Source Table'!$A$33 | M28: ='Source Table'!$J$33 | N28: 23791 | O28: 2023
A29: العاملون المؤمن عليهم اجتماعيا | B29: Socially Insured Employees | C29: M1 | D29: Number | E29: عدد | F29: ='Source Table'!$F$6 | G29: ='Source Table'!$F$5 | H29: ='Source Table'!$H$8 | I29: ='Source Table'!$H$7 | J29: ='Source Table'!$B$10 | K29: ='Source Table'!$I$10 | L29: ='Source Table'!$A$33 | M29: ='Source Table'!$J$33 | N29: 17388 | O29: 2023
A30: العاملون المؤمن عليهم اجتماعيا | B30: Socially Insured Employees | C30: M1 | D30: Number | E30: عدد | F30: ='Source Table'!$F$6 | G30: ='Source Table'!$F$5 | H30: ='Source Table'!$H$8 | I30: ='Source Table'!$H$7 | J30: ='Source Table'!$B$9 | K30: ='Source Table'!$I$9 | L30: ='Source Table'!$A$35 | M30: ='Source Table'!$J$35 | N30: 9565 | O30: 2023
A31: العاملون المؤمن عليهم اجتماعيا | B31: Socially Insured Employees | C31: M1 | D31: Number | E31: عدد | F31: ='Source Table'!$F$6 | G31: ='Source Table'!$F$5 | H31: ='Source Table'!$H$8 | I31: ='Source Table'!$H$7 | J31: ='Source Table'!$B$10 | K31: ='Source Table'!$I$10 | L31: ='Source Table'!$A$35 | M31: ='Source Table'!$J$35 | N31: 15834 | O31: 2023
A32: العاملون المؤمن عليهم اجتماعيا | B32: Socially Insured Employees | C32: M1 | D32: Number | E32: عدد | F32: ='Source Table'!$F$6 | G32: ='Source Table'!$F$5 | H32: ='Source Table'!$H$8 | I32: ='Source Table'!$H$7 | J32: ='Source Table'!$B$9 | K32: ='Source Table'!$I$9 | L32: ='Source Table'!$A$37 | M32: ='Source Table'!$J$37 | N32: 2175 | O32: 2023
A33: العاملون المؤمن عليهم اجتماعيا | B33: Socially Insured Employees | C33: M1 | D33: Number | E33: عدد | F33: ='Source Table'!$F$6 | G33: ='Source Table'!$F$5 | H33: ='Source Table'!$H$8 | I33: ='Source Table'!$H$7 | J33: ='Source Table'!$B$10 | K33: ='Source Table'!$I$10 | L33: ='Source Table'!$A$37 | M33: ='Source Table'!$J$37 | N33: 2406 | O33: 2023
A34: العاملون المؤمن عليهم اجتماعيا | B34: Socially Insured Employees | C34: M1 | D34: Number | E34: عدد | F34: ='Source Table'!$F$6 | G34: ='Source Table'!$F$5 | H34: ='Source Table'!$H$8 | I34: ='Source Table'!$H$7 | J34: ='Source Table'!$B$9 | K34: ='Source Table'!$I$9 | L34: ='Source Table'!$A$39 | M34: ='Source Table'!$J$39 | N34: 442 | O34: 2023
A35: العاملون المؤمن عليهم اجتماعيا | B35: Socially Insured Employees | C35: M1 | D35: Number | E35: عدد | F35: ='Source Table'!$F$6 | G35: ='Source Table'!$F$5 | H35: ='Source Table'!$H$8 | I35: ='Source Table'!$H$7 | J35: ='Source Table'!$B$10 | K35: ='Source Table'!$I$10 | L35: ='Source Table'!$A$39 | M35: ='Source Table'!$J$39 | N35: 527 | O35: 2023
A36: العاملون المؤمن عليهم اجتماعيا | B36: Socially Insured Employees | C36: M1 | D36: Number | E36: عدد | F36: ='Source Table'!$F$6 | G36: ='Source Table'!$F$5 | H36: ='Source Table'!$H$8 | I36: ='Source Table'!$H$7 | J36: ='Source Table'!$B$9 | K36: ='Source Table'!$I$9 | L36: ='Source Table'!$A$41 | M36: ='Source Table'!$J$41 | N36: 0 | O36: 2023
A37: العاملون المؤمن عليهم اجتماعيا | B37: Socially Insured Employees | C37: M1 | D37: Number | E37: عدد | F37: ='Source Table'!$F$6 | G37: ='Source Table'!$F$5 | H37: ='Source Table'!$H$8 | I37: ='Source Table'!$H$7 | J37: ='Source Table'!$B$10 | K37: ='Source Table'!$I$10 | L37: ='Source Table'!$A$41 | M37: ='Source Table'!$J$41 | N37: 0 | O37: 2023
A38: العاملون المؤمن عليهم اجتماعيا | B38: Socially Insured Employees | C38: M1 | D38: Number | E38: عدد | F38: ='Source Table'!$F$6 | G38: ='Source Table'!$F$5 | H38: ='Source Table'!$H$8 | I38: ='Source Table'!$H$7 | J38: ='Source Table'!$B$9 | K38: ='Source Table'!$I$9 | L38: ='Source Table'!$A$43 | M38: ='Source Table'!$J$43 | N38: 30543 | O38: 2023
A39: العاملون المؤمن عليهم اجتماعيا | B39: Socially Insured Employees | C39: M1 | D39: Number | E39: عدد | F39: ='Source Table'!$F$6 | G39: ='Source Table'!$F$5 | H39: ='Source Table'!$H$8 | I39: ='Source Table'!$H$7 | J39: ='Source Table'!$B$10 | K39: ='Source Table'!$I$10 | L39: ='Source Table'!$A$43 | M39: ='Source Table'!$J$43 | N39: 59941 | O39: 2023
A40: العاملون المؤمن عليهم اجتماعيا | B40: Socially Insured Employees | C40: M1 | D40: JD | E40: دينار | F40: ='Source Table'!$F$6 | G40: ='Source Table'!$F$5 | H40: ='Source Table'!$G$8 | I40: ='Source Table'!$G$7 | J40: ='Source Table'!$B$9 | K40: ='Source Table'!$I$9 | L40: ='Source Table'!$A$9 | M40: ='Source Table'!$J$9 | N40: 314400 | O40: 2023
...

Sheet Template Data
A1: Date | B1: =DATE(B2,B3,1)
A2: Year | B2: 2024
A3: Month | B3: 1
A4: Measure_Name_Ar | B4: Measure_Name_En | C4: Measure_ID | D4: Unit_EN | E4: Unit_AR | F4: CL_NATIONALITY_EN_V1 | G4: CL_NATIONALITY_AR_V1 | H4: CL_SI_STATS_EN_V1 | I4: CL_SI_STATS_AR_V1 | J4: CL_SEX_EN_V1 | K4: CL_SEX_EN_V1 | L4: CL_SI_ACTIVITIES_EN_V2 | M4: CL_SI_ACTIVITIES_AR_V2 | N4: Obs_Value | O4: Time_Period_Y | P4: Time_Period_M
A5: اسم المؤشر | B5: Measure Name | C5: رمز المؤشر | D5: Unit | E5: الوحدة | F5: Nationality | G5: الجنسية | H5: Social Insures Statistics | I5: إحصاءات الضمان الاجتماعي | J5: Sex | K5: الجنس | L5: Economic Activity | M5: النشاط الإقتصادي | N5: قيمة المؤشر | O5: سنة فترة القياس | P5: شهر فترة القياس

Sheet Help
A2: Step 1: Cover Page | C2: الخطوة 1: Cover Page
A4: Update the template information, to ensure that any meta-information about the template, such as the title, version, and description, is accurate and up-to-date. | C4: قم بتحديث معلومات القالب للتأكد من أن أي معلومات وصفية حول القالب، مثل العنوان والإصدار والوصف، دقيقة ومحدثة.
A6: Step 2: Source Table | C6: الخطوة 2: Source Table
A8: Design your template, ensuring that the time period is mapped correctly to the date information in rows 1-3 of the Template Data Sheet. | C8: قم بتصميم القالب الخاص بك، مع التأكد من أن فترة الوقت مرتبطة بشكل صحيح مع معلومات التاريخ في الصفوف 1-3 في ورقة Template Data.
A10: Step 3: Relational Sheet | C10: الخطوة 3: Relational Sheet
A12: Unpivot the data in the source table into a flat format. Follow these guidelines: | C12: قم بتحويل البيانات في جدول المصدر إلى تنسيق مسطح. اتبع هذه الإرشادات:
A13: 1. Blue Columns: Do not change the names of the blue columns. Update the data as per the current template. | C13: 1. الأعمدة الزرقاء: لا تقم بتغيير أسماء الأعمدة الزرقاء. قم بتحديث البيانات وفقًا للقالب الحالي.
A14: 2. Code Lists: Use the naming convention CL_XXX_EN_V# for code lists, where XXX is the name, and V# is the version, conforming with the definitions in the data dictionary. | C14: 2. قوائم الرموز: استخدم قاعدة التسمية CL_XXX_EN_V# لقوائم الرموز، حيث أن XXX هو الاسم و V# هو الإصدار، وفقًا للتعريفات في قاموس البيانات.
A15: 3. Code List Values: Ensure the code list values match the definitions in the data dictionary. | C15: 3. قيم قائمة الرموز: تأكد من أن قيم قائمة الرموز تتوافق مع التعريفات في قاموس البيانات.
A16: 4. Time_Period_M: Leave empty if the data frequency is yearly. | C16: 4. Time_Period_M: اتركها فارغة إذا كانت دورية البيانات سنوية.
A17: 5. Time_Period_M Format: Use one of these formats: | C17: 5. تنسيق Time_Period_M: استخدم أحد التنسيقات التالية:
A18: Numeric: (1, 2, 3, ..., 12) for months. | C18: رقمي: (1، 2، 3، ...، 12) للأشهر.
... A38: Protect the entire workbook to prevent unauthorized or accidental changes to the structure of the file. | C38: قم بحماية الكتاب بأكمله لمنع التغييرات غير المصرح بها أو غير المقصودة على هيكل الملف.
