Workbook

Sheet Cover Page
A1: Code | B1: SYB_11_1_2
A2: Version | B2: V1
A3: اسم القالب | B3: أطوال شبكات الطرق الخارجية حسب نوع الطريق والمحافظة
A4: Template Name | B4: Lengths of Road Networks by Type of Road and Governorate
A5: دورية البيانات | B5: سنوي
A6: Data Frequency | B6: Yearly
A7: الجهة المصدرية | B7: وزارة الأشغال العامة والإسكان
A8: Data Source | B8: Ministry of Public Works & Housing

Sheet Source Table
B2: ='Cover Page'!B4 -> Lengths of Road Networks by Type of Road and Governorate
B3: ='Cover Page'!B3 -> أطوال شبكات الطرق الخارجية حسب نوع الطريق والمحافظة
B4: Year | D4: =YEAR('Template Data'!B1) -> 2024 | F4: السنة
B5: Governorate | C5: طرق رئيسية | D5: طرق ثانوية | E5: طرق قروية | F5: المحافظة
C6: Highways | D6: Secondary Roads | E6: Rural Roads
B7: Amman | F7: العاصمة
B8: Balqa | F8: البلقاء
B9: Zarqa | F9: الزرقاء
B10: Madaba | F10: مأدبا
B11: Irbid | F11: إربد
B12: Mafraq | F12: المفرق
B13: Jarash | F13: جرش
B14: Ajloun | F14: عجلون
B15: Karak | F15: الكرك
B16: Tafiela | F16: الطفيله
B17: Ma'an | F17: معان
B18: Aqaba | F18: العقبة

Sheet Relational DB
A1: Relational Sheet
A2: Measure_Name_Ar | B2: Measure_Name_En | C2: Measure_ID | D2: Unit_EN | E2: Unit_AR | F2: CL_GOVERNORATE_EN_V1 | G2: CL_GOVERNORATE_AR_V1 | H2: CL_ROAD_NETWROKS_EN_V1 | I2: CL_ROAD_NETWROKS_AR_V1 | J2: Obs_Value | K2: Time_Period_Y | L2: Time_Period_M
A3: اسم المؤشر | B3: Measure Name | C3: رمز المؤشر | D3: Unit | E3: الوحدة | F3: Governorate | G3: المحافظة | H3: Road Networks | I3: شبكات الطرق | J3: قيمة المؤشر | K3: سنة فترة القياس | L3: شهر فترة القياس
A4: أطوال شبكات الطرق الخارجية | B4: Lengths of Road Networks | C4: M1 | D4: KM | E4: كم | F4: ='Source Table'!$B$7 -> Amman | G4: ='Source Table'!$F$7 -> العاصمة | H4: ='Source Table'!$E$6 -> Rural Roads | I4: ='Source Table'!$E$5 -> طرق قروية | J4: 529 | K4: 2023
A5: أطوال شبكات الطرق الخارجية | B5: Lengths of Road Networks | C5: M1 | D5: KM | E5: كم | F5: ='Source Table'!$B$8 -> Balqa | G5: ='Source Table'!$F$8 -> البلقاء | H5: ='Source Table'!$E$6 -> Rural Roads | I5: ='Source Table'!$E$5 -> طرق قروية | J5: 287 | K5: 2023
A6: أطوال شبكات الطرق الخارجية | B6: Lengths of Road Networks | C6: M1 | D6: KM | E6: كم | F6: ='Source Table'!$B$9 -> Zarqa | G6: ='Source Table'!$F$9 -> الزرقاء | H6: ='Source Table'!$E$6 -> Rural Roads | I6: ='Source Table'!$E$5 -> طرق قروية | J6: 154 | K6: 2023
A7: أطوال شبكات الطرق الخارجية | B7: Lengths of Road Networks | C7: M1 | D7: KM | E7: كم | F7: ='Source Table'!$B$10 -> Madaba | G7: ='Source Table'!$F$10 -> مأدبا | H7: ='Source Table'!$E$6 -> Rural Roads | I7: ='Source Table'!$E$5 -> طرق قروية | J7: 188 | K7: 2023
A8: أطوال شبكات الطرق الخارجية | B8: Lengths of Road Networks | C8: M1 | D8: KM | E8: كم | F8: ='Source Table'!$B$11 -> Irbid | G8: ='Source Table'!$F$11 -> إربد | H8: ='Source Table'!$E$6 -> Rural Roads | I8: ='Source Table'!$E$5 -> طرق قروية | J8: 360 | K8: 2023
A9: أطوال شبكات الطرق الخارجية | B9: Lengths of Road Networks | C9: M1 | D9: KM | E9: كم | F9: ='Source Table'!$B$12 -> Mafraq | G9: ='Source Table'!$F$12 -> المفرق | H9: ='Source Table'!$E$6 -> Rural Roads | I9: ='Source Table'!$E$5 -> طرق قروية | J9: 581 | K9: 2023
A10: أطوال شبكات الطرق الخارجية | B10: Lengths of Road Networks | C10: M1 | D10: KM | E10: كم | F10: ='Source Table'!$B$13 -> Jarash | G10: ='Source Table'!$F$13 -> جرش | H10: ='Source Table'!$E$6 -> Rural Roads | I10: ='Source Table'!$E$5 -> طرق قروية | J10: 235 | K10: 2023
A11: أطوال شبكات الطرق الخارجية | B11: Lengths of Road Networks | C11: M1 | D11: KM | E11: كم | F11: ='Source Table'!$B$14 -> Ajloun | G11: ='Source Table'!$F$14 -> عجلون | H11: ='Source Table'!$E$6 -> Rural Roads | I11: ='Source Table'!$E$5 -> طرق قروية | J11: 56 | K11: 2023
A12: أطوال شبكات الطرق الخارجية | B12: Lengths of Road Networks | C12: M1 | D12: KM | E12: كم | F12: ='Source Table'!$B$15 -> Karak | G12: ='Source Table'!$F$15 -> الكرك | H12: ='Source Table'!$E$6 -> Rural Roads | I12: ='Source Table'!$E$5 -> طرق قروية | J12: 207 | K12: 2023
A13: أطوال شبكات الطرق الخارجية | B13: Lengths of Road Networks | C13: M1 | D13: KM | E13: كم | F13: ='Source Table'!$B$16 -> Tafiela | G13: ='Source Table'!$F$16 -> الطفيله | H13: ='Source Table'!$E$6 -> Rural Roads | I13: ='Source Table'!$E$5 -> طرق قروية | J13: 171 | K13: 2023
A14: أطوال شبكات الطرق الخارجية | B14: Lengths of Road Networks | C14: M1 | D14: KM | E14: كم | F14: ='Source Table'!$B$17 -> Ma'an | G14: ='Source Table'!$F$17 -> معان | H14: ='Source Table'!$E$6 -> Rural Roads | I14: ='Source Table'!$E$5 -> طرق قروية | J14: 80 | K14: 2023
A15: أطوال شبكات الطرق الخارجية | B15: Lengths of Road Networks | C15: M1 | D15: KM | E15: كم | F15: ='Source Table'!$B$18 -> Aqaba | G15: ='Source Table'!$F$18 -> العقبة | H15: ='Source Table'!$E$6 -> Rural Roads | I15: ='Source Table'!$E$5 -> طرق قروية | J15: 51 | K15: 2023
A16: أطوال شبكات الطرق الخارجية | B16: Lengths of Road Networks | C16: M1 | D16: KM | E16: كم | F16: ='Source Table'!$B$7 -> Amman | G16: ='Source Table'!$F$7 -> العاصمة | H16: ='Source Table'!$D$6 -> Secondary Roads | I16: ='Source Table'!$D$5 -> طرق ثانوية | J16: 190 | K16: 2023
A17: أطوال شبكات الطرق الخارجية | B17: Lengths of Road Networks | C17: M1 | D17: KM | E17: كم | F17: ='Source Table'!$B$8 -> Balqa | G17: ='Source Table'!$F$8 -> البلقاء | H17: ='Source Table'!$D$6 -> Secondary Roads | I17: ='Source Table'!$D$5 -> طرق ثانوية | J17: 136 | K17: 2023
A18: أطوال شبكات الطرق الخارجية | B18: Lengths of Road Networks | C18: M1 | D18: KM | E18: كم | F18: ='Source Table'!$B$9 -> Zarqa | G18: ='Source Table'!$F$9 -> الزرقاء | H18: ='Source Table'!$D$6 -> Secondary Roads | I18: ='Source Table'!$D$5 -> طرق ثانوية | J18: 153 | K18: 2023
A19: أطوال شبكات الطرق الخارجية | B19: Lengths of Road Networks | C19: M1 | D19: KM | E19: كم | F19: ='Source Table'!$B$10 -> Madaba | G19: ='Source Table'!$F$10 -> مأدبا | H19: ='Source Table'!$D$6 -> Secondary Roads | I19: ='Source Table'!$D$5 -> طرق ثانوية | J19: 120 | K19: 2023
A20: أطوال شبكات الطرق الخارجية | B20: Lengths of Road Networks | C20: M1 | D20: KM | E20: كم | F20: ='Source Table'!$B$11 -> Irbid | G20: ='Source Table'!$F$11 -> إربد | H20: ='Source Table'!$D$6 -> Secondary Roads | I20: ='Source Table'!$D$5 -> طرق ثانوية | J20: 319 | K20: 2023
A21: أطوال شبكات الطرق الخارجية | B21: Lengths of Road Networks | C21: M1 | D21: KM | E21: كم | F21: ='Source Table'!$B$12 -> Mafraq | G21: ='Source Table'!$F$12 -> المفرق | H21: ='Source Table'!$D$6 -> Secondary Roads | I21: ='Source Table'!$D$5 -> طرق ثانوية | J21: 270 | K21: 2023
A22: أطوال شبكات الطرق الخارجية | B22: Lengths of Road Networks | C22: M1 | D22: KM | E22: كم | F22: ='Source Table'!$B$13 -> Jarash | G22: ='Source Table'!$F$13 -> جرش | H22: ='Source Table'!$D$6 -> Secondary Roads | I22: ='Source Table'!$D$5 -> طرق ثانوية | J22: 108 | K22: 2023
A23: أطوال شبكات الطرق الخارجية | B23: Lengths of Road Networks | C23: M1 | D23: KM | E23: كم | F23: ='Source Table'!$B$14 -> Ajloun | G23: ='Source Table'!$F$14 -> عجلون | H23: ='Source Table'!$D$6 -> Secondary Roads | I23: ='Source Table'!$D$5 -> طرق ثانوية | J23: 142 | K23: 2023
A24: أطوال شبكات الطرق الخارجية | B24: Lengths of Road Networks | C24: M1 | D24: KM | E24: كم | F24: ='Source Table'!$B$15 -> Karak | G24: ='Source Table'!$F$15 -> الكرك | H24: ='Source Table'!$D$6 -> Secondary Roads | I24: ='Source Table'!$D$5 -> طرق ثانوية | J24: 190 | K24: 2023
A25: أطوال شبكات الطرق الخارجية | B25: Lengths of Road Networks | C25: M1 | D25: KM | E25: كم | F25: ='Source Table'!$B$16 -> Tafiela | G25: ='Source Table'!$F$16 -> الطفيله | H25: ='Source Table'!$D$6 -> Secondary Roads | I25: ='Source Table'!$D$5 -> طرق ثانوية | J25: 165 | K25: 2023
A26: أطوال شبكات الطرق الخارجية | B26: Lengths of Road Networks | C26: M1 | D26: KM | E26: كم | F26: ='Source Table'!$B$17 -> Ma'an | G26: ='Source Table'!$F$17 -> معان | H26: ='Source Table'!$D$6 -> Secondary Roads | I26: ='Source Table'!$D$5 -> طرق ثانوية | J26: 339 | K26: 2023
A27: أطوال شبكات الطرق الخارجية | B27: Lengths of Road Networks | C27: M1 | D27: KM | E27: كم | F27: ='Source Table'!$B$18 -> Aqaba | G27: ='Source Table'!$F$18 -> العقبة | H27: ='Source Table'!$D$6 -> Secondary Roads | I27: ='Source Table'!$D$5 -> طرق ثانوية | J27: 172 | K27: 2023
A28: أطوال شبكات الطرق الخارجية | B28: Lengths of Road Networks | C28: M1 | D28: KM | E28: كم | F28: ='Source Table'!$B$7 -> Amman | G28: ='Source Table'!$F$7 -> العاصمة | H28: ='Source Table'!$C$6 -> Highways | I28: ='Source Table'!$C$5 -> طرق رئيسية | J28: 306 | K28: 2023
A29: أطوال شبكات الطرق الخارجية | B29: Lengths of Road Networks | C29: M1 | D29: KM | E29: كم | F29: ='Source Table'!$B$8 -> Balqa | G29: ='Source Table'!$F$8 -> البلقاء | H29: ='Source Table'!$C$6 -> Highways | I29: ='Source Table'!$C$5 -> طرق رئيسية | J29: 227 | K29: 2023
A30: أطوال شبكات الطرق الخارجية | B30: Lengths of Road Networks | C30: M1 | D30: KM | E30: كم | F30: ='Source Table'!$B$9 -> Zarqa | G30: ='Source Table'!$F$9 -> الزرقاء | H30: ='Source Table'!$C$6 -> Highways | I30: ='Source Table'!$C$5 -> طرق رئيسية | J30: 350 | K30: 2023
A31: أطوال شبكات الطرق الخارجية | B31: Lengths of Road Networks | C31: M1 | D31: KM | E31: كم | F31: ='Source Table'!$B$10 -> Madaba | G31: ='Source Table'!$F$10 -> مأدبا | H31: ='Source Table'!$C$6 -> Highways | I31: ='Source Table'!$C$5 -> طرق رئيسية | J31: 131 | K31: 2023
A32: أطوال شبكات الطرق الخارجية | B32: Lengths of Road Networks | C32: M1 | D32: KM | E32: كم | F32: ='Source Table'!$B$11 -> Irbid | G32: ='Source Table'!$F$11 -> إربد | H32: ='Source Table'!$C$6 -> Highways | I32: ='Source Table'!$C$5 -> طرق رئيسية | J32: 238 | K32: 2023
A33: أطوال شبكات الطرق الخارجية | B33: Lengths of Road Networks | C33: M1 | D33: KM | E33: كم | F33: ='Source Table'!$B$12 -> Mafraq | G33: ='Source Table'!$F$12 -> المفرق | H33: ='Source Table'!$C$6 -> Highways | I33: ='Source Table'!$C$5 -> طرق رئيسية | J33: 520 | K33: 2023
A34: أطوال شبكات الطرق الخارجية | B34: Lengths of Road Networks | C34: M1 | D34: KM | E34: كم | F34: ='Source Table'!$B$13 -> Jarash | G34: ='Source Table'!$F$13 -> جرش | H34: ='Source Table'!$C$6 -> Highways | I34: ='Source Table'!$C$5 -> طرق رئيسية | J34: 97 | K34: 2023
A35: أطوال شبكات الطرق الخارجية | B35: Lengths of Road Networks | C35: M1 | D35: KM | E35: كم | F35: ='Source Table'!$B$14 -> Ajloun | G35: ='Source Table'!$F$14 -> عجلون | H35: ='Source Table'!$C$6 -> Highways | I35: ='Source Table'!$C$5 -> طرق رئيسية | J35: 50 | K35: 2023
A36: أطوال شبكات الطرق الخارجية | B36: Lengths of Road Networks | C36: M1 | D36: KM | E36: كم | F36: ='Source Table'!$B$15 -> Karak | G36: ='Source Table'!$F$15 -> الكرك | H36: ='Source Table'!$C$6 -> Highways | I36: ='Source Table'!$C$5 -> طرق رئيسية | J36: 295 | K36: 2023
A37: أطوال شبكات الطرق الخارجية | B37: Lengths of Road Networks | C37: M1 | D37: KM | E37: كم | F37: ='Source Table'!$B$16 -> Tafiela | G37: ='Source Table'!$F$16 -> الطفيله | H37: ='Source Table'!$C$6 -> Highways | I37: ='Source Table'!$C$5 -> طرق رئيسية | J37: 271 | K37: 2023
A38: أطوال شبكات الطرق الخارجية | B38: Lengths of Road Networks | C38: M1 | D38: KM | E38: كم | F38: ='Source Table'!$B$17 -> Ma'an | G38: ='Source Table'!$F$17 -> معان | H38: ='Source Table'!$C$6 -> Highways | I38: ='Source Table'!$C$5 -> طرق رئيسية | J38: 622 | K38: 2023
A39: أطوال شبكات الطرق الخارجية | B39: Lengths of Road Networks | C39: M1 | D39: KM | E39: كم | F39: ='Source Table'!$B$18 -> Aqaba | G39: ='Source Table'!$F$18 -> العقبة | H39: ='Source Table'!$C$6 -> Highways | I39: ='Source Table'!$C$5 -> طرق رئيسية | J39: 321 | K39: 2023
A40: أطوال شبكات الطرق الخارجية | B40: Lengths of Road Networks | C40: M1 | D40: KM | E40: كم | F40: ='Source Table'!$B$7 -> Amman | G40: ='Source Table'!$F$7 -> العاصمة | H40: ='Source Table'!$E$6 -> Rural Roads | I40: ='Source Table'!$E$5 -> طرق قروية | J40: 529 | K40: 2022
...

Sheet Template Data
A1: Date | B1: =DATE(B2,B3,1) -> 45292
A2: Year | B2: 2024
A3: Month | B3: 1
A4: Measure_Name_Ar | B4: Measure_Name_En | C4: Measure_ID | D4: Unit_EN | E4: Unit_AR | F4: CL_GOVERNORATE_EN_V1 | G4: CL_GOVERNORATE_AR_V1 | H4: CL_ROAD_NETWROKS_EN_V1 | I4: CL_ROAD_NETWROKS_AR_V1 | J4: Obs_Value | K4: Time_Period_Y | L4: Time_Period_M
A5: اسم المؤشر | B5: Measure Name | C5: رمز المؤشر | D5: Unit | E5: الوحدة | F5: Governorate | G5: المحافظة | H5: Road Networks | I5: شبكات الطرق | J5: قيمة المؤشر | K5: سنة فترة القياس | L5: شهر فترة القياس

Sheet Help
A2: Step 1: Cover Page | C2: الخطوة 1: Cover Page
A4: Update the template information, to ensure that any meta-information about the template, such as the title, version, and description, is accurate and up-to-date. | C4: قم بتحديث معلومات القالب للتأكد من أن أي معلومات وصفية حول القالب، مثل العنوان والإصدار والوصف، دقيقة ومحدثة.
A6: Step 2: Source Table | C6: الخطوة 2: Source Table
A8: Design your template, ensuring that the time period is mapped correctly to the date information in rows 1-3 of the Template Data Sheet. | C8: قم بتصميم القالب الخاص بك، مع التأكد من أن فترة الوقت مرتبطة بشكل صحيح مع معلومات التاريخ في الصفوف 1-3 في ورقة Template Data.
A10: Step 3: Relational Sheet | C10: الخطوة 3: Relational Sheet
A12: Unpivot the data in the source table into a flat format. Follow these guidelines: | C12: قم بتحويل البيانات في جدول المصدر إلى تنسيق مسطح. اتبع هذه الإرشادات:
A13: 1. Blue Columns: Do not change the names of the blue columns. Update the data as per the current template. | C13: 1. الأعمدة الزرقاء: لا تقم بتغيير أسماء الأعمدة الزرقاء. قم بتحديث البيانات وفقًا للقالب الحالي.
A14: 2. Code Lists: Use the naming convention CL_XXX_EN_V# for code lists, where XXX is the name, and V# is the version, conforming with the definitions in the data dictionary. | C14: 2. قوائم الرموز: استخدم قاعدة التسمية CL_XXX_EN_V# لقوائم الرموز، حيث أن XXX هو الاسم و V# هو الإصدار، وفقًا للتعريفات في قاموس البيانات.
A15: 3. Code List Values: Ensure the code list values match the definitions in the data dictionary. | C15: 3. قيم قائمة الرموز: تأكد من أن قيم قائمة الرموز تتوافق مع التعريفات في قاموس البيانات.
A16: 4. Time_Period_M: Leave empty if the data frequency is yearly. | C16: 4. Time_Period_M: اتركها فارغة إذا كانت دورية البيانات سنوية.
A17: 5. Time_Period_M Format: Use one of these formats: | C17: 5. تنسيق Time_Period_M: استخدم أحد التنسيقات التالية:
A18: Numeric: (1, 2, 3, ..., 12) for months. | C18: رقمي: (1، 2، 3، ...، 12) للأشهر.
... A38: Protect the entire workbook to prevent unauthorized or accidental changes to the structure of the file. | C38: قم بحماية الكتاب بأكمله لمنع التغييرات غير المصرح بها أو غير المقصودة على هيكل الملف.
