Workbook
Name _Toc175801403: 'Source Table'!$F$7
Name _Toc175801404: 'Source Table'!$F$8
Name _Toc175801406: 'Source Table'!$B$7
Name _Toc175801407: 'Source Table'!$B$8

Sheet Cover Page
A1: Code | B1: SYB_11_3_1
A2: Version | B2: V1
A3: اسم القالب | B3: البريد الداخلي والخارجي
A4: Template Name | B4: Local and External Mail
A5: دورية البيانات | B5: سنوي
A6: Data Frequency | B6: Annual
A7: الجهة المصدرية | B7: شركة البريد الأردني
A8: Data Source | B8: Jordan Post Company

Sheet Source Table
B2: ='Cover Page'!B4 -> Local and External Mail
B3: ='Cover Page'!B3 -> البريد الداخلي والخارجي
B4: Year | D4: =YEAR('Template Data'!B1) -> 2024 | F4: السنة
B5: Mail Activity | C5: البريد الخارجي الصادر | D5: البريد الخارجي لوارد | E5: البريد الداخلي | F5: الحركة البريدية
C6: External Mail Out | D6: External Mail In | E6: Local Mail
B7: Ordinary Mail | F7: البريد العادي
B8: Registered Mail | F8: البريد المسجل

Sheet Relational DB
A1: Relational Sheet
A2: Measure_Name_Ar | B2: Measure_Name_En | C2: Measure_ID | D2: Unit_EN | E2: Unit_AR | F2: CL_MAIL_ACTIVITY_EN_V1 | G2: CL_MAIL_ACTIVITY_AR_V1 | H2: CL_MAIL_TYPE_EN_V1 | I2: CL_MAIL_TYPE_AR_V1 | J2: Obs_Value | K2: Time_Period_Y | L2: Time_Period_M
A3: اسم المؤشر | B3: Measure Name | C3: رمز المؤشر | D3: Unit | E3: الوحدة | F3: Mail Avtivity | G3: الحركة البريدية | H3: Mail Type | I3: نوع البريد | J3: قيمة المؤشر | K3: سنة فترة القياس | L3: شهر فترة القياس
A4: البريد الداخلي والخارجي | B4: Local and External Mail | C4: M1 | D4: 000 | E4: ألف | F4: ='Source Table'!$E$6 -> Local Mail | G4: ='Source Table'!$E$5 -> البريد الداخلي | H4: ='Source Table'!_Toc175801406 -> Ordinary Mail | I4: ='Source Table'!_Toc175801403 -> البريد العادي | J4: 443.6 | K4: 2023
A5: البريد الداخلي والخارجي | B5: Local and External Mail | C5: M1 | D5: 000 | E5: ألف | F5: ='Source Table'!$E$6 -> Local Mail | G5: ='Source Table'!$E$5 -> البريد الداخلي | H5: ='Source Table'!_Toc175801407 -> Registered Mail | I5: ='Source Table'!_Toc175801404 -> البريد المسجل | J5: 238.9 | K5: 2023
A6: البريد الداخلي والخارجي | B6: Local and External Mail | C6: M1 | D6: 000 | E6: ألف | F6: ='Source Table'!$D$6 -> External Mail In | G6: ='Source Table'!$D$5 -> البريد الخارجي لوارد | H6: ='Source Table'!_Toc175801406 -> Ordinary Mail | I6: ='Source Table'!_Toc175801403 -> البريد العادي | J6: 415.7 | K6: 2023
A7: البريد الداخلي والخارجي | B7: Local and External Mail | C7: M1 | D7: 000 | E7: ألف | F7: ='Source Table'!$D$6 -> External Mail In | G7: ='Source Table'!$D$5 -> البريد الخارجي لوارد | H7: ='Source Table'!_Toc175801407 -> Registered Mail | I7: ='Source Table'!_Toc175801404 -> البريد المسجل | J7: 35.6 | K7: 2023
A8: البريد الداخلي والخارجي | B8: Local and External Mail | C8: M1 | D8: 000 | E8: ألف | F8: ='Source Table'!$C$6 -> External Mail Out | G8: ='Source Table'!$C$5 -> البريد الخارجي الصادر | H8: ='Source Table'!_Toc175801406 -> Ordinary Mail | I8: ='Source Table'!_Toc175801403 -> البريد العادي | J8: 29.8 | K8: 2023
A9: البريد الداخلي والخارجي | B9: Local and External Mail | C9: M1 | D9: 000 | E9: ألف | F9: ='Source Table'!$C$6 -> External Mail Out | G9: ='Source Table'!$C$5 -> البريد الخارجي الصادر | H9: ='Source Table'!_Toc175801407 -> Registered Mail | I9: ='Source Table'!_Toc175801404 -> البريد المسجل | J9: 129.7 | K9: 2023
A10: البريد الداخلي والخارجي | B10: Local and External Mail | C10: M1 | D10: 000 | E10: ألف | F10: ='Source Table'!$E$6 -> Local Mail | G10: ='Source Table'!$E$5 -> البريد الداخلي | H10: ='Source Table'!_Toc175801406 -> Ordinary Mail | I10: ='Source Table'!_Toc175801403 -> البريد العادي | J10: 783 | K10: 2022
A11: البريد الداخلي والخارجي | B11: Local and External Mail | C11: M1 | D11: 000 | E11: ألف | F11: ='Source Table'!$E$6 -> Local Mail | G11: ='Source Table'!$E$5 -> البريد الداخلي | H11: ='Source Table'!_Toc175801407 -> Registered Mail | I11: ='Source Table'!_Toc175801404 -> البريد المسجل | J11: 207.6 | K11: 2022
A12: البريد الداخلي والخارجي | B12: Local and External Mail | C12: M1 | D12: 000 | E12: ألف | F12: ='Source Table'!$D$6 -> External Mail In | G12: ='Source Table'!$D$5 -> البريد الخارجي لوارد | H12: ='Source Table'!_Toc175801406 -> Ordinary Mail | I12: ='Source Table'!_Toc175801403 -> البريد العادي | J12: 465.9 | K12: 2022
A13: البريد الداخلي والخارجي | B13: Local and External Mail | C13: M1 | D13: 000 | E13: ألف | F13: ='Source Table'!$D$6 -> External Mail In | G13: ='Source Table'!$D$5 -> البريد الخارجي لوارد | H13: ='Source Table'!_Toc175801407 -> Registered Mail | I13: ='Source Table'!_Toc175801404 -> البريد المسجل | J13: 33.8 | K13: 2022
A14: البريد الداخلي والخارجي | B14: Local and External Mail | C14: M1 | D14: 000 | E14: ألف | F14: ='Source Table'!$C$6 -> External Mail Out | G14: ='Source Table'!$C$5 -> البريد الخارجي الصادر | H14: ='Source Table'!_Toc175801406 -> Ordinary Mail | I14: ='Source Table'!_Toc175801403 -> البريد العادي | J14: 23.6 | K14: 2022
A15: البريد الداخلي والخارجي | B15: Local and External Mail | C15: M1 | D15: 000 | E15: ألف | F15: ='Source Table'!$C$6 -> External Mail Out | G15: ='Source Table'!$C$5 -> البريد الخارجي الصادر | H15: ='Source Table'!_Toc175801407 -> Registered Mail | I15: ='Source Table'!_Toc175801404 -> البريد المسجل | J15: 79 | K15: 2022
A16: البريد الداخلي والخارجي | B16: Local and External Mail | C16: M1 | D16: 000 | E16: ألف | F16: ='Source Table'!$E$6 -> Local Mail | G16: ='Source Table'!$E$5 -> البريد الداخلي | H16: ='Source Table'!_Toc175801406 -> Ordinary Mail | I16: ='Source Table'!_Toc175801403 -> البريد العادي | J16: 1035.4 | K16: 2021
A17: البريد الداخلي والخارجي | B17: Local and External Mail | C17: M1 | D17: 000 | E17: ألف | F17: ='Source Table'!$E$6 -> Local Mail | G17: ='Source Table'!$E$5 -> البريد الداخلي | H17: ='Source Table'!_Toc175801407 -> Registered Mail | I17: ='Source Table'!_Toc175801404 -> البريد المسجل | J17: 129 | K17: 2021
A18: البريد الداخلي والخارجي | B18: Local and External Mail | C18: M1 | D18: 000 | E18: ألف | F18: ='Source Table'!$D$6 -> External Mail In | G18: ='Source Table'!$D$5 -> البريد الخارجي لوارد | H18: ='Source Table'!_Toc175801406 -> Ordinary Mail | I18: ='Source Table'!_Toc175801403 -> البريد العادي | J18: 666 | K18: 2021
A19: البريد الداخلي والخارجي | B19: Local and External Mail | C19: M1 | D19: 000 | E19: ألف | F19: ='Source Table'!$D$6 -> External Mail In | G19: ='Source Table'!$D$5 -> البريد الخارجي لوارد | H19: ='Source Table'!_Toc175801407 -> Registered Mail | I19: ='Source Table'!_Toc175801404 -> البريد المسجل | J19: 37.3 | K19: 2021
A20: البريد الداخلي والخارجي | B20: Local and External Mail | C20: M1 | D20: 000 | E20: ألف | F20: ='Source Table'!$C$6 -> External Mail Out | G20: ='Source Table'!$C$5 -> البريد الخارجي الصادر | H20: ='Source Table'!_Toc175801406 -> Ordinary Mail | I20: ='Source Table'!_Toc175801403 -> البريد العادي | J20: 14.2 | K20: 2021
A21: البريد الداخلي والخارجي | B21: Local and External Mail | C21: M1 | D21: 000 | E21: ألف | F21: ='Source Table'!$C$6 -> External Mail Out | G21: ='Source Table'!$C$5 -> البريد الخارجي الصادر | H21: ='Source Table'!_Toc175801407 -> Registered Mail | I21: ='Source Table'!_Toc175801404 -> البريد المسجل | J21: 58.6 | K21: 2021
A22: البريد الداخلي والخارجي | B22: Local and External Mail | C22: M1 | D22: Number | E22: عدد | F22: ='Source Table'!$E$6 -> Local Mail | G22: ='Source Table'!$E$5 -> البريد الداخلي | H22: ='Source Table'!_Toc175801406 -> Ordinary Mail | I22: ='Source Table'!_Toc175801403 -> البريد العادي | J22: 1374900 | K22: 2020
A23: البريد الداخلي والخارجي | B23: Local and External Mail | C23: M1 | D23: Number | E23: عدد | F23: ='Source Table'!$E$6 -> Local Mail | G23: ='Source Table'!$E$5 -> البريد الداخلي | H23: ='Source Table'!_Toc175801407 -> Registered Mail | I23: ='Source Table'!_Toc175801404 -> البريد المسجل | J23: 229315 | K23: 2020
A24: البريد الداخلي والخارجي | B24: Local and External Mail | C24: M1 | D24: Number | E24: عدد | F24: ='Source Table'!$D$6 -> External Mail In | G24: ='Source Table'!$D$5 -> البريد الخارجي لوارد | H24: ='Source Table'!_Toc175801406 -> Ordinary Mail | I24: ='Source Table'!_Toc175801403 -> البريد العادي | J24: 555782 | K24: 2020
A25: البريد الداخلي والخارجي | B25: Local and External Mail | C25: M1 | D25: Number | E25: عدد | F25: ='Source Table'!$D$6 -> External Mail In | G25: ='Source Table'!$D$5 -> البريد الخارجي لوارد | H25: ='Source Table'!_Toc175801407 -> Registered Mail | I25: ='Source Table'!_Toc175801404 -> البريد المسجل | J25: 47352 | K25: 2020
A26: البريد الداخلي والخارجي | B26: Local and External Mail | C26: M1 | D26: Number | E26: عدد | F26: ='Source Table'!$C$6 -> External Mail Out | G26: ='Source Table'!$C$5 -> البريد الخارجي الصادر | H26: ='Source Table'!_Toc175801406 -> Ordinary Mail | I26: ='Source Table'!_Toc175801403 -> البريد العادي | J26: 11974 | K26: 2020
A27: البريد الداخلي والخارجي | B27: Local and External Mail | C27: M1 | D27: Number | E27: عدد | F27: ='Source Table'!$C$6 -> External Mail Out | G27: ='Source Table'!$C$5 -> البريد الخارجي الصادر | H27: ='Source Table'!_Toc175801407 -> Registered Mail | I27: ='Source Table'!_Toc175801404 -> البريد المسجل | J27: 45597 | K27: 2020
A28: البريد الداخلي والخارجي | B28: Local and External Mail | C28: M1 | D28: Number | E28: عدد | F28: ='Source Table'!$E$6 -> Local Mail | G28: ='Source Table'!$E$5 -> البريد الداخلي | H28: ='Source Table'!_Toc175801406 -> Ordinary Mail | I28: ='Source Table'!_Toc175801403 -> البريد العادي | J28: 1900 | K28: 2019
A29: البريد الداخلي والخارجي | B29: Local and External Mail | C29: M1 | D29: Number | E29: عدد | F29: ='Source Table'!$E$6 -> Local Mail | G29: ='Source Table'!$E$5 -> البريد الداخلي | H29: ='Source Table'!_Toc175801407 -> Registered Mail | I29: ='Source Table'!_Toc175801404 -> البريد المسجل | J29: 373 | K29: 2019
A30: البريد الداخلي والخارجي | B30: Local and External Mail | C30: M1 | D30: Number | E30: عدد | F30: ='Source Table'!$D$6 -> External Mail In | G30: ='Source Table'!$D$5 -> البريد الخارجي لوارد | H30: ='Source Table'!_Toc175801406 -> Ordinary Mail | I30: ='Source Table'!_Toc175801403 -> البريد العادي | J30: 950 | K30: 2019
A31: البريد الداخلي والخارجي | B31: Local and External Mail | C31: M1 | D31: Number | E31: عدد | F31: ='Source Table'!$D$6 -> External Mail In | G31: ='Source Table'!$D$5 -> البريد الخارجي لوارد | H31: ='Source Table'!_Toc175801407 -> Registered Mail | I31: ='Source Table'!_Toc175801404 -> البريد المسجل | J31: 345 | K31: 2019
A32: البريد الداخلي والخارجي | B32: Local and External Mail | C32: M1 | D32: Number | E32: عدد | F32: ='Source Table'!$C$6 -> External Mail Out | G32: ='Source Table'!$C$5 -> البريد الخارجي الصادر | H32: ='Source Table'!_Toc175801406 -> Ordinary Mail | I32: ='Source Table'!_Toc175801403 -> البريد العادي | J32: 63 | K32: 2019
A33: البريد الداخلي والخارجي | B33: Local and External Mail | C33: M1 | D33: Number | E33: عدد | F33: ='Source Table'!$C$6 -> External Mail Out | G33: ='Source Table'!$C$5 -> البريد الخارجي الصادر | H33: ='Source Table'!_Toc175801407 -> Registered Mail | I33: ='Source Table'!_Toc175801404 -> البريد المسجل | J33: 43 | K33: 2019
A34: البريد الداخلي والخارجي | B34: Local and External Mail | C34: M1 | D34: Number | E34: عدد | F34: ='Source Table'!$E$6 -> Local Mail | G34: ='Source Table'!$E$5 -> البريد الداخلي | H34: ='Source Table'!_Toc175801406 -> Ordinary Mail | I34: ='Source Table'!_Toc175801403 -> البريد العادي | J34: 2598 | K34: 2018
A35: البريد الداخلي والخارجي | B35: Local and External Mail | C35: M1 | D35: Number | E35: عدد | F35: ='Source Table'!$E$6 -> Local Mail | G35: ='Source Table'!$E$5 -> البريد الداخلي | H35: ='Source Table'!_Toc175801407 -> Registered Mail | I35: ='Source Table'!_Toc175801404 -> البريد المسجل | J35: 404 | K35: 2018
A36: البريد الداخلي والخارجي | B36: Local and External Mail | C36: M1 | D36: Number | E36: عدد | F36: ='Source Table'!$D$6 -> External Mail In | G36: ='Source Table'!$D$5 -> البريد الخارجي لوارد | H36: ='Source Table'!_Toc175801406 -> Ordinary Mail | I36: ='Source Table'!_Toc175801403 -> البريد العادي | J36: 627.6 | K36: 2018
A37: البريد الداخلي والخارجي | B37: Local and External Mail | C37: M1 | D37: Number | E37: عدد | F37: ='Source Table'!$D$6 -> External Mail In | G37: ='Source Table'!$D$5 -> البريد الخارجي لوارد | H37: ='Source Table'!_Toc175801407 -> Registered Mail | I37: ='Source Table'!_Toc175801404 -> البريد المسجل | J37: 151.9 | K37: 2018
A38: البريد الداخلي والخارجي | B38: Local and External Mail | C38: M1 | D38: Number | E38: عدد | F38: ='Source Table'!$C$6 -> External Mail Out | G38: ='Source Table'!$C$5 -> البريد الخارجي الصادر | H38: ='Source Table'!_Toc175801406 -> Ordinary Mail | I38: ='Source Table'!_Toc175801403 -> البريد العادي | J38: 157.1 | K38: 2018
A39: البريد الداخلي والخارجي | B39: Local and External Mail | C39: M1 | D39: Number | E39: عدد | F39: ='Source Table'!$C$6 -> External Mail Out | G39: ='Source Table'!$C$5 -> البريد الخارجي الصادر | H39: ='Source Table'!_Toc175801407 -> Registered Mail | I39: ='Source Table'!_Toc175801404 -> البريد المسجل | J39: 14.6 | K39: 2018
A40: البريد الداخلي والخارجي | B40: Local and External Mail | C40: M1 | D40: Number | E40: عدد | F40: ='Source Table'!$E$6 -> Local Mail | G40: ='Source Table'!$E$5 -> البريد الداخلي | H40: ='Source Table'!_Toc175801406 -> Ordinary Mail | I40: ='Source Table'!_Toc175801403 -> البريد العادي | J40: 3130.9 | K40: 2017
...

Sheet Template Data
A1: Date | B1: =DATE(B2,B3,1) -> 45292
A2: Year | B2: 2024
A3: Month | B3: 1
A4: Measure_Name_Ar | B4: Measure_Name_En | C4: Measure_ID | D4: Unit_EN | E4: Unit_AR | F4: CL_MAIL_ACTIVITY_EN_V1 | G4: CL_MAIL_ACTIVITY_AR_V1 | H4: CL_MAIL_TYPE_EN_V1 | I4: CL_MAIL_TYPE_AR_V1 | J4: Obs_Value | K4: Time_Period_Y | L4: Time_Period_M
A5: اسم المؤشر | B5: Measure Name | C5: رمز المؤشر | D5: Unit | E5: الوحدة | F5: Mail Avtivity | G5: الحركة البريدية | H5: Mail Type | I5: نوع البريد | J5: قيمة المؤشر | K5: سنة فترة القياس | L5: شهر فترة القياس

Sheet Help
A2: Step 1: Cover Page | C2: الخطوة 1: Cover Page
A4: Update the template information, to ensure that any meta-information about the template, such as the title, version, and description, is accurate and up-to-date. | C4: قم بتحديث معلومات القالب للتأكد من أن أي معلومات وصفية حول القالب، مثل العنوان والإصدار والوصف، دقيقة ومحدثة.
A6: Step 2: Source Table | C6: الخطوة 2: Source Table
A8: Design your template, ensuring that the time period is mapped correctly to the date information in rows 1-3 of the Template Data Sheet. | C8: قم بتصميم القالب الخاص بك، مع التأكد من أن فترة الوقت مرتبطة بشكل صحيح مع معلومات التاريخ في الصفوف 1-3 في ورقة Template Data.
A10: Step 3: Relational Sheet | C10: الخطوة 3: Relational Sheet
A12: Unpivot the data in the source table into a flat format. Follow these guidelines: | C12: قم بتحويل البيانات في جدول المصدر إلى تنسيق مسطح. اتبع هذه الإرشادات:
A13: 1. Blue Columns: Do not change the names of the blue columns. Update the data as per the current template. | C13: 1. الأعمدة الزرقاء: لا تقم بتغيير أسماء الأعمدة الزرقاء. قم بتحديث البيانات وفقًا للقالب الحالي.
A14: 2. Code Lists: Use the naming convention CL_XXX_EN_V# for code lists, where XXX is the name, and V# is the version, conforming with the definitions in the data dictionary. | C14: 2. قوائم الرموز: استخدم قاعدة التسمية CL_XXX_EN_V# لقوائم الرموز، حيث أن XXX هو الاسم و V# هو الإصدار، وفقًا للتعريفات في قاموس البيانات.
A15: 3. Code List Values: Ensure the code list values match the definitions in the data dictionary. | C15: 3. قيم قائمة الرموز: تأكد من أن قيم قائمة الرموز تتوافق مع التعريفات في قاموس البيانات.
A16: 4. Time_Period_M: Leave empty if the data frequency is yearly. | C16: 4. Time_Period_M: اتركها فارغة إذا كانت دورية البيانات سنوية.
A17: 5. Time_Period_M Format: Use one of these formats: | C17: 5. تنسيق Time_Period_M: استخدم أحد التنسيقات التالية:
A18: Numeric: (1, 2, 3, ..., 12) for months. | C18: رقمي: (1، 2، 3، ...، 12) للأشهر.
... A38: Protect the entire workbook to prevent unauthorized or accidental changes to the structure of the file. | C38: قم بحماية الكتاب بأكمله لمنع التغييرات غير المصرح بها أو غير المقصودة على هيكل الملف.
