Workbook

Sheet Cover Page
A1: Code | B1: SYB_15_1_1
A2: Version | B2: V1
A3: اسم القالب | B3: القادمون حسب وسيلة السفر ومركز الدخول
A4: Template Name | B4: Arrivals by Means of Transport and Point of Entry
A5: دورية البيانات | B5: سنوي
A6: Data Frequency | B6: Yearly
A7: الجهة المصدرية | B7: مديرية الأمن العام
A8: Data Source | B8: Public Security Directorate

Sheet Source Table
B2: ='Cover Page'!B4 -> Arrivals by Means of Transport and Point of Entry
B3: ='Cover Page'!B3 -> القادمون حسب وسيلة السفر ومركز الدخول
B4: Year | C4: 2024 | D4: السنة
B5: Means of Transport | D5: وسيلة السفر
B6: Land | D6: بر
B7: Sea | D7: بحر
B8: Air | D8: جو
B9: Point of Entry | D9: مركز الدخول
B10: Queen Alia Int. Airport | D10: مطار الملكة علياء الدولي
B11: Amman Civil Airport | D11: مطار عمان المدني
B12: Aqaba Airport | D12: مطار العقبة
B13: Ramtha | D13: الرمثا
B14: Omari | D14: العمري
B15: Mudawara | D15: المدورة
B16: Durrah | D16: الدرة
... B22: Jaber | D22: جابر

Sheet Relational DB
A2: Measure_Name_Ar | B2: Measure_Name_En | C2: Measure_ID | D2: Unit_EN | E2: Unit_AR | F2: CL_MEANS_OF_TRANSPORT_AR_V1 | G2: CL_MEANS_OF_TRANSPORT_EN_v1 | H2: CL_POINTS_OF_ENTRY_AND_DEPARTURE_AR_V1 | I2: CL_POINTS_OF_ENTRY_AND_DEPARTURE_EN_V1 | J2: Obs_Value | K2: Time_Period_Y | L2: Time_Period_M
A3: اسم المؤشر | B3: Measure Name | C3: رمز المؤشر | D3: Unit | E3: الوحدة | F3: ='Source Table'!$D$5 -> وسيلة السفر | G3: ='Source Table'!$B$5 -> Means of Transport | H3: مراكز الدخول و المغادرة | I3: Points and of Entry and Departure | J3: قيمة المؤشر | K3: سنة فترة القياس | L3: شهر فترة القياس
A4: القادمون | B4: Arrivals | C4: M1 | D4: Number | E4: عدد | F4: ='Source Table'!$D$6 -> بر | G4: ='Source Table'!$B$6 -> Land | H4: Not Applicable | I4: Not Applicable | J4: 4994 | K4: 2023
A5: القادمون | B5: Arrivals | C5: M1 | D5: Number | E5: عدد | F5: ='Source Table'!$D$7 -> بحر | G5: ='Source Table'!$B$7 -> Sea | H5: Not Applicable | I5: Not Applicable | J5: 226 | K5: 2023
A6: القادمون | B6: Arrivals | C6: M1 | D6: Number | E6: عدد | F6: ='Source Table'!$D$8 -> جو | G6: ='Source Table'!$B$8 -> Air | H6: Not Applicable | I6: Not Applicable | J6: 4074 | K6: 2023
A7: القادمون | B7: Arrivals | C7: M1 | D7: Number | E7: عدد | F7: Not Applicable | G7: Not Applicable | H7: ='Source Table'!$D$10 -> مطار الملكة علياء الدولي | I7: ='Source Table'!$B$10 -> Queen Alia Int. Airport | J7: 3962 | K7: 2023
A8: القادمون | B8: Arrivals | C8: M1 | D8: Number | E8: عدد | F8: Not Applicable | G8: Not Applicable | H8: ='Source Table'!$D$11 -> مطار عمان المدني | I8: ='Source Table'!$B$11 -> Amman Civil Airport | J8: 15 | K8: 2023
A9: القادمون | B9: Arrivals | C9: M1 | D9: Number | E9: عدد | F9: Not Applicable | G9: Not Applicable | H9: ='Source Table'!$D$12 -> مطار العقبة | I9: ='Source Table'!$B$12 -> Aqaba Airport | J9: 96 | K9: 2023
A10: القادمون | B10: Arrivals | C10: M1 | D10: Number | E10: عدد | F10: Not Applicable | G10: Not Applicable | H10: ='Source Table'!$D$13 -> الرمثا | I10: ='Source Table'!$B$13 -> Ramtha | J10: 0 | K10: 2023
A11: القادمون | B11: Arrivals | C11: M1 | D11: Number | E11: عدد | F11: Not Applicable | G11: Not Applicable | H11: ='Source Table'!$D$14 -> العمري | I11: ='Source Table'!$B$14 -> Omari | J11: 1650 | K11: 2023
A12: القادمون | B12: Arrivals | C12: M1 | D12: Number | E12: عدد | F12: Not Applicable | G12: Not Applicable | H12: ='Source Table'!$D$15 -> المدورة | I12: ='Source Table'!$B$15 -> Mudawara | J12: 344 | K12: 2023
A13: القادمون | B13: Arrivals | C13: M1 | D13: Number | E13: عدد | F13: Not Applicable | G13: Not Applicable | H13: ='Source Table'!$D$16 -> الدرة | I13: ='Source Table'!$B$16 -> Durrah | J13: 631 | K13: 2023
A14: القادمون | B14: Arrivals | C14: M1 | D14: Number | E14: عدد | F14: Not Applicable | G14: Not Applicable | H14: ='Source Table'!$D$17 -> ميناء العقبة | I14: ='Source Table'!$B$17 -> Aqaba Port | J14: 226 | K14: 2023
A15: القادمون | B15: Arrivals | C15: M1 | D15: Number | E15: عدد | F15: Not Applicable | G15: Not Applicable | H15: ='Source Table'!$D$18 -> معبر وادي الأردن | I15: ='Source Table'!$B$18 -> Jordan Vally | J15: 246 | K15: 2023
A16: القادمون | B16: Arrivals | C16: M1 | D16: Number | E16: عدد | F16: Not Applicable | G16: Not Applicable | H16: ='Source Table'!$D$19 -> الكرامة | I16: ='Source Table'!$B$19 -> Alkaramah | J16: 101 | K16: 2023
A17: القادمون | B17: Arrivals | C17: M1 | D17: Number | E17: عدد | F17: Not Applicable | G17: Not Applicable | H17: ='Source Table'!$D$20 -> معبر وادي عربة | I17: ='Source Table'!$B$20 -> Wadi Araba Crossing | J17: 221 | K17: 2023
A18: القادمون | B18: Arrivals | C18: M1 | D18: Number | E18: عدد | F18: Not Applicable | G18: Not Applicable | H18: ='Source Table'!$D$21 -> الجسور | I18: ='Source Table'!$B$21 -> Bridges | J18: 1190 | K18: 2023
A19: القادمون | B19: Arrivals | C19: M1 | D19: Number | E19: عدد | F19: Not Applicable | G19: Not Applicable | H19: ='Source Table'!$D$22 -> جابر | I19: ='Source Table'!$B$22 -> Jaber | J19: 612 | K19: 2023
A20: القادمون | B20: Arrivals | C20: M1 | D20: Number | E20: عدد | F20: ='Source Table'!$D$6 -> بر | G20: ='Source Table'!$B$6 -> Land | H20: Not Applicable | I20: Not Applicable | J20: 3867 | K20: 2022
A21: القادمون | B21: Arrivals | C21: M1 | D21: Number | E21: عدد | F21: ='Source Table'!$D$7 -> بحر | G21: ='Source Table'!$B$7 -> Sea | H21: Not Applicable | I21: Not Applicable | J21: 171 | K21: 2022
A22: القادمون | B22: Arrivals | C22: M1 | D22: Number | E22: عدد | F22: ='Source Table'!$D$8 -> جو | G22: ='Source Table'!$B$8 -> Air | H22: Not Applicable | I22: Not Applicable | J22: 3540 | K22: 2022
A23: القادمون | B23: Arrivals | C23: M1 | D23: Number | E23: عدد | F23: Not Applicable | G23: Not Applicable | H23: ='Source Table'!$D$10 -> مطار الملكة علياء الدولي | I23: ='Source Table'!$B$10 -> Queen Alia Int. Airport | J23: 3442 | K23: 2022
A24: القادمون | B24: Arrivals | C24: M1 | D24: Number | E24: عدد | F24: Not Applicable | G24: Not Applicable | H24: ='Source Table'!$D$11 -> مطار عمان المدني | I24: ='Source Table'!$B$11 -> Amman Civil Airport | J24: 11 | K24: 2022
A25: القادمون | B25: Arrivals | C25: M1 | D25: Number | E25: عدد | F25: Not Applicable | G25: Not Applicable | H25: ='Source Table'!$D$12 -> مطار العقبة | I25: ='Source Table'!$B$12 -> Aqaba Airport | J25: 86 | K25: 2022
A26: القادمون | B26: Arrivals | C26: M1 | D26: Number | E26: عدد | F26: Not Applicable | G26: Not Applicable | H26: ='Source Table'!$D$13 -> الرمثا | I26: ='Source Table'!$B$13 -> Ramtha | J26: 0 | K26: 2022
A27: القادمون | B27: Arrivals | C27: M1 | D27: Number | E27: عدد | F27: Not Applicable | G27: Not Applicable | H27: ='Source Table'!$D$14 -> العمري | I27: ='Source Table'!$B$14 -> Omari | J27: 1342 | K27: 2022
A28: القادمون | B28: Arrivals | C28: M1 | D28: Number | E28: عدد | F28: Not Applicable | G28: Not Applicable | H28: ='Source Table'!$D$15 -> المدورة | I28: ='Source Table'!$B$15 -> Mudawara | J28: 237 | K28: 2022
A29: القادمون | B29: Arrivals | C29: M1 | D29: Number | E29: عدد | F29: Not Applicable | G29: Not Applicable | H29: ='Source Table'!$D$16 -> الدرة | I29: ='Source Table'!$B$16 -> Durrah | J29: 314 | K29: 2022
A30: القادمون | B30: Arrivals | C30: M1 | D30: Number | E30: عدد | F30: Not Applicable | G30: Not Applicable | H30: ='Source Table'!$D$17 -> ميناء العقبة | I30: ='Source Table'!$B$17 -> Aqaba Port | J30: 171 | K30: 2022
A31: القادمون | B31: Arrivals | C31: M1 | D31: Number | E31: عدد | F31: Not Applicable | G31: Not Applicable | H31: ='Source Table'!$D$18 -> معبر وادي الأردن | I31: ='Source Table'!$B$18 -> Jordan Vally | J31: 190 | K31: 2022
A32: القادمون | B32: Arrivals | C32: M1 | D32: Number | E32: عدد | F32: Not Applicable | G32: Not Applicable | H32: ='Source Table'!$D$19 -> الكرامة | I32: ='Source Table'!$B$19 -> Alkaramah | J32: 85 | K32: 2022
A33: القادمون | B33: Arrivals | C33: M1 | D33: Number | E33: عدد | F33: Not Applicable | G33: Not Applicable | H33: ='Source Table'!$D$20 -> معبر وادي عربة | I33: ='Source Table'!$B$20 -> Wadi Araba Crossing | J33: 140 | K33: 2022
A34: القادمون | B34: Arrivals | C34: M1 | D34: Number | E34: عدد | F34: Not Applicable | G34: Not Applicable | H34: ='Source Table'!$D$21 -> الجسور | I34: ='Source Table'!$B$21 -> Bridges | J34: 1082 | K34: 2022
A35: القادمون | B35: Arrivals | C35: M1 | D35: Number | E35: عدد | F35: Not Applicable | G35: Not Applicable | H35: ='Source Table'!$D$22 -> جابر | I35: ='Source Table'!$B$22 -> Jaber | J35: 477 | K35: 2022
A36: القادمون | B36: Arrivals | C36: M1 | D36: Number | E36: عدد | F36: ='Source Table'!$D$6 -> بر | G36: ='Source Table'!$B$6 -> Land | H36: Not Applicable | I36: Not Applicable | J36: 2193 | K36: 2021
A37: القادمون | B37: Arrivals | C37: M1 | D37: Number | E37: عدد | F37: ='Source Table'!$D$7 -> بحر | G37: ='Source Table'!$B$7 -> Sea | H37: Not Applicable | I37: Not Applicable | J37: 204 | K37: 2021
A38: القادمون | B38: Arrivals | C38: M1 | D38: Number | E38: عدد | F38: ='Source Table'!$D$8 -> جو | G38: ='Source Table'!$B$8 -> Air | H38: Not Applicable | I38: Not Applicable | J38: 1391 | K38: 2021
A39: القادمون | B39: Arrivals | C39: M1 | D39: Number | E39: عدد | F39: Not Applicable | G39: Not Applicable | H39: ='Source Table'!$D$10 -> مطار الملكة علياء الدولي | I39: ='Source Table'!$B$10 -> Queen Alia Int. Airport | J39: 2145 | K39: 2021
A40: القادمون | B40: Arrivals | C40: M1 | D40: Number | E40: عدد | F40: Not Applicable | G40: Not Applicable | H40: ='Source Table'!$D$11 -> مطار عمان المدني | I40: ='Source Table'!$B$11 -> Amman Civil Airport | J40: 11 | K40: 2021
A41: القادمون | B41: Arrivals | C41: M1 | D41: Number | E41: عدد | F41: Not Applicable | G41: Not Applicable | H41: ='Source Table'!$D$12 -> مطار العقبة | I41: ='Source Table'!$B$12 -> Aqaba Airport | J41: 38 | K41: 2021
...

Sheet Template Data
A1: Date | B1: =DATE(B2,B3,1) -> 44927
A2: Year | B2: 2023
A3: Month | B3: 1
A4: Measure_Name_Ar | B4: Measure_Name_En | C4: Measure_ID | D4: Unit_EN | E4: Unit_AR | F4: CL_MEANS_OF_TRANSPORT_AR_V1 | G4: CL_MEANS_OF_TRANSPORT_EN_v1 | H4: CL_POINTS_OF_ENTRY_AND_DEPARTURE_AR_V1 | I4: CL_POINTS_OF_ENTRY_AND_DEPARTURE_EN_V1 | J4: Obs_Value | K4: Time_Period_Y | L4: Time_Period_M
A5: اسم المؤشر | B5: Measure Name | C5: رمز المؤشر | D5: Unit | E5: الوحدة | F5: ='Source Table'!$D$5 -> وسيلة السفر | G5: ='Source Table'!$B$5 -> Means of Transport | H5: مراكز الدخول و المغادرة | I5: Points and of Entry and Departure | J5: قيمة المؤشر | K5: سنة فترة القياس | L5: شهر فترة القياس

Sheet Help
A2: Step 1: Cover Page | C2: الخطوة 1: Cover Page
A4: Update the template information, to ensure that any meta-information about the template, such as the title, version, and description, is accurate and up-to-date. | C4: قم بتحديث معلومات القالب للتأكد من أن أي معلومات وصفية حول القالب، مثل العنوان والإصدار والوصف، دقيقة ومحدثة.
A6: Step 2: Source Table | C6: الخطوة 2: Source Table
A8: Design your template, ensuring that the time period is mapped correctly to the date information in rows 1-3 of the Template Data Sheet. | C8: قم بتصميم القالب الخاص بك، مع التأكد من أن فترة الوقت مرتبطة بشكل صحيح مع معلومات التاريخ في الصفوف 1-3 في ورقة Template Data.
A10: Step 3: Relational Sheet | C10: الخطوة 3: Relational Sheet
A12: Unpivot the data in the source table into a flat format. Follow these guidelines: | C12: قم بتحويل البيانات في جدول المصدر إلى تنسيق مسطح. اتبع هذه الإرشادات:
A13: 1. Blue Columns: Do not change the names of the blue columns. Update the data as per the current template. | C13: 1. الأعمدة الزرقاء: لا تقم بتغيير أسماء الأعمدة الزرقاء. قم بتحديث البيانات وفقًا للقالب الحالي.
A14: 2. Code Lists: Use the naming convention CL_XXX_EN_V# for code lists, where XXX is the name, and V# is the version, conforming with the definitions in the data dictionary. | C14: 2. قوائم الرموز: استخدم قاعدة التسمية CL_XXX_EN_V# لقوائم الرموز، حيث أن XXX هو الاسم و V# هو الإصدار، وفقًا للتعريفات في قاموس البيانات.
A15: 3. Code List Values: Ensure the code list values match the definitions in the data dictionary. | C15: 3. قيم قائمة الرموز: تأكد من أن قيم قائمة الرموز تتوافق مع التعريفات في قاموس البيانات.
A16: 4. Time_Period_M: Leave empty if the data frequency is yearly. | C16: 4. Time_Period_M: اتركها فارغة إذا كانت دورية البيانات سنوية.
A17: 5. Time_Period_M Format: Use one of these formats: | C17: 5. تنسيق Time_Period_M: استخدم أحد التنسيقات التالية:
A18: Numeric: (1, 2, 3, ..., 12) for months. | C18: رقمي: (1، 2، 3، ...، 12) للأشهر.
... A38: Protect the entire workbook to prevent unauthorized or accidental changes to the structure of the file. | C38: قم بحماية الكتاب بأكمله لمنع التغييرات غير المصرح بها أو غير المقصودة على هيكل الملف.

Sheet Sheet1
A1: القادمون | B1: Arrivals | C1: M1 | D1: Number | E1: عدد | F1: ='Source Table'!$D$6 -> بر | G1: ='Source Table'!$B$6 -> Land | H1: Not Applicable | I1: Not Applicable
A2: القادمون | B2: Arrivals | C2: M1 | D2: Number | E2: عدد | F2: ='Source Table'!$D$7 -> بحر | G2: ='Source Table'!$B$7 -> Sea | H2: Not Applicable | I2: Not Applicable
A3: القادمون | B3: Arrivals | C3: M1 | D3: Number | E3: عدد | F3: ='Source Table'!$D$8 -> جو | G3: ='Source Table'!$B$8 -> Air | H3: Not Applicable | I3: Not Applicable
A4: القادمون | B4: Arrivals | C4: M1 | D4: Number | E4: عدد | F4: Not Applicable | G4: Not Applicable | H4: ='Source Table'!$D$10 -> مطار الملكة علياء الدولي | I4: ='Source Table'!$B$10 -> Queen Alia Int. Airport
A5: القادمون | B5: Arrivals | C5: M1 | D5: Number | E5: عدد | F5: Not Applicable | G5: Not Applicable | H5: ='Source Table'!$D$11 -> مطار عمان المدني | I5: ='Source Table'!$B$11 -> Amman Civil Airport
A6: القادمون | B6: Arrivals | C6: M1 | D6: Number | E6: عدد | F6: Not Applicable | G6: Not Applicable | H6: ='Source Table'!$D$12 -> مطار العقبة | I6: ='Source Table'!$B$12 -> Aqaba Airport
A7: القادمون | B7: Arrivals | C7: M1 | D7: Number | E7: عدد | F7: Not Applicable | G7: Not Applicable | H7: ='Source Table'!$D$13 -> الرمثا | I7: ='Source Table'!$B$13 -> Ramtha
A8: القادمون | B8: Arrivals | C8: M1 | D8: Number | E8: عدد | F8: Not Applicable | G8: Not Applicable | H8: ='Source Table'!$D$14 -> العمري | I8: ='Source Table'!$B$14 -> Omari
A9: القادمون | B9: Arrivals | C9: M1 | D9: Number | E9: عدد | F9: Not Applicable | G9: Not Applicable | H9: ='Source Table'!$D$15 -> المدورة | I9: ='Source Table'!$B$15 -> Mudawara
A10: القادمون | B10: Arrivals | C10: M1 | D10: Number | E10: عدد | F10: Not Applicable | G10: Not Applicable | H10: ='Source Table'!$D$16 -> الدرة | I10: ='Source Table'!$B$16 -> Durrah
A11: القادمون | B11: Arrivals | C11: M1 | D11: Number | E11: عدد | F11: Not Applicable | G11: Not Applicable | H11: ='Source Table'!$D$17 -> ميناء العقبة | I11: ='Source Table'!$B$17 -> Aqaba Port
A12: القادمون | B12: Arrivals | C12: M1 | D12: Number | E12: عدد | F12: Not Applicable | G12: Not Applicable | H12: ='Source Table'!$D$18 -> معبر وادي الأردن | I12: ='Source Table'!$B$18 -> Jordan Vally
A13: القادمون | B13: Arrivals | C13: M1 | D13: Number | E13: عدد | F13: Not Applicable | G13: Not Applicable | H13: ='Source Table'!$D$19 -> الكرامة | I13: ='Source Table'!$B$19 -> Alkaramah
A14: القادمون | B14: Arrivals | C14: M1 | D14: Number | E14: عدد | F14: Not Applicable | G14: Not Applicable | H14: ='Source Table'!$D$20 -> معبر وادي عربة | I14: ='Source Table'!$B$20 -> Wadi Araba Crossing
A15: القادمون | B15: Arrivals | C15: M1 | D15: Number | E15: عدد | F15: Not Applicable | G15: Not Applicable | H15: ='Source Table'!$D$21 -> الجسور | I15: ='Source Table'!$B$21 -> Bridges
A16: القادمون | B16: Arrivals | C16: M1 | D16: Number | E16: عدد | F16: Not Applicable | G16: Not Applicable | H16: ='Source Table'!$D$22 -> جابر | I16: ='Source Table'!$B$22 -> Jaber
