Workbook
Name _Toc175805304: 'Source Table'!#REF!
Name _Toc175805305: 'Source Table'!#REF!
Name _Toc175805306: 'Source Table'!#REF!
Name _Toc175805309: 'Source Table'!$D$1
Name _Toc175805312: 'Source Table'!#REF!
Name _Toc175805313: 'Source Table'!#REF!
Name _Toc175805314: 'Source Table'!#REF!
Name _Toc175805315: 'Source Table'!#REF!
Name _Toc175805316: 'Source Table'!#REF!
Name _Toc175805317: 'Source Table'!#REF!
Name _Toc175805318: 'Source Table'!#REF!
Name _Toc175805319: 'Source Table'!#REF!
Name _Toc175805320: 'Source Table'!#REF!
Name _Toc175805321: 'Source Table'!#REF!
Name _Toc175805322: 'Source Table'!#REF!
Name _Toc175805323: 'Source Table'!#REF!
Name _Toc175805942: 'Source Table'!$C$10
Name _Toc175805952: 'Source Table'!$D$10
Name _Toc175805962: 'Source Table'!$D$11
Name _Toc175805972: 'Source Table'!$D$12
Name _Toc175805982: 'Source Table'!$D$13
Name _Toc175805992: 'Source Table'!$D$14
Name _Toc175806002: 'Source Table'!$D$15
Name _Toc175806012: 'Source Table'!$D$16
Name _Toc175806022: 'Source Table'!$D$17
Name _Toc175806032: 'Source Table'!$D$18
Name _Toc175806042: 'Source Table'!$C$19
Name _Toc175806052: 'Source Table'!$D$19
Name _Toc175806062: 'Source Table'!$D$20
Name _Toc175806072: 'Source Table'!$D$21
Name _Toc175806082: 'Source Table'!$D$22
Name _Toc175806092: 'Source Table'!$C$23
Name _Toc175806102: 'Source Table'!#REF!
Name _Toc175806112: 'Source Table'!#REF!
Name _Toc175806122: 'Source Table'!#REF!
Name _Toc175806132: 'Source Table'!#REF!
Name _Toc175806142: 'Source Table'!$D$26
Name _Toc175806152: 'Source Table'!$D$27
Name _Toc175806162: 'Source Table'!#REF!
Name _Toc175806172: 'Source Table'!$D$28
Name _Toc175806182: 'Source Table'!$D$29
Name _Toc175806207: 'Source Table'!$I$30
Name _Toc175806216: 'Source Table'!$D$30
Name _Toc175806217: 'Source Table'!$I$31
Name _Toc175806226: 'Source Table'!$D$31
Name _Toc175806227: 'Source Table'!$I$32
Name _Toc175806236: 'Source Table'!$D$32
Name _Toc175806237: 'Source Table'!$I$33
Name _Toc175806246: 'Source Table'!$D$33
Name _Toc175806247: 'Source Table'!$I$34
Name _Toc175806256: 'Source Table'!$D$34
Name _Toc175806257: 'Source Table'!$I$35
Name _Toc175806266: 'Source Table'!$D$35
Name _Toc175806267: 'Source Table'!$J$36
Name _Toc175806276: 'Source Table'!$C$36
Name _Toc175806277: 'Source Table'!$I$36
Name _Toc175806286: 'Source Table'!#REF!
Name _Toc175806287: 'Source Table'!$I$37
Name _Toc175806296: 'Source Table'!#REF!
Name _Toc175806297: 'Source Table'!$I$38

Sheet Cover Page
A1: Code | B1: SYB_13_1_7
A2: Version | B2: V1
A3: اسم القالب | B3: عدد الطلبة والمعلمين حسب المحافظة والمديرية والجنس في السنة الدراسية
A4: Template Name | B4: Number of Students and Teachers by Governorate, Directorate and Sex schooling year
A5: دورية البيانات | B5: سنوي
A6: Data Frequency | B6: Yearly
A7: الجهة المصدرية | B7: وزارة التربية والتعليم
A8: Data Source | B8: Ministry of Education

Sheet Source Table
C2: ='Cover Page'!B4 -> Number of Students and Teachers by Governorate, Directorate and Sex schooling year
C3: ='Cover Page'!B3 -> عدد الطلبة والمعلمين حسب المحافظة والمديرية والجنس في السنة الدراسية
C4: Year | E4: =YEAR('Template Data'!B1) -> 2024 | I4: السنة
C5: Governorate and Directorate | I5: المحافظة والمديرية
E6: المعلمون | G6: الطلبة
E7: Teachers | G7: Students
E8: أنثى | F8: ذكر | G8: أنثى | H8: ذكر
E9: Female | F9: Male | G9: Female | H9: Male
C10: Amman | D10: Amman Qasbah | I10: قصبه عمان | J10: العاصمة
D11: Aljamaah | I11: الجامعه
D12: Sahab | I12: سحاب
D13: AL_qwesmeh | I13: القويسمه
D14: Marka | I14: ماركا
D15: Wadi Alseer | I15: وادي السير
D16: Naaor | I16: ناعور
D17: Badiyyeh Wosta/Mwagar | I17: البادية الوسطى/ الموقر
D18: Badiyyeh Wosta/Jezah | I18: البادية الوسطى/ الجيزة
C19: Balqa | D19: Salt Qasabah | I19: قصبة السلط | J19: البلقاء
D20: Dair Alla | I20: دير علا
D21: Shoonah Janoobiyyeh | I21: الشونة الجنوبية
D22: Ein Albasha | I22: عين الباشا
C23: Zarqa | D23: Zarqa 1 | I23: الزرقاء الاولى | J23: الزرقاء
D24: Zarqa 2 | I24: الزرقاء الثانية
D25: Ruseifa | I25: الرصيفة | J25: مأدبا
C26: Madaba | D26: Madaba Qasabah | I26: قصبة مادبا
D27: Dieban District | I27: لواء ذيبان | J27: إربد
C28: Irbid | D28: Irbid Qasbah | I28: قصبه إربد
D29: Bani Obaid | I29: بني عبيد
D30: North Mazar | I30: المزار الشمالي
D31: Al-taibah & Al-wasteiah | I31: لوائي الطيبة والوسطية
D32: Koorah | I32: الكورة
D33: Bani Kenanah | I33: بني كنانة
D34: Aghwar Shamaliyyeh | I34: الأغوار الشمالية
D35: Ramtha | I35: الرمثا
C36: Mafraq | D36: Mafraq Qasabah | I36: قصبة المفرق | J36: المفرق
D37: Badyah Shamaliyyeh .E | I37: البادية الشمالية الشرقية
D38: Badyah Shamaliyyeh .W | I38: البادية الشمالية الغربية
C39: Jarash | D39: Jarash | I39: جرش | J39: جرش
C40: Ajloun | D40: Ajloun | I40: عجلون | J40: عجلون
C41: Karak | D41: Karak Qasabah | I41: قصبة الكرك | J41: الكرك
...

Sheet Relational DB
A1: Relational Sheet
A2: Measure_Name_Ar | B2: Measure_Name_En | C2: Measure_ID | D2: Unit_EN | E2: Unit_AR | F2: CL_EDU_DIRECTORATE_EN_V1 | G2: CL_EDU_DIRECTORATE_AR_V1 | H2: CL_EDU_SEX_EN_V1 | I2: CL_EDU_SEX_AR_V1 | J2: CL_EDU_YEARS_AR_V1 | K2: CL_EDU_YEARS_EN_V1 | L2: Obs_Value | M2: Time_Period_Y | N2: Time_Period_M
A3: اسم المؤشر | B3: Measure Name | C3: رمز المؤشر | D3: Unit | E3: الوحدة | F3: Governorate and Directorate | G3: المحافظة والمديرية | H3: Sex | I3: الجنس | J3: السنة الدراسية | K3: Educational Year | L3: قيمة المؤشر | M3: سنة فترة القياس | N3: شهر فترة القياس
A4: عدد الطلبة والمعلمين | B4: Number of Students and Teachers | C4: M1 | D4: Number | E4: عدد | F4: Amman Qasbah | G4: قصبه عمان | H4: ='Source Table'!$H$9 -> Male | I4: ='Source Table'!$H$8 -> ذكر | J4: =TEXT(M4+1,"0")&"/"&TEXT(M4,"0") -> 2023/2022 | K4: =TEXT(M4+1,"0")&"/"&TEXT(M4,"0") -> 2023/2022 | L4: 72601 | M4: 2022
A5: عدد الطلبة والمعلمين | B5: Number of Students and Teachers | C5: M1 | D5: Number | E5: عدد | F5: Aljamaah | G5: الجامعه | H5: ='Source Table'!$H$9 -> Male | I5: ='Source Table'!$H$8 -> ذكر | J5: =TEXT(M5+1,"0")&"/"&TEXT(M5,"0") -> 2023/2022 | K5: =TEXT(M5+1,"0")&"/"&TEXT(M5,"0") -> 2023/2022 | L5: 78785 | M5: 2022
A6: عدد الطلبة والمعلمين | B6: Number of Students and Teachers | C6: M1 | D6: Number | E6: عدد | F6: Sahab | G6: سحاب | H6: ='Source Table'!$H$9 -> Male | I6: ='Source Table'!$H$8 -> ذكر | J6: =TEXT(M6+1,"0")&"/"&TEXT(M6,"0") -> 2023/2022 | K6: =TEXT(M6+1,"0")&"/"&TEXT(M6,"0") -> 2023/2022 | L6: 18642 | M6: 2022
A7: عدد الطلبة والمعلمين | B7: Number of Students and Teachers | C7: M1 | D7: Number | E7: عدد | F7: AL_qwesmeh | G7: القويسمه | H7: ='Source Table'!$H$9 -> Male | I7: ='Source Table'!$H$8 -> ذكر | J7: =TEXT(M7+1,"0")&"/"&TEXT(M7,"0") -> 2023/2022 | K7: =TEXT(M7+1,"0")&"/"&TEXT(M7,"0") -> 2023/2022 | L7: 75907 | M7: 2022
A8: عدد الطلبة والمعلمين | B8: Number of Students and Teachers | C8: M1 | D8: Number | E8: عدد | F8: Marka | G8: ماركا | H8: ='Source Table'!$H$9 -> Male | I8: ='Source Table'!$H$8 -> ذكر | J8: =TEXT(M8+1,"0")&"/"&TEXT(M8,"0") -> 2023/2022 | K8: =TEXT(M8+1,"0")&"/"&TEXT(M8,"0") -> 2023/2022 | L8: 100654 | M8: 2022
A9: عدد الطلبة والمعلمين | B9: Number of Students and Teachers | C9: M1 | D9: Number | E9: عدد | F9: Wadi Alseer | G9: وادي السير | H9: ='Source Table'!$H$9 -> Male | I9: ='Source Table'!$H$8 -> ذكر | J9: =TEXT(M9+1,"0")&"/"&TEXT(M9,"0") -> 2023/2022 | K9: =TEXT(M9+1,"0")&"/"&TEXT(M9,"0") -> 2023/2022 | L9: 34442 | M9: 2022
A10: عدد الطلبة والمعلمين | B10: Number of Students and Teachers | C10: M1 | D10: Number | E10: عدد | F10: Naaor | G10: ناعور | H10: ='Source Table'!$H$9 -> Male | I10: ='Source Table'!$H$8 -> ذكر | J10: =TEXT(M10+1,"0")&"/"&TEXT(M10,"0") -> 2023/2022 | K10: =TEXT(M10+1,"0")&"/"&TEXT(M10,"0") -> 2023/2022 | L10: 17268 | M10: 2022
A11: عدد الطلبة والمعلمين | B11: Number of Students and Teachers | C11: M1 | D11: Number | E11: عدد | F11: Badiyyeh Wosta/Mwagar | G11: البادية الوسطى/ الموقر | H11: ='Source Table'!$H$9 -> Male | I11: ='Source Table'!$H$8 -> ذكر | J11: =TEXT(M11+1,"0")&"/"&TEXT(M11,"0") -> 2023/2022 | K11: =TEXT(M11+1,"0")&"/"&TEXT(M11,"0") -> 2023/2022 | L11: 9720 | M11: 2022
A12: عدد الطلبة والمعلمين | B12: Number of Students and Teachers | C12: M1 | D12: Number | E12: عدد | F12: Badiyyeh Wosta/Jezah | G12: البادية الوسطى/ الجيزة | H12: ='Source Table'!$H$9 -> Male | I12: ='Source Table'!$H$8 -> ذكر | J12: =TEXT(M12+1,"0")&"/"&TEXT(M12,"0") -> 2023/2022 | K12: =TEXT(M12+1,"0")&"/"&TEXT(M12,"0") -> 2023/2022 | L12: 10571 | M12: 2022
A13: عدد الطلبة والمعلمين | B13: Number of Students and Teachers | C13: M1 | D13: Number | E13: عدد | F13: Salt Qasabah | G13: قصبة السلط | H13: ='Source Table'!$H$9 -> Male | I13: ='Source Table'!$H$8 -> ذكر | J13: =TEXT(M13+1,"0")&"/"&TEXT(M13,"0") -> 2023/2022 | K13: =TEXT(M13+1,"0")&"/"&TEXT(M13,"0") -> 2023/2022 | L13: 28166 | M13: 2022
A14: عدد الطلبة والمعلمين | B14: Number of Students and Teachers | C14: M1 | D14: Number | E14: عدد | F14: Dair Alla | G14: دير علا | H14: ='Source Table'!$H$9 -> Male | I14: ='Source Table'!$H$8 -> ذكر | J14: =TEXT(M14+1,"0")&"/"&TEXT(M14,"0") -> 2023/2022 | K14: =TEXT(M14+1,"0")&"/"&TEXT(M14,"0") -> 2023/2022 | L14: 10144 | M14: 2022
A15: عدد الطلبة والمعلمين | B15: Number of Students and Teachers | C15: M1 | D15: Number | E15: عدد | F15: Shoonah Janoobiyyeh | G15: الشونة الجنوبية | H15: ='Source Table'!$H$9 -> Male | I15: ='Source Table'!$H$8 -> ذكر | J15: =TEXT(M15+1,"0")&"/"&TEXT(M15,"0") -> 2023/2022 | K15: =TEXT(M15+1,"0")&"/"&TEXT(M15,"0") -> 2023/2022 | L15: 9215 | M15: 2022
... A45: عدد الطلبة والمعلمين | B45: Number of Students and Teachers | C45: M1 | D45: Number | E45: عدد | F45: Aqaba | G45: العقبة | H45: ='Source Table'!$H$9 -> Male | I45: ='Source Table'!$H$8 -> ذكر | J45: =TEXT(M45+1,"0")&"/"&TEXT(M45,"0") -> 2023/2022 | K45: =TEXT(M45+1,"0")&"/"&TEXT(M45,"0") -> 2023/2022 | L45: 27630 | M45: 2022
A46: عدد الطلبة والمعلمين | B46: Number of Students and Teachers | C46: M1 | D46: Number | E46: عدد | F46: Amman Qasbah | G46: قصبه عمان | H46: ='Source Table'!$G$9 -> Female | I46: ='Source Table'!$G$8 -> أنثى | J46: =TEXT(M46+1,"0")&"/"&TEXT(M46,"0") -> 2023/2022 | K46: =TEXT(M46+1,"0")&"/"&TEXT(M46,"0") -> 2023/2022 | L46: 75957 | M46: 2022
A47: عدد الطلبة والمعلمين | B47: Number of Students and Teachers | C47: M1 | D47: Number | E47: عدد | F47: Aljamaah | G47: الجامعه | H47: ='Source Table'!$G$9 -> Female | I47: ='Source Table'!$G$8 -> أنثى | J47: =TEXT(M47+1,"0")&"/"&TEXT(M47,"0") -> 2023/2022 | K47: =TEXT(M47+1,"0")&"/"&TEXT(M47,"0") -> 2023/2022 | L47: 75145 | M47: 2022
A48: عدد الطلبة والمعلمين | B48: Number of Students and Teachers | C48: M1 | D48: Number | E48: عدد | F48: Sahab | G48: سحاب | H48: ='Source Table'!$G$9 -> Female | I48: ='Source Table'!$G$8 -> أنثى | J48: =TEXT(M48+1,"0")&"/"&TEXT(M48,"0") -> 2023/2022 | K48: =TEXT(M48+1,"0")&"/"&TEXT(M48,"0") -> 2023/2022 | L48: 17787 | M48: 2022
A49: عدد الطلبة والمعلمين | B49: Number of Students and Teachers | C49: M1 | D49: Number | E49: عدد | F49: AL_qwesmeh | G49: القويسمه | H49: ='Source Table'!$G$9 -> Female | I49: ='Source Table'!$G$8 -> أنثى | J49: =TEXT(M49+1,"0")&"/"&TEXT(M49,"0") -> 2023/2022 | K49: =TEXT(M49+1,"0")&"/"&TEXT(M49,"0") -> 2023/2022 | L49: 75605 | M49: 2022
A50: عدد الطلبة والمعلمين | B50: Number of Students and Teachers | C50: M1 | D50: Number | E50: عدد | F50: Marka | G50: ماركا | H50: ='Source Table'!$G$9 -> Female | I50: ='Source Table'!$G$8 -> أنثى | J50: =TEXT(M50+1,"0")&"/"&TEXT(M50,"0") -> 2023/2022 | K50: =TEXT(M50+1,"0")&"/"&TEXT(M50,"0") -> 2023/2022 | L50: 96407 | M50: 2022
A51: عدد الطلبة والمعلمين | B51: Number of Students and Teachers | C51: M1 | D51: Number | E51: عدد | F51: Wadi Alseer | G51: وادي السير | H51: ='Source Table'!$G$9 -> Female | I51: ='Source Table'!$G$8 -> أنثى | J51: =TEXT(M51+1,"0")&"/"&TEXT(M51,"0") -> 2023/2022 | K51: =TEXT(M51+1,"0")&"/"&TEXT(M51,"0") -> 2023/2022 | L51: 33790 | M51: 2022
A52: عدد الطلبة والمعلمين | B52: Number of Students and Teachers | C52: M1 | D52: Number | E52: عدد | F52: Naaor | G52: ناعور | H52: ='Source Table'!$G$9 -> Female | I52: ='Source Table'!$G$8 -> أنثى | J52: =TEXT(M52+1,"0")&"/"&TEXT(M52,"0") -> 2023/2022 | K52: =TEXT(M52+1,"0")&"/"&TEXT(M52,"0") -> 2023/2022 | L52: 17314 | M52: 2022
A53: عدد الطلبة والمعلمين | B53: Number of Students and Teachers | C53: M1 | D53: Number | E53: عدد | F53: Badiyyeh Wosta/Mwagar | G53: البادية الوسطى/ الموقر | H53: ='Source Table'!$G$9 -> Female | I53: ='Source Table'!$G$8 -> أنثى | J53: =TEXT(M53+1,"0")&"/"&TEXT(M53,"0") -> 2023/2022 | K53: =TEXT(M53+1,"0")&"/"&TEXT(M53,"0") -> 2023/2022 | L53: 9865 | M53: 2022
A54: عدد الطلبة والمعلمين | B54: Number of Students and Teachers | C54: M1 | D54: Number | E54: عدد | F54: Badiyyeh Wosta/Jezah | G54: البادية الوسطى/ الجيزة | H54: ='Source Table'!$G$9 -> Female | I54: ='Source Table'!$G$8 -> أنثى | J54: =TEXT(M54+1,"0")&"/"&TEXT(M54,"0") -> 2023/2022 | K54: =TEXT(M54+1,"0")&"/"&TEXT(M54,"0") -> 2023/2022 | L54: 10744 | M54: 2022
A55: عدد الطلبة والمعلمين | B55: Number of Students and Teachers | C55: M1 | D55: Number | E55: عدد | F55: Salt Qasabah | G55: قصبة السلط | H55: ='Source Table'!$G$9 -> Female | I55: ='Source Table'!$G$8 -> أنثى | J55: =TEXT(M55+1,"0")&"/"&TEXT(M55,"0") -> 2023/2022 | K55: =TEXT(M55+1,"0")&"/"&TEXT(M55,"0") -> 2023/2022 | L55: 26505 | M55: 2022
A56: عدد الطلبة والمعلمين | B56: Number of Students and Teachers | C56: M1 | D56: Number | E56: عدد | F56: Dair Alla | G56: دير علا | H56: ='Source Table'!$G$9 -> Female | I56: ='Source Table'!$G$8 -> أنثى | J56: =TEXT(M56+1,"0")&"/"&TEXT(M56,"0") -> 2023/2022 | K56: =TEXT(M56+1,"0")&"/"&TEXT(M56,"0") -> 2023/2022 | L56: 9796 | M56: 2022
A57: عدد الطلبة والمعلمين | B57: Number of Students and Teachers | C57: M1 | D57: Number | E57: عدد | F57: Shoonah Janoobiyyeh | G57: الشونة الجنوبية | H57: ='Source Table'!$G$9 -> Female | I57: ='Source Table'!$G$8 -> أنثى | J57: =TEXT(M57+1,"0")&"/"&TEXT(M57,"0") -> 2023/2022 | K57: =TEXT(M57+1,"0")&"/"&TEXT(M57,"0") -> 2023/2022 | L57: 8569 | M57: 2022
... A87: عدد الطلبة والمعلمين | B87: Number of Students and Teachers | C87: M1 | D87: Number | E87: عدد | F87: Aqaba | G87: العقبة | H87: ='Source Table'!$G$9 -> Female | I87: ='Source Table'!$G$8 -> أنثى | J87: =TEXT(M87+1,"0")&"/"&TEXT(M87,"0") -> 2023/2022 | K87: =TEXT(M87+1,"0")&"/"&TEXT(M87,"0") -> 2023/2022 | L87: 26847 | M87: 2022
A88: عدد الطلبة والمعلمين | B88: Number of Students and Teachers | C88: M2 | D88: Number | E88: عدد | F88: Amman Qasbah | G88: قصبه عمان | H88: ='Source Table'!$H$9 -> Male | I88: ='Source Table'!$H$8 -> ذكر | J88: =TEXT(M88+1,"0")&"/"&TEXT(M88,"0") -> 2023/2022 | K88: =TEXT(M88+1,"0")&"/"&TEXT(M88,"0") -> 2023/2022 | L88: 2560 | M88: 2022
A89: عدد الطلبة والمعلمين | B89: Number of Students and Teachers | C89: M2 | D89: Number | E89: عدد | F89: Aljamaah | G89: الجامعه | H89: ='Source Table'!$H$9 -> Male | I89: ='Source Table'!$H$8 -> ذكر | J89: =TEXT(M89+1,"0")&"/"&TEXT(M89,"0") -> 2023/2022 | K89: =TEXT(M89+1,"0")&"/"&TEXT(M89,"0") -> 2023/2022 | L89: 2317 | M89: 2022
A90: عدد الطلبة والمعلمين | B90: Number of Students and Teachers | C90: M2 | D90: Number | E90: عدد | F90: Sahab | G90: سحاب | H90: ='Source Table'!$H$9 -> Male | I90: ='Source Table'!$H$8 -> ذكر | J90: =TEXT(M90+1,"0")&"/"&TEXT(M90,"0") -> 2023/2022 | K90: =TEXT(M90+1,"0")&"/"&TEXT(M90,"0") -> 2023/2022 | L90: 595 | M90: 2022
A91: عدد الطلبة والمعلمين | B91: Number of Students and Teachers | C91: M2 | D91: Number | E91: عدد | F91: AL_qwesmeh | G91: القويسمه | H91: ='Source Table'!$H$9 -> Male | I91: ='Source Table'!$H$8 -> ذكر | J91: =TEXT(M91+1,"0")&"/"&TEXT(M91,"0") -> 2023/2022 | K91: =TEXT(M91+1,"0")&"/"&TEXT(M91,"0") -> 2023/2022 | L91: 2026 | M91: 2022
A92: عدد الطلبة والمعلمين | B92: Number of Students and Teachers | C92: M2 | D92: Number | E92: عدد | F92: Marka | G92: ماركا | H92: ='Source Table'!$H$9 -> Male | I92: ='Source Table'!$H$8 -> ذكر | J92: =TEXT(M92+1,"0")&"/"&TEXT(M92,"0") -> 2023/2022 | K92: =TEXT(M92+1,"0")&"/"&TEXT(M92,"0") -> 2023/2022 | L92: 3329 | M92: 2022
A93: عدد الطلبة والمعلمين | B93: Number of Students and Teachers | C93: M2 | D93: Number | E93: عدد | F93: Wadi Alseer | G93: وادي السير | H93: ='Source Table'!$H$9 -> Male | I93: ='Source Table'!$H$8 -> ذكر | J93: =TEXT(M93+1,"0")&"/"&TEXT(M93,"0") -> 2023/2022 | K93: =TEXT(M93+1,"0")&"/"&TEXT(M93,"0") -> 2023/2022 | L93: 1026 | M93: 2022
A94: عدد الطلبة والمعلمين | B94: Number of Students and Teachers | C94: M2 | D94: Number | E94: عدد | F94: Naaor | G94: ناعور | H94: ='Source Table'!$H$9 -> Male | I94: ='Source Table'!$H$8 -> ذكر | J94: =TEXT(M94+1,"0")&"/"&TEXT(M94,"0") -> 2023/2022 | K94: =TEXT(M94+1,"0")&"/"&TEXT(M94,"0") -> 2023/2022 | L94: 657 | M94: 2022
A95: عدد الطلبة والمعلمين | B95: Number of Students and Teachers | C95: M2 | D95: Number | E95: عدد | F95: Badiyyeh Wosta/Mwagar | G95: البادية الوسطى/ الموقر | H95: ='Source Table'!$H$9 -> Male | I95: ='Source Table'!$H$8 -> ذكر | J95: =TEXT(M95+1,"0")&"/"&TEXT(M95,"0") -> 2023/2022 | K95: =TEXT(M95+1,"0")&"/"&TEXT(M95,"0") -> 2023/2022 | L95: 516 | M95: 2022
A96: عدد الطلبة والمعلمين | B96: Number of Students and Teachers | C96: M2 | D96: Number | E96: عدد | F96: Badiyyeh Wosta/Jezah | G96: البادية الوسطى/ الجيزة | H96: ='Source Table'!$H$9 -> Male | I96: ='Source Table'!$H$8 -> ذكر | J96: =TEXT(M96+1,"0")&"/"&TEXT(M96,"0") -> 2023/2022 | K96: =TEXT(M96+1,"0")&"/"&TEXT(M96,"0") -> 2023/2022 | L96: 713 | M96: 2022
A97: عدد الطلبة والمعلمين | B97: Number of Students and Teachers | C97: M2 | D97: Number | E97: عدد | F97: Salt Qasabah | G97: قصبة السلط | H97: ='Source Table'!$H$9 -> Male | I97: ='Source Table'!$H$8 -> ذكر | J97: =TEXT(M97+1,"0")&"/"&TEXT(M97,"0") -> 2023/2022 | K97: =TEXT(M97+1,"0")&"/"&TEXT(M97,"0") -> 2023/2022 | L97: 939 | M97: 2022
A98: عدد الطلبة والمعلمين | B98: Number of Students and Teachers | C98: M2 | D98: Number | E98: عدد | F98: Dair Alla | G98: دير علا | H98: ='Source Table'!$H$9 -> Male | I98: ='Source Table'!$H$8 -> ذكر | J98: =TEXT(M98+1,"0")&"/"&TEXT(M98,"0") -> 2023/2022 | K98: =TEXT(M98+1,"0")&"/"&TEXT(M98,"0") -> 2023/2022 | L98: 446 | M98: 2022
...

Sheet Template Data
A1: Date | B1: =DATE(B2,B3,1) -> 45292
A2: Year | B2: 2024
A3: Month | B3: 1
A4: Measure_Name_Ar | B4: Measure_Name_En | C4: Measure_ID | D4: Unit_EN | E4: Unit_AR | F4: CL_EDU_DIRECTORATE_EN_V1 | G4: CL_EDU_DIRECTORATE_AR_V1 | H4: CL_EDU_SEX_EN_V1 | I4: CL_EDU_SEX_AR_V1 | J4: CL_EDU_YEARS_AR_V1 | K4: CL_EDU_YEARS_EN_V1 | L4: Obs_Value | M4: Time_Period_Y | N4: Time_Period_M
A5: اسم المؤشر | B5: Measure Name | C5: رمز المؤشر | D5: Unit | E5: الوحدة | F5: Governorate and Directorate | G5: المحافظة والمديرية | H5: Sex | I5: الجنس | J5: السنة الدراسية | K5: Educational Year | L5: قيمة المؤشر | M5: سنة فترة القياس | N5: شهر فترة القياس

Sheet Help
A2: Step 1: Cover Page | C2: الخطوة 1: Cover Page
A4: Update the template information, to ensure that any meta-information about the template, such as the title, version, and description, is accurate and up-to-date. | C4: قم بتحديث معلومات القالب للتأكد من أن أي معلومات وصفية حول القالب، مثل العنوان والإصدار والوصف، دقيقة ومحدثة.
A6: Step 2: Source Table | C6: الخطوة 2: Source Table
A8: Design your template, ensuring that the time period is mapped correctly to the date information in rows 1-3 of the Template Data Sheet. | C8: قم بتصميم القالب الخاص بك، مع التأكد من أن فترة الوقت مرتبطة بشكل صحيح مع معلومات التاريخ في الصفوف 1-3 في ورقة Template Data.
A10: Step 3: Relational Sheet | C10: الخطوة 3: Relational Sheet
A12: Unpivot the data in the source table into a flat format. Follow these guidelines: | C12: قم بتحويل البيانات في جدول المصدر إلى تنسيق مسطح. اتبع هذه الإرشادات:
A13: 1. Blue Columns: Do not change the names of the blue columns. Update the data as per the current template. | C13: 1. الأعمدة الزرقاء: لا تقم بتغيير أسماء الأعمدة الزرقاء. قم بتحديث البيانات وفقًا للقالب الحالي.
A14: 2. Code Lists: Use the naming convention CL_XXX_EN_V# for code lists, where XXX is the name, and V# is the version, conforming with the definitions in the data dictionary. | C14: 2. قوائم الرموز: استخدم قاعدة التسمية CL_XXX_EN_V# لقوائم الرموز، حيث أن XXX هو الاسم و V# هو الإصدار، وفقًا للتعريفات في قاموس البيانات.
A15: 3. Code List Values: Ensure the code list values match the definitions in the data dictionary. | C15: 3. قيم قائمة الرموز: تأكد من أن قيم قائمة الرموز تتوافق مع التعريفات في قاموس البيانات.
A16: 4. Time_Period_M: Leave empty if the data frequency is yearly. | C16: 4. Time_Period_M: اتركها فارغة إذا كانت دورية البيانات سنوية.
A17: 5. Time_Period_M Format: Use one of these formats: | C17: 5. تنسيق Time_Period_M: استخدم أحد التنسيقات التالية:
A18: Numeric: (1, 2, 3, ..., 12) for months. | C18: رقمي: (1، 2، 3، ...، 12) للأشهر.
... A38: Protect the entire workbook to prevent unauthorized or accidental changes to the structure of the file. | C38: قم بحماية الكتاب بأكمله لمنع التغييرات غير المصرح بها أو غير المقصودة على هيكل الملف.
