Workbook
Name _Toc175805304: 'Source Table'!#REF!
Name _Toc175805305: 'Source Table'!#REF!
Name _Toc175805306: 'Source Table'!#REF!
Name _Toc175805309: 'Source Table'!$D$1
Name _Toc175805312: 'Source Table'!#REF!
Name _Toc175805313: 'Source Table'!#REF!
Name _Toc175805314: 'Source Table'!#REF!
Name _Toc175805315: 'Source Table'!#REF!
Name _Toc175805316: 'Source Table'!#REF!
Name _Toc175805317: 'Source Table'!#REF!
Name _Toc175805318: 'Source Table'!#REF!
Name _Toc175805319: 'Source Table'!#REF!
Name _Toc175805320: 'Source Table'!#REF!
Name _Toc175805321: 'Source Table'!#REF!
Name _Toc175805322: 'Source Table'!#REF!
Name _Toc175805323: 'Source Table'!#REF!

Sheet Cover Page
A1: Code | B1: SYB_13_1_5
A2: Version | B2: V1
A3: اسم القالب | B3: عدد المعلمين حسب الجهة المشرفة والمرحلة التعليمية والجنس في السنة الدراسية
A4: Template Name | B4: Number of Teachers by Authority of Supervision, Educational Stage and Sex schooling year
A5: دورية البيانات | B5: سنوي
A6: Data Frequency | B6: Yearly
A7: الجهة المصدرية | B7: وزارة التربية والتعليم
A8: Data Source | B8: Ministry of Education

Sheet Source Table
C2: ='Cover Page'!B4 -> Number of Teachers by Authority of Supervision, Educational Stage and Sex schooling year
C3: ='Cover Page'!B3 -> عدد المعلمين حسب الجهة المشرفة والمرحلة التعليمية والجنس في السنة الدراسية
C4: Year | E4: =YEAR('Template Data'!B1) -> 2024 | H4: السنة
C5: Authority of Supervision and Sex | H5: السلطة المشرفة والجنس
E6: المرحلة التعليمية
E7: Educational Stage
E8: الثانوي الأكاديمي والمهني | F8: الأساسي | G8: الروضة
E9: Acadamic and Vocational Secondary | F9: Basic | G9: Kinder-garten
C10: Ministry of Education | D10: Male | H10: ذكر | I10: وزارة التربية والتعليم
D11: Female | H11: أنثى
C12: Other Government | D12: Male | H12: ذكر | I12: حكومية اخرى
D13: Female | H13: أنثى
C14: UNRWA | D14: Male | H14: ذكر | I14: وكالة الغوث
D15: Female | H15: أنثى
C16: Private Education | D16: Male | H16: ذكر | I16: التعليم الخاص
D17: Female | H17: أنثى

Sheet Relational DB
A1: Relational Sheet
A2: Measure_Name_Ar | B2: Measure_Name_En | C2: Measure_ID | D2: Unit_EN | E2: Unit_AR | F2: CL_AUTHORITY_OF_SUPERVISION_EN_V1 | G2: CL_AUTHORITY_OF_SUPERVISION_AR_V1 | H2: CL_EDU_SEX_EN_V1 | I2: CL_EDU_SEX_AR_V1 | J2: CL_EDU_STAGE_EN_V1 | K2: CL_EDU_STAGE_AR_V1 | L2: CL_EDU_YEARS_AR_V1 | M2: CL_EDU_YEARS_EN_V1 | N2: Obs_Value | O2: Time_Period_Y | P2: Time_Period_M
A3: اسم المؤشر | B3: Measure Name | C3: رمز المؤشر | D3: Unit | E3: الوحدة | F3: Authority of Supervision | G3: السلطة المشرفة | H3: Sex | I3: الجنس | J3: Educational Stage | K3: المرحلة التعليمية | L3: السنة الدراسية | M3: Educational Year | N3: قيمة المؤشر | O3: سنة فترة القياس | P3: شهر فترة القياس
A4: عدد المعلمين | B4: Number of Teachers | C4: M1 | D4: Number | E4: عدد | F4: وزارة التربية والتعليم | G4: Ministry of Education | H4: ='Source Table'!$D$10 -> Male | I4: ='Source Table'!$H$10 -> ذكر | J4: Kinder-garten | K4: الروضة | L4: =TEXT(O4+1,"0")&"/"&TEXT(O4,"0") -> 2023/2022 | M4: =TEXT(O4+1,"0")&"/"&TEXT(O4,"0") -> 2023/2022 | N4: 3 | O4: 2022
A5: عدد المعلمين | B5: Number of Teachers | C5: M1 | D5: Number | E5: عدد | F5: وزارة التربية والتعليم | G5: Ministry of Education | H5: ='Source Table'!$D$11 -> Female | I5: ='Source Table'!$H$11 -> أنثى | J5: Kinder-garten | K5: الروضة | L5: =TEXT(O5+1,"0")&"/"&TEXT(O5,"0") -> 2023/2022 | M5: =TEXT(O5+1,"0")&"/"&TEXT(O5,"0") -> 2023/2022 | N5: 2992 | O5: 2022
A6: عدد المعلمين | B6: Number of Teachers | C6: M1 | D6: Number | E6: عدد | F6: حكومية اخرى | G6: Other Government | H6: ='Source Table'!$D$10 -> Male | I6: ='Source Table'!$H$10 -> ذكر | J6: Kinder-garten | K6: الروضة | L6: =TEXT(O6+1,"0")&"/"&TEXT(O6,"0") -> 2023/2022 | M6: =TEXT(O6+1,"0")&"/"&TEXT(O6,"0") -> 2023/2022 | N6: 0 | O6: 2022
A7: عدد المعلمين | B7: Number of Teachers | C7: M1 | D7: Number | E7: عدد | F7: حكومية اخرى | G7: Other Government | H7: ='Source Table'!$D$11 -> Female | I7: ='Source Table'!$H$11 -> أنثى | J7: Kinder-garten | K7: الروضة | L7: =TEXT(O7+1,"0")&"/"&TEXT(O7,"0") -> 2023/2022 | M7: =TEXT(O7+1,"0")&"/"&TEXT(O7,"0") -> 2023/2022 | N7: 5 | O7: 2022
A8: عدد المعلمين | B8: Number of Teachers | C8: M1 | D8: Number | E8: عدد | F8: وكالة الغوث | G8: UNRWA | H8: ='Source Table'!$D$10 -> Male | I8: ='Source Table'!$H$10 -> ذكر | J8: Kinder-garten | K8: الروضة | L8: =TEXT(O8+1,"0")&"/"&TEXT(O8,"0") -> 2023/2022 | M8: =TEXT(O8+1,"0")&"/"&TEXT(O8,"0") -> 2023/2022 | N8: 0 | O8: 2022
A9: عدد المعلمين | B9: Number of Teachers | C9: M1 | D9: Number | E9: عدد | F9: وكالة الغوث | G9: UNRWA | H9: ='Source Table'!$D$11 -> Female | I9: ='Source Table'!$H$11 -> أنثى | J9: Kinder-garten | K9: الروضة | L9: =TEXT(O9+1,"0")&"/"&TEXT(O9,"0") -> 2023/2022 | M9: =TEXT(O9+1,"0")&"/"&TEXT(O9,"0") -> 2023/2022 | N9: 0 | O9: 2022
A10: عدد المعلمين | B10: Number of Teachers | C10: M1 | D10: Number | E10: عدد | F10: التعليم الخاص | G10: Private Education | H10: ='Source Table'!$D$10 -> Male | I10: ='Source Table'!$H$10 -> ذكر | J10: Kinder-garten | K10: الروضة | L10: =TEXT(O10+1,"0")&"/"&TEXT(O10,"0") -> 2023/2022 | M10: =TEXT(O10+1,"0")&"/"&TEXT(O10,"0") -> 2023/2022 | N10: 3 | O10: 2022
A11: عدد المعلمين | B11: Number of Teachers | C11: M1 | D11: Number | E11: عدد | F11: التعليم الخاص | G11: Private Education | H11: ='Source Table'!$D$11 -> Female | I11: ='Source Table'!$H$11 -> أنثى | J11: Kinder-garten | K11: الروضة | L11: =TEXT(O11+1,"0")&"/"&TEXT(O11,"0") -> 2023/2022 | M11: =TEXT(O11+1,"0")&"/"&TEXT(O11,"0") -> 2023/2022 | N11: 6462 | O11: 2022
A12: عدد المعلمين | B12: Number of Teachers | C12: M1 | D12: Number | E12: عدد | F12: وزارة التربية والتعليم | G12: Ministry of Education | H12: ='Source Table'!$D$10 -> Male | I12: ='Source Table'!$H$10 -> ذكر | J12: Basic | K12: الأساسي | L12: =TEXT(O12+1,"0")&"/"&TEXT(O12,"0") -> 2023/2022 | M12: =TEXT(O12+1,"0")&"/"&TEXT(O12,"0") -> 2023/2022 | N12: 26752 | O12: 2022
A13: عدد المعلمين | B13: Number of Teachers | C13: M1 | D13: Number | E13: عدد | F13: وزارة التربية والتعليم | G13: Ministry of Education | H13: ='Source Table'!$D$11 -> Female | I13: ='Source Table'!$H$11 -> أنثى | J13: Basic | K13: الأساسي | L13: =TEXT(O13+1,"0")&"/"&TEXT(O13,"0") -> 2023/2022 | M13: =TEXT(O13+1,"0")&"/"&TEXT(O13,"0") -> 2023/2022 | N13: 46234 | O13: 2022
A14: عدد المعلمين | B14: Number of Teachers | C14: M1 | D14: Number | E14: عدد | F14: حكومية اخرى | G14: Other Government | H14: ='Source Table'!$D$10 -> Male | I14: ='Source Table'!$H$10 -> ذكر | J14: Basic | K14: الأساسي | L14: =TEXT(O14+1,"0")&"/"&TEXT(O14,"0") -> 2023/2022 | M14: =TEXT(O14+1,"0")&"/"&TEXT(O14,"0") -> 2023/2022 | N14: 1117 | O14: 2022
A15: عدد المعلمين | B15: Number of Teachers | C15: M1 | D15: Number | E15: عدد | F15: حكومية اخرى | G15: Other Government | H15: ='Source Table'!$D$11 -> Female | I15: ='Source Table'!$H$11 -> أنثى | J15: Basic | K15: الأساسي | L15: =TEXT(O15+1,"0")&"/"&TEXT(O15,"0") -> 2023/2022 | M15: =TEXT(O15+1,"0")&"/"&TEXT(O15,"0") -> 2023/2022 | N15: 259 | O15: 2022
A16: عدد المعلمين | B16: Number of Teachers | C16: M1 | D16: Number | E16: عدد | F16: وكالة الغوث | G16: UNRWA | H16: ='Source Table'!$D$10 -> Male | I16: ='Source Table'!$H$10 -> ذكر | J16: Basic | K16: الأساسي | L16: =TEXT(O16+1,"0")&"/"&TEXT(O16,"0") -> 2023/2022 | M16: =TEXT(O16+1,"0")&"/"&TEXT(O16,"0") -> 2023/2022 | N16: 2069 | O16: 2022
A17: عدد المعلمين | B17: Number of Teachers | C17: M1 | D17: Number | E17: عدد | F17: وكالة الغوث | G17: UNRWA | H17: ='Source Table'!$D$11 -> Female | I17: ='Source Table'!$H$11 -> أنثى | J17: Basic | K17: الأساسي | L17: =TEXT(O17+1,"0")&"/"&TEXT(O17,"0") -> 2023/2022 | M17: =TEXT(O17+1,"0")&"/"&TEXT(O17,"0") -> 2023/2022 | N17: 2200 | O17: 2022
A18: عدد المعلمين | B18: Number of Teachers | C18: M1 | D18: Number | E18: عدد | F18: التعليم الخاص | G18: Private Education | H18: ='Source Table'!$D$10 -> Male | I18: ='Source Table'!$H$10 -> ذكر | J18: Basic | K18: الأساسي | L18: =TEXT(O18+1,"0")&"/"&TEXT(O18,"0") -> 2023/2022 | M18: =TEXT(O18+1,"0")&"/"&TEXT(O18,"0") -> 2023/2022 | N18: 2404 | O18: 2022
A19: عدد المعلمين | B19: Number of Teachers | C19: M1 | D19: Number | E19: عدد | F19: التعليم الخاص | G19: Private Education | H19: ='Source Table'!$D$11 -> Female | I19: ='Source Table'!$H$11 -> أنثى | J19: Basic | K19: الأساسي | L19: =TEXT(O19+1,"0")&"/"&TEXT(O19,"0") -> 2023/2022 | M19: =TEXT(O19+1,"0")&"/"&TEXT(O19,"0") -> 2023/2022 | N19: 28144 | O19: 2022
A20: عدد المعلمين | B20: Number of Teachers | C20: M1 | D20: Number | E20: عدد | F20: وزارة التربية والتعليم | G20: Ministry of Education | H20: ='Source Table'!$D$10 -> Male | I20: ='Source Table'!$H$10 -> ذكر | J20: Acadamic and Vocational Secondary | K20: الثانوي الأكاديمي والمهني | L20: =TEXT(O20+1,"0")&"/"&TEXT(O20,"0") -> 2023/2022 | M20: =TEXT(O20+1,"0")&"/"&TEXT(O20,"0") -> 2023/2022 | N20: 8994 | O20: 2022
A21: عدد المعلمين | B21: Number of Teachers | C21: M1 | D21: Number | E21: عدد | F21: وزارة التربية والتعليم | G21: Ministry of Education | H21: ='Source Table'!$D$11 -> Female | I21: ='Source Table'!$H$11 -> أنثى | J21: Acadamic and Vocational Secondary | K21: الثانوي الأكاديمي والمهني | L21: =TEXT(O21+1,"0")&"/"&TEXT(O21,"0") -> 2023/2022 | M21: =TEXT(O21+1,"0")&"/"&TEXT(O21,"0") -> 2023/2022 | N21: 11253 | O21: 2022
A22: عدد المعلمين | B22: Number of Teachers | C22: M1 | D22: Number | E22: عدد | F22: حكومية اخرى | G22: Other Government | H22: ='Source Table'!$D$10 -> Male | I22: ='Source Table'!$H$10 -> ذكر | J22: Acadamic and Vocational Secondary | K22: الثانوي الأكاديمي والمهني | L22: =TEXT(O22+1,"0")&"/"&TEXT(O22,"0") -> 2023/2022 | M22: =TEXT(O22+1,"0")&"/"&TEXT(O22,"0") -> 2023/2022 | N22: 564 | O22: 2022
A23: عدد المعلمين | B23: Number of Teachers | C23: M1 | D23: Number | E23: عدد | F23: حكومية اخرى | G23: Other Government | H23: ='Source Table'!$D$11 -> Female | I23: ='Source Table'!$H$11 -> أنثى | J23: Acadamic and Vocational Secondary | K23: الثانوي الأكاديمي والمهني | L23: =TEXT(O23+1,"0")&"/"&TEXT(O23,"0") -> 2023/2022 | M23: =TEXT(O23+1,"0")&"/"&TEXT(O23,"0") -> 2023/2022 | N23: 85 | O23: 2022
A24: عدد المعلمين | B24: Number of Teachers | C24: M1 | D24: Number | E24: عدد | F24: وكالة الغوث | G24: UNRWA | H24: ='Source Table'!$D$10 -> Male | I24: ='Source Table'!$H$10 -> ذكر | J24: Acadamic and Vocational Secondary | K24: الثانوي الأكاديمي والمهني | L24: =TEXT(O24+1,"0")&"/"&TEXT(O24,"0") -> 2023/2022 | M24: =TEXT(O24+1,"0")&"/"&TEXT(O24,"0") -> 2023/2022 | N24: 0 | O24: 2022
A25: عدد المعلمين | B25: Number of Teachers | C25: M1 | D25: Number | E25: عدد | F25: وكالة الغوث | G25: UNRWA | H25: ='Source Table'!$D$11 -> Female | I25: ='Source Table'!$H$11 -> أنثى | J25: Acadamic and Vocational Secondary | K25: الثانوي الأكاديمي والمهني | L25: =TEXT(O25+1,"0")&"/"&TEXT(O25,"0") -> 2023/2022 | M25: =TEXT(O25+1,"0")&"/"&TEXT(O25,"0") -> 2023/2022 | N25: 0 | O25: 2022
A26: عدد المعلمين | B26: Number of Teachers | C26: M1 | D26: Number | E26: عدد | F26: التعليم الخاص | G26: Private Education | H26: ='Source Table'!$D$10 -> Male | I26: ='Source Table'!$H$10 -> ذكر | J26: Acadamic and Vocational Secondary | K26: الثانوي الأكاديمي والمهني | L26: =TEXT(O26+1,"0")&"/"&TEXT(O26,"0") -> 2023/2022 | M26: =TEXT(O26+1,"0")&"/"&TEXT(O26,"0") -> 2023/2022 | N26: 2228 | O26: 2022
A27: عدد المعلمين | B27: Number of Teachers | C27: M1 | D27: Number | E27: عدد | F27: التعليم الخاص | G27: Private Education | H27: ='Source Table'!$D$11 -> Female | I27: ='Source Table'!$H$11 -> أنثى | J27: Acadamic and Vocational Secondary | K27: الثانوي الأكاديمي والمهني | L27: =TEXT(O27+1,"0")&"/"&TEXT(O27,"0") -> 2023/2022 | M27: =TEXT(O27+1,"0")&"/"&TEXT(O27,"0") -> 2023/2022 | N27: 3625 | O27: 2022
A28: عدد المعلمين | B28: Number of Teachers | C28: M1 | D28: Number | E28: عدد | F28: وزارة التربية والتعليم | G28: Ministry of Education | H28: ='Source Table'!$D$10 -> Male | I28: ='Source Table'!$H$10 -> ذكر | J28: Kinder-garten | K28: الروضة | L28: =TEXT(O28+1,"0")&"/"&TEXT(O28,"0") -> 2022/2021 | M28: =TEXT(O28+1,"0")&"/"&TEXT(O28,"0") -> 2022/2021 | N28: 1 | O28: 2021
A29: عدد المعلمين | B29: Number of Teachers | C29: M1 | D29: Number | E29: عدد | F29: وزارة التربية والتعليم | G29: Ministry of Education | H29: ='Source Table'!$D$11 -> Female | I29: ='Source Table'!$H$11 -> أنثى | J29: Kinder-garten | K29: الروضة | L29: =TEXT(O29+1,"0")&"/"&TEXT(O29,"0") -> 2022/2021 | M29: =TEXT(O29+1,"0")&"/"&TEXT(O29,"0") -> 2022/2021 | N29: 2751 | O29: 2021
A30: عدد المعلمين | B30: Number of Teachers | C30: M1 | D30: Number | E30: عدد | F30: حكومية اخرى | G30: Other Government | H30: ='Source Table'!$D$10 -> Male | I30: ='Source Table'!$H$10 -> ذكر | J30: Kinder-garten | K30: الروضة | L30: =TEXT(O30+1,"0")&"/"&TEXT(O30,"0") -> 2022/2021 | M30: =TEXT(O30+1,"0")&"/"&TEXT(O30,"0") -> 2022/2021 | N30: 0 | O30: 2021
A31: عدد المعلمين | B31: Number of Teachers | C31: M1 | D31: Number | E31: عدد | F31: حكومية اخرى | G31: Other Government | H31: ='Source Table'!$D$11 -> Female | I31: ='Source Table'!$H$11 -> أنثى | J31: Kinder-garten | K31: الروضة | L31: =TEXT(O31+1,"0")&"/"&TEXT(O31,"0") -> 2022/2021 | M31: =TEXT(O31+1,"0")&"/"&TEXT(O31,"0") -> 2022/2021 | N31: 5 | O31: 2021
A32: عدد المعلمين | B32: Number of Teachers | C32: M1 | D32: Number | E32: عدد | F32: وكالة الغوث | G32: UNRWA | H32: ='Source Table'!$D$10 -> Male | I32: ='Source Table'!$H$10 -> ذكر | J32: Kinder-garten | K32: الروضة | L32: =TEXT(O32+1,"0")&"/"&TEXT(O32,"0") -> 2022/2021 | M32: =TEXT(O32+1,"0")&"/"&TEXT(O32,"0") -> 2022/2021 | N32: 0 | O32: 2021
A33: عدد المعلمين | B33: Number of Teachers | C33: M1 | D33: Number | E33: عدد | F33: وكالة الغوث | G33: UNRWA | H33: ='Source Table'!$D$11 -> Female | I33: ='Source Table'!$H$11 -> أنثى | J33: Kinder-garten | K33: الروضة | L33: =TEXT(O33+1,"0")&"/"&TEXT(O33,"0") -> 2022/2021 | M33: =TEXT(O33+1,"0")&"/"&TEXT(O33,"0") -> 2022/2021 | N33: 0 | O33: 2021
A34: عدد المعلمين | B34: Number of Teachers | C34: M1 | D34: Number | E34: عدد | F34: التعليم الخاص | G34: Private Education | H34: ='Source Table'!$D$10 -> Male | I34: ='Source Table'!$H$10 -> ذكر | J34: Kinder-garten | K34: الروضة | L34: =TEXT(O34+1,"0")&"/"&TEXT(O34,"0") -> 2022/2021 | M34: =TEXT(O34+1,"0")&"/"&TEXT(O34,"0") -> 2022/2021 | N34: 4 | O34: 2021
A35: عدد المعلمين | B35: Number of Teachers | C35: M1 | D35: Number | E35: عدد | F35: التعليم الخاص | G35: Private Education | H35: ='Source Table'!$D$11 -> Female | I35: ='Source Table'!$H$11 -> أنثى | J35: Kinder-garten | K35: الروضة | L35: =TEXT(O35+1,"0")&"/"&TEXT(O35,"0") -> 2022/2021 | M35: =TEXT(O35+1,"0")&"/"&TEXT(O35,"0") -> 2022/2021 | N35: 5087 | O35: 2021
A36: عدد المعلمين | B36: Number of Teachers | C36: M1 | D36: Number | E36: عدد | F36: وزارة التربية والتعليم | G36: Ministry of Education | H36: ='Source Table'!$D$10 -> Male | I36: ='Source Table'!$H$10 -> ذكر | J36: Basic | K36: الأساسي | L36: =TEXT(O36+1,"0")&"/"&TEXT(O36,"0") -> 2022/2021 | M36: =TEXT(O36+1,"0")&"/"&TEXT(O36,"0") -> 2022/2021 | N36: 25932 | O36: 2021
A37: عدد المعلمين | B37: Number of Teachers | C37: M1 | D37: Number | E37: عدد | F37: وزارة التربية والتعليم | G37: Ministry of Education | H37: ='Source Table'!$D$11 -> Female | I37: ='Source Table'!$H$11 -> أنثى | J37: Basic | K37: الأساسي | L37: =TEXT(O37+1,"0")&"/"&TEXT(O37,"0") -> 2022/2021 | M37: =TEXT(O37+1,"0")&"/"&TEXT(O37,"0") -> 2022/2021 | N37: 45995 | O37: 2021
A38: عدد المعلمين | B38: Number of Teachers | C38: M1 | D38: Number | E38: عدد | F38: حكومية اخرى | G38: Other Government | H38: ='Source Table'!$D$10 -> Male | I38: ='Source Table'!$H$10 -> ذكر | J38: Basic | K38: الأساسي | L38: =TEXT(O38+1,"0")&"/"&TEXT(O38,"0") -> 2022/2021 | M38: =TEXT(O38+1,"0")&"/"&TEXT(O38,"0") -> 2022/2021 | N38: 994 | O38: 2021
A39: عدد المعلمين | B39: Number of Teachers | C39: M1 | D39: Number | E39: عدد | F39: حكومية اخرى | G39: Other Government | H39: ='Source Table'!$D$11 -> Female | I39: ='Source Table'!$H$11 -> أنثى | J39: Basic | K39: الأساسي | L39: =TEXT(O39+1,"0")&"/"&TEXT(O39,"0") -> 2022/2021 | M39: =TEXT(O39+1,"0")&"/"&TEXT(O39,"0") -> 2022/2021 | N39: 262 | O39: 2021
A40: عدد المعلمين | B40: Number of Teachers | C40: M1 | D40: Number | E40: عدد | F40: وكالة الغوث | G40: UNRWA | H40: ='Source Table'!$D$10 -> Male | I40: ='Source Table'!$H$10 -> ذكر | J40: Basic | K40: الأساسي | L40: =TEXT(O40+1,"0")&"/"&TEXT(O40,"0") -> 2022/2021 | M40: =TEXT(O40+1,"0")&"/"&TEXT(O40,"0") -> 2022/2021 | N40: 2003 | O40: 2021
...

Sheet Template Data
A1: Date | B1: =DATE(B2,B3,1) -> 45292
A2: Year | B2: 2024
A3: Month | B3: 1
A4: Measure_Name_Ar | B4: Measure_Name_En | C4: Measure_ID | D4: Unit_EN | E4: Unit_AR | F4: CL_AUTHORITY_OF_SUPERVISION_EN_V1 | G4: CL_AUTHORITY_OF_SUPERVISION_AR_V1 | H4: CL_EDU_SEX_EN_V1 | I4: CL_EDU_SEX_AR_V1 | J4: CL_EDU_STAGE_EN_V1 | K4: CL_EDU_STAGE_AR_V1 | L4: CL_EDU_YEARS_AR_V1 | M4: CL_EDU_YEARS_EN_V1 | N4: Obs_Value | O4: Time_Period_Y | P4: Time_Period_M
A5: اسم المؤشر | B5: Measure Name | C5: رمز المؤشر | D5: Unit | E5: الوحدة | F5: Authority of Supervision | G5: السلطة المشرفة | H5: Sex | I5: الجنس | J5: Educational Stage | K5: المرحلة التعليمية | L5: السنة الدراسية | M5: Educational Year | N5: قيمة المؤشر | O5: سنة فترة القياس | P5: شهر فترة القياس

Sheet Help
A2: Step 1: Cover Page | C2: الخطوة 1: Cover Page
A4: Update the template information, to ensure that any meta-information about the template, such as the title, version, and description, is accurate and up-to-date. | C4: قم بتحديث معلومات القالب للتأكد من أن أي معلومات وصفية حول القالب، مثل العنوان والإصدار والوصف، دقيقة ومحدثة.
A6: Step 2: Source Table | C6: الخطوة 2: Source Table
A8: Design your template, ensuring that the time period is mapped correctly to the date information in rows 1-3 of the Template Data Sheet. | C8: قم بتصميم القالب الخاص بك، مع التأكد من أن فترة الوقت مرتبطة بشكل صحيح مع معلومات التاريخ في الصفوف 1-3 في ورقة Template Data.
A10: Step 3: Relational Sheet | C10: الخطوة 3: Relational Sheet
A12: Unpivot the data in the source table into a flat format. Follow these guidelines: | C12: قم بتحويل البيانات في جدول المصدر إلى تنسيق مسطح. اتبع هذه الإرشادات:
A13: 1. Blue Columns: Do not change the names of the blue columns. Update the data as per the current template. | C13: 1. الأعمدة الزرقاء: لا تقم بتغيير أسماء الأعمدة الزرقاء. قم بتحديث البيانات وفقًا للقالب الحالي.
A14: 2. Code Lists: Use the naming convention CL_XXX_EN_V# for code lists, where XXX is the name, and V# is the version, conforming with the definitions in the data dictionary. | C14: 2. قوائم الرموز: استخدم قاعدة التسمية CL_XXX_EN_V# لقوائم الرموز، حيث أن XXX هو الاسم و V# هو الإصدار، وفقًا للتعريفات في قاموس البيانات.
A15: 3. Code List Values: Ensure the code list values match the definitions in the data dictionary. | C15: 3. قيم قائمة الرموز: تأكد من أن قيم قائمة الرموز تتوافق مع التعريفات في قاموس البيانات.
A16: 4. Time_Period_M: Leave empty if the data frequency is yearly. | C16: 4. Time_Period_M: اتركها فارغة إذا كانت دورية البيانات سنوية.
A17: 5. Time_Period_M Format: Use one of these formats: | C17: 5. تنسيق Time_Period_M: استخدم أحد التنسيقات التالية:
A18: Numeric: (1, 2, 3, ..., 12) for months. | C18: رقمي: (1، 2، 3، ...، 12) للأشهر.
... A38: Protect the entire workbook to prevent unauthorized or accidental changes to the structure of the file. | C38: قم بحماية الكتاب بأكمله لمنع التغييرات غير المصرح بها أو غير المقصودة على هيكل الملف.
