Workbook

Sheet Cover Page
A1: Code | B1: SYB_20_5
A2: Version | B2: V1
A3: اسم القالب | B3: حجم الاستثمارات المستفيدة من قانون الاستثمار حسب جنسية الاستثمار,(مليون دينار)
A4: Template Name | B4: Size of Projects Investment Beneficiaries from Investment Promotion Law by Nationality,(Million JDs)
A5: دورية البيانات | B5: سنوي
A6: Data Frequency | B6: Annual
A7: الجهة المصدرية | B7: وزارة الاستثمار
A8: Data Source | B8: Ministry of Investment

Sheet Source Table
B2: ='Cover Page'!B4 -> Size of Projects Investment Beneficiaries from Investment Promotion Law by Nationality,(Million JDs)
B3: ='Cover Page'!B3 -> حجم الاستثمارات المستفيدة من قانون الاستثمار حسب جنسية الاستثمار,(مليون دينار)
B4: Year | C4: =YEAR('Template Data'!B1) -> 2024 | E4: السنة
B5: Sector | C5: الاستثمار الاجنبي | D5: الاستثمار المحلي | E5: القطاع
C6: Foreign investment | D6: local investment
B7: Industry | E7: الصناعة
B8: Commerce | E8: التجارة
B9: Tourism | E9: السياحة
B10: Agriculture | E10: الزراعة
B11: Hospitals | E11: المستشفيات
B12: Services | E12: الخدمات
B13: Information Technology | E13: تكنولوجيا المعلومات
B14: Artistic production | E14: انتاج فني
B15: Gas transportation and distribution | E15: نقل وتوزيع الغاز
B16: call centers | E16: مراكز اتصال
B17: Scientific research centers | E17: مراكز بحث علمي

Sheet Relational DB
A1: Relational Sheet
A2: Measure_Name_Ar | B2: Measure_Name_En | C2: Measure_ID | D2: Unit_EN | E2: Unit_AR | F2: CL_SECTOR__EN_V3 | G2: CL_SECTOR__AR_V3 | H2: CL_INV_NAT_EN_V1 | I2: CL_INV_NAT_AR_V1 | J2: Obs_Value | K2: Time_Period_Y | L2: Time_Period_M
A3: اسم المؤشر | B3: Measure Name | C3: رمز المؤشر | D3: Unit | E3: الوحدة | F3: Sector | G3: القطاع | H3: Investment Nationality | I3: جنسية الاستثمار | J3: قيمة المؤشر | K3: سنة فترة القياس | L3: شهر فترة القياس
A4: حجم الاستثمارات المستفيدة من قانون الاستثمار | B4: Size of Projects Investment Beneficiaries from Investment Promotion Law | C4: M1 | D4: Million JDs | E4: مليون دينار | F4: ='Source Table'!$B$7 -> Industry | G4: ='Source Table'!$E$7 -> الصناعة | H4: ='Source Table'!$D$6 -> local investment | I4: ='Source Table'!$D$5 -> الاستثمار المحلي | J4: 610.1 | K4: 2023
A5: حجم الاستثمارات المستفيدة من قانون الاستثمار | B5: Size of Projects Investment Beneficiaries from Investment Promotion Law | C5: M1 | D5: Million JDs | E5: مليون دينار | F5: ='Source Table'!$B$8 -> Commerce | G5: ='Source Table'!$E$8 -> التجارة | H5: ='Source Table'!$D$6 -> local investment | I5: ='Source Table'!$D$5 -> الاستثمار المحلي | J5: 184.5 | K5: 2023
A6: حجم الاستثمارات المستفيدة من قانون الاستثمار | B6: Size of Projects Investment Beneficiaries from Investment Promotion Law | C6: M1 | D6: Million JDs | E6: مليون دينار | F6: ='Source Table'!$B$9 -> Tourism | G6: ='Source Table'!$E$9 -> السياحة | H6: ='Source Table'!$D$6 -> local investment | I6: ='Source Table'!$D$5 -> الاستثمار المحلي | J6: 59.8 | K6: 2023
A7: حجم الاستثمارات المستفيدة من قانون الاستثمار | B7: Size of Projects Investment Beneficiaries from Investment Promotion Law | C7: M1 | D7: Million JDs | E7: مليون دينار | F7: ='Source Table'!$B$10 -> Agriculture | G7: ='Source Table'!$E$10 -> الزراعة | H7: ='Source Table'!$D$6 -> local investment | I7: ='Source Table'!$D$5 -> الاستثمار المحلي | J7: 13.9 | K7: 2023
A8: حجم الاستثمارات المستفيدة من قانون الاستثمار | B8: Size of Projects Investment Beneficiaries from Investment Promotion Law | C8: M1 | D8: Million JDs | E8: مليون دينار | F8: ='Source Table'!$B$11 -> Hospitals | G8: ='Source Table'!$E$11 -> المستشفيات | H8: ='Source Table'!$D$6 -> local investment | I8: ='Source Table'!$D$5 -> الاستثمار المحلي | J8: 59.7 | K8: 2023
A9: حجم الاستثمارات المستفيدة من قانون الاستثمار | B9: Size of Projects Investment Beneficiaries from Investment Promotion Law | C9: M1 | D9: Million JDs | E9: مليون دينار | F9: ='Source Table'!$B$12 -> Services | G9: ='Source Table'!$E$12 -> الخدمات | H9: ='Source Table'!$D$6 -> local investment | I9: ='Source Table'!$D$5 -> الاستثمار المحلي | J9: 18.2 | K9: 2023
A10: حجم الاستثمارات المستفيدة من قانون الاستثمار | B10: Size of Projects Investment Beneficiaries from Investment Promotion Law | C10: M1 | D10: Million JDs | E10: مليون دينار | F10: ='Source Table'!$B$13 -> Information Technology | G10: ='Source Table'!$E$13 -> تكنولوجيا المعلومات | H10: ='Source Table'!$D$6 -> local investment | I10: ='Source Table'!$D$5 -> الاستثمار المحلي | J10: 32.4 | K10: 2023
A11: حجم الاستثمارات المستفيدة من قانون الاستثمار | B11: Size of Projects Investment Beneficiaries from Investment Promotion Law | C11: M1 | D11: Million JDs | E11: مليون دينار | F11: ='Source Table'!$B$14 -> Artistic production | G11: ='Source Table'!$E$14 -> انتاج فني | H11: ='Source Table'!$D$6 -> local investment | I11: ='Source Table'!$D$5 -> الاستثمار المحلي | J11: 10 | K11: 2023
A12: حجم الاستثمارات المستفيدة من قانون الاستثمار | B12: Size of Projects Investment Beneficiaries from Investment Promotion Law | C12: M1 | D12: Million JDs | E12: مليون دينار | F12: ='Source Table'!$B$15 -> Gas transportation and distribution | G12: ='Source Table'!$E$15 -> نقل وتوزيع الغاز | H12: ='Source Table'!$D$6 -> local investment | I12: ='Source Table'!$D$5 -> الاستثمار المحلي | J12: 19 | K12: 2023
A13: حجم الاستثمارات المستفيدة من قانون الاستثمار | B13: Size of Projects Investment Beneficiaries from Investment Promotion Law | C13: M1 | D13: Million JDs | E13: مليون دينار | F13: ='Source Table'!$B$16 -> call centers | G13: ='Source Table'!$E$16 -> مراكز اتصال | H13: ='Source Table'!$D$6 -> local investment | I13: ='Source Table'!$D$5 -> الاستثمار المحلي | J13: 0 | K13: 2023
A14: حجم الاستثمارات المستفيدة من قانون الاستثمار | B14: Size of Projects Investment Beneficiaries from Investment Promotion Law | C14: M1 | D14: Million JDs | E14: مليون دينار | F14: ='Source Table'!$B$17 -> Scientific research centers | G14: ='Source Table'!$E$17 -> مراكز بحث علمي | H14: ='Source Table'!$D$6 -> local investment | I14: ='Source Table'!$D$5 -> الاستثمار المحلي | J14: 0.1 | K14: 2023
A15: حجم الاستثمارات المستفيدة من قانون الاستثمار | B15: Size of Projects Investment Beneficiaries from Investment Promotion Law | C15: M1 | D15: Million JDs | E15: مليون دينار | F15: ='Source Table'!$B$7 -> Industry | G15: ='Source Table'!$E$7 -> الصناعة | H15: ='Source Table'!$C$6 -> Foreign investment | I15: ='Source Table'!$C$5 -> الاستثمار الاجنبي | J15: 45.8 | K15: 2023
A16: حجم الاستثمارات المستفيدة من قانون الاستثمار | B16: Size of Projects Investment Beneficiaries from Investment Promotion Law | C16: M1 | D16: Million JDs | E16: مليون دينار | F16: ='Source Table'!$B$8 -> Commerce | G16: ='Source Table'!$E$8 -> التجارة | H16: ='Source Table'!$C$6 -> Foreign investment | I16: ='Source Table'!$C$5 -> الاستثمار الاجنبي | J16: 0 | K16: 2023
A17: حجم الاستثمارات المستفيدة من قانون الاستثمار | B17: Size of Projects Investment Beneficiaries from Investment Promotion Law | C17: M1 | D17: Million JDs | E17: مليون دينار | F17: ='Source Table'!$B$9 -> Tourism | G17: ='Source Table'!$E$9 -> السياحة | H17: ='Source Table'!$C$6 -> Foreign investment | I17: ='Source Table'!$C$5 -> الاستثمار الاجنبي | J17: 0 | K17: 2023
A18: حجم الاستثمارات المستفيدة من قانون الاستثمار | B18: Size of Projects Investment Beneficiaries from Investment Promotion Law | C18: M1 | D18: Million JDs | E18: مليون دينار | F18: ='Source Table'!$B$10 -> Agriculture | G18: ='Source Table'!$E$10 -> الزراعة | H18: ='Source Table'!$C$6 -> Foreign investment | I18: ='Source Table'!$C$5 -> الاستثمار الاجنبي | J18: 1.5 | K18: 2023
A19: حجم الاستثمارات المستفيدة من قانون الاستثمار | B19: Size of Projects Investment Beneficiaries from Investment Promotion Law | C19: M1 | D19: Million JDs | E19: مليون دينار | F19: ='Source Table'!$B$11 -> Hospitals | G19: ='Source Table'!$E$11 -> المستشفيات | H19: ='Source Table'!$C$6 -> Foreign investment | I19: ='Source Table'!$C$5 -> الاستثمار الاجنبي | J19: 0 | K19: 2023
A20: حجم الاستثمارات المستفيدة من قانون الاستثمار | B20: Size of Projects Investment Beneficiaries from Investment Promotion Law | C20: M1 | D20: Million JDs | E20: مليون دينار | F20: ='Source Table'!$B$12 -> Services | G20: ='Source Table'!$E$12 -> الخدمات | H20: ='Source Table'!$C$6 -> Foreign investment | I20: ='Source Table'!$C$5 -> الاستثمار الاجنبي | J20: 1 | K20: 2023
A21: حجم الاستثمارات المستفيدة من قانون الاستثمار | B21: Size of Projects Investment Beneficiaries from Investment Promotion Law | C21: M1 | D21: Million JDs | E21: مليون دينار | F21: ='Source Table'!$B$13 -> Information Technology | G21: ='Source Table'!$E$13 -> تكنولوجيا المعلومات | H21: ='Source Table'!$C$6 -> Foreign investment | I21: ='Source Table'!$C$5 -> الاستثمار الاجنبي | J21: 1.4 | K21: 2023
A22: حجم الاستثمارات المستفيدة من قانون الاستثمار | B22: Size of Projects Investment Beneficiaries from Investment Promotion Law | C22: M1 | D22: Million JDs | E22: مليون دينار | F22: ='Source Table'!$B$14 -> Artistic production | G22: ='Source Table'!$E$14 -> انتاج فني | H22: ='Source Table'!$C$6 -> Foreign investment | I22: ='Source Table'!$C$5 -> الاستثمار الاجنبي | J22: 0 | K22: 2023
A23: حجم الاستثمارات المستفيدة من قانون الاستثمار | B23: Size of Projects Investment Beneficiaries from Investment Promotion Law | C23: M1 | D23: Million JDs | E23: مليون دينار | F23: ='Source Table'!$B$15 -> Gas transportation and distribution | G23: ='Source Table'!$E$15 -> نقل وتوزيع الغاز | H23: ='Source Table'!$C$6 -> Foreign investment | I23: ='Source Table'!$C$5 -> الاستثمار الاجنبي | J23: 0 | K23: 2023
A24: حجم الاستثمارات المستفيدة من قانون الاستثمار | B24: Size of Projects Investment Beneficiaries from Investment Promotion Law | C24: M1 | D24: Million JDs | E24: مليون دينار | F24: ='Source Table'!$B$16 -> call centers | G24: ='Source Table'!$E$16 -> مراكز اتصال | H24: ='Source Table'!$C$6 -> Foreign investment | I24: ='Source Table'!$C$5 -> الاستثمار الاجنبي | J24: 0 | K24: 2023
A25: حجم الاستثمارات المستفيدة من قانون الاستثمار | B25: Size of Projects Investment Beneficiaries from Investment Promotion Law | C25: M1 | D25: Million JDs | E25: مليون دينار | F25: ='Source Table'!$B$17 -> Scientific research centers | G25: ='Source Table'!$E$17 -> مراكز بحث علمي | H25: ='Source Table'!$C$6 -> Foreign investment | I25: ='Source Table'!$C$5 -> الاستثمار الاجنبي | J25: 0 | K25: 2023
A26: حجم الاستثمارات المستفيدة من قانون الاستثمار | B26: Size of Projects Investment Beneficiaries from Investment Promotion Law | C26: M1 | D26: Million JDs | E26: مليون دينار | F26: ='Source Table'!$B$7 -> Industry | G26: ='Source Table'!$E$7 -> الصناعة | H26: Total investment | I26: الاستثمار الكلي | J26: 655.9 | K26: 2023
A27: حجم الاستثمارات المستفيدة من قانون الاستثمار | B27: Size of Projects Investment Beneficiaries from Investment Promotion Law | C27: M1 | D27: Million JDs | E27: مليون دينار | F27: ='Source Table'!$B$8 -> Commerce | G27: ='Source Table'!$E$8 -> التجارة | H27: Total investment | I27: الاستثمار الكلي | J27: 184.5 | K27: 2023
A28: حجم الاستثمارات المستفيدة من قانون الاستثمار | B28: Size of Projects Investment Beneficiaries from Investment Promotion Law | C28: M1 | D28: Million JDs | E28: مليون دينار | F28: ='Source Table'!$B$9 -> Tourism | G28: ='Source Table'!$E$9 -> السياحة | H28: Total investment | I28: الاستثمار الكلي | J28: 59.8 | K28: 2023
A29: حجم الاستثمارات المستفيدة من قانون الاستثمار | B29: Size of Projects Investment Beneficiaries from Investment Promotion Law | C29: M1 | D29: Million JDs | E29: مليون دينار | F29: ='Source Table'!$B$10 -> Agriculture | G29: ='Source Table'!$E$10 -> الزراعة | H29: Total investment | I29: الاستثمار الكلي | J29: 15.4 | K29: 2023
A30: حجم الاستثمارات المستفيدة من قانون الاستثمار | B30: Size of Projects Investment Beneficiaries from Investment Promotion Law | C30: M1 | D30: Million JDs | E30: مليون دينار | F30: ='Source Table'!$B$11 -> Hospitals | G30: ='Source Table'!$E$11 -> المستشفيات | H30: Total investment | I30: الاستثمار الكلي | J30: 59.7 | K30: 2023
A31: حجم الاستثمارات المستفيدة من قانون الاستثمار | B31: Size of Projects Investment Beneficiaries from Investment Promotion Law | C31: M1 | D31: Million JDs | E31: مليون دينار | F31: ='Source Table'!$B$12 -> Services | G31: ='Source Table'!$E$12 -> الخدمات | H31: Total investment | I31: الاستثمار الكلي | J31: 19.2 | K31: 2023
A32: حجم الاستثمارات المستفيدة من قانون الاستثمار | B32: Size of Projects Investment Beneficiaries from Investment Promotion Law | C32: M1 | D32: Million JDs | E32: مليون دينار | F32: ='Source Table'!$B$13 -> Information Technology | G32: ='Source Table'!$E$13 -> تكنولوجيا المعلومات | H32: Total investment | I32: الاستثمار الكلي | J32: 33.9 | K32: 2023
A33: حجم الاستثمارات المستفيدة من قانون الاستثمار | B33: Size of Projects Investment Beneficiaries from Investment Promotion Law | C33: M1 | D33: Million JDs | E33: مليون دينار | F33: ='Source Table'!$B$14 -> Artistic production | G33: ='Source Table'!$E$14 -> انتاج فني | H33: Total investment | I33: الاستثمار الكلي | J33: 10 | K33: 2023
A34: حجم الاستثمارات المستفيدة من قانون الاستثمار | B34: Size of Projects Investment Beneficiaries from Investment Promotion Law | C34: M1 | D34: Million JDs | E34: مليون دينار | F34: ='Source Table'!$B$15 -> Gas transportation and distribution | G34: ='Source Table'!$E$15 -> نقل وتوزيع الغاز | H34: Total investment | I34: الاستثمار الكلي | J34: 19 | K34: 2023
A35: حجم الاستثمارات المستفيدة من قانون الاستثمار | B35: Size of Projects Investment Beneficiaries from Investment Promotion Law | C35: M1 | D35: Million JDs | E35: مليون دينار | F35: ='Source Table'!$B$16 -> call centers | G35: ='Source Table'!$E$16 -> مراكز اتصال | H35: Total investment | I35: الاستثمار الكلي | J35: 0 | K35: 2023
A36: حجم الاستثمارات المستفيدة من قانون الاستثمار | B36: Size of Projects Investment Beneficiaries from Investment Promotion Law | C36: M1 | D36: Million JDs | E36: مليون دينار | F36: ='Source Table'!$B$17 -> Scientific research centers | G36: ='Source Table'!$E$17 -> مراكز بحث علمي | H36: Total investment | I36: الاستثمار الكلي | J36: 0.1 | K36: 2023
A37: حجم الاستثمارات المستفيدة من قانون الاستثمار | B37: Size of Projects Investment Beneficiaries from Investment Promotion Law | C37: M1 | D37: Million JDs | E37: مليون دينار | F37: ='Source Table'!$B$7 -> Industry | G37: ='Source Table'!$E$7 -> الصناعة | H37: ='Source Table'!$D$6 -> local investment | I37: ='Source Table'!$D$5 -> الاستثمار المحلي | J37: 544 | K37: 2022
A38: حجم الاستثمارات المستفيدة من قانون الاستثمار | B38: Size of Projects Investment Beneficiaries from Investment Promotion Law | C38: M1 | D38: Million JDs | E38: مليون دينار | F38: ='Source Table'!$B$8 -> Commerce | G38: ='Source Table'!$E$8 -> التجارة | H38: ='Source Table'!$D$6 -> local investment | I38: ='Source Table'!$D$5 -> الاستثمار المحلي | J38: 0 | K38: 2022
A39: حجم الاستثمارات المستفيدة من قانون الاستثمار | B39: Size of Projects Investment Beneficiaries from Investment Promotion Law | C39: M1 | D39: Million JDs | E39: مليون دينار | F39: ='Source Table'!$B$9 -> Tourism | G39: ='Source Table'!$E$9 -> السياحة | H39: ='Source Table'!$D$6 -> local investment | I39: ='Source Table'!$D$5 -> الاستثمار المحلي | J39: 226.9 | K39: 2022
A40: حجم الاستثمارات المستفيدة من قانون الاستثمار | B40: Size of Projects Investment Beneficiaries from Investment Promotion Law | C40: M1 | D40: Million JDs | E40: مليون دينار | F40: ='Source Table'!$B$10 -> Agriculture | G40: ='Source Table'!$E$10 -> الزراعة | H40: ='Source Table'!$D$6 -> local investment | I40: ='Source Table'!$D$5 -> الاستثمار المحلي | J40: 35.8 | K40: 2022
...

Sheet Sheet1
A1: حجم الاستثمارات المستفيدة من قانون الاستثمار | B1: Size of Projects Investment Beneficiaries from Investment Promotion Law | C1: M1 | D1: Million JDs | E1: مليون دينار | F1: ='Source Table'!$B$7 -> Industry | G1: ='Source Table'!$E$7 -> الصناعة | H1: ='Source Table'!$D$6 -> local investment | I1: ='Source Table'!$D$5 -> الاستثمار المحلي
A2: حجم الاستثمارات المستفيدة من قانون الاستثمار | B2: Size of Projects Investment Beneficiaries from Investment Promotion Law | C2: M1 | D2: Million JDs | E2: مليون دينار | F2: ='Source Table'!$B$8 -> Commerce | G2: ='Source Table'!$E$8 -> التجارة | H2: ='Source Table'!$D$6 -> local investment | I2: ='Source Table'!$D$5 -> الاستثمار المحلي
A3: حجم الاستثمارات المستفيدة من قانون الاستثمار | B3: Size of Projects Investment Beneficiaries from Investment Promotion Law | C3: M1 | D3: Million JDs | E3: مليون دينار | F3: ='Source Table'!$B$9 -> Tourism | G3: ='Source Table'!$E$9 -> السياحة | H3: ='Source Table'!$D$6 -> local investment | I3: ='Source Table'!$D$5 -> الاستثمار المحلي
A4: حجم الاستثمارات المستفيدة من قانون الاستثمار | B4: Size of Projects Investment Beneficiaries from Investment Promotion Law | C4: M1 | D4: Million JDs | E4: مليون دينار | F4: ='Source Table'!$B$10 -> Agriculture | G4: ='Source Table'!$E$10 -> الزراعة | H4: ='Source Table'!$D$6 -> local investment | I4: ='Source Table'!$D$5 -> الاستثمار المحلي
A5: حجم الاستثمارات المستفيدة من قانون الاستثمار | B5: Size of Projects Investment Beneficiaries from Investment Promotion Law | C5: M1 | D5: Million JDs | E5: مليون دينار | F5: ='Source Table'!$B$11 -> Hospitals | G5: ='Source Table'!$E$11 -> المستشفيات | H5: ='Source Table'!$D$6 -> local investment | I5: ='Source Table'!$D$5 -> الاستثمار المحلي
A6: حجم الاستثمارات المستفيدة من قانون الاستثمار | B6: Size of Projects Investment Beneficiaries from Investment Promotion Law | C6: M1 | D6: Million JDs | E6: مليون دينار | F6: ='Source Table'!$B$12 -> Services | G6: ='Source Table'!$E$12 -> الخدمات | H6: ='Source Table'!$D$6 -> local investment | I6: ='Source Table'!$D$5 -> الاستثمار المحلي
A7: حجم الاستثمارات المستفيدة من قانون الاستثمار | B7: Size of Projects Investment Beneficiaries from Investment Promotion Law | C7: M1 | D7: Million JDs | E7: مليون دينار | F7: ='Source Table'!$B$13 -> Information Technology | G7: ='Source Table'!$E$13 -> تكنولوجيا المعلومات | H7: ='Source Table'!$D$6 -> local investment | I7: ='Source Table'!$D$5 -> الاستثمار المحلي
A8: حجم الاستثمارات المستفيدة من قانون الاستثمار | B8: Size of Projects Investment Beneficiaries from Investment Promotion Law | C8: M1 | D8: Million JDs | E8: مليون دينار | F8: ='Source Table'!$B$14 -> Artistic production | G8: ='Source Table'!$E$14 -> انتاج فني | H8: ='Source Table'!$D$6 -> local investment | I8: ='Source Table'!$D$5 -> الاستثمار المحلي
A9: حجم الاستثمارات المستفيدة من قانون الاستثمار | B9: Size of Projects Investment Beneficiaries from Investment Promotion Law | C9: M1 | D9: Million JDs | E9: مليون دينار | F9: ='Source Table'!$B$15 -> Gas transportation and distribution | G9: ='Source Table'!$E$15 -> نقل وتوزيع الغاز | H9: ='Source Table'!$D$6 -> local investment | I9: ='Source Table'!$D$5 -> الاستثمار المحلي
A10: حجم الاستثمارات المستفيدة من قانون الاستثمار | B10: Size of Projects Investment Beneficiaries from Investment Promotion Law | C10: M1 | D10: Million JDs | E10: مليون دينار | F10: ='Source Table'!$B$16 -> call centers | G10: ='Source Table'!$E$16 -> مراكز اتصال | H10: ='Source Table'!$D$6 -> local investment | I10: ='Source Table'!$D$5 -> الاستثمار المحلي
A11: حجم الاستثمارات المستفيدة من قانون الاستثمار | B11: Size of Projects Investment Beneficiaries from Investment Promotion Law | C11: M1 | D11: Million JDs | E11: مليون دينار | F11: ='Source Table'!$B$17 -> Scientific research centers | G11: ='Source Table'!$E$17 -> مراكز بحث علمي | H11: ='Source Table'!$D$6 -> local investment | I11: ='Source Table'!$D$5 -> الاستثمار المحلي
A12: حجم الاستثمارات المستفيدة من قانون الاستثمار | B12: Size of Projects Investment Beneficiaries from Investment Promotion Law | C12: M1 | D12: Million JDs | E12: مليون دينار | F12: ='Source Table'!$B$7 -> Industry | G12: ='Source Table'!$E$7 -> الصناعة | H12: ='Source Table'!$C$6 -> Foreign investment | I12: ='Source Table'!$C$5 -> الاستثمار الاجنبي
A13: حجم الاستثمارات المستفيدة من قانون الاستثمار | B13: Size of Projects Investment Beneficiaries from Investment Promotion Law | C13: M1 | D13: Million JDs | E13: مليون دينار | F13: ='Source Table'!$B$8 -> Commerce | G13: ='Source Table'!$E$8 -> التجارة | H13: ='Source Table'!$C$6 -> Foreign investment | I13: ='Source Table'!$C$5 -> الاستثمار الاجنبي
A14: حجم الاستثمارات المستفيدة من قانون الاستثمار | B14: Size of Projects Investment Beneficiaries from Investment Promotion Law | C14: M1 | D14: Million JDs | E14: مليون دينار | F14: ='Source Table'!$B$9 -> Tourism | G14: ='Source Table'!$E$9 -> السياحة | H14: ='Source Table'!$C$6 -> Foreign investment | I14: ='Source Table'!$C$5 -> الاستثمار الاجنبي
A15: حجم الاستثمارات المستفيدة من قانون الاستثمار | B15: Size of Projects Investment Beneficiaries from Investment Promotion Law | C15: M1 | D15: Million JDs | E15: مليون دينار | F15: ='Source Table'!$B$10 -> Agriculture | G15: ='Source Table'!$E$10 -> الزراعة | H15: ='Source Table'!$C$6 -> Foreign investment | I15: ='Source Table'!$C$5 -> الاستثمار الاجنبي
A16: حجم الاستثمارات المستفيدة من قانون الاستثمار | B16: Size of Projects Investment Beneficiaries from Investment Promotion Law | C16: M1 | D16: Million JDs | E16: مليون دينار | F16: ='Source Table'!$B$11 -> Hospitals | G16: ='Source Table'!$E$11 -> المستشفيات | H16: ='Source Table'!$C$6 -> Foreign investment | I16: ='Source Table'!$C$5 -> الاستثمار الاجنبي
A17: حجم الاستثمارات المستفيدة من قانون الاستثمار | B17: Size of Projects Investment Beneficiaries from Investment Promotion Law | C17: M1 | D17: Million JDs | E17: مليون دينار | F17: ='Source Table'!$B$12 -> Services | G17: ='Source Table'!$E$12 -> الخدمات | H17: ='Source Table'!$C$6 -> Foreign investment | I17: ='Source Table'!$C$5 -> الاستثمار الاجنبي
A18: حجم الاستثمارات المستفيدة من قانون الاستثمار | B18: Size of Projects Investment Beneficiaries from Investment Promotion Law | C18: M1 | D18: Million JDs | E18: مليون دينار | F18: ='Source Table'!$B$13 -> Information Technology | G18: ='Source Table'!$E$13 -> تكنولوجيا المعلومات | H18: ='Source Table'!$C$6 -> Foreign investment | I18: ='Source Table'!$C$5 -> الاستثمار الاجنبي
A19: حجم الاستثمارات المستفيدة من قانون الاستثمار | B19: Size of Projects Investment Beneficiaries from Investment Promotion Law | C19: M1 | D19: Million JDs | E19: مليون دينار | F19: ='Source Table'!$B$14 -> Artistic production | G19: ='Source Table'!$E$14 -> انتاج فني | H19: ='Source Table'!$C$6 -> Foreign investment | I19: ='Source Table'!$C$5 -> الاستثمار الاجنبي
A20: حجم الاستثمارات المستفيدة من قانون الاستثمار | B20: Size of Projects Investment Beneficiaries from Investment Promotion Law | C20: M1 | D20: Million JDs | E20: مليون دينار | F20: ='Source Table'!$B$15 -> Gas transportation and distribution | G20: ='Source Table'!$E$15 -> نقل وتوزيع الغاز | H20: ='Source Table'!$C$6 -> Foreign investment | I20: ='Source Table'!$C$5 -> الاستثمار الاجنبي
A21: حجم الاستثمارات المستفيدة من قانون الاستثمار | B21: Size of Projects Investment Beneficiaries from Investment Promotion Law | C21: M1 | D21: Million JDs | E21: مليون دينار | F21: ='Source Table'!$B$16 -> call centers | G21: ='Source Table'!$E$16 -> مراكز اتصال | H21: ='Source Table'!$C$6 -> Foreign investment | I21: ='Source Table'!$C$5 -> الاستثمار الاجنبي
A22: حجم الاستثمارات المستفيدة من قانون الاستثمار | B22: Size of Projects Investment Beneficiaries from Investment Promotion Law | C22: M1 | D22: Million JDs | E22: مليون دينار | F22: ='Source Table'!$B$17 -> Scientific research centers | G22: ='Source Table'!$E$17 -> مراكز بحث علمي | H22: ='Source Table'!$C$6 -> Foreign investment | I22: ='Source Table'!$C$5 -> الاستثمار الاجنبي

Sheet Template Data
A1: Date | B1: =DATE(B2,B3,1) -> 45292
A2: Year | B2: 2024
A3: Month | B3: 1
A4: Measure_Name_Ar | B4: Measure_Name_En | C4: Measure_ID | D4: Unit_EN | E4: Unit_AR | F4: CL_SECTOR__EN_V3 | G4: CL_SECTOR__AR_V3 | H4: CL_INV_NAT_EN_V1 | I4: CL_INV_NAT_AR_V1 | J4: Obs_Value | K4: Time_Period_Y | L4: Time_Period_M
A5: اسم المؤشر | B5: Measure Name | C5: رمز المؤشر | D5: Unit | E5: الوحدة | F5: Sector | G5: القطاع | H5: Investment Nationality | I5: جنسية الاستثمار | J5: قيمة المؤشر | K5: سنة فترة القياس | L5: شهر فترة القياس

Sheet Help
A2: Step 1: Cover Page | C2: الخطوة 1: Cover Page
A4: Update the template information, to ensure that any meta-information about the template, such as the title, version, and description, is accurate and up-to-date. | C4: قم بتحديث معلومات القالب للتأكد من أن أي معلومات وصفية حول القالب، مثل العنوان والإصدار والوصف، دقيقة ومحدثة.
A6: Step 2: Source Table | C6: الخطوة 2: Source Table
A8: Design your template, ensuring that the time period is mapped correctly to the date information in rows 1-3 of the Template Data Sheet. | C8: قم بتصميم القالب الخاص بك، مع التأكد من أن فترة الوقت مرتبطة بشكل صحيح مع معلومات التاريخ في الصفوف 1-3 في ورقة Template Data.
A10: Step 3: Relational Sheet | C10: الخطوة 3: Relational Sheet
A12: Unpivot the data in the source table into a flat format. Follow these guidelines: | C12: قم بتحويل البيانات في جدول المصدر إلى تنسيق مسطح. اتبع هذه الإرشادات:
A13: 1. Blue Columns: Do not change the names of the blue columns. Update the data as per the current template. | C13: 1. الأعمدة الزرقاء: لا تقم بتغيير أسماء الأعمدة الزرقاء. قم بتحديث البيانات وفقًا للقالب الحالي.
A14: 2. Code Lists: Use the naming convention CL_XXX_EN_V# for code lists, where XXX is the name, and V# is the version, conforming with the definitions in the data dictionary. | C14: 2. قوائم الرموز: استخدم قاعدة التسمية CL_XXX_EN_V# لقوائم الرموز، حيث أن XXX هو الاسم و V# هو الإصدار، وفقًا للتعريفات في قاموس البيانات.
A15: 3. Code List Values: Ensure the code list values match the definitions in the data dictionary. | C15: 3. قيم قائمة الرموز: تأكد من أن قيم قائمة الرموز تتوافق مع التعريفات في قاموس البيانات.
A16: 4. Time_Period_M: Leave empty if the data frequency is yearly. | C16: 4. Time_Period_M: اتركها فارغة إذا كانت دورية البيانات سنوية.
A17: 5. Time_Period_M Format: Use one of these formats: | C17: 5. تنسيق Time_Period_M: استخدم أحد التنسيقات التالية:
A18: Numeric: (1, 2, 3, ..., 12) for months. | C18: رقمي: (1، 2، 3، ...، 12) للأشهر.
... A38: Protect the entire workbook to prevent unauthorized or accidental changes to the structure of the file. | C38: قم بحماية الكتاب بأكمله لمنع التغييرات غير المصرح بها أو غير المقصودة على هيكل الملف.
