Workbook

Sheet Cover Page
A1: Code | B1: SYB_20_4
A2: Version | B2: V1
A3: اسم القالب | B3: حجم الاستثمارات المستفيدة من قانون الاستثمار حسب القطاع,(مليون دينار)
A4: Template Name | B4: Size of Projects Investment Beneficiaries from Investment Promotion Law by Sector,(Million JDs)
A5: دورية البيانات | B5: سنوي
A6: Data Frequency | B6: Annual
A7: الجهة المصدرية | B7: وزارة الاستثمار
A8: Data Source | B8: Ministry of Investment

Sheet Source Table
B2: ='Cover Page'!B4 -> Size of Projects Investment Beneficiaries from Investment Promotion Law by Sector,(Million JDs)
B3: ='Cover Page'!B3 -> حجم الاستثمارات المستفيدة من قانون الاستثمار حسب القطاع,(مليون دينار)
B4: Year | C4: =YEAR('Template Data'!B1) -> 2024 | D4: السنة
B5: Industry | D5: الصناعة
B6: Commerce | D6: التجارة
B7: Tourism | D7: السياحة
B8: Agriculture | D8: الزراعة
B9: Hospitals | D9: المستشفيات
B10: Services | D10: الخدمات
B11: Information Technology | D11: تكنولوجيا المعلومات
B12: Artistic production | D12: انتاج فني
B13: Gas transportation and distribution | D13: نقل وتوزيع الغاز
B14: call centers | D14: مراكز اتصال
B15: Scientific research centers | D15: مراكز بحث علمي

Sheet Relational DB
A1: Relational Sheet
A2: Measure_Name_Ar | B2: Measure_Name_En | C2: Measure_ID | D2: Unit_EN | E2: Unit_AR | F2: CL_SECTOR__EN_V3 | G2: CL_SECTOR__AR_V3 | H2: Obs_Value | I2: Time_Period_Y | J2: Time_Period_M
A3: اسم المؤشر | B3: Measure Name | C3: رمز المؤشر | D3: Unit | E3: الوحدة | F3: Sector | G3: القطاع | H3: قيمة المؤشر | I3: سنة فترة القياس | J3: شهر فترة القياس
A4: حجم الاستثمارات المستفيدة من قانون الاستثمار | B4: Size of Projects Investment Beneficiaries from Investment Promotion Law | C4: M1 | D4: Million JDs | E4: مليون دينار | F4: ='Source Table'!$B$5 -> Industry | G4: ='Source Table'!$D$5 -> الصناعة | H4: 655.9 | I4: 2023
A5: حجم الاستثمارات المستفيدة من قانون الاستثمار | B5: Size of Projects Investment Beneficiaries from Investment Promotion Law | C5: M1 | D5: Million JDs | E5: مليون دينار | F5: ='Source Table'!$B$6 -> Commerce | G5: ='Source Table'!$D$6 -> التجارة | H5: 184.5 | I5: 2023
A6: حجم الاستثمارات المستفيدة من قانون الاستثمار | B6: Size of Projects Investment Beneficiaries from Investment Promotion Law | C6: M1 | D6: Million JDs | E6: مليون دينار | F6: ='Source Table'!$B$7 -> Tourism | G6: ='Source Table'!$D$7 -> السياحة | H6: 59.8 | I6: 2023
A7: حجم الاستثمارات المستفيدة من قانون الاستثمار | B7: Size of Projects Investment Beneficiaries from Investment Promotion Law | C7: M1 | D7: Million JDs | E7: مليون دينار | F7: ='Source Table'!$B$8 -> Agriculture | G7: ='Source Table'!$D$8 -> الزراعة | H7: 15.4 | I7: 2023
A8: حجم الاستثمارات المستفيدة من قانون الاستثمار | B8: Size of Projects Investment Beneficiaries from Investment Promotion Law | C8: M1 | D8: Million JDs | E8: مليون دينار | F8: ='Source Table'!$B$9 -> Hospitals | G8: ='Source Table'!$D$9 -> المستشفيات | H8: 59.7 | I8: 2023
A9: حجم الاستثمارات المستفيدة من قانون الاستثمار | B9: Size of Projects Investment Beneficiaries from Investment Promotion Law | C9: M1 | D9: Million JDs | E9: مليون دينار | F9: ='Source Table'!$B$10 -> Services | G9: ='Source Table'!$D$10 -> الخدمات | H9: 19.2 | I9: 2023
A10: حجم الاستثمارات المستفيدة من قانون الاستثمار | B10: Size of Projects Investment Beneficiaries from Investment Promotion Law | C10: M1 | D10: Million JDs | E10: مليون دينار | F10: ='Source Table'!$B$11 -> Information Technology | G10: ='Source Table'!$D$11 -> تكنولوجيا المعلومات | H10: 33.9 | I10: 2023
A11: حجم الاستثمارات المستفيدة من قانون الاستثمار | B11: Size of Projects Investment Beneficiaries from Investment Promotion Law | C11: M1 | D11: Million JDs | E11: مليون دينار | F11: ='Source Table'!$B$12 -> Artistic production | G11: ='Source Table'!$D$12 -> انتاج فني | H11: 10 | I11: 2023
A12: حجم الاستثمارات المستفيدة من قانون الاستثمار | B12: Size of Projects Investment Beneficiaries from Investment Promotion Law | C12: M1 | D12: Million JDs | E12: مليون دينار | F12: ='Source Table'!$B$13 -> Gas transportation and distribution | G12: ='Source Table'!$D$13 -> نقل وتوزيع الغاز | H12: 19 | I12: 2023
A13: حجم الاستثمارات المستفيدة من قانون الاستثمار | B13: Size of Projects Investment Beneficiaries from Investment Promotion Law | C13: M1 | D13: Million JDs | E13: مليون دينار | F13: ='Source Table'!$B$14 -> call centers | G13: ='Source Table'!$D$14 -> مراكز اتصال | H13: 0 | I13: 2023
A14: حجم الاستثمارات المستفيدة من قانون الاستثمار | B14: Size of Projects Investment Beneficiaries from Investment Promotion Law | C14: M1 | D14: Million JDs | E14: مليون دينار | F14: ='Source Table'!$B$15 -> Scientific research centers | G14: ='Source Table'!$D$15 -> مراكز بحث علمي | H14: 0.1 | I14: 2023
A15: حجم الاستثمارات المستفيدة من قانون الاستثمار | B15: Size of Projects Investment Beneficiaries from Investment Promotion Law | C15: M1 | D15: Million JDs | E15: مليون دينار | F15: ='Source Table'!$B$5 -> Industry | G15: ='Source Table'!$D$5 -> الصناعة | H15: 648.6 | I15: 2022
A16: حجم الاستثمارات المستفيدة من قانون الاستثمار | B16: Size of Projects Investment Beneficiaries from Investment Promotion Law | C16: M1 | D16: Million JDs | E16: مليون دينار | F16: ='Source Table'!$B$6 -> Commerce | G16: ='Source Table'!$D$6 -> التجارة | H16: 0 | I16: 2022
A17: حجم الاستثمارات المستفيدة من قانون الاستثمار | B17: Size of Projects Investment Beneficiaries from Investment Promotion Law | C17: M1 | D17: Million JDs | E17: مليون دينار | F17: ='Source Table'!$B$7 -> Tourism | G17: ='Source Table'!$D$7 -> السياحة | H17: 233 | I17: 2022
A18: حجم الاستثمارات المستفيدة من قانون الاستثمار | B18: Size of Projects Investment Beneficiaries from Investment Promotion Law | C18: M1 | D18: Million JDs | E18: مليون دينار | F18: ='Source Table'!$B$8 -> Agriculture | G18: ='Source Table'!$D$8 -> الزراعة | H18: 37.8 | I18: 2022
A19: حجم الاستثمارات المستفيدة من قانون الاستثمار | B19: Size of Projects Investment Beneficiaries from Investment Promotion Law | C19: M1 | D19: Million JDs | E19: مليون دينار | F19: ='Source Table'!$B$9 -> Hospitals | G19: ='Source Table'!$D$9 -> المستشفيات | H19: 136.5 | I19: 2022
A20: حجم الاستثمارات المستفيدة من قانون الاستثمار | B20: Size of Projects Investment Beneficiaries from Investment Promotion Law | C20: M1 | D20: Million JDs | E20: مليون دينار | F20: ='Source Table'!$B$10 -> Services | G20: ='Source Table'!$D$10 -> الخدمات | H20: 0.5 | I20: 2022
A21: حجم الاستثمارات المستفيدة من قانون الاستثمار | B21: Size of Projects Investment Beneficiaries from Investment Promotion Law | C21: M1 | D21: Million JDs | E21: مليون دينار | F21: ='Source Table'!$B$11 -> Information Technology | G21: ='Source Table'!$D$11 -> تكنولوجيا المعلومات | H21: 55.5 | I21: 2022
A22: حجم الاستثمارات المستفيدة من قانون الاستثمار | B22: Size of Projects Investment Beneficiaries from Investment Promotion Law | C22: M1 | D22: Million JDs | E22: مليون دينار | F22: ='Source Table'!$B$12 -> Artistic production | G22: ='Source Table'!$D$12 -> انتاج فني | H22: 1.4 | I22: 2022
A23: حجم الاستثمارات المستفيدة من قانون الاستثمار | B23: Size of Projects Investment Beneficiaries from Investment Promotion Law | C23: M1 | D23: Million JDs | E23: مليون دينار | F23: ='Source Table'!$B$13 -> Gas transportation and distribution | G23: ='Source Table'!$D$13 -> نقل وتوزيع الغاز | H23: 0 | I23: 2022
A24: حجم الاستثمارات المستفيدة من قانون الاستثمار | B24: Size of Projects Investment Beneficiaries from Investment Promotion Law | C24: M1 | D24: Million JDs | E24: مليون دينار | F24: ='Source Table'!$B$14 -> call centers | G24: ='Source Table'!$D$14 -> مراكز اتصال | H24: 0 | I24: 2022
A25: حجم الاستثمارات المستفيدة من قانون الاستثمار | B25: Size of Projects Investment Beneficiaries from Investment Promotion Law | C25: M1 | D25: Million JDs | E25: مليون دينار | F25: ='Source Table'!$B$15 -> Scientific research centers | G25: ='Source Table'!$D$15 -> مراكز بحث علمي | H25: 0 | I25: 2022
A26: حجم الاستثمارات المستفيدة من قانون الاستثمار | B26: Size of Projects Investment Beneficiaries from Investment Promotion Law | C26: M1 | D26: Million JDs | E26: مليون دينار | F26: ='Source Table'!$B$5 -> Industry | G26: ='Source Table'!$D$5 -> الصناعة | H26: 408 | I26: 2021
A27: حجم الاستثمارات المستفيدة من قانون الاستثمار | B27: Size of Projects Investment Beneficiaries from Investment Promotion Law | C27: M1 | D27: Million JDs | E27: مليون دينار | F27: ='Source Table'!$B$6 -> Commerce | G27: ='Source Table'!$D$6 -> التجارة | I27: 2021
A28: حجم الاستثمارات المستفيدة من قانون الاستثمار | B28: Size of Projects Investment Beneficiaries from Investment Promotion Law | C28: M1 | D28: Million JDs | E28: مليون دينار | F28: ='Source Table'!$B$7 -> Tourism | G28: ='Source Table'!$D$7 -> السياحة | H28: 66 | I28: 2021
A29: حجم الاستثمارات المستفيدة من قانون الاستثمار | B29: Size of Projects Investment Beneficiaries from Investment Promotion Law | C29: M1 | D29: Million JDs | E29: مليون دينار | F29: ='Source Table'!$B$8 -> Agriculture | G29: ='Source Table'!$D$8 -> الزراعة | H29: 52.9 | I29: 2021
A30: حجم الاستثمارات المستفيدة من قانون الاستثمار | B30: Size of Projects Investment Beneficiaries from Investment Promotion Law | C30: M1 | D30: Million JDs | E30: مليون دينار | F30: ='Source Table'!$B$9 -> Hospitals | G30: ='Source Table'!$D$9 -> المستشفيات | H30: 44.1 | I30: 2021
A31: حجم الاستثمارات المستفيدة من قانون الاستثمار | B31: Size of Projects Investment Beneficiaries from Investment Promotion Law | C31: M1 | D31: Million JDs | E31: مليون دينار | F31: ='Source Table'!$B$10 -> Services | G31: ='Source Table'!$D$10 -> الخدمات | H31: 0.6 | I31: 2021
A32: حجم الاستثمارات المستفيدة من قانون الاستثمار | B32: Size of Projects Investment Beneficiaries from Investment Promotion Law | C32: M1 | D32: Million JDs | E32: مليون دينار | F32: ='Source Table'!$B$11 -> Information Technology | G32: ='Source Table'!$D$11 -> تكنولوجيا المعلومات | H32: 40.1 | I32: 2021
A33: حجم الاستثمارات المستفيدة من قانون الاستثمار | B33: Size of Projects Investment Beneficiaries from Investment Promotion Law | C33: M1 | D33: Million JDs | E33: مليون دينار | F33: ='Source Table'!$B$12 -> Artistic production | G33: ='Source Table'!$D$12 -> انتاج فني | H33: 8.5 | I33: 2021
A34: حجم الاستثمارات المستفيدة من قانون الاستثمار | B34: Size of Projects Investment Beneficiaries from Investment Promotion Law | C34: M1 | D34: Million JDs | E34: مليون دينار | F34: ='Source Table'!$B$13 -> Gas transportation and distribution | G34: ='Source Table'!$D$13 -> نقل وتوزيع الغاز | H34: 0 | I34: 2021
A35: حجم الاستثمارات المستفيدة من قانون الاستثمار | B35: Size of Projects Investment Beneficiaries from Investment Promotion Law | C35: M1 | D35: Million JDs | E35: مليون دينار | F35: ='Source Table'!$B$14 -> call centers | G35: ='Source Table'!$D$14 -> مراكز اتصال | H35: 0 | I35: 2021
A36: حجم الاستثمارات المستفيدة من قانون الاستثمار | B36: Size of Projects Investment Beneficiaries from Investment Promotion Law | C36: M1 | D36: Million JDs | E36: مليون دينار | F36: ='Source Table'!$B$15 -> Scientific research centers | G36: ='Source Table'!$D$15 -> مراكز بحث علمي | H36: 0.9 | I36: 2021
A37: حجم الاستثمارات المستفيدة من قانون الاستثمار | B37: Size of Projects Investment Beneficiaries from Investment Promotion Law | C37: M1 | D37: Million JDs | E37: مليون دينار | F37: ='Source Table'!$B$5 -> Industry | G37: ='Source Table'!$D$5 -> الصناعة | H37: 404.1 | I37: 2020
A38: حجم الاستثمارات المستفيدة من قانون الاستثمار | B38: Size of Projects Investment Beneficiaries from Investment Promotion Law | C38: M1 | D38: Million JDs | E38: مليون دينار | F38: ='Source Table'!$B$6 -> Commerce | G38: ='Source Table'!$D$6 -> التجارة | I38: 2020
A39: حجم الاستثمارات المستفيدة من قانون الاستثمار | B39: Size of Projects Investment Beneficiaries from Investment Promotion Law | C39: M1 | D39: Million JDs | E39: مليون دينار | F39: ='Source Table'!$B$7 -> Tourism | G39: ='Source Table'!$D$7 -> السياحة | H39: 25.6 | I39: 2020
A40: حجم الاستثمارات المستفيدة من قانون الاستثمار | B40: Size of Projects Investment Beneficiaries from Investment Promotion Law | C40: M1 | D40: Million JDs | E40: مليون دينار | F40: ='Source Table'!$B$8 -> Agriculture | G40: ='Source Table'!$D$8 -> الزراعة | H40: 43.1 | I40: 2020
...

Sheet Sheet1
A1: حجم الاستثمارات المستفيدة من قانون الاستثمار | B1: Size of Projects Investment Beneficiaries from Investment Promotion Law | C1: M1 | D1: Million JDs | E1: مليون دينار | F1: ='Source Table'!$B$5 -> Industry | G1: ='Source Table'!$D$5 -> الصناعة
A2: حجم الاستثمارات المستفيدة من قانون الاستثمار | B2: Size of Projects Investment Beneficiaries from Investment Promotion Law | C2: M1 | D2: Million JDs | E2: مليون دينار | F2: ='Source Table'!$B$6 -> Commerce | G2: ='Source Table'!$D$6 -> التجارة
A3: حجم الاستثمارات المستفيدة من قانون الاستثمار | B3: Size of Projects Investment Beneficiaries from Investment Promotion Law | C3: M1 | D3: Million JDs | E3: مليون دينار | F3: ='Source Table'!$B$7 -> Tourism | G3: ='Source Table'!$D$7 -> السياحة
A4: حجم الاستثمارات المستفيدة من قانون الاستثمار | B4: Size of Projects Investment Beneficiaries from Investment Promotion Law | C4: M1 | D4: Million JDs | E4: مليون دينار | F4: ='Source Table'!$B$8 -> Agriculture | G4: ='Source Table'!$D$8 -> الزراعة
A5: حجم الاستثمارات المستفيدة من قانون الاستثمار | B5: Size of Projects Investment Beneficiaries from Investment Promotion Law | C5: M1 | D5: Million JDs | E5: مليون دينار | F5: ='Source Table'!$B$9 -> Hospitals | G5: ='Source Table'!$D$9 -> المستشفيات
A6: حجم الاستثمارات المستفيدة من قانون الاستثمار | B6: Size of Projects Investment Beneficiaries from Investment Promotion Law | C6: M1 | D6: Million JDs | E6: مليون دينار | F6: ='Source Table'!$B$10 -> Services | G6: ='Source Table'!$D$10 -> الخدمات
A7: حجم الاستثمارات المستفيدة من قانون الاستثمار | B7: Size of Projects Investment Beneficiaries from Investment Promotion Law | C7: M1 | D7: Million JDs | E7: مليون دينار | F7: ='Source Table'!$B$11 -> Information Technology | G7: ='Source Table'!$D$11 -> تكنولوجيا المعلومات
A8: حجم الاستثمارات المستفيدة من قانون الاستثمار | B8: Size of Projects Investment Beneficiaries from Investment Promotion Law | C8: M1 | D8: Million JDs | E8: مليون دينار | F8: ='Source Table'!$B$12 -> Artistic production | G8: ='Source Table'!$D$12 -> انتاج فني
A9: حجم الاستثمارات المستفيدة من قانون الاستثمار | B9: Size of Projects Investment Beneficiaries from Investment Promotion Law | C9: M1 | D9: Million JDs | E9: مليون دينار | F9: ='Source Table'!$B$13 -> Gas transportation and distribution | G9: ='Source Table'!$D$13 -> نقل وتوزيع الغاز
A10: حجم الاستثمارات المستفيدة من قانون الاستثمار | B10: Size of Projects Investment Beneficiaries from Investment Promotion Law | C10: M1 | D10: Million JDs | E10: مليون دينار | F10: ='Source Table'!$B$14 -> call centers | G10: ='Source Table'!$D$14 -> مراكز اتصال
A11: حجم الاستثمارات المستفيدة من قانون الاستثمار | B11: Size of Projects Investment Beneficiaries from Investment Promotion Law | C11: M1 | D11: Million JDs | E11: مليون دينار | F11: ='Source Table'!$B$15 -> Scientific research centers | G11: ='Source Table'!$D$15 -> مراكز بحث علمي

Sheet Template Data
A1: Date | B1: =DATE(B2,B3,1) -> 45292
A2: Year | B2: 2024
A3: Month | B3: 1
A4: Measure_Name_Ar | B4: Measure_Name_En | C4: Measure_ID | D4: Unit_EN | E4: Unit_AR | F4: CL_SECTOR__EN_V3 | G4: CL_SECTOR__AR_V3 | H4: Obs_Value | I4: Time_Period_Y | J4: Time_Period_M
A5: اسم المؤشر | B5: Measure Name | C5: رمز المؤشر | D5: Unit | E5: الوحدة | F5: Sector | G5: القطاع | H5: قيمة المؤشر | I5: سنة فترة القياس | J5: شهر فترة القياس

Sheet Help
A2: Step 1: Cover Page | C2: الخطوة 1: Cover Page
A4: Update the template information, to ensure that any meta-information about the template, such as the title, version, and description, is accurate and up-to-date. | C4: قم بتحديث معلومات القالب للتأكد من أن أي معلومات وصفية حول القالب، مثل العنوان والإصدار والوصف، دقيقة ومحدثة.
A6: Step 2: Source Table | C6: الخطوة 2: Source Table
A8: Design your template, ensuring that the time period is mapped correctly to the date information in rows 1-3 of the Template Data Sheet. | C8: قم بتصميم القالب الخاص بك، مع التأكد من أن فترة الوقت مرتبطة بشكل صحيح مع معلومات التاريخ في الصفوف 1-3 في ورقة Template Data.
A10: Step 3: Relational Sheet | C10: الخطوة 3: Relational Sheet
A12: Unpivot the data in the source table into a flat format. Follow these guidelines: | C12: قم بتحويل البيانات في جدول المصدر إلى تنسيق مسطح. اتبع هذه الإرشادات:
A13: 1. Blue Columns: Do not change the names of the blue columns. Update the data as per the current template. | C13: 1. الأعمدة الزرقاء: لا تقم بتغيير أسماء الأعمدة الزرقاء. قم بتحديث البيانات وفقًا للقالب الحالي.
A14: 2. Code Lists: Use the naming convention CL_XXX_EN_V# for code lists, where XXX is the name, and V# is the version, conforming with the definitions in the data dictionary. | C14: 2. قوائم الرموز: استخدم قاعدة التسمية CL_XXX_EN_V# لقوائم الرموز، حيث أن XXX هو الاسم و V# هو الإصدار، وفقًا للتعريفات في قاموس البيانات.
A15: 3. Code List Values: Ensure the code list values match the definitions in the data dictionary. | C15: 3. قيم قائمة الرموز: تأكد من أن قيم قائمة الرموز تتوافق مع التعريفات في قاموس البيانات.
A16: 4. Time_Period_M: Leave empty if the data frequency is yearly. | C16: 4. Time_Period_M: اتركها فارغة إذا كانت دورية البيانات سنوية.
A17: 5. Time_Period_M Format: Use one of these formats: | C17: 5. تنسيق Time_Period_M: استخدم أحد التنسيقات التالية:
A18: Numeric: (1, 2, 3, ..., 12) for months. | C18: رقمي: (1، 2، 3، ...، 12) للأشهر.
... A38: Protect the entire workbook to prevent unauthorized or accidental changes to the structure of the file. | C38: قم بحماية الكتاب بأكمله لمنع التغييرات غير المصرح بها أو غير المقصودة على هيكل الملف.
