Workbook

Sheet Cover Page
A1: Code | B1: SYB_17_4
A2: Version | B2: V1
A3: اسم القالب | B3: الجرائم العامة حسب نوع الجريمة
A4: Template Name | B4: General Crimes by Kind of Crime
A5: دورية البيانات | B5: سنوي
A6: Data Frequency | B6: Annual
A7: الجهة المصدرية | B7: مديرية الأمن العام
A8: Data Source | B8: Public Security Directorate

Sheet Source Table
A2: ='Cover Page'!B4 -> General Crimes by Kind of Crime
A3: ='Cover Page'!B3 -> الجرائم العامة حسب نوع الجريمة
A4: Year | C4: =YEAR('Template Data'!B1) -> 2024 | D4: السنة
A5: Kind of Crime | D5: نوع الجريمة
A6: Felony Crimes | B6: Attempted Murder | D6: الشروع بالقتل | E6: الجرائم الجنائية
B7: premeditated Murder | D7: القتل العمد
B8: Murder | D8: القتل القصد
B9: Beating Leading to Death | D9: الضرب المفضي إلى الموت
B10: Criminal Theft | D10: السرقة الجنائية
B11: Kidnapping | D11: الخطف
B12: Sexual Abuse | D12: هـتك العرض
B13: Forgery | D13: التزوير الجنائي
B14: Currency Counterfeit | D14: تزييف النقد
B15: Aggravated Assault | D15: الإيذاء البليغ
B16: Bribery | D16: الرشوة
B17: Criminal Conspiracy | D17: الإتفاق الجنائي
B18: Abortion | D18: الإجهاض
B19: Embezzlement | D19: الاختلاس
A20: Misdemeanor Crimes | B20: Manslaughter | D20: القتل من غير قصد(القتل الخطأ) | E20: الجرائم الجنحوية
B21: Misdemeanor Theft | D21: السرقة الجنحوية
B22: Fraud | D22: الاحتيال
B23: Attempted Theft | D23: الشروع بالسرقة
B24: Resisting & Assaulting Public Employees | D24: المقاومةو الاعتداء على الموظفين
B25: Car Theft /Auto Theft | D25: سرقة السيارات
B26: Jobbery | D26: استثمار الوظيفة
B27: Prostitution | D27: جرائم البغاء
B28: Adultery | D28: الزنا
B29: Violating The Law of Archaeology | D29: مخالفة قانون الآثار
B30: Firing Gunshots | D30: إطلاق العيارات النارية
B31: Gambling | D31: المقامرة

Sheet Relational DB
A1: Relational Sheet
A2: Measure_Name_Ar | B2: Measure_Name_En | C2: Measure_ID | D2: Unit_EN | E2: Unit_AR | F2: CL_KIND_OF_GENERAL_CRIME_EN_V1 | G2: CL_KIND_OF_GENERAL_CRIME_AR_V1 | H2: CL_CRIME_DETAILS_EN_V1 | I2: CL_CRIME_DETAILS_AR_V1 | J2: Obs_Value | K2: Time_Period_Y | L2: Time_Period_M
A3: اسم المؤشر | B3: Measure Name | C3: رمز المؤشر | D3: Unit | E3: الوحدة | F3: Kind of General Crime | G3: نوع الجريمة العامة | H3: Crime details | I3: تفاصيل الجريمة | J3: قيمة المؤشر | K3: سنة فترة القياس | L3: شهر فترة القياس
A4: الجرائم العامة | B4: General Crimes | C4: M1 | D4: Number | E4: عدد | F4: ='Source Table'!$A$6 -> Felony Crimes | G4: ='Source Table'!$E$6 -> الجرائم الجنائية | H4: ='Source Table'!$B$6 -> Attempted Murder | I4: ='Source Table'!$D$6 -> الشروع بالقتل | J4: 314 | K4: 2023
A5: الجرائم العامة | B5: General Crimes | C5: M1 | D5: Number | E5: عدد | F5: ='Source Table'!$A$6 -> Felony Crimes | G5: ='Source Table'!$E$6 -> الجرائم الجنائية | H5: ='Source Table'!$B$7 -> premeditated Murder | I5: ='Source Table'!$D$7 -> القتل العمد | J5: 56 | K5: 2023
A6: الجرائم العامة | B6: General Crimes | C6: M1 | D6: Number | E6: عدد | F6: ='Source Table'!$A$6 -> Felony Crimes | G6: ='Source Table'!$E$6 -> الجرائم الجنائية | H6: ='Source Table'!$B$8 -> Murder | I6: ='Source Table'!$D$8 -> القتل القصد | J6: 47 | K6: 2023
A7: الجرائم العامة | B7: General Crimes | C7: M1 | D7: Number | E7: عدد | F7: ='Source Table'!$A$6 -> Felony Crimes | G7: ='Source Table'!$E$6 -> الجرائم الجنائية | H7: ='Source Table'!$B$9 -> Beating Leading to Death | I7: ='Source Table'!$D$9 -> الضرب المفضي إلى الموت | J7: 2 | K7: 2023
A8: الجرائم العامة | B8: General Crimes | C8: M1 | D8: Number | E8: عدد | F8: ='Source Table'!$A$6 -> Felony Crimes | G8: ='Source Table'!$E$6 -> الجرائم الجنائية | H8: ='Source Table'!$B$10 -> Criminal Theft | I8: ='Source Table'!$D$10 -> السرقة الجنائية | J8: 2848 | K8: 2023
A9: الجرائم العامة | B9: General Crimes | C9: M1 | D9: Number | E9: عدد | F9: ='Source Table'!$A$6 -> Felony Crimes | G9: ='Source Table'!$E$6 -> الجرائم الجنائية | H9: ='Source Table'!$B$11 -> Kidnapping | I9: ='Source Table'!$D$11 -> الخطف | J9: 151 | K9: 2023
A10: الجرائم العامة | B10: General Crimes | C10: M1 | D10: Number | E10: عدد | F10: ='Source Table'!$A$6 -> Felony Crimes | G10: ='Source Table'!$E$6 -> الجرائم الجنائية | H10: ='Source Table'!$B$12 -> Sexual Abuse | I10: ='Source Table'!$D$12 -> هـتك العرض | J10: 931 | K10: 2023
A11: الجرائم العامة | B11: General Crimes | C11: M1 | D11: Number | E11: عدد | F11: ='Source Table'!$A$6 -> Felony Crimes | G11: ='Source Table'!$E$6 -> الجرائم الجنائية | H11: ='Source Table'!$B$13 -> Forgery | I11: ='Source Table'!$D$13 -> التزوير الجنائي | J11: 158 | K11: 2023
A12: الجرائم العامة | B12: General Crimes | C12: M1 | D12: Number | E12: عدد | F12: ='Source Table'!$A$6 -> Felony Crimes | G12: ='Source Table'!$E$6 -> الجرائم الجنائية | H12: ='Source Table'!$B$14 -> Currency Counterfeit | I12: ='Source Table'!$D$14 -> تزييف النقد | J12: 177 | K12: 2023
A13: الجرائم العامة | B13: General Crimes | C13: M1 | D13: Number | E13: عدد | F13: ='Source Table'!$A$6 -> Felony Crimes | G13: ='Source Table'!$E$6 -> الجرائم الجنائية | H13: ='Source Table'!$B$15 -> Aggravated Assault | I13: ='Source Table'!$D$15 -> الإيذاء البليغ | J13: 772 | K13: 2023
A14: الجرائم العامة | B14: General Crimes | C14: M1 | D14: Number | E14: عدد | F14: ='Source Table'!$A$6 -> Felony Crimes | G14: ='Source Table'!$E$6 -> الجرائم الجنائية | H14: ='Source Table'!$B$16 -> Bribery | I14: ='Source Table'!$D$16 -> الرشوة | J14: 90 | K14: 2023
A15: الجرائم العامة | B15: General Crimes | C15: M1 | D15: Number | E15: عدد | F15: ='Source Table'!$A$6 -> Felony Crimes | G15: ='Source Table'!$E$6 -> الجرائم الجنائية | H15: ='Source Table'!$B$17 -> Criminal Conspiracy | I15: ='Source Table'!$D$17 -> الإتفاق الجنائي | J15: 7 | K15: 2023
A16: الجرائم العامة | B16: General Crimes | C16: M1 | D16: Number | E16: عدد | F16: ='Source Table'!$A$6 -> Felony Crimes | G16: ='Source Table'!$E$6 -> الجرائم الجنائية | H16: ='Source Table'!$B$18 -> Abortion | I16: ='Source Table'!$D$18 -> الإجهاض | J16: 22 | K16: 2023
A17: الجرائم العامة | B17: General Crimes | C17: M1 | D17: Number | E17: عدد | F17: ='Source Table'!$A$6 -> Felony Crimes | G17: ='Source Table'!$E$6 -> الجرائم الجنائية | H17: ='Source Table'!$B$19 -> Embezzlement | I17: ='Source Table'!$D$19 -> الاختلاس | J17: 4 | K17: 2023
A18: الجرائم العامة | B18: General Crimes | C18: M1 | D18: Number | E18: عدد | F18: ='Source Table'!$A$20 -> Misdemeanor Crimes | G18: ='Source Table'!$E$20 -> الجرائم الجنحوية | H18: ='Source Table'!$B$20 -> Manslaughter | I18: ='Source Table'!$D$20 -> القتل من غير قصد(القتل الخطأ) | J18: 46 | K18: 2023
A19: الجرائم العامة | B19: General Crimes | C19: M1 | D19: Number | E19: عدد | F19: ='Source Table'!$A$20 -> Misdemeanor Crimes | G19: ='Source Table'!$E$20 -> الجرائم الجنحوية | H19: ='Source Table'!$B$21 -> Misdemeanor Theft | I19: ='Source Table'!$D$21 -> السرقة الجنحوية | J19: 7873 | K19: 2023
A20: الجرائم العامة | B20: General Crimes | C20: M1 | D20: Number | E20: عدد | F20: ='Source Table'!$A$20 -> Misdemeanor Crimes | G20: ='Source Table'!$E$20 -> الجرائم الجنحوية | H20: ='Source Table'!$B$22 -> Fraud | I20: ='Source Table'!$D$22 -> الاحتيال | J20: 3828 | K20: 2023
A21: الجرائم العامة | B21: General Crimes | C21: M1 | D21: Number | E21: عدد | F21: ='Source Table'!$A$20 -> Misdemeanor Crimes | G21: ='Source Table'!$E$20 -> الجرائم الجنحوية | H21: ='Source Table'!$B$23 -> Attempted Theft | I21: ='Source Table'!$D$23 -> الشروع بالسرقة | J21: 360 | K21: 2023
A22: الجرائم العامة | B22: General Crimes | C22: M1 | D22: Number | E22: عدد | F22: ='Source Table'!$A$20 -> Misdemeanor Crimes | G22: ='Source Table'!$E$20 -> الجرائم الجنحوية | H22: ='Source Table'!$B$24 -> Resisting & Assaulting Public Employees | I22: ='Source Table'!$D$24 -> المقاومةو الاعتداء على الموظفين | J22: 2529 | K22: 2023
A23: الجرائم العامة | B23: General Crimes | C23: M1 | D23: Number | E23: عدد | F23: ='Source Table'!$A$20 -> Misdemeanor Crimes | G23: ='Source Table'!$E$20 -> الجرائم الجنحوية | H23: ='Source Table'!$B$25 -> Car Theft /Auto Theft | I23: ='Source Table'!$D$25 -> سرقة السيارات | J23: 367 | K23: 2023
A24: الجرائم العامة | B24: General Crimes | C24: M1 | D24: Number | E24: عدد | F24: ='Source Table'!$A$20 -> Misdemeanor Crimes | G24: ='Source Table'!$E$20 -> الجرائم الجنحوية | H24: ='Source Table'!$B$26 -> Jobbery | I24: ='Source Table'!$D$26 -> استثمار الوظيفة | J24: 4 | K24: 2023
A25: الجرائم العامة | B25: General Crimes | C25: M1 | D25: Number | E25: عدد | F25: ='Source Table'!$A$20 -> Misdemeanor Crimes | G25: ='Source Table'!$E$20 -> الجرائم الجنحوية | H25: ='Source Table'!$B$27 -> Prostitution | I25: ='Source Table'!$D$27 -> جرائم البغاء | J25: 64 | K25: 2023
A26: الجرائم العامة | B26: General Crimes | C26: M1 | D26: Number | E26: عدد | F26: ='Source Table'!$A$20 -> Misdemeanor Crimes | G26: ='Source Table'!$E$20 -> الجرائم الجنحوية | H26: ='Source Table'!$B$28 -> Adultery | I26: ='Source Table'!$D$28 -> الزنا | J26: 144 | K26: 2023
A27: الجرائم العامة | B27: General Crimes | C27: M1 | D27: Number | E27: عدد | F27: ='Source Table'!$A$20 -> Misdemeanor Crimes | G27: ='Source Table'!$E$20 -> الجرائم الجنحوية | H27: ='Source Table'!$B$29 -> Violating The Law of Archaeology | I27: ='Source Table'!$D$29 -> مخالفة قانون الآثار | J27: 268 | K27: 2023
A28: الجرائم العامة | B28: General Crimes | C28: M1 | D28: Number | E28: عدد | F28: ='Source Table'!$A$20 -> Misdemeanor Crimes | G28: ='Source Table'!$E$20 -> الجرائم الجنحوية | H28: ='Source Table'!$B$30 -> Firing Gunshots | I28: ='Source Table'!$D$30 -> إطلاق العيارات النارية | J28: 1716 | K28: 2023
A29: الجرائم العامة | B29: General Crimes | C29: M1 | D29: Number | E29: عدد | F29: ='Source Table'!$A$20 -> Misdemeanor Crimes | G29: ='Source Table'!$E$20 -> الجرائم الجنحوية | H29: ='Source Table'!$B$31 -> Gambling | I29: ='Source Table'!$D$31 -> المقامرة | J29: 6 | K29: 2023
A30: الجرائم العامة | B30: General Crimes | C30: M1 | D30: Number | E30: عدد | F30: ='Source Table'!$A$6 -> Felony Crimes | G30: ='Source Table'!$E$6 -> الجرائم الجنائية | H30: ='Source Table'!$B$6 -> Attempted Murder | I30: ='Source Table'!$D$6 -> الشروع بالقتل | J30: 364 | K30: 2022
A31: الجرائم العامة | B31: General Crimes | C31: M1 | D31: Number | E31: عدد | F31: ='Source Table'!$A$6 -> Felony Crimes | G31: ='Source Table'!$E$6 -> الجرائم الجنائية | H31: ='Source Table'!$B$7 -> premeditated Murder | I31: ='Source Table'!$D$7 -> القتل العمد | J31: 49 | K31: 2022
A32: الجرائم العامة | B32: General Crimes | C32: M1 | D32: Number | E32: عدد | F32: ='Source Table'!$A$6 -> Felony Crimes | G32: ='Source Table'!$E$6 -> الجرائم الجنائية | H32: ='Source Table'!$B$8 -> Murder | I32: ='Source Table'!$D$8 -> القتل القصد | J32: 57 | K32: 2022
A33: الجرائم العامة | B33: General Crimes | C33: M1 | D33: Number | E33: عدد | F33: ='Source Table'!$A$6 -> Felony Crimes | G33: ='Source Table'!$E$6 -> الجرائم الجنائية | H33: ='Source Table'!$B$9 -> Beating Leading to Death | I33: ='Source Table'!$D$9 -> الضرب المفضي إلى الموت | J33: 2 | K33: 2022
A34: الجرائم العامة | B34: General Crimes | C34: M1 | D34: Number | E34: عدد | F34: ='Source Table'!$A$6 -> Felony Crimes | G34: ='Source Table'!$E$6 -> الجرائم الجنائية | H34: ='Source Table'!$B$10 -> Criminal Theft | I34: ='Source Table'!$D$10 -> السرقة الجنائية | J34: 2826 | K34: 2022
A35: الجرائم العامة | B35: General Crimes | C35: M1 | D35: Number | E35: عدد | F35: ='Source Table'!$A$6 -> Felony Crimes | G35: ='Source Table'!$E$6 -> الجرائم الجنائية | H35: ='Source Table'!$B$11 -> Kidnapping | I35: ='Source Table'!$D$11 -> الخطف | J35: 214 | K35: 2022
A36: الجرائم العامة | B36: General Crimes | C36: M1 | D36: Number | E36: عدد | F36: ='Source Table'!$A$6 -> Felony Crimes | G36: ='Source Table'!$E$6 -> الجرائم الجنائية | H36: ='Source Table'!$B$12 -> Sexual Abuse | I36: ='Source Table'!$D$12 -> هـتك العرض | J36: 991 | K36: 2022
A37: الجرائم العامة | B37: General Crimes | C37: M1 | D37: Number | E37: عدد | F37: ='Source Table'!$A$6 -> Felony Crimes | G37: ='Source Table'!$E$6 -> الجرائم الجنائية | H37: ='Source Table'!$B$13 -> Forgery | I37: ='Source Table'!$D$13 -> التزوير الجنائي | J37: 116 | K37: 2022
A38: الجرائم العامة | B38: General Crimes | C38: M1 | D38: Number | E38: عدد | F38: ='Source Table'!$A$6 -> Felony Crimes | G38: ='Source Table'!$E$6 -> الجرائم الجنائية | H38: ='Source Table'!$B$14 -> Currency Counterfeit | I38: ='Source Table'!$D$14 -> تزييف النقد | J38: 101 | K38: 2022
A39: الجرائم العامة | B39: General Crimes | C39: M1 | D39: Number | E39: عدد | F39: ='Source Table'!$A$6 -> Felony Crimes | G39: ='Source Table'!$E$6 -> الجرائم الجنائية | H39: ='Source Table'!$B$15 -> Aggravated Assault | I39: ='Source Table'!$D$15 -> الإيذاء البليغ | J39: 741 | K39: 2022
A40: الجرائم العامة | B40: General Crimes | C40: M1 | D40: Number | E40: عدد | F40: ='Source Table'!$A$6 -> Felony Crimes | G40: ='Source Table'!$E$6 -> الجرائم الجنائية | H40: ='Source Table'!$B$16 -> Bribery | I40: ='Source Table'!$D$16 -> الرشوة | J40: 104 | K40: 2022
...

Sheet Template Data
A1: Date | B1: =DATE(B2,B3,1) -> 45292
A2: Year | B2: 2024
A3: Month | B3: 1
A4: Measure_Name_Ar | B4: Measure_Name_En | C4: Measure_ID | D4: Unit_EN | E4: Unit_AR | F4: CL_KIND_OF_GENERAL_CRIME_EN_V1 | G4: CL_KIND_OF_GENERAL_CRIME_AR_V1 | H4: CL_CRIME_DETAILS_EN_V1 | I4: CL_CRIME_DETAILS_AR_V1 | J4: Obs_Value | K4: Time_Period_Y | L4: Time_Period_M
A5: اسم المؤشر | B5: Measure Name | C5: رمز المؤشر | D5: Unit | E5: الوحدة | F5: Kind of General Crime | G5: نوع الجريمة العامة | H5: Crime details | I5: تفاصيل الجريمة | J5: قيمة المؤشر | K5: سنة فترة القياس | L5: شهر فترة القياس

Sheet Help
A2: Step 1: Cover Page | C2: الخطوة 1: Cover Page
A4: Update the template information, to ensure that any meta-information about the template, such as the title, version, and description, is accurate and up-to-date. | C4: قم بتحديث معلومات القالب للتأكد من أن أي معلومات وصفية حول القالب، مثل العنوان والإصدار والوصف، دقيقة ومحدثة.
A6: Step 2: Source Table | C6: الخطوة 2: Source Table
A8: Design your template, ensuring that the time period is mapped correctly to the date information in rows 1-3 of the Template Data Sheet. | C8: قم بتصميم القالب الخاص بك، مع التأكد من أن فترة الوقت مرتبطة بشكل صحيح مع معلومات التاريخ في الصفوف 1-3 في ورقة Template Data.
A10: Step 3: Relational Sheet | C10: الخطوة 3: Relational Sheet
A12: Unpivot the data in the source table into a flat format. Follow these guidelines: | C12: قم بتحويل البيانات في جدول المصدر إلى تنسيق مسطح. اتبع هذه الإرشادات:
A13: 1. Blue Columns: Do not change the names of the blue columns. Update the data as per the current template. | C13: 1. الأعمدة الزرقاء: لا تقم بتغيير أسماء الأعمدة الزرقاء. قم بتحديث البيانات وفقًا للقالب الحالي.
A14: 2. Code Lists: Use the naming convention CL_XXX_EN_V# for code lists, where XXX is the name, and V# is the version, conforming with the definitions in the data dictionary. | C14: 2. قوائم الرموز: استخدم قاعدة التسمية CL_XXX_EN_V# لقوائم الرموز، حيث أن XXX هو الاسم و V# هو الإصدار، وفقًا للتعريفات في قاموس البيانات.
A15: 3. Code List Values: Ensure the code list values match the definitions in the data dictionary. | C15: 3. قيم قائمة الرموز: تأكد من أن قيم قائمة الرموز تتوافق مع التعريفات في قاموس البيانات.
A16: 4. Time_Period_M: Leave empty if the data frequency is yearly. | C16: 4. Time_Period_M: اتركها فارغة إذا كانت دورية البيانات سنوية.
A17: 5. Time_Period_M Format: Use one of these formats: | C17: 5. تنسيق Time_Period_M: استخدم أحد التنسيقات التالية:
A18: Numeric: (1, 2, 3, ..., 12) for months. | C18: رقمي: (1، 2، 3، ...، 12) للأشهر.
... A38: Protect the entire workbook to prevent unauthorized or accidental changes to the structure of the file. | C38: قم بحماية الكتاب بأكمله لمنع التغييرات غير المصرح بها أو غير المقصودة على هيكل الملف.
