Workbook

Sheet Cover Page
A1: Code | B1: SYB_17_11
A2: Version | B2: V1
A3: اسم القالب | B3: إحصاءات الدفاع المدني حسب الشهر
A4: Template Name | B4: Civil Defense Statistics by Month
A5: دورية البيانات | B5: سنوي
A6: Data Frequency | B6: Annual
A7: الجهة المصدرية | B7: مديرية الأمن العام
A8: Data Source | B8: Public Security Directorate

Sheet Source Table
B2: ='Cover Page'!B4 -> Civil Defense Statistics by Month
B3: ='Cover Page'!B3 -> إحصاءات الدفاع المدني حسب الشهر
B4: Year | F4: =YEAR('Template Data'!B1) -> 2024 | L4: السنة
B5: Month | C5: الإنقاذ | F5: الإسعاف | I5: الإطفاء | L5: الشهر
C6: Rescue | F6: First Aid | I6: Fire Fighting
C7: الوفيات | D7: الإصابات | E7: العدد | F7: الوفيات | G7: الإصابات | H7: العدد | I7: الوفيات | J7: الإصابات | K7: العدد
C8: Deaths | D8: Injuries | E8: Number | F8: Deaths | G8: Injuries | H8: Number | I8: Deaths | J8: Injuries | K8: Number
B9: January | L9: كانون الثاني
B10: February | L10: شباط
B11: March | L11: آذار
B12: April | L12: نيسان
B13: May | L13: أيار
B14: June | L14: حزيران
B15: July | L15: تموز
B16: August | L16: آب
B17: September | L17: أيلول
B18: October | L18: تشرين الأول
B19: November | L19: تشرين الثاني
B20: December | L20: كانون الأول

Sheet Relational DB
A1: Relational Sheet
A2: Measure_Name_Ar | B2: Measure_Name_En | C2: Measure_ID | D2: Unit_EN | E2: Unit_AR | F2: CL_CIVIL_DEFENSE_ACTIVITIES_EN_V1 | G2: CL_CIVIL_DEFENSE_ACTIVITIES_AR_V1 | H2: CL_CIVIL_DEFENSE_STATISTICS_EN_V1 | I2: CL_CIVIL_DEFENSE_STATISTICS_AR_V1 | J2: CL_MONTH_EN_V1 | K2: CL_MONTH_AR_V1 | L2: Obs_Value | M2: Time_Period_Y | N2: Time_Period_M
A3: اسم المؤشر | B3: Measure Name | C3: رمز المؤشر | D3: Unit | E3: الوحدة | F3: Civil Defense Activities | G3: أنشطة ا لدفاع المدني | H3: Civil Defense Statistics | I3: إحصاءات الدفاع المدني | J3: Police Directorate | K3: مديرية الشرطة | L3: قيمة المؤشر | M3: سنة فترة القياس | N3: شهر فترة القياس
A4: إحصاءات الدفاع المدني | B4: Civil Defense Statistics | C4: M1 | D4: Number | E4: عدد | F4: ='Source Table'!$I$6 -> Fire Fighting | G4: ='Source Table'!$I$5 -> الإطفاء | H4: ='Source Table'!$K$8 -> Number | I4: ='Source Table'!$K$7 -> العدد | J4: ='Source Table'!$B$9 -> January | K4: ='Source Table'!$L$9 -> كانون الثاني | L4: 1739 | M4: 2023
A5: إحصاءات الدفاع المدني | B5: Civil Defense Statistics | C5: M1 | D5: Number | E5: عدد | F5: ='Source Table'!$I$6 -> Fire Fighting | G5: ='Source Table'!$I$5 -> الإطفاء | H5: ='Source Table'!$K$8 -> Number | I5: ='Source Table'!$K$7 -> العدد | J5: ='Source Table'!$B$10 -> February | K5: ='Source Table'!$L$10 -> شباط | L5: 1441 | M5: 2023
A6: إحصاءات الدفاع المدني | B6: Civil Defense Statistics | C6: M1 | D6: Number | E6: عدد | F6: ='Source Table'!$I$6 -> Fire Fighting | G6: ='Source Table'!$I$5 -> الإطفاء | H6: ='Source Table'!$K$8 -> Number | I6: ='Source Table'!$K$7 -> العدد | J6: ='Source Table'!$B$11 -> March | K6: ='Source Table'!$L$11 -> آذار | L6: 1687 | M6: 2023
A7: إحصاءات الدفاع المدني | B7: Civil Defense Statistics | C7: M1 | D7: Number | E7: عدد | F7: ='Source Table'!$I$6 -> Fire Fighting | G7: ='Source Table'!$I$5 -> الإطفاء | H7: ='Source Table'!$K$8 -> Number | I7: ='Source Table'!$K$7 -> العدد | J7: ='Source Table'!$B$12 -> April | K7: ='Source Table'!$L$12 -> نيسان | L7: 1600 | M7: 2023
A8: إحصاءات الدفاع المدني | B8: Civil Defense Statistics | C8: M1 | D8: Number | E8: عدد | F8: ='Source Table'!$I$6 -> Fire Fighting | G8: ='Source Table'!$I$5 -> الإطفاء | H8: ='Source Table'!$K$8 -> Number | I8: ='Source Table'!$K$7 -> العدد | J8: ='Source Table'!$B$13 -> May | K8: ='Source Table'!$L$13 -> أيار | L8: 3767 | M8: 2023
A9: إحصاءات الدفاع المدني | B9: Civil Defense Statistics | C9: M1 | D9: Number | E9: عدد | F9: ='Source Table'!$I$6 -> Fire Fighting | G9: ='Source Table'!$I$5 -> الإطفاء | H9: ='Source Table'!$K$8 -> Number | I9: ='Source Table'!$K$7 -> العدد | J9: ='Source Table'!$B$14 -> June | K9: ='Source Table'!$L$14 -> حزيران | L9: 5285 | M9: 2023
A10: إحصاءات الدفاع المدني | B10: Civil Defense Statistics | C10: M1 | D10: Number | E10: عدد | F10: ='Source Table'!$I$6 -> Fire Fighting | G10: ='Source Table'!$I$5 -> الإطفاء | H10: ='Source Table'!$K$8 -> Number | I10: ='Source Table'!$K$7 -> العدد | J10: ='Source Table'!$B$15 -> July | K10: ='Source Table'!$L$15 -> تموز | L10: 4979 | M10: 2023
A11: إحصاءات الدفاع المدني | B11: Civil Defense Statistics | C11: M1 | D11: Number | E11: عدد | F11: ='Source Table'!$I$6 -> Fire Fighting | G11: ='Source Table'!$I$5 -> الإطفاء | H11: ='Source Table'!$K$8 -> Number | I11: ='Source Table'!$K$7 -> العدد | J11: ='Source Table'!$B$16 -> August | K11: ='Source Table'!$L$16 -> آب | L11: 3650 | M11: 2023
A12: إحصاءات الدفاع المدني | B12: Civil Defense Statistics | C12: M1 | D12: Number | E12: عدد | F12: ='Source Table'!$I$6 -> Fire Fighting | G12: ='Source Table'!$I$5 -> الإطفاء | H12: ='Source Table'!$K$8 -> Number | I12: ='Source Table'!$K$7 -> العدد | J12: ='Source Table'!$B$17 -> September | K12: ='Source Table'!$L$17 -> أيلول | L12: 3217 | M12: 2023
A13: إحصاءات الدفاع المدني | B13: Civil Defense Statistics | C13: M1 | D13: Number | E13: عدد | F13: ='Source Table'!$I$6 -> Fire Fighting | G13: ='Source Table'!$I$5 -> الإطفاء | H13: ='Source Table'!$K$8 -> Number | I13: ='Source Table'!$K$7 -> العدد | J13: ='Source Table'!$B$18 -> October | K13: ='Source Table'!$L$18 -> تشرين الأول | L13: 2757 | M13: 2023
A14: إحصاءات الدفاع المدني | B14: Civil Defense Statistics | C14: M1 | D14: Number | E14: عدد | F14: ='Source Table'!$I$6 -> Fire Fighting | G14: ='Source Table'!$I$5 -> الإطفاء | H14: ='Source Table'!$K$8 -> Number | I14: ='Source Table'!$K$7 -> العدد | J14: ='Source Table'!$B$19 -> November | K14: ='Source Table'!$L$19 -> تشرين الثاني | L14: 2118 | M14: 2023
A15: إحصاءات الدفاع المدني | B15: Civil Defense Statistics | C15: M1 | D15: Number | E15: عدد | F15: ='Source Table'!$I$6 -> Fire Fighting | G15: ='Source Table'!$I$5 -> الإطفاء | H15: ='Source Table'!$K$8 -> Number | I15: ='Source Table'!$K$7 -> العدد | J15: ='Source Table'!$B$20 -> December | K15: ='Source Table'!$L$20 -> كانون الأول | L15: 1700 | M15: 2023
A16: إحصاءات الدفاع المدني | B16: Civil Defense Statistics | C16: M1 | D16: Number | E16: عدد | F16: ='Source Table'!$I$6 -> Fire Fighting | G16: ='Source Table'!$I$5 -> الإطفاء | H16: ='Source Table'!$J$8 -> Injuries | I16: ='Source Table'!$J$7 -> الإصابات | J16: ='Source Table'!$B$9 -> January | K16: ='Source Table'!$L$9 -> كانون الثاني | L16: 176 | M16: 2023
A17: إحصاءات الدفاع المدني | B17: Civil Defense Statistics | C17: M1 | D17: Number | E17: عدد | F17: ='Source Table'!$I$6 -> Fire Fighting | G17: ='Source Table'!$I$5 -> الإطفاء | H17: ='Source Table'!$J$8 -> Injuries | I17: ='Source Table'!$J$7 -> الإصابات | J17: ='Source Table'!$B$10 -> February | K17: ='Source Table'!$L$10 -> شباط | L17: 125 | M17: 2023
A18: إحصاءات الدفاع المدني | B18: Civil Defense Statistics | C18: M1 | D18: Number | E18: عدد | F18: ='Source Table'!$I$6 -> Fire Fighting | G18: ='Source Table'!$I$5 -> الإطفاء | H18: ='Source Table'!$J$8 -> Injuries | I18: ='Source Table'!$J$7 -> الإصابات | J18: ='Source Table'!$B$11 -> March | K18: ='Source Table'!$L$11 -> آذار | L18: 155 | M18: 2023
A19: إحصاءات الدفاع المدني | B19: Civil Defense Statistics | C19: M1 | D19: Number | E19: عدد | F19: ='Source Table'!$I$6 -> Fire Fighting | G19: ='Source Table'!$I$5 -> الإطفاء | H19: ='Source Table'!$J$8 -> Injuries | I19: ='Source Table'!$J$7 -> الإصابات | J19: ='Source Table'!$B$12 -> April | K19: ='Source Table'!$L$12 -> نيسان | L19: 142 | M19: 2023
A20: إحصاءات الدفاع المدني | B20: Civil Defense Statistics | C20: M1 | D20: Number | E20: عدد | F20: ='Source Table'!$I$6 -> Fire Fighting | G20: ='Source Table'!$I$5 -> الإطفاء | H20: ='Source Table'!$J$8 -> Injuries | I20: ='Source Table'!$J$7 -> الإصابات | J20: ='Source Table'!$B$13 -> May | K20: ='Source Table'!$L$13 -> أيار | L20: 148 | M20: 2023
A21: إحصاءات الدفاع المدني | B21: Civil Defense Statistics | C21: M1 | D21: Number | E21: عدد | F21: ='Source Table'!$I$6 -> Fire Fighting | G21: ='Source Table'!$I$5 -> الإطفاء | H21: ='Source Table'!$J$8 -> Injuries | I21: ='Source Table'!$J$7 -> الإصابات | J21: ='Source Table'!$B$14 -> June | K21: ='Source Table'!$L$14 -> حزيران | L21: 124 | M21: 2023
A22: إحصاءات الدفاع المدني | B22: Civil Defense Statistics | C22: M1 | D22: Number | E22: عدد | F22: ='Source Table'!$I$6 -> Fire Fighting | G22: ='Source Table'!$I$5 -> الإطفاء | H22: ='Source Table'!$J$8 -> Injuries | I22: ='Source Table'!$J$7 -> الإصابات | J22: ='Source Table'!$B$15 -> July | K22: ='Source Table'!$L$15 -> تموز | L22: 167 | M22: 2023
A23: إحصاءات الدفاع المدني | B23: Civil Defense Statistics | C23: M1 | D23: Number | E23: عدد | F23: ='Source Table'!$I$6 -> Fire Fighting | G23: ='Source Table'!$I$5 -> الإطفاء | H23: ='Source Table'!$J$8 -> Injuries | I23: ='Source Table'!$J$7 -> الإصابات | J23: ='Source Table'!$B$16 -> August | K23: ='Source Table'!$L$16 -> آب | L23: 178 | M23: 2023
A24: إحصاءات الدفاع المدني | B24: Civil Defense Statistics | C24: M1 | D24: Number | E24: عدد | F24: ='Source Table'!$I$6 -> Fire Fighting | G24: ='Source Table'!$I$5 -> الإطفاء | H24: ='Source Table'!$J$8 -> Injuries | I24: ='Source Table'!$J$7 -> الإصابات | J24: ='Source Table'!$B$17 -> September | K24: ='Source Table'!$L$17 -> أيلول | L24: 80 | M24: 2023
A25: إحصاءات الدفاع المدني | B25: Civil Defense Statistics | C25: M1 | D25: Number | E25: عدد | F25: ='Source Table'!$I$6 -> Fire Fighting | G25: ='Source Table'!$I$5 -> الإطفاء | H25: ='Source Table'!$J$8 -> Injuries | I25: ='Source Table'!$J$7 -> الإصابات | J25: ='Source Table'!$B$18 -> October | K25: ='Source Table'!$L$18 -> تشرين الأول | L25: 121 | M25: 2023
A26: إحصاءات الدفاع المدني | B26: Civil Defense Statistics | C26: M1 | D26: Number | E26: عدد | F26: ='Source Table'!$I$6 -> Fire Fighting | G26: ='Source Table'!$I$5 -> الإطفاء | H26: ='Source Table'!$J$8 -> Injuries | I26: ='Source Table'!$J$7 -> الإصابات | J26: ='Source Table'!$B$19 -> November | K26: ='Source Table'!$L$19 -> تشرين الثاني | L26: 127 | M26: 2023
A27: إحصاءات الدفاع المدني | B27: Civil Defense Statistics | C27: M1 | D27: Number | E27: عدد | F27: ='Source Table'!$I$6 -> Fire Fighting | G27: ='Source Table'!$I$5 -> الإطفاء | H27: ='Source Table'!$J$8 -> Injuries | I27: ='Source Table'!$J$7 -> الإصابات | J27: ='Source Table'!$B$20 -> December | K27: ='Source Table'!$L$20 -> كانون الأول | L27: 177 | M27: 2023
A28: إحصاءات الدفاع المدني | B28: Civil Defense Statistics | C28: M1 | D28: Number | E28: عدد | F28: ='Source Table'!$I$6 -> Fire Fighting | G28: ='Source Table'!$I$5 -> الإطفاء | H28: ='Source Table'!$J$8 -> Injuries | I28: ='Source Table'!$J$7 -> الإصابات | J28: ='Source Table'!$B$9 -> January | K28: ='Source Table'!$L$9 -> كانون الثاني | L28: 13 | M28: 2023
A29: إحصاءات الدفاع المدني | B29: Civil Defense Statistics | C29: M1 | D29: Number | E29: عدد | F29: ='Source Table'!$I$6 -> Fire Fighting | G29: ='Source Table'!$I$5 -> الإطفاء | H29: ='Source Table'!$I$8 -> Deaths | I29: ='Source Table'!$I$7 -> الوفيات | J29: ='Source Table'!$B$10 -> February | K29: ='Source Table'!$L$10 -> شباط | L29: 5 | M29: 2023
A30: إحصاءات الدفاع المدني | B30: Civil Defense Statistics | C30: M1 | D30: Number | E30: عدد | F30: ='Source Table'!$I$6 -> Fire Fighting | G30: ='Source Table'!$I$5 -> الإطفاء | H30: ='Source Table'!$I$8 -> Deaths | I30: ='Source Table'!$I$7 -> الوفيات | J30: ='Source Table'!$B$11 -> March | K30: ='Source Table'!$L$11 -> آذار | L30: 8 | M30: 2023
A31: إحصاءات الدفاع المدني | B31: Civil Defense Statistics | C31: M1 | D31: Number | E31: عدد | F31: ='Source Table'!$I$6 -> Fire Fighting | G31: ='Source Table'!$I$5 -> الإطفاء | H31: ='Source Table'!$I$8 -> Deaths | I31: ='Source Table'!$I$7 -> الوفيات | J31: ='Source Table'!$B$12 -> April | K31: ='Source Table'!$L$12 -> نيسان | L31: 3 | M31: 2023
A32: إحصاءات الدفاع المدني | B32: Civil Defense Statistics | C32: M1 | D32: Number | E32: عدد | F32: ='Source Table'!$I$6 -> Fire Fighting | G32: ='Source Table'!$I$5 -> الإطفاء | H32: ='Source Table'!$I$8 -> Deaths | I32: ='Source Table'!$I$7 -> الوفيات | J32: ='Source Table'!$B$13 -> May | K32: ='Source Table'!$L$13 -> أيار | L32: 10 | M32: 2023
A33: إحصاءات الدفاع المدني | B33: Civil Defense Statistics | C33: M1 | D33: Number | E33: عدد | F33: ='Source Table'!$I$6 -> Fire Fighting | G33: ='Source Table'!$I$5 -> الإطفاء | H33: ='Source Table'!$I$8 -> Deaths | I33: ='Source Table'!$I$7 -> الوفيات | J33: ='Source Table'!$B$14 -> June | K33: ='Source Table'!$L$14 -> حزيران | L33: 1 | M33: 2023
A34: إحصاءات الدفاع المدني | B34: Civil Defense Statistics | C34: M1 | D34: Number | E34: عدد | F34: ='Source Table'!$I$6 -> Fire Fighting | G34: ='Source Table'!$I$5 -> الإطفاء | H34: ='Source Table'!$I$8 -> Deaths | I34: ='Source Table'!$I$7 -> الوفيات | J34: ='Source Table'!$B$15 -> July | K34: ='Source Table'!$L$15 -> تموز | L34: 3 | M34: 2023
A35: إحصاءات الدفاع المدني | B35: Civil Defense Statistics | C35: M1 | D35: Number | E35: عدد | F35: ='Source Table'!$I$6 -> Fire Fighting | G35: ='Source Table'!$I$5 -> الإطفاء | H35: ='Source Table'!$I$8 -> Deaths | I35: ='Source Table'!$I$7 -> الوفيات | J35: ='Source Table'!$B$16 -> August | K35: ='Source Table'!$L$16 -> آب | L35: 1 | M35: 2023
A36: إحصاءات الدفاع المدني | B36: Civil Defense Statistics | C36: M1 | D36: Number | E36: عدد | F36: ='Source Table'!$I$6 -> Fire Fighting | G36: ='Source Table'!$I$5 -> الإطفاء | H36: ='Source Table'!$I$8 -> Deaths | I36: ='Source Table'!$I$7 -> الوفيات | J36: ='Source Table'!$B$17 -> September | K36: ='Source Table'!$L$17 -> أيلول | L36: 0 | M36: 2023
A37: إحصاءات الدفاع المدني | B37: Civil Defense Statistics | C37: M1 | D37: Number | E37: عدد | F37: ='Source Table'!$I$6 -> Fire Fighting | G37: ='Source Table'!$I$5 -> الإطفاء | H37: ='Source Table'!$I$8 -> Deaths | I37: ='Source Table'!$I$7 -> الوفيات | J37: ='Source Table'!$B$18 -> October | K37: ='Source Table'!$L$18 -> تشرين الأول | L37: 0 | M37: 2023
A38: إحصاءات الدفاع المدني | B38: Civil Defense Statistics | C38: M1 | D38: Number | E38: عدد | F38: ='Source Table'!$I$6 -> Fire Fighting | G38: ='Source Table'!$I$5 -> الإطفاء | H38: ='Source Table'!$I$8 -> Deaths | I38: ='Source Table'!$I$7 -> الوفيات | J38: ='Source Table'!$B$19 -> November | K38: ='Source Table'!$L$19 -> تشرين الثاني | L38: 3 | M38: 2023
A39: إحصاءات الدفاع المدني | B39: Civil Defense Statistics | C39: M1 | D39: Number | E39: عدد | F39: ='Source Table'!$I$6 -> Fire Fighting | G39: ='Source Table'!$I$5 -> الإطفاء | H39: ='Source Table'!$I$8 -> Deaths | I39: ='Source Table'!$I$7 -> الوفيات | J39: ='Source Table'!$B$20 -> December | K39: ='Source Table'!$L$20 -> كانون الأول | L39: 7 | M39: 2023
A40: إحصاءات الدفاع المدني | B40: Civil Defense Statistics | C40: M1 | D40: Number | E40: عدد | F40: ='Source Table'!$F$6 -> First Aid | G40: ='Source Table'!$F$5 -> الإسعاف | H40: ='Source Table'!$K$8 -> Number | I40: ='Source Table'!$K$7 -> العدد | J40: ='Source Table'!$B$9 -> January | K40: ='Source Table'!$L$9 -> كانون الثاني | L40: 36026 | M40: 2023
...

Sheet Template Data
A1: Date | B1: =DATE(B2,B3,1) -> 45292
A2: Year | B2: 2024
A3: Month | B3: 1
A4: Measure_Name_Ar | B4: Measure_Name_En | C4: Measure_ID | D4: Unit_EN | E4: Unit_AR | F4: CL_CIVIL_DEFENSE_ACTIVITIES_EN_V1 | G4: CL_CIVIL_DEFENSE_ACTIVITIES_AR_V1 | H4: CL_CIVIL_DEFENSE_STATISTICS_EN_V1 | I4: CL_CIVIL_DEFENSE_STATISTICS_AR_V1 | J4: CL_MONTH_EN_V1 | K4: CL_MONTH_AR_V1 | L4: Obs_Value | M4: Time_Period_Y | N4: Time_Period_M
A5: اسم المؤشر | B5: Measure Name | C5: رمز المؤشر | D5: Unit | E5: الوحدة | F5: Civil Defense Activities | G5: أنشطة ا لدفاع المدني | H5: Civil Defense Statistics | I5: إحصاءات الدفاع المدني | J5: Police Directorate | K5: مديرية الشرطة | L5: قيمة المؤشر | M5: سنة فترة القياس | N5: شهر فترة القياس

Sheet Help
A2: Step 1: Cover Page | C2: الخطوة 1: Cover Page
A4: Update the template information, to ensure that any meta-information about the template, such as the title, version, and description, is accurate and up-to-date. | C4: قم بتحديث معلومات القالب للتأكد من أن أي معلومات وصفية حول القالب، مثل العنوان والإصدار والوصف، دقيقة ومحدثة.
A6: Step 2: Source Table | C6: الخطوة 2: Source Table
A8: Design your template, ensuring that the time period is mapped correctly to the date information in rows 1-3 of the Template Data Sheet. | C8: قم بتصميم القالب الخاص بك، مع التأكد من أن فترة الوقت مرتبطة بشكل صحيح مع معلومات التاريخ في الصفوف 1-3 في ورقة Template Data.
A10: Step 3: Relational Sheet | C10: الخطوة 3: Relational Sheet
A12: Unpivot the data in the source table into a flat format. Follow these guidelines: | C12: قم بتحويل البيانات في جدول المصدر إلى تنسيق مسطح. اتبع هذه الإرشادات:
A13: 1. Blue Columns: Do not change the names of the blue columns. Update the data as per the current template. | C13: 1. الأعمدة الزرقاء: لا تقم بتغيير أسماء الأعمدة الزرقاء. قم بتحديث البيانات وفقًا للقالب الحالي.
A14: 2. Code Lists: Use the naming convention CL_XXX_EN_V# for code lists, where XXX is the name, and V# is the version, conforming with the definitions in the data dictionary. | C14: 2. قوائم الرموز: استخدم قاعدة التسمية CL_XXX_EN_V# لقوائم الرموز، حيث أن XXX هو الاسم و V# هو الإصدار، وفقًا للتعريفات في قاموس البيانات.
A15: 3. Code List Values: Ensure the code list values match the definitions in the data dictionary. | C15: 3. قيم قائمة الرموز: تأكد من أن قيم قائمة الرموز تتوافق مع التعريفات في قاموس البيانات.
A16: 4. Time_Period_M: Leave empty if the data frequency is yearly. | C16: 4. Time_Period_M: اتركها فارغة إذا كانت دورية البيانات سنوية.
A17: 5. Time_Period_M Format: Use one of these formats: | C17: 5. تنسيق Time_Period_M: استخدم أحد التنسيقات التالية:
A18: Numeric: (1, 2, 3, ..., 12) for months. | C18: رقمي: (1، 2، 3، ...، 12) للأشهر.
... A38: Protect the entire workbook to prevent unauthorized or accidental changes to the structure of the file. | C38: قم بحماية الكتاب بأكمله لمنع التغييرات غير المصرح بها أو غير المقصودة على هيكل الملف.
