Workbook
Name _Toc175815732: 'Source Table'!$E$5
Name _Toc175815736: 'Source Table'!$B$5

Sheet Cover Page
A1: Code | B1: SYB_17_6
A2: Version | B2: V1
A3: اسم القالب | B3: الجرائم العامة حسب مناطق وقوعها
A4: Template Name | B4: General Crimes by Location of Occurrence
A5: دورية البيانات | B5: سنوي
A6: Data Frequency | B6: Annual
A7: الجهة المصدرية | B7: مديرية الأمن العام
A8: Data Source | B8: Public Security Directorate

Sheet Source Table
B2: ='Cover Page'!B4 -> General Crimes by Location of Occurrence
B3: ='Cover Page'!B3 -> الجرائم العامة حسب مناطق وقوعها
B4: Year | C4: =YEAR('Template Data'!B1) -> 2024 | E4: السنة
B5: Police Directorate | C5: الجرائم الجنحوية | D5: الجرائم الجنائية | E5: مديرية الشرطة
C6: Misdemeanor Crimes | D6: Felony Crimes
B7: Middle Amman | E7: وسط عمان
B8: South Amman | E8: جنوب عمان
B9: North Amman | E9: شمال عمان
B10: East Amman | E10: شرق عمان
B11: Balqa | E11: البلقاء
B12: West Balqa | E12: غرب البلقاء
B13: Zarqa | E13: الزرقاء
B14: Al-Russaifa | E14: الرصيفة
B15: Madaba | E15: مادبا
B16: Irbid | E16: إربد
B17: West Irbid | E17: غرب إربد
B18: Al-Ramtha | E18: الرمثا
... B29: Aqaba | E29: العقبة

Sheet Relational DB
A1: Relational Sheet
A2: Measure_Name_Ar | B2: Measure_Name_En | C2: Measure_ID | D2: Unit_EN | E2: Unit_AR | F2: CL_KIND_OF_GENERAL_CRIME_EN_V1 | G2: CL_KIND_OF_GENERAL_CRIME_AR_V1 | H2: CL_POLICE_DIRECTORATE_EN_V1 | I2: CL_POLICE_DIRECTORATE_ARV1 | J2: Obs_Value | K2: Time_Period_Y | L2: Time_Period_M
A3: اسم المؤشر | B3: Measure Name | C3: رمز المؤشر | D3: Unit | E3: الوحدة | F3: General Kind of Crime | G3: نوع الجريمة العامة | H3: Police Directorate | I3: مديرية الشرطة | J3: قيمة المؤشر | K3: سنة فترة القياس | L3: شهر فترة القياس
A4: الجرائم العامة | B4: General Crimes | C4: M1 | D4: Number | E4: عدد | F4: ='Source Table'!$D$6 -> Felony Crimes | G4: ='Source Table'!$D$5 -> الجرائم الجنائية | H4: ='Source Table'!$B$7 -> Middle Amman | I4: ='Source Table'!$E$7 -> وسط عمان | J4: 603 | K4: 2023
A5: الجرائم العامة | B5: General Crimes | C5: M1 | D5: Number | E5: عدد | F5: ='Source Table'!$D$6 -> Felony Crimes | G5: ='Source Table'!$D$5 -> الجرائم الجنائية | H5: ='Source Table'!$B$8 -> South Amman | I5: ='Source Table'!$E$8 -> جنوب عمان | J5: 450 | K5: 2023
A6: الجرائم العامة | B6: General Crimes | C6: M1 | D6: Number | E6: عدد | F6: ='Source Table'!$D$6 -> Felony Crimes | G6: ='Source Table'!$D$5 -> الجرائم الجنائية | H6: ='Source Table'!$B$9 -> North Amman | I6: ='Source Table'!$E$9 -> شمال عمان | J6: 477 | K6: 2023
A7: الجرائم العامة | B7: General Crimes | C7: M1 | D7: Number | E7: عدد | F7: ='Source Table'!$D$6 -> Felony Crimes | G7: ='Source Table'!$D$5 -> الجرائم الجنائية | H7: ='Source Table'!$B$10 -> East Amman | I7: ='Source Table'!$E$10 -> شرق عمان | J7: 619 | K7: 2023
A8: الجرائم العامة | B8: General Crimes | C8: M1 | D8: Number | E8: عدد | F8: ='Source Table'!$D$6 -> Felony Crimes | G8: ='Source Table'!$D$5 -> الجرائم الجنائية | H8: ='Source Table'!$B$11 -> Balqa | I8: ='Source Table'!$E$11 -> البلقاء | J8: 302 | K8: 2023
A9: الجرائم العامة | B9: General Crimes | C9: M1 | D9: Number | E9: عدد | F9: ='Source Table'!$D$6 -> Felony Crimes | G9: ='Source Table'!$D$5 -> الجرائم الجنائية | H9: ='Source Table'!$B$12 -> West Balqa | I9: ='Source Table'!$E$12 -> غرب البلقاء | J9: 124 | K9: 2023
A10: الجرائم العامة | B10: General Crimes | C10: M1 | D10: Number | E10: عدد | F10: ='Source Table'!$D$6 -> Felony Crimes | G10: ='Source Table'!$D$5 -> الجرائم الجنائية | H10: ='Source Table'!$B$13 -> Zarqa | I10: ='Source Table'!$E$13 -> الزرقاء | J10: 489 | K10: 2023
A11: الجرائم العامة | B11: General Crimes | C11: M1 | D11: Number | E11: عدد | F11: ='Source Table'!$D$6 -> Felony Crimes | G11: ='Source Table'!$D$5 -> الجرائم الجنائية | H11: ='Source Table'!$B$14 -> Al-Russaifa | I11: ='Source Table'!$E$14 -> الرصيفة | J11: 179 | K11: 2023
A12: الجرائم العامة | B12: General Crimes | C12: M1 | D12: Number | E12: عدد | F12: ='Source Table'!$D$6 -> Felony Crimes | G12: ='Source Table'!$D$5 -> الجرائم الجنائية | H12: ='Source Table'!$B$15 -> Madaba | I12: ='Source Table'!$E$15 -> مادبا | J12: 137 | K12: 2023
A13: الجرائم العامة | B13: General Crimes | C13: M1 | D13: Number | E13: عدد | F13: ='Source Table'!$D$6 -> Felony Crimes | G13: ='Source Table'!$D$5 -> الجرائم الجنائية | H13: ='Source Table'!$B$16 -> Irbid | I13: ='Source Table'!$E$16 -> إربد | J13: 737 | K13: 2023
A14: الجرائم العامة | B14: General Crimes | C14: M1 | D14: Number | E14: عدد | F14: ='Source Table'!$D$6 -> Felony Crimes | G14: ='Source Table'!$D$5 -> الجرائم الجنائية | H14: ='Source Table'!$B$17 -> West Irbid | I14: ='Source Table'!$E$17 -> غرب إربد | J14: 168 | K14: 2023
A15: الجرائم العامة | B15: General Crimes | C15: M1 | D15: Number | E15: عدد | F15: ='Source Table'!$D$6 -> Felony Crimes | G15: ='Source Table'!$D$5 -> الجرائم الجنائية | H15: ='Source Table'!$B$18 -> Al-Ramtha | I15: ='Source Table'!$E$18 -> الرمثا | J15: 63 | K15: 2023
A16: الجرائم العامة | B16: General Crimes | C16: M1 | D16: Number | E16: عدد | F16: ='Source Table'!$D$6 -> Felony Crimes | G16: ='Source Table'!$D$5 -> الجرائم الجنائية | H16: ='Source Table'!$B$19 -> Mafraq | I16: ='Source Table'!$E$19 -> المفرق | J16: 210 | K16: 2023
A17: الجرائم العامة | B17: General Crimes | C17: M1 | D17: Number | E17: عدد | F17: ='Source Table'!$D$6 -> Felony Crimes | G17: ='Source Table'!$D$5 -> الجرائم الجنائية | H17: ='Source Table'!$B$20 -> North Bedouin | I17: ='Source Table'!$E$20 -> الباديةالشمالية | J17: 96 | K17: 2023
A18: الجرائم العامة | B18: General Crimes | C18: M1 | D18: Number | E18: عدد | F18: ='Source Table'!$D$6 -> Felony Crimes | G18: ='Source Table'!$D$5 -> الجرائم الجنائية | H18: ='Source Table'!$B$21 -> Middle Bedouin | I18: ='Source Table'!$E$21 -> البادية الوسطى | J18: 138 | K18: 2023
A19: الجرائم العامة | B19: General Crimes | C19: M1 | D19: Number | E19: عدد | F19: ='Source Table'!$D$6 -> Felony Crimes | G19: ='Source Table'!$D$5 -> الجرائم الجنائية | H19: ='Source Table'!$B$22 -> South Bedouin | I19: ='Source Table'!$E$22 -> البادية الجنوبية | J19: 14 | K19: 2023
A20: الجرائم العامة | B20: General Crimes | C20: M1 | D20: Number | E20: عدد | F20: ='Source Table'!$D$6 -> Felony Crimes | G20: ='Source Table'!$D$5 -> الجرائم الجنائية | H20: ='Source Table'!$B$23 -> Jarash | I20: ='Source Table'!$E$23 -> جرش | J20: 136 | K20: 2023
A21: الجرائم العامة | B21: General Crimes | C21: M1 | D21: Number | E21: عدد | F21: ='Source Table'!$D$6 -> Felony Crimes | G21: ='Source Table'!$D$5 -> الجرائم الجنائية | H21: ='Source Table'!$B$24 -> Ajloun | I21: ='Source Table'!$E$24 -> عجلون | J21: 86 | K21: 2023
A22: الجرائم العامة | B22: General Crimes | C22: M1 | D22: Number | E22: عدد | F22: ='Source Table'!$D$6 -> Felony Crimes | G22: ='Source Table'!$D$5 -> الجرائم الجنائية | H22: ='Source Table'!$B$25 -> Karak | I22: ='Source Table'!$E$25 -> الكرك | J22: 235 | K22: 2023
A23: الجرائم العامة | B23: General Crimes | C23: M1 | D23: Number | E23: عدد | F23: ='Source Table'!$D$6 -> Felony Crimes | G23: ='Source Table'!$D$5 -> الجرائم الجنائية | H23: ='Source Table'!$B$26 -> Tafiela | I23: ='Source Table'!$E$26 -> الطفيلة | J23: 51 | K23: 2023
A24: الجرائم العامة | B24: General Crimes | C24: M1 | D24: Number | E24: عدد | F24: ='Source Table'!$D$6 -> Felony Crimes | G24: ='Source Table'!$D$5 -> الجرائم الجنائية | H24: ='Source Table'!$B$27 -> Ma'an | I24: ='Source Table'!$E$27 -> معان | J24: 95 | K24: 2023
A25: الجرائم العامة | B25: General Crimes | C25: M1 | D25: Number | E25: عدد | F25: ='Source Table'!$D$6 -> Felony Crimes | G25: ='Source Table'!$D$5 -> الجرائم الجنائية | H25: ='Source Table'!$B$28 -> West ofMa'an | I25: ='Source Table'!$E$28 -> غرب معان | J25: 17 | K25: 2023
A26: الجرائم العامة | B26: General Crimes | C26: M1 | D26: Number | E26: عدد | F26: ='Source Table'!$D$6 -> Felony Crimes | G26: ='Source Table'!$D$5 -> الجرائم الجنائية | H26: ='Source Table'!$B$29 -> Aqaba | I26: ='Source Table'!$E$29 -> العقبة | J26: 153 | K26: 2023
A27: الجرائم العامة | B27: General Crimes | C27: M1 | D27: Number | E27: عدد | F27: ='Source Table'!$C$6 -> Misdemeanor Crimes | G27: ='Source Table'!$C$5 -> الجرائم الجنحوية | H27: ='Source Table'!$B$7 -> Middle Amman | I27: ='Source Table'!$E$7 -> وسط عمان | J27: 1907 | K27: 2023
A28: الجرائم العامة | B28: General Crimes | C28: M1 | D28: Number | E28: عدد | F28: ='Source Table'!$C$6 -> Misdemeanor Crimes | G28: ='Source Table'!$C$5 -> الجرائم الجنحوية | H28: ='Source Table'!$B$8 -> South Amman | I28: ='Source Table'!$E$8 -> جنوب عمان | J28: 1908 | K28: 2023
A29: الجرائم العامة | B29: General Crimes | C29: M1 | D29: Number | E29: عدد | F29: ='Source Table'!$C$6 -> Misdemeanor Crimes | G29: ='Source Table'!$C$5 -> الجرائم الجنحوية | H29: ='Source Table'!$B$9 -> North Amman | I29: ='Source Table'!$E$9 -> شمال عمان | J29: 1955 | K29: 2023
A30: الجرائم العامة | B30: General Crimes | C30: M1 | D30: Number | E30: عدد | F30: ='Source Table'!$C$6 -> Misdemeanor Crimes | G30: ='Source Table'!$C$5 -> الجرائم الجنحوية | H30: ='Source Table'!$B$10 -> East Amman | I30: ='Source Table'!$E$10 -> شرق عمان | J30: 1633 | K30: 2023
A31: الجرائم العامة | B31: General Crimes | C31: M1 | D31: Number | E31: عدد | F31: ='Source Table'!$C$6 -> Misdemeanor Crimes | G31: ='Source Table'!$C$5 -> الجرائم الجنحوية | H31: ='Source Table'!$B$11 -> Balqa | I31: ='Source Table'!$E$11 -> البلقاء | J31: 765 | K31: 2023
A32: الجرائم العامة | B32: General Crimes | C32: M1 | D32: Number | E32: عدد | F32: ='Source Table'!$C$6 -> Misdemeanor Crimes | G32: ='Source Table'!$C$5 -> الجرائم الجنحوية | H32: ='Source Table'!$B$12 -> West Balqa | I32: ='Source Table'!$E$12 -> غرب البلقاء | J32: 292 | K32: 2023
A33: الجرائم العامة | B33: General Crimes | C33: M1 | D33: Number | E33: عدد | F33: ='Source Table'!$C$6 -> Misdemeanor Crimes | G33: ='Source Table'!$C$5 -> الجرائم الجنحوية | H33: ='Source Table'!$B$13 -> Zarqa | I33: ='Source Table'!$E$13 -> الزرقاء | J33: 1328 | K33: 2023
A34: الجرائم العامة | B34: General Crimes | C34: M1 | D34: Number | E34: عدد | F34: ='Source Table'!$C$6 -> Misdemeanor Crimes | G34: ='Source Table'!$C$5 -> الجرائم الجنحوية | H34: ='Source Table'!$B$14 -> Al-Russaifa | I34: ='Source Table'!$E$14 -> الرصيفة | J34: 570 | K34: 2023
A35: الجرائم العامة | B35: General Crimes | C35: M1 | D35: Number | E35: عدد | F35: ='Source Table'!$C$6 -> Misdemeanor Crimes | G35: ='Source Table'!$C$5 -> الجرائم الجنحوية | H35: ='Source Table'!$B$15 -> Madaba | I35: ='Source Table'!$E$15 -> مادبا | J35: 370 | K35: 2023
A36: الجرائم العامة | B36: General Crimes | C36: M1 | D36: Number | E36: عدد | F36: ='Source Table'!$C$6 -> Misdemeanor Crimes | G36: ='Source Table'!$C$5 -> الجرائم الجنحوية | H36: ='Source Table'!$B$16 -> Irbid | I36: ='Source Table'!$E$16 -> إربد | J36: 2635 | K36: 2023
A37: الجرائم العامة | B37: General Crimes | C37: M1 | D37: Number | E37: عدد | F37: ='Source Table'!$C$6 -> Misdemeanor Crimes | G37: ='Source Table'!$C$5 -> الجرائم الجنحوية | H37: ='Source Table'!$B$17 -> West Irbid | I37: ='Source Table'!$E$17 -> غرب إربد | J37: 346 | K37: 2023
A38: الجرائم العامة | B38: General Crimes | C38: M1 | D38: Number | E38: عدد | F38: ='Source Table'!$C$6 -> Misdemeanor Crimes | G38: ='Source Table'!$C$5 -> الجرائم الجنحوية | H38: ='Source Table'!$B$18 -> Al-Ramtha | I38: ='Source Table'!$E$18 -> الرمثا | J38: 297 | K38: 2023
A39: الجرائم العامة | B39: General Crimes | C39: M1 | D39: Number | E39: عدد | F39: ='Source Table'!$C$6 -> Misdemeanor Crimes | G39: ='Source Table'!$C$5 -> الجرائم الجنحوية | H39: ='Source Table'!$B$19 -> Mafraq | I39: ='Source Table'!$E$19 -> المفرق | J39: 556 | K39: 2023
A40: الجرائم العامة | B40: General Crimes | C40: M1 | D40: Number | E40: عدد | F40: ='Source Table'!$C$6 -> Misdemeanor Crimes | G40: ='Source Table'!$C$5 -> الجرائم الجنحوية | H40: ='Source Table'!$B$20 -> North Bedouin | I40: ='Source Table'!$E$20 -> الباديةالشمالية | J40: 253 | K40: 2023
...

Sheet Template Data
A1: Date | B1: =DATE(B2,B3,1) -> 45292
A2: Year | B2: 2024
A3: Month | B3: 1
A4: Measure_Name_Ar | B4: Measure_Name_En | C4: Measure_ID | D4: Unit_EN | E4: Unit_AR | F4: CL_KIND_OF_GENERAL_CRIME_EN_V1 | G4: CL_KIND_OF_GENERAL_CRIME_AR_V1 | H4: CL_POLICE_DIRECTORATE_EN_V1 | I4: CL_POLICE_DIRECTORATE_ARV1 | J4: Obs_Value | K4: Time_Period_Y | L4: Time_Period_M
A5: اسم المؤشر | B5: Measure Name | C5: رمز المؤشر | D5: Unit | E5: الوحدة | F5: General Kind of Crime | G5: نوع الجريمة العامة | H5: Police Directorate | I5: مديرية الشرطة | J5: قيمة المؤشر | K5: سنة فترة القياس | L5: شهر فترة القياس

Sheet Help
A2: Step 1: Cover Page | C2: الخطوة 1: Cover Page
A4: Update the template information, to ensure that any meta-information about the template, such as the title, version, and description, is accurate and up-to-date. | C4: قم بتحديث معلومات القالب للتأكد من أن أي معلومات وصفية حول القالب، مثل العنوان والإصدار والوصف، دقيقة ومحدثة.
A6: Step 2: Source Table | C6: الخطوة 2: Source Table
A8: Design your template, ensuring that the time period is mapped correctly to the date information in rows 1-3 of the Template Data Sheet. | C8: قم بتصميم القالب الخاص بك، مع التأكد من أن فترة الوقت مرتبطة بشكل صحيح مع معلومات التاريخ في الصفوف 1-3 في ورقة Template Data.
A10: Step 3: Relational Sheet | C10: الخطوة 3: Relational Sheet
A12: Unpivot the data in the source table into a flat format. Follow these guidelines: | C12: قم بتحويل البيانات في جدول المصدر إلى تنسيق مسطح. اتبع هذه الإرشادات:
A13: 1. Blue Columns: Do not change the names of the blue columns. Update the data as per the current template. | C13: 1. الأعمدة الزرقاء: لا تقم بتغيير أسماء الأعمدة الزرقاء. قم بتحديث البيانات وفقًا للقالب الحالي.
A14: 2. Code Lists: Use the naming convention CL_XXX_EN_V# for code lists, where XXX is the name, and V# is the version, conforming with the definitions in the data dictionary. | C14: 2. قوائم الرموز: استخدم قاعدة التسمية CL_XXX_EN_V# لقوائم الرموز، حيث أن XXX هو الاسم و V# هو الإصدار، وفقًا للتعريفات في قاموس البيانات.
A15: 3. Code List Values: Ensure the code list values match the definitions in the data dictionary. | C15: 3. قيم قائمة الرموز: تأكد من أن قيم قائمة الرموز تتوافق مع التعريفات في قاموس البيانات.
A16: 4. Time_Period_M: Leave empty if the data frequency is yearly. | C16: 4. Time_Period_M: اتركها فارغة إذا كانت دورية البيانات سنوية.
A17: 5. Time_Period_M Format: Use one of these formats: | C17: 5. تنسيق Time_Period_M: استخدم أحد التنسيقات التالية:
A18: Numeric: (1, 2, 3, ..., 12) for months. | C18: رقمي: (1، 2، 3، ...، 12) للأشهر.
... A38: Protect the entire workbook to prevent unauthorized or accidental changes to the structure of the file. | C38: قم بحماية الكتاب بأكمله لمنع التغييرات غير المصرح بها أو غير المقصودة على هيكل الملف.

Sheet Sheet1
A1: الجرائم العامة | B1: General Crimes | C1: M1 | D1: Number | E1: عدد | F1: ='Source Table'!$D$6 -> Felony Crimes | G1: ='Source Table'!$D$5 -> الجرائم الجنائية | H1: ='Source Table'!$B$7 -> Middle Amman | I1: ='Source Table'!$E$7 -> وسط عمان
A2: الجرائم العامة | B2: General Crimes | C2: M1 | D2: Number | E2: عدد | F2: ='Source Table'!$D$6 -> Felony Crimes | G2: ='Source Table'!$D$5 -> الجرائم الجنائية | H2: ='Source Table'!$B$8 -> South Amman | I2: ='Source Table'!$E$8 -> جنوب عمان
A3: الجرائم العامة | B3: General Crimes | C3: M1 | D3: Number | E3: عدد | F3: ='Source Table'!$D$6 -> Felony Crimes | G3: ='Source Table'!$D$5 -> الجرائم الجنائية | H3: ='Source Table'!$B$9 -> North Amman | I3: ='Source Table'!$E$9 -> شمال عمان
A4: الجرائم العامة | B4: General Crimes | C4: M1 | D4: Number | E4: عدد | F4: ='Source Table'!$D$6 -> Felony Crimes | G4: ='Source Table'!$D$5 -> الجرائم الجنائية | H4: ='Source Table'!$B$10 -> East Amman | I4: ='Source Table'!$E$10 -> شرق عمان
A5: الجرائم العامة | B5: General Crimes | C5: M1 | D5: Number | E5: عدد | F5: ='Source Table'!$D$6 -> Felony Crimes | G5: ='Source Table'!$D$5 -> الجرائم الجنائية | H5: ='Source Table'!$B$11 -> Balqa | I5: ='Source Table'!$E$11 -> البلقاء
A6: الجرائم العامة | B6: General Crimes | C6: M1 | D6: Number | E6: عدد | F6: ='Source Table'!$D$6 -> Felony Crimes | G6: ='Source Table'!$D$5 -> الجرائم الجنائية | H6: ='Source Table'!$B$12 -> West Balqa | I6: ='Source Table'!$E$12 -> غرب البلقاء
A7: الجرائم العامة | B7: General Crimes | C7: M1 | D7: Number | E7: عدد | F7: ='Source Table'!$D$6 -> Felony Crimes | G7: ='Source Table'!$D$5 -> الجرائم الجنائية | H7: ='Source Table'!$B$13 -> Zarqa | I7: ='Source Table'!$E$13 -> الزرقاء
A8: الجرائم العامة | B8: General Crimes | C8: M1 | D8: Number | E8: عدد | F8: ='Source Table'!$D$6 -> Felony Crimes | G8: ='Source Table'!$D$5 -> الجرائم الجنائية | H8: ='Source Table'!$B$14 -> Al-Russaifa | I8: ='Source Table'!$E$14 -> الرصيفة
A9: الجرائم العامة | B9: General Crimes | C9: M1 | D9: Number | E9: عدد | F9: ='Source Table'!$D$6 -> Felony Crimes | G9: ='Source Table'!$D$5 -> الجرائم الجنائية | H9: ='Source Table'!$B$15 -> Madaba | I9: ='Source Table'!$E$15 -> مادبا
A10: الجرائم العامة | B10: General Crimes | C10: M1 | D10: Number | E10: عدد | F10: ='Source Table'!$D$6 -> Felony Crimes | G10: ='Source Table'!$D$5 -> الجرائم الجنائية | H10: ='Source Table'!$B$16 -> Irbid | I10: ='Source Table'!$E$16 -> إربد
A11: الجرائم العامة | B11: General Crimes | C11: M1 | D11: Number | E11: عدد | F11: ='Source Table'!$D$6 -> Felony Crimes | G11: ='Source Table'!$D$5 -> الجرائم الجنائية | H11: ='Source Table'!$B$17 -> West Irbid | I11: ='Source Table'!$E$17 -> غرب إربد
A12: الجرائم العامة | B12: General Crimes | C12: M1 | D12: Number | E12: عدد | F12: ='Source Table'!$D$6 -> Felony Crimes | G12: ='Source Table'!$D$5 -> الجرائم الجنائية | H12: ='Source Table'!$B$18 -> Al-Ramtha | I12: ='Source Table'!$E$18 -> الرمثا
A13: الجرائم العامة | B13: General Crimes | C13: M1 | D13: Number | E13: عدد | F13: ='Source Table'!$D$6 -> Felony Crimes | G13: ='Source Table'!$D$5 -> الجرائم الجنائية | H13: ='Source Table'!$B$19 -> Mafraq | I13: ='Source Table'!$E$19 -> المفرق
A14: الجرائم العامة | B14: General Crimes | C14: M1 | D14: Number | E14: عدد | F14: ='Source Table'!$D$6 -> Felony Crimes | G14: ='Source Table'!$D$5 -> الجرائم الجنائية | H14: ='Source Table'!$B$20 -> North Bedouin | I14: ='Source Table'!$E$20 -> الباديةالشمالية
A15: الجرائم العامة | B15: General Crimes | C15: M1 | D15: Number | E15: عدد | F15: ='Source Table'!$D$6 -> Felony Crimes | G15: ='Source Table'!$D$5 -> الجرائم الجنائية | H15: ='Source Table'!$B$21 -> Middle Bedouin | I15: ='Source Table'!$E$21 -> البادية الوسطى
A16: الجرائم العامة | B16: General Crimes | C16: M1 | D16: Number | E16: عدد | F16: ='Source Table'!$D$6 -> Felony Crimes | G16: ='Source Table'!$D$5 -> الجرائم الجنائية | H16: ='Source Table'!$B$22 -> South Bedouin | I16: ='Source Table'!$E$22 -> البادية الجنوبية
A17: الجرائم العامة | B17: General Crimes | C17: M1 | D17: Number | E17: عدد | F17: ='Source Table'!$D$6 -> Felony Crimes | G17: ='Source Table'!$D$5 -> الجرائم الجنائية | H17: ='Source Table'!$B$23 -> Jarash | I17: ='Source Table'!$E$23 -> جرش
A18: الجرائم العامة | B18: General Crimes | C18: M1 | D18: Number | E18: عدد | F18: ='Source Table'!$D$6 -> Felony Crimes | G18: ='Source Table'!$D$5 -> الجرائم الجنائية | H18: ='Source Table'!$B$24 -> Ajloun | I18: ='Source Table'!$E$24 -> عجلون
A19: الجرائم العامة | B19: General Crimes | C19: M1 | D19: Number | E19: عدد | F19: ='Source Table'!$D$6 -> Felony Crimes | G19: ='Source Table'!$D$5 -> الجرائم الجنائية | H19: ='Source Table'!$B$25 -> Karak | I19: ='Source Table'!$E$25 -> الكرك
A20: الجرائم العامة | B20: General Crimes | C20: M1 | D20: Number | E20: عدد | F20: ='Source Table'!$D$6 -> Felony Crimes | G20: ='Source Table'!$D$5 -> الجرائم الجنائية | H20: ='Source Table'!$B$26 -> Tafiela | I20: ='Source Table'!$E$26 -> الطفيلة
A21: الجرائم العامة | B21: General Crimes | C21: M1 | D21: Number | E21: عدد | F21: ='Source Table'!$D$6 -> Felony Crimes | G21: ='Source Table'!$D$5 -> الجرائم الجنائية | H21: ='Source Table'!$B$27 -> Ma'an | I21: ='Source Table'!$E$27 -> معان
A22: الجرائم العامة | B22: General Crimes | C22: M1 | D22: Number | E22: عدد | F22: ='Source Table'!$D$6 -> Felony Crimes | G22: ='Source Table'!$D$5 -> الجرائم الجنائية | H22: ='Source Table'!$B$28 -> West ofMa'an | I22: ='Source Table'!$E$28 -> غرب معان
A23: الجرائم العامة | B23: General Crimes | C23: M1 | D23: Number | E23: عدد | F23: ='Source Table'!$D$6 -> Felony Crimes | G23: ='Source Table'!$D$5 -> الجرائم الجنائية | H23: ='Source Table'!$B$29 -> Aqaba | I23: ='Source Table'!$E$29 -> العقبة
A24: الجرائم العامة | B24: General Crimes | C24: M1 | D24: Number | E24: عدد | F24: ='Source Table'!$C$6 -> Misdemeanor Crimes | G24: ='Source Table'!$C$5 -> الجرائم الجنحوية | H24: ='Source Table'!$B$7 -> Middle Amman | I24: ='Source Table'!$E$7 -> وسط عمان
A25: الجرائم العامة | B25: General Crimes | C25: M1 | D25: Number | E25: عدد | F25: ='Source Table'!$C$6 -> Misdemeanor Crimes | G25: ='Source Table'!$C$5 -> الجرائم الجنحوية | H25: ='Source Table'!$B$8 -> South Amman | I25: ='Source Table'!$E$8 -> جنوب عمان
A26: الجرائم العامة | B26: General Crimes | C26: M1 | D26: Number | E26: عدد | F26: ='Source Table'!$C$6 -> Misdemeanor Crimes | G26: ='Source Table'!$C$5 -> الجرائم الجنحوية | H26: ='Source Table'!$B$9 -> North Amman | I26: ='Source Table'!$E$9 -> شمال عمان
A27: الجرائم العامة | B27: General Crimes | C27: M1 | D27: Number | E27: عدد | F27: ='Source Table'!$C$6 -> Misdemeanor Crimes | G27: ='Source Table'!$C$5 -> الجرائم الجنحوية | H27: ='Source Table'!$B$10 -> East Amman | I27: ='Source Table'!$E$10 -> شرق عمان
A28: الجرائم العامة | B28: General Crimes | C28: M1 | D28: Number | E28: عدد | F28: ='Source Table'!$C$6 -> Misdemeanor Crimes | G28: ='Source Table'!$C$5 -> الجرائم الجنحوية | H28: ='Source Table'!$B$11 -> Balqa | I28: ='Source Table'!$E$11 -> البلقاء
A29: الجرائم العامة | B29: General Crimes | C29: M1 | D29: Number | E29: عدد | F29: ='Source Table'!$C$6 -> Misdemeanor Crimes | G29: ='Source Table'!$C$5 -> الجرائم الجنحوية | H29: ='Source Table'!$B$12 -> West Balqa | I29: ='Source Table'!$E$12 -> غرب البلقاء
A30: الجرائم العامة | B30: General Crimes | C30: M1 | D30: Number | E30: عدد | F30: ='Source Table'!$C$6 -> Misdemeanor Crimes | G30: ='Source Table'!$C$5 -> الجرائم الجنحوية | H30: ='Source Table'!$B$13 -> Zarqa | I30: ='Source Table'!$E$13 -> الزرقاء
A31: الجرائم العامة | B31: General Crimes | C31: M1 | D31: Number | E31: عدد | F31: ='Source Table'!$C$6 -> Misdemeanor Crimes | G31: ='Source Table'!$C$5 -> الجرائم الجنحوية | H31: ='Source Table'!$B$14 -> Al-Russaifa | I31: ='Source Table'!$E$14 -> الرصيفة
A32: الجرائم العامة | B32: General Crimes | C32: M1 | D32: Number | E32: عدد | F32: ='Source Table'!$C$6 -> Misdemeanor Crimes | G32: ='Source Table'!$C$5 -> الجرائم الجنحوية | H32: ='Source Table'!$B$15 -> Madaba | I32: ='Source Table'!$E$15 -> مادبا
A33: الجرائم العامة | B33: General Crimes | C33: M1 | D33: Number | E33: عدد | F33: ='Source Table'!$C$6 -> Misdemeanor Crimes | G33: ='Source Table'!$C$5 -> الجرائم الجنحوية | H33: ='Source Table'!$B$16 -> Irbid | I33: ='Source Table'!$E$16 -> إربد
A34: الجرائم العامة | B34: General Crimes | C34: M1 | D34: Number | E34: عدد | F34: ='Source Table'!$C$6 -> Misdemeanor Crimes | G34: ='Source Table'!$C$5 -> الجرائم الجنحوية | H34: ='Source Table'!$B$17 -> West Irbid | I34: ='Source Table'!$E$17 -> غرب إربد
A35: الجرائم العامة | B35: General Crimes | C35: M1 | D35: Number | E35: عدد | F35: ='Source Table'!$C$6 -> Misdemeanor Crimes | G35: ='Source Table'!$C$5 -> الجرائم الجنحوية | H35: ='Source Table'!$B$18 -> Al-Ramtha | I35: ='Source Table'!$E$18 -> الرمثا
A36: الجرائم العامة | B36: General Crimes | C36: M1 | D36: Number | E36: عدد | F36: ='Source Table'!$C$6 -> Misdemeanor Crimes | G36: ='Source Table'!$C$5 -> الجرائم الجنحوية | H36: ='Source Table'!$B$19 -> Mafraq | I36: ='Source Table'!$E$19 -> المفرق
A37: الجرائم العامة | B37: General Crimes | C37: M1 | D37: Number | E37: عدد | F37: ='Source Table'!$C$6 -> Misdemeanor Crimes | G37: ='Source Table'!$C$5 -> الجرائم الجنحوية | H37: ='Source Table'!$B$20 -> North Bedouin | I37: ='Source Table'!$E$20 -> الباديةالشمالية
A38: الجرائم العامة | B38: General Crimes | C38: M1 | D38: Number | E38: عدد | F38: ='Source Table'!$C$6 -> Misdemeanor Crimes | G38: ='Source Table'!$C$5 -> الجرائم الجنحوية | H38: ='Source Table'!$B$21 -> Middle Bedouin | I38: ='Source Table'!$E$21 -> البادية الوسطى
A39: الجرائم العامة | B39: General Crimes | C39: M1 | D39: Number | E39: عدد | F39: ='Source Table'!$C$6 -> Misdemeanor Crimes | G39: ='Source Table'!$C$5 -> الجرائم الجنحوية | H39: ='Source Table'!$B$22 -> South Bedouin | I39: ='Source Table'!$E$22 -> البادية الجنوبية
A40: الجرائم العامة | B40: General Crimes | C40: M1 | D40: Number | E40: عدد | F40: ='Source Table'!$C$6 -> Misdemeanor Crimes | G40: ='Source Table'!$C$5 -> الجرائم الجنحوية | H40: ='Source Table'!$B$23 -> Jarash | I40: ='Source Table'!$E$23 -> جرش
...
