Workbook
Name _Toc175815732: 'Source Table'!$E$5
Name _Toc175815736: 'Source Table'!$B$5

Sheet Cover Page
A1: Code | B1: SYB_17_7
A2: Version | B2: V1
A3: اسم القالب | B3: جرائم المخدرات حسب مناطق وقوعها
A4: Template Name | B4: Drug Crimes by Location of Occurrence
A5: دورية البيانات | B5: سنوي
A6: Data Frequency | B6: Annual
A7: الجهة المصدرية | B7: مديرية الأمن العام
A8: Data Source | B8: Public Security Directorate

Sheet Source Table
B2: ='Cover Page'!B4 -> Drug Crimes by Location of Occurrence
B3: ='Cover Page'!B3 -> جرائم المخدرات حسب مناطق وقوعها
B4: Year | C4: =YEAR('Template Data'!B1) -> 2024 | E4: السنة
B5: Police Directorate | C5: %نسبة المكتشف | D5: العدد | E5: مديرية الشرطة
C6: % Ratio Discoverer | D6: .No
B7: Middle Amman | E7: وسط عمان
B8: South Amman | E8: جنوب عمان
B9: North Amman | E9: شمال عمان
B10: East Amman | E10: شرق عمان
B11: Zarqa | E11: الزرقاء
B12: Balqa | E12: البلقاء
B13: Madaba | E13: مادبا
B14: Al-Russaifa | E14: الرصيفة
B15: West Balqa | E15: غرب البلقاء
B16: Irbid | E16: إربد
B17: West Irbid | E17: غرب إربد
B18: Mafraq | E18: المفرق
... B29: South Bedouin | E29: البادية الجنوبية

Sheet Relational DB
A1: Relational Sheet
A2: Measure_Name_Ar | B2: Measure_Name_En | C2: Measure_ID | D2: Unit_EN | E2: Unit_AR | F2: CL_POLICE_DIRECTORATE_EN_V1 | G2: CL_POLICE_DIRECTORATE_ARV1 | H2: Obs_Value | I2: Time_Period_Y | J2: Time_Period_M
A3: اسم المؤشر | B3: Measure Name | C3: رمز المؤشر | D3: Unit | E3: الوحدة | F3: Police Directorate | G3: مديرية الشرطة | H3: قيمة المؤشر | I3: سنة فترة القياس | J3: شهر فترة القياس
A4: جرائم المخدرات | B4: Drug Crimes | C4: M1 | D4: Number | E4: عدد | F4: ='Source Table'!$B$7 -> Middle Amman | G4: ='Source Table'!$E$7 -> وسط عمان | H4: 2269 | I4: 2023
A5: جرائم المخدرات | B5: Drug Crimes | C5: M1 | D5: Number | E5: عدد | F5: ='Source Table'!$B$8 -> South Amman | G5: ='Source Table'!$E$8 -> جنوب عمان | H5: 2510 | I5: 2023
A6: جرائم المخدرات | B6: Drug Crimes | C6: M1 | D6: Number | E6: عدد | F6: ='Source Table'!$B$9 -> North Amman | G6: ='Source Table'!$E$9 -> شمال عمان | H6: 2106 | I6: 2023
A7: جرائم المخدرات | B7: Drug Crimes | C7: M1 | D7: Number | E7: عدد | F7: ='Source Table'!$B$10 -> East Amman | G7: ='Source Table'!$E$10 -> شرق عمان | H7: 2532 | I7: 2023
A8: جرائم المخدرات | B8: Drug Crimes | C8: M1 | D8: Number | E8: عدد | F8: ='Source Table'!$B$11 -> Zarqa | G8: ='Source Table'!$E$11 -> الزرقاء | H8: 1802 | I8: 2023
A9: جرائم المخدرات | B9: Drug Crimes | C9: M1 | D9: Number | E9: عدد | F9: ='Source Table'!$B$12 -> Balqa | G9: ='Source Table'!$E$12 -> البلقاء | H9: 1127 | I9: 2023
A10: جرائم المخدرات | B10: Drug Crimes | C10: M1 | D10: Number | E10: عدد | F10: ='Source Table'!$B$13 -> Madaba | G10: ='Source Table'!$E$13 -> مادبا | H10: 434 | I10: 2023
A11: جرائم المخدرات | B11: Drug Crimes | C11: M1 | D11: Number | E11: عدد | F11: ='Source Table'!$B$14 -> Al-Russaifa | G11: ='Source Table'!$E$14 -> الرصيفة | H11: 1098 | I11: 2023
A12: جرائم المخدرات | B12: Drug Crimes | C12: M1 | D12: Number | E12: عدد | F12: ='Source Table'!$B$15 -> West Balqa | G12: ='Source Table'!$E$15 -> غرب البلقاء | H12: 430 | I12: 2023
A13: جرائم المخدرات | B13: Drug Crimes | C13: M1 | D13: Number | E13: عدد | F13: ='Source Table'!$B$16 -> Irbid | G13: ='Source Table'!$E$16 -> إربد | H13: 1835 | I13: 2023
A14: جرائم المخدرات | B14: Drug Crimes | C14: M1 | D14: Number | E14: عدد | F14: ='Source Table'!$B$17 -> West Irbid | G14: ='Source Table'!$E$17 -> غرب إربد | H14: 579 | I14: 2023
A15: جرائم المخدرات | B15: Drug Crimes | C15: M1 | D15: Number | E15: عدد | F15: ='Source Table'!$B$18 -> Mafraq | G15: ='Source Table'!$E$18 -> المفرق | H15: 930 | I15: 2023
A16: جرائم المخدرات | B16: Drug Crimes | C16: M1 | D16: Number | E16: عدد | F16: ='Source Table'!$B$19 -> Jarash | G16: ='Source Table'!$E$19 -> جرش | H16: 485 | I16: 2023
A17: جرائم المخدرات | B17: Drug Crimes | C17: M1 | D17: Number | E17: عدد | F17: ='Source Table'!$B$20 -> Ajlun | G17: ='Source Table'!$E$20 -> عجلون | H17: 246 | I17: 2023
A18: جرائم المخدرات | B18: Drug Crimes | C18: M1 | D18: Number | E18: عدد | F18: ='Source Table'!$B$21 -> Al Ramtha | G18: ='Source Table'!$E$21 -> الرمثا | H18: 584 | I18: 2023
A19: جرائم المخدرات | B19: Drug Crimes | C19: M1 | D19: Number | E19: عدد | F19: ='Source Table'!$B$22 -> Karak | G19: ='Source Table'!$E$22 -> الكرك | H19: 685 | I19: 2023
A20: جرائم المخدرات | B20: Drug Crimes | C20: M1 | D20: Number | E20: عدد | F20: ='Source Table'!$B$23 -> Tafiela | G20: ='Source Table'!$E$23 -> الطفيلة | H20: 270 | I20: 2023
A21: جرائم المخدرات | B21: Drug Crimes | C21: M1 | D21: Number | E21: عدد | F21: ='Source Table'!$B$24 -> Maan | G21: ='Source Table'!$E$24 -> معان | H21: 412 | I21: 2023
A22: جرائم المخدرات | B22: Drug Crimes | C22: M1 | D22: Number | E22: عدد | F22: ='Source Table'!$B$25 -> West Maan | G22: ='Source Table'!$E$25 -> غرب معان | H22: 145 | I22: 2023
A23: جرائم المخدرات | B23: Drug Crimes | C23: M1 | D23: Number | E23: عدد | F23: ='Source Table'!$B$26 -> Aqaba | G23: ='Source Table'!$E$26 -> العقبة | H23: 1139 | I23: 2023
A24: جرائم المخدرات | B24: Drug Crimes | C24: M1 | D24: Number | E24: عدد | F24: ='Source Table'!$B$27 -> North Bedouin | G24: ='Source Table'!$E$27 -> البادية الشمالية | H24: 498 | I24: 2023
A25: جرائم المخدرات | B25: Drug Crimes | C25: M1 | D25: Number | E25: عدد | F25: ='Source Table'!$B$28 -> Middle Bedouin | G25: ='Source Table'!$E$28 -> البادية الوسطى | H25: 828 | I25: 2023
A26: جرائم المخدرات | B26: Drug Crimes | C26: M1 | D26: Number | E26: عدد | F26: ='Source Table'!$B$29 -> South Bedouin | G26: ='Source Table'!$E$29 -> البادية الجنوبية | H26: 12 | I26: 2023
A27: جرائم المخدرات | B27: Drug Crimes | C27: M2 | D27: Ratio | E27: نسبة | F27: ='Source Table'!$B$7 -> Middle Amman | G27: ='Source Table'!$E$7 -> وسط عمان | H27: 99.91 | I27: 2023
A28: جرائم المخدرات | B28: Drug Crimes | C28: M2 | D28: Ratio | E28: نسبة | F28: ='Source Table'!$B$8 -> South Amman | G28: ='Source Table'!$E$8 -> جنوب عمان | H28: 99.68 | I28: 2023
A29: جرائم المخدرات | B29: Drug Crimes | C29: M2 | D29: Ratio | E29: نسبة | F29: ='Source Table'!$B$9 -> North Amman | G29: ='Source Table'!$E$9 -> شمال عمان | H29: 99.81 | I29: 2023
A30: جرائم المخدرات | B30: Drug Crimes | C30: M2 | D30: Ratio | E30: نسبة | F30: ='Source Table'!$B$10 -> East Amman | G30: ='Source Table'!$E$10 -> شرق عمان | H30: 99.84 | I30: 2023
A31: جرائم المخدرات | B31: Drug Crimes | C31: M2 | D31: Ratio | E31: نسبة | F31: ='Source Table'!$B$11 -> Zarqa | G31: ='Source Table'!$E$11 -> الزرقاء | H31: 99.83 | I31: 2023
A32: جرائم المخدرات | B32: Drug Crimes | C32: M2 | D32: Ratio | E32: نسبة | F32: ='Source Table'!$B$12 -> Balqa | G32: ='Source Table'!$E$12 -> البلقاء | H32: 99.73 | I32: 2023
A33: جرائم المخدرات | B33: Drug Crimes | C33: M2 | D33: Ratio | E33: نسبة | F33: ='Source Table'!$B$13 -> Madaba | G33: ='Source Table'!$E$13 -> مادبا | H33: 100 | I33: 2023
A34: جرائم المخدرات | B34: Drug Crimes | C34: M2 | D34: Ratio | E34: نسبة | F34: ='Source Table'!$B$14 -> Al-Russaifa | G34: ='Source Table'!$E$14 -> الرصيفة | H34: 99.82 | I34: 2023
A35: جرائم المخدرات | B35: Drug Crimes | C35: M2 | D35: Ratio | E35: نسبة | F35: ='Source Table'!$B$15 -> West Balqa | G35: ='Source Table'!$E$15 -> غرب البلقاء | H35: 99.07 | I35: 2023
A36: جرائم المخدرات | B36: Drug Crimes | C36: M2 | D36: Ratio | E36: نسبة | F36: ='Source Table'!$B$16 -> Irbid | G36: ='Source Table'!$E$16 -> إربد | H36: 99.73 | I36: 2023
A37: جرائم المخدرات | B37: Drug Crimes | C37: M2 | D37: Ratio | E37: نسبة | F37: ='Source Table'!$B$17 -> West Irbid | G37: ='Source Table'!$E$17 -> غرب إربد | H37: 99.83 | I37: 2023
A38: جرائم المخدرات | B38: Drug Crimes | C38: M2 | D38: Ratio | E38: نسبة | F38: ='Source Table'!$B$18 -> Mafraq | G38: ='Source Table'!$E$18 -> المفرق | H38: 99.57 | I38: 2023
A39: جرائم المخدرات | B39: Drug Crimes | C39: M2 | D39: Ratio | E39: نسبة | F39: ='Source Table'!$B$19 -> Jarash | G39: ='Source Table'!$E$19 -> جرش | H39: 100 | I39: 2023
A40: جرائم المخدرات | B40: Drug Crimes | C40: M2 | D40: Ratio | E40: نسبة | F40: ='Source Table'!$B$20 -> Ajlun | G40: ='Source Table'!$E$20 -> عجلون | H40: 99.19 | I40: 2023
...

Sheet Template Data
A1: Date | B1: =DATE(B2,B3,1) -> 45292
A2: Year | B2: 2024
A3: Month | B3: 1
A4: Measure_Name_Ar | B4: Measure_Name_En | C4: Measure_ID | D4: Unit_EN | E4: Unit_AR | F4: CL_POLICE_DIRECTORATE_EN_V1 | G4: CL_POLICE_DIRECTORATE_ARV1 | H4: Obs_Value | I4: Time_Period_Y | J4: Time_Period_M
A5: اسم المؤشر | B5: Measure Name | C5: رمز المؤشر | D5: Unit | E5: الوحدة | F5: Police Directorate | G5: مديرية الشرطة | H5: قيمة المؤشر | I5: سنة فترة القياس | J5: شهر فترة القياس

Sheet Help
A2: Step 1: Cover Page | C2: الخطوة 1: Cover Page
A4: Update the template information, to ensure that any meta-information about the template, such as the title, version, and description, is accurate and up-to-date. | C4: قم بتحديث معلومات القالب للتأكد من أن أي معلومات وصفية حول القالب، مثل العنوان والإصدار والوصف، دقيقة ومحدثة.
A6: Step 2: Source Table | C6: الخطوة 2: Source Table
A8: Design your template, ensuring that the time period is mapped correctly to the date information in rows 1-3 of the Template Data Sheet. | C8: قم بتصميم القالب الخاص بك، مع التأكد من أن فترة الوقت مرتبطة بشكل صحيح مع معلومات التاريخ في الصفوف 1-3 في ورقة Template Data.
A10: Step 3: Relational Sheet | C10: الخطوة 3: Relational Sheet
A12: Unpivot the data in the source table into a flat format. Follow these guidelines: | C12: قم بتحويل البيانات في جدول المصدر إلى تنسيق مسطح. اتبع هذه الإرشادات:
A13: 1. Blue Columns: Do not change the names of the blue columns. Update the data as per the current template. | C13: 1. الأعمدة الزرقاء: لا تقم بتغيير أسماء الأعمدة الزرقاء. قم بتحديث البيانات وفقًا للقالب الحالي.
A14: 2. Code Lists: Use the naming convention CL_XXX_EN_V# for code lists, where XXX is the name, and V# is the version, conforming with the definitions in the data dictionary. | C14: 2. قوائم الرموز: استخدم قاعدة التسمية CL_XXX_EN_V# لقوائم الرموز، حيث أن XXX هو الاسم و V# هو الإصدار، وفقًا للتعريفات في قاموس البيانات.
A15: 3. Code List Values: Ensure the code list values match the definitions in the data dictionary. | C15: 3. قيم قائمة الرموز: تأكد من أن قيم قائمة الرموز تتوافق مع التعريفات في قاموس البيانات.
A16: 4. Time_Period_M: Leave empty if the data frequency is yearly. | C16: 4. Time_Period_M: اتركها فارغة إذا كانت دورية البيانات سنوية.
A17: 5. Time_Period_M Format: Use one of these formats: | C17: 5. تنسيق Time_Period_M: استخدم أحد التنسيقات التالية:
A18: Numeric: (1, 2, 3, ..., 12) for months. | C18: رقمي: (1، 2، 3، ...، 12) للأشهر.
... A38: Protect the entire workbook to prevent unauthorized or accidental changes to the structure of the file. | C38: قم بحماية الكتاب بأكمله لمنع التغييرات غير المصرح بها أو غير المقصودة على هيكل الملف.
